Workbook

Sheet الملخص التنفيذي
A1: درب · تانكي · النموذج المالي الاحترافي
A2: Inflated Points Economy · نقاط مُضخّمة لإحساس بالثراء
A4: 🤍 الكاش باك (الأبيض) | D4: 🩶 الكاش باك (الفضي) | G4: 🟠 الكاش باك (البرتقالي)
A5: =السيناريوهات!C7/السيناريوهات!C6 | D5: =السيناريوهات!C8/السيناريوهات!C6 | G5: =السيناريوهات!C9/السيناريوهات!C6
A6: 0.5% من كل ريال إنفاق | D6: 0.5% + منافع للأعضاء النشطين | G6: 0.5% + منافع VIP
A8: 🎯 المستويات الثلاثة · تفاصيل شاملة
A9: المستوى | B9: الكسب (نقاط/ريال) | C9: الحد الأدنى | D9: الحد الأعلى | E9: إنفاق نموذجي | F9: النقاط/سنة | G9: القيمة بالريال | H9: الكاش باك % | I9: تكلفة درب
A10: 🤍 الأبيض | B10: =السيناريوهات!C7 | C10: 0 | D10: 10000 | E10: 5000 | F10: =E10*B10 | G10: =F10/السيناريوهات!$C$6 | H10: =G10/E10 | I10: =E10*السيناريوهات!$C$10/100
A11: 🩶 الفضي | B11: =السيناريوهات!C8 | C11: 10000 | D11: 30000 | E11: 20000 | F11: =E11*B11 | G11: =F11/السيناريوهات!$C$6 | H11: =G11/E11 | I11: =E11*السيناريوهات!$C$10/100
A12: 🟠 البرتقالي | B12: =السيناريوهات!C9 | C12: 30001 | D12: بلا حد | E12: 50000 | F12: =E12*B12 | G12: =F12/السيناريوهات!$C$6 | H12: =G12/E12 | I12: =E12*السيناريوهات!$C$10/100
A14: 🆚 مقارنة درب مع ساسكو · الميزة التنافسية
A15: المعيار | C15: ساسكو | D15: الأبيض | E15: الفضي | F15: البرتقالي | G15: ميزة درب
A16: نقاط لكل ريال | C16: 0.43 نقطة | D16: 1 نقطة | E16: 1 نقطة | F16: 1 نقطة | G16: 2.3x
A17: قيمة النقطة | C17: 100 = ريال | D17: 200 = ريال | E17: 200 = ريال | F17: 200 = ريال | G17: نقطة = نص هللة
A18: الكاش باك الفعلي | C18: 0.43% | D18: 0.50% | E18: 0.50% | F18: 0.50% | G18: 1.2x
A19: نقاط لـ 100 ريال | C19: 43 نقطة | D19: 100 نقطة | E19: 100 نقطة | F19: 100 نقطة | G19: إحساس بالثراء
A20: سرعة المكافأة | C20: بطيء | D20: سريع | E20: أسرع | F20: الأسرع | G20: انخراط أعلى
A22: 🎯 التوصيات الاستراتيجية
A23: 1. اعتمد النموذج الشفّاف: كل ريال = نقطة · النقطة = نص هللة (200 نقطة = ريال) = 0.5%
A24: 2. ابدأ بـ 3 مستويات (أبيض/فضي/برتقالي) من اليوم الأول
A25: 3. هدية ترحيب 1,000 نقطة = 5 ريال · ترحيب بسيط وواضح
A26: 4. التسويق: 'كل ريال نقطة · أكثر كاش باك من ساسكو'
A27: 5. محطات الامتياز: 50/50 مع تحصيل شهري تلقائي
A28: 6. راجع الأرقام كل 3 أشهر · عدّل في شيت السيناريوهات
A30: درب · إدارة الشراكات · النموذج المالي · 2026

Sheet السيناريوهات
A1: درب · تانكي · لوحة التحكم بالسيناريوهات
A2: ⚡ غيّر القيم في الخلايا الصفراء · كل الشيتات تتحدث تلقائياً
A4: 1️⃣ قيمة النقطة ومعدلات الكسب (النموذج المُضخّم)
A5: # | B5: الإفتراض | C5: القيمة | D5: الوصف | F5: 💡 المؤشر التفاعلي
A6: 1 | B6: قيمة النقطة (نقطة = 1 ريال) | C6: 200 | D6: كم نقطة تساوي 1 ريال عند الاستبدال | F6: =IF(C6<=5000,"🔴 سخي جداً",IF(C6<=10000,"✅ موصى به",IF(C6<=15000,"⚠️ متحفظ","🔴 بخيل جداً")))
A7: 2 | B7: معدل الكسب · المستوى الأبيض (نقطة/ريال) | C7: 1 | D7: عدد النقاط لكل ريال إنفاق | F7: =IF(C7/C6<0.005,"🔴 ضعيف",IF(C7/C6<=0.01,"✅ مثالي",IF(C7/C6<=0.015,"⚠️ سخي","🔴 مكلف جداً")))
A8: 3 | B8: معدل الكسب · المستوى الفضي (نقطة/ريال) | C8: 1 | D8: نقاط أكثر بـ 50% | F8: =IF(C8/C6<0.0075,"⚠️ ضعيف",IF(C8/C6<=0.015,"✅ مناسب","⚠️ سخي"))
A9: 4 | B9: معدل الكسب · المستوى البرتقالي (نقطة/ريال) | C9: 1 | D9: ضعف نقاط الأبيض | F9: =IF(C9/C6<0.01,"⚠️ ضعيف",IF(C9/C6<=0.02,"✅ مناسب",IF(C9/C6<=0.03,"⚠️ سخي","🔴 خسارة")))
A10: 5 | B10: تكلفة النقطة على درب (هللة/ريال) | C10: 0.5 | D10: التكلفة الفعلية على درب | F10: =IF(C10<=0.75,"✅ مستدام",IF(C10<=1.25,"⚠️ مقبول",IF(C10<=1.5,"⚠️ ضغط على الامتياز","🔴 خسارة")))
A11: 6 | B11: سعر اللتر المتوسط (ريال) | C11: 2.33 | D11: متوسط سعر بنزين 91 | F11: =IF(C11>=2,"✅ منطقي","⚠️ تحقق")
A12: 7 | B12: هدية الترحيب (نقطة) | C12: 5000 | D12: نقاط مجانية عند التسجيل | F12: =IF(C12>=5000,"✅ جذاب","⚠️ صغير")
A14: 2️⃣ معايير الترقية بين المستويات (إنفاق سنوي بالريال)
A15: # | B15: الإفتراض | C15: القيمة | D15: الوصف | F15: 💡 المؤشر
A16: 1 | B16: حد الترقية للفضي (إنفاق ريال/سنة) | C16: 3600 | D16: 300 ر/شهر = 3,600 ر/سنة → ترقية للفضي | F16: =IF(C16<=5000,"⚠️ منخفض",IF(C16<=15000,"✅ مناسب","⚠️ مرتفع"))
A17: 2 | B17: حد الترقية للبرتقالي (إنفاق ريال/سنة) | C17: 14400 | D17: 1,200 ر/شهر = 14,400 ر/سنة → ترقية للبرتقالي | F17: =IF(C17<=20000,"⚠️ منخفض",IF(C17<=50000,"✅ مناسب","⚠️ مرتفع"))
A18: 3 | B18: فترة احتساب الإنفاق (شهر) | C18: 12 | D18: احتساب الإنفاق آخر 12 شهر متحرك | F18: =IF(C18<=12,"✅ سنوي","⚠️ طويل")
A19: 4 | B19: فترة سماح بعد التنزيل (يوم) | C19: 30 | D19: فرصة لاستعادة المستوى | F19: =IF(C19<=30,"✅ معقول","⚠️ طويل")
A21: 3️⃣ المحطات وهوامش الربح
A22: #
A23: 1 | B23: عدد محطات التشغيل | C23: 30 | D23: محطات تديرها درب مباشرة | F23: =IF(C23+C24+C25>=150,"✅ منطقي","⚠️ تحقق")
A24: 2 | B24: عدد محطات الاستثمار | C24: 70 | D24: محطات المستثمرين الشركاء
A25: 3 | B25: عدد محطات الامتياز | C25: 73 | D25: محطات الامتياز التجاري
A26: 4 | B26: متوسط هامش التشغيل (هللة/لتر) | C26: 13 | D26: متوسط 5-15 هللة | F26: =IF(C26>=5,"✅ معقول","⚠️ منخفض")
A27: 5 | B27: متوسط هامش الاستثمار (هللة/لتر) | C27: 13 | D27: متوسط 5-15 هللة | F27: =IF(C27>=5,"✅ معقول","⚠️ منخفض")
A28: 6 | B28: متوسط هامش الامتياز (هللة/لتر) | C28: 1.5 | D28: متوسط 0-3 هللة | F28: =IF(C28>=1,"✅ معقول","⚠️ ضيق")
A29: 7 | B29: مساهمة درب في الامتياز (%) | C29: 0.5 | D29: 50% من تكلفة النقاط
A30: 8 | B30: مساهمة صاحب الامتياز (%) | C30: =1-C29 | D30: 50% من تكلفة النقاط | F30: =IF(C29+C30=1,"✅ صحيح","🔴 خطأ المجموع")
A31: 9 | B31: متوسط مبيعات المحطة (لتر/شهر) | C31: 80000 | D31: الاستهلاك الشهري للمحطة | F31: =IF(C31>=50000,"✅ ممتاز",IF(C31>=30000,"⚠️ متوسط","🔴 منخفض"))
A33: 💡 الفلسفة · نموذج شفّاف: كل ريال = نقطة · النقطة = نص هللة (200 نقطة = ريال) = 0.5% · موحّد مع المتاجر · بلا تضخيم
A35: 🆕 الاقتصاد الموسّع — مدخلات
A36: + | B36: سعر لتر الديزل (ريال) | C36: 1.79 | D36: يناير 2026
A37: + | B37: هامش الديزل (هللة/لتر) | C37: 4 | D37: ضعيف جداً
A38: + | B38: كسب الديزل (نقطة/ريال) | C38: 0.5 | D38: كاش باك 0.25% (هامش ضعيف)
A39: + | B39: كسب الشركاء (نقطة/ريال) | C39: 8 | D39: ~4% ممولة من الشريك
A40: + | B40: مساهمة الشريك لدرب (هللة/ريال) | C40: 1 | D40: ما يدفعه الشريك مقابل عملاء درب
A41: + | B41: هدية الترحيب الموصى بها (نقطة) | C41: 1000 | D41: =5 ريال تكلفة فعلية

Sheet كيف يعمل النظام
A1: درب · كيف يعمل تانكي · النقاط مقابل المستويات 📚
A2: الفكرة الأساسية · النقاط للاستبدال · الإنفاق للترقية · شيئان منفصلان تماماً
A4: 💡 المفهوم الأساسي
A5: 💎 النقاط (Points) | F5: 🎯 المستويات (Tiers)
A6: للاستبدال فقط | F6: للحالة والمزايا
A7: ✅ تكتسبها مع كل عملية تعبئة | F7: ✅ تترقى بناءً على الإنفاق السنوي
A8: ✅ تستبدلها بمكافآت من الشركاء | F8: ✅ تمنحك معدل كسب أعلى
A9: ✅ يمكن إهداؤها للعائلة | F9: ✅ تمنحك مزايا حصرية
A10: ❌ تنقص عند الاستبدال | F10: ✅ لا تتأثر باستبدال النقاط
A11: 🎯 ربط مباشر بقيمة الإنفاق | F11: 🎯 الإنفاق يحدد مستواك
A13: 📊 الفرق بين العدّاديْن
A14: المعيار | D14: 💎 رصيد النقاط | G14: 🎯 عدّاد التقدم
A15: الغرض | D15: الاستبدال بمكافآت | G15: تحديد المستوى
A16: متى يزيد؟ | D16: مع كل تعبئة | G16: مع كل تعبئة (إنفاق)
A17: متى ينقص؟ | D17: عند استبدال نقاط | G17: لا ينقص داخل السنة
A18: يتجدد؟ | D18: لا · رصيد متراكم | G18: نعم · كل 12 شهر
A19: يؤثر على المستوى؟ | D19: ❌ لا | G19: ✅ نعم
A20: مثال | D20: 500K نقطة = 50 ريال | G20: 7,200 ر = فضي
A22: 🎬 سيناريو حقيقي · سنة كاملة
A23: الوقت | C23: النشاط | E23: 💎 ما يحدث للنقاط | H23: 🎯 ما يحدث للمستوى
A24: 📅 يناير | C24: تنفق 600 ر هذا الشهر | E24: +60,000 نقطة → الرصيد 60K | H24: +600 ر تقدم → 600/14,400
A25: 📅 فبراير-يونيو | C25: تستمر بنفس المعدل | E25: +360,000 نقطة (المجموع 420K) | H25: التقدم 4,200 ر → 🩶 فضي ✅
A26: 📅 يوليو | C26: تستبدل 400K نقطة بقهوة | E26: ⬇️ الرصيد ينزل إلى 20K | H26: التقدم 5,400 · لا يتأثر ✅
A27: 📅 ديسمبر | C27: الإنفاق السنوي 7,200 ر | E27: كاش باك 1.5% (الفضي) | H27: التقدم 7,200 → 🩶 فضي مستمر
A28: 📅 يناير القادم | C28: بداية سنة جديدة | E28: الرصيد محفوظ · لا ينقص | H28: العدّاد يبدأ من 0 · المستوى محفوظ
A30: 🌟 الرسائل المفتاحية للعميل
A31: 💯 استبدل نقاطك متى تشاء · مستواك لن يتأثر أبداً
A32: 📈 كلما أنفقت أكثر · ارتقيت أعلى · لا علاقة لذلك بنقاطك
A33: 🎁 النقاط هي متعتك · المستوى هو إنجازك · شيئان منفصلان
A34: 🔒 مستواك محفوظ لمدة 12 شهر بعد الترقية · حتى لو قل إنفاقك
A36: درب · كيف يعمل تانكي · 2026

Sheet محاكي العميل
A1: درب · محاكي العميل التفاعلي 🎮
A2: أدخل الإنفاق الشهري في الخلية الصفراء · شوف النقاط (للاستبدال) منفصلة عن المستوى (للحالة)
A4: 📝 أدخل بيانات العميل
A5: 💰 الإنفاق الشهري على الوقود (ريال) → | F5: 600 | H5: ← غيّر القيمة هنا
A7: 🎯 الملخص الفوري
A8: 📅 الإنفاق السنوي | C8: 🎯 المستوى الحالي | E8: 💎 نقاط/سنة | H8: 💰 القيمة المالية
A9: =F5*12 | C9: =IF(F5*12<السيناريوهات!C16,"🤍 الأبيض",IF(F5*12<السيناريوهات!C17,"🩶 الفضي","🟠 البرتقالي")) | E9: =F5*12*IF(C9="🤍 الأبيض",السيناريوهات!C7,IF(C9="🩶 الفضي",السيناريوهات!C8,السيناريوهات!C9)) | H9: =E9/السيناريوهات!C6
A10: إنفاق على الوقود | C10: مستواك بناء على الإنفاق | E10: للاستبدال بمكافآت | H10: قيمة الكاش باك السنوي
A12: 📊 تقدمك للمستوى التالي
A13: 🎯 المستوى التالي → | D13: =IF(C9="🤍 الأبيض","🩶 الفضي",IF(C9="🩶 الفضي","🟠 البرتقالي","✨ أعلى مستوى")) | F13: 💪 الإنفاق المتبقي → | H13: =IF(C9="🤍 الأبيض",MAX(0,السيناريوهات!C16-F5*12),IF(C9="🩶 الفضي",MAX(0,السيناريوهات!C17-F5*12),0))
A14: نسبة التقدم | C14: =IF(C9="🤍 الأبيض",F5*12/السيناريوهات!C16,IF(C9="🩶 الفضي",(F5*12-السيناريوهات!C16)/(السيناريوهات!C17-السيناريوهات!C16),1))
A16: 🔍 الفصل بين النقاط والمستوى
A17: البند | C17: 💎 النقاط (للاستبدال) | G17: 🎯 المستوى (للحالة)
A18: ما يحدث عند الإنفاق | C18: =TEXT(F5*IF(C9="🤍 الأبيض",السيناريوهات!C7,IF(C9="🩶 الفضي",السيناريوهات!C8,السيناريوهات!C9)),"#,##0")&" نقطة تُضاف" | G18: =TEXT(F5,"#,##0")&" ر تضاف للعدّاد"
A19: بعد سنة كاملة | C19: =TEXT(E9,"#,##0")&" نقطة (= "&TEXT(H9,"#,##0")&" ر)" | G19: =TEXT(F5*12,"#,##0")&" ر إنفاق سنوي"
A20: ماذا يحدث عند الاستبدال؟ | C20: تنقص بحسب قيمة المكافأة | G20: لا تتأثر · المستوى محفوظ
A21: بعد سنة (تجديد) | C21: الرصيد يبقى كما هو | G21: العدّاد يبدأ من 0 · المستوى محفوظ 12 شهر
A23: 💡 جرّب · غيّر الإنفاق في F5 وشوف كيف تتغير كل الأرقام · النقاط والمستوى منفصلان تماماً
A25: 🎲 عينات نموذجية لتجريب أنواع العملاء
A26: ملف العميل | C26: إنفاق/شهر | D26: إنفاق/سنة | E26: المستوى | F26: النقاط/سنة | G26: قيمتها (ر) | H26: الكاش باك | I26: الملاحظة
A27: 🚗 سيارة اقتصادية واحدة | C27: 600 | D27: =C27*12 | E27: =IF(D27<السيناريوهات!$C$16,"🤍 أبيض",IF(D27<السيناريوهات!$C$17,"🩶 فضي","🟠 برتقالي")) | F27: =D27*IF(E27="🤍 أبيض",السيناريوهات!$C$7,IF(E27="🩶 فضي",السيناريوهات!$C$8,السيناريوهات!$C$9)) | G27: =F27/السيناريوهات!$C$6 | H27: =G27/D27 | I27: حالتك! · سيارة كورولا أو سنتافي
A28: 🚙 سيارة عادية واحدة | C28: 1000 | D28: =C28*12 | E28: =IF(D28<السيناريوهات!$C$16,"🤍 أبيض",IF(D28<السيناريوهات!$C$17,"🩶 فضي","🟠 برتقالي")) | F28: =D28*IF(E28="🤍 أبيض",السيناريوهات!$C$7,IF(E28="🩶 فضي",السيناريوهات!$C$8,السيناريوهات!$C$9)) | G28: =F28/السيناريوهات!$C$6 | H28: =G28/D28 | I28: سيارة متوسطة · استخدام يومي
A29: 🚕 سيارة أكبر/SUV | C29: 1500 | D29: =C29*12 | E29: =IF(D29<السيناريوهات!$C$16,"🤍 أبيض",IF(D29<السيناريوهات!$C$17,"🩶 فضي","🟠 برتقالي")) | F29: =D29*IF(E29="🤍 أبيض",السيناريوهات!$C$7,IF(E29="🩶 فضي",السيناريوهات!$C$8,السيناريوهات!$C$9)) | G29: =F29/السيناريوهات!$C$6 | H29: =G29/D29 | I29: تاهو/باترول صغير
A30: 🚐 عائلة بسيارتين | C30: 2500 | D30: =C30*12 | E30: =IF(D30<السيناريوهات!$C$16,"🤍 أبيض",IF(D30<السيناريوهات!$C$17,"🩶 فضي","🟠 برتقالي")) | F30: =D30*IF(E30="🤍 أبيض",السيناريوهات!$C$7,IF(E30="🩶 فضي",السيناريوهات!$C$8,السيناريوهات!$C$9)) | G30: =F30/السيناريوهات!$C$6 | H30: =G30/D30 | I30: عائلة نشطة · سيارتين
A31: 🏢 عائلة كبيرة | C31: 4000 | D31: =C31*12 | E31: =IF(D31<السيناريوهات!$C$16,"🤍 أبيض",IF(D31<السيناريوهات!$C$17,"🩶 فضي","🟠 برتقالي")) | F31: =D31*IF(E31="🤍 أبيض",السيناريوهات!$C$7,IF(E31="🩶 فضي",السيناريوهات!$C$8,السيناريوهات!$C$9)) | G31: =F31/السيناريوهات!$C$6 | H31: =G31/D31 | I31: أبو خالد · 3-4 سيارات
A32: 🚚 أسطول صغير | C32: 8000 | D32: =C32*12 | E32: =IF(D32<السيناريوهات!$C$16,"🤍 أبيض",IF(D32<السيناريوهات!$C$17,"🩶 فضي","🟠 برتقالي")) | F32: =D32*IF(E32="🤍 أبيض",السيناريوهات!$C$7,IF(E32="🩶 فضي",السيناريوهات!$C$8,السيناريوهات!$C$9)) | G32: =F32/السيناريوهات!$C$6 | H32: =G32/D32 | I32: شركة صغيرة · 4-5 سيارات
A34: درب · محاكي العميل التفاعلي · النقاط منفصلة عن المستوى · 2026

Sheet خطة التوسع
A1: درب · خطة التوسع التدريجي لتانكي 🚀
A2: من إطلاق الوقود فقط إلى منظومة مكافآت شاملة · 18 شهراً
A4: 📅 المراحل الأربع · تفاصيل كاملة
A5: المرحلة | B5: الفترة | C5: العنوان | D5: الهدف الرئيسي | G5: الحالة | I5: التكلفة المتوقعة
A6: 🟢 | B6: شهر 1-3 | C6: إطلاق الوقود | D6: بناء قاعدة 50K مستخدم بالوقود فقط | G6: ✅ جاهز للإطلاق | I6: 2.3 مليون ر/سنة
A7: 🔵 | B7: شهر 3-6 | C7: تفاوض المستأجرين | D7: توقيع 3-5 عقود + Pilot كافيه واحد | G7: 🟡 تحضير | I7: + تكاليف تكامل
A8: 🟣 | B8: شهر 6-12 | C8: التوسع التدريجي | D8: 5+ أقسام نشطة + 100K مستخدم | G8: 🔵 تنفيذ تدريجي | I8: 3.5 مليون ر/سنة
A9: 🟠 | B9: شهر 12-18 | C9: النضج الكامل | D9: 200K مستخدم + 7+ أقسام + بطاقات مشتركة | G9: 🟠 توسع | I9: 5+ مليون ر/سنة
A11: 📋 الأنشطة التفصيلية لكل مرحلة
A12: المرحلة | B12: الأنشطة الرئيسية | E12: المخرجات المتوقعة | H12: المخاطر والتحديات
A13: 🟢 المرحلة 1 شهر 1-3 إطلاق الوقود | B13: • إطلاق التطبيق رسمياً • حملة تسويقية كبرى • تدريب فريق المحطات • مراقبة وتحسين | E13: • 50,000+ مستخدم • 65% نسبة تنشيط • معدلات 100/150/200 • قاعدة بيانات أولية | H13: • مشاكل تقنية • ضعف التسويق • عدم الاستخدام • شكاوى المحطات
A14: 🔵 المرحلة 2 شهر 3-6 تفاوض المستأجرين | B14: • إعداد حقيبة عرض • اجتماعات مستأجرين • Pilot كافيهات • تطوير التكامل | E14: • 3-5 عقود موقعة • Pilot ناجح للكافيه • APIs جاهزة • نموذج مالي مختبر | H14: • رفض المستأجرين • شروط مالية صعبة • تعقيد تقني • تأخر في التوقيع
A15: 🟣 المرحلة 3 شهر 6-12 التوسع التدريجي | B15: • إطلاق قسم شهرياً • حملات حصرية • لوحات تحكم • توسيع الفريق | E15: • 5+ أقسام نشطة • 100,000+ مستخدم • +25% إنفاق • 1.5M معاملة/شهر | H15: • فشل بعض الأقسام • تعقيد المضاعفات • ضغط على الدعم • شكاوى مستخدمين
A16: 🟠 المرحلة 4 شهر 12-18 النضج الكامل | B16: • حملات موسمية • بطاقات مشتركة • شركاء خارجيون • توسع لكل المحطات | E16: • 200,000+ مستخدم • 7+ أقسام • شركاء سفر/مطاعم • ROI إيجابي مثبت | H16: • زيادة التكاليف • منافسة ساسكو • تشبع السوق • الاحتفاظ بالعملاء
A18: 🗓️ الخط الزمني البصري (Roadmap)
A19: النشاط | B19: Q1 شهر 1-3 | C19: Q2 شهر 4-6 | D19: Q3 شهر 7-9 | E19: Q4 شهر 10-12 | F19: Q5 شهر 13-15 | G19: Q6 شهر 16-18 | H19: الملاحظات الرئيسية
A20: إطلاق الوقود | B20: 🟢🟢🟢 | C20: 🟢🟢 | D20: ✅ | H20: 50K مستخدم Q1 · المنتج الأساسي
A21: التسويق الكبير | B21: 🟢🟢🟢 | C21: 🟢🟢 | D21: 🟢 | E21: 🟢 | F21: 🟡 | G21: 🟡 | H21: حملة إطلاق كبرى ثم متابعة
A22: تفاوض المستأجرين | C22: 🟡🟡 | D22: 🟡🟡🟡 | E22: 🟡🟡 | H22: 5+ عقود بنهاية Q3
A23: Pilot الكافيه | D23: 🟣 Pilot | E23: 🟣🟣 Launch | H23: محطة واحدة كتجربة
A24: إضافة المغسلة | E24: 🟣 Pilot | F24: 🟣🟣 Launch | G24: 🟣 | H24: بعد نجاح الكافيه
A25: إضافة الزيوت/سوبرماركت | F25: 🟣 Pilot | G25: 🟣🟣 Launch | H25: أقسام سهلة الإضافة
A26: حملات موسمية | C26: 🟢 رمضان | D26: 🟢 صيف | E26: 🟢 شتاء | F26: 🟢 رمضان | G26: 🟢 صيف | H26: حملات حصرية كل ربع
A27: بطاقات مشتركة | F27: 🟠 تحضير | G27: 🟠🟠 إطلاق | H27: تعاون مع بنك سعودي
A29: درب · خطة التوسع · 2026

Sheet محرر المستأجرين
A1: درب · محرر المستأجرين · أداة التفاوض والمتابعة 🤝
A2: قاعدة بيانات المستأجرين · بنود التفاوض · النموذج المالي لكل سيناريو
A4: 📋 قاعدة بيانات المستأجرين المحتملين
A5: # | B5: اسم المستأجر | C5: النوع | D5: عدد المحطات | E5: الإيرادات الشهرية المقدّرة (ر) | F5: هامش الربح المقدّر | G5: نموذج التفاوض | H5: مساهمة المستأجر/ريال | I5: حالة التفاوض | J5: تاريخ آخر اجتماع | K5: الموعد القادم | L5: ملاحظات
A6: 1 | B6: سلسلة كافيه (مثال: ستاربكس) | C6: كافيه | D6: 30 | E6: 150000 | F6: 0.65 | G6: مشاركة 50/50 | H6: 1 | I6: لم نتواصل | L6: هدف استراتيجي · حضور قوي
A7: 2 | B7: كافيه محلي (دانكن/تيم هورتنز) | C7: كافيه | D7: 25 | E7: 100000 | F7: 0.55 | G7: مشاركة 70/30 (المستأجر) | H7: 1.5 | I7: لم نتواصل | L7: مرونة أعلى من العالمية
A8: 3 | B8: سلسلة سوبرماركت (مثال: العثيم) | C8: سوبرماركت | D8: 40 | E8: 500000 | F8: 0.2 | G8: مشاركة 30/70 (درب) | H8: 0.5 | I8: لم نتواصل | L8: حجم كبير · هامش منخفض
A9: 4 | B9: مغسلة (مثال: Magic Wash) | C9: مغسلة | D9: 50 | E9: 80000 | F9: 0.7 | G9: المستأجر يدفع 100% | H9: 2 | I9: لم نتواصل | L9: خدمة درب الخاصة
A10: 5 | B10: مطعم سريع (مثال: البيك/كودو) | C10: مطعم | D10: 35 | E10: 200000 | F10: 0.45 | G10: مشاركة 50/50 | H10: 1.5 | I10: لم نتواصل | L10: حركة عالية · فرص ممتازة
A11: 6
A12: 7
A13: 8
A14: 9
A15: 10
A16: 11
A17: 12
A18: 13
A19: 14
A20: 15
A21: 16
A22: 17
... A25: 20
A27: 🤝 نماذج التفاوض الأربعة · أيها يناسب كل مستأجر
A28: النموذج | B28: مساهمة المستأجر | C28: مساهمة درب | D28: مناسب لمن؟ | H28: حجة التفاوض | L28: التقييم
A29: 🟢 المستأجر 100% | B29: 2 هللة/ريال | C29: 0 | D29: هامش عالي (>60%) · المستأجر الذي يحتاج عملاء درب أكثر مما تحتاجه درب · مغاسل/كافيهات صغيرة محلية | H29: العميل يأتيك من تطبيق درب مجاناً · أنت تربح من المبيعات الإضافية · المقابل بسيط: 2 هللة من كل ريال (أقل من 1% من إيرادك) | L29: ⭐⭐⭐⭐⭐ الأفضل لدرب
A30: 🔵 مشاركة 70/30 (المستأجر) | B30: 1.5 هللة/ريال | C30: 0.5 هللة/ريال | D30: هامش متوسط (40-60%) · مستأجر متوسط الحجم · مطاعم متوسطة · سلاسل صغيرة محلية | H30: أنت تتحمل 70% فقط · درب تشارك معك 30% · في المقابل تحصل على بيانات العملاء + تسويق مجاني داخل التطبيق | L30: ⭐⭐⭐⭐ ممتاز
A31: 🟡 مشاركة 50/50 | B31: 1 هللة/ريال | C31: 1 هللة/ريال | D31: هامش متوسط · مستأجر كبير له ثقل تفاوضي · سلاسل عالمية · شركاء استراتيجيون | H31: شراكة عادلة 50/50 · كلانا يستفيد · درب توفر تسويق وقاعدة بيانات · أنت توفر الخدمة والخصومات | L31: ⭐⭐⭐ متوازن
A32: 🟠 مشاركة 30/70 (درب) | B32: 0.5 هللة/ريال | C32: 1.5 هللة/ريال | D32: هامش منخفض (<25%) · سوبرماركت · مستأجر استراتيجي مهم لكن صعب الإقناع · حالات خاصة | H32: درب تتحمل 70% · أنت 30% فقط · هذا لأننا نقدّر هامشك الضعيف · لكنك تساعدنا في تكامل المنظومة | L32: ⭐⭐ مكلف لدرب
A34: 💰 حاسبة الأثر المالي لكل مستأجر
A35: 📝 أدخل بيانات المستأجر
A36: اسم المستأجر | C36: سلسلة كافيه افتراضية | E36: ← اسم الشركة المحتمل
A37: الإيرادات الشهرية المقدّرة (ريال) | C37: 150000 | E37: ← متوسط مبيعاتها داخل محطات درب
A38: هامش الربح المقدّر (%) | C38: 0.65 | E38: ← هامش الربح الإجمالي
A39: مساهمة المستأجر (هللة/ريال) | C39: 1 | E39: ← كم تدفع لدرب من كل ريال
A41: 📊 النتائج المحسوبة تلقائياً
A42: 📅 الإيرادات السنوية | D42: =C37*12 | G42: 💰 الربح السنوي للمستأجر | J42: =D42*C38
A43: 💸 تكلفة النقاط على المستأجر/سنة | D43: =D42*C39/100 | G43: 📊 % من ربح المستأجر | J43: =D43/J42
A44: 📈 الزيادة المتوقعة (15%) | D44: =D42*0.15 | G44: 💎 الربح الإضافي المتوقع | J44: =D44*C38
A45: ✅ صافي العائد للمستأجر | D45: =J44-D43 | G45: 🎯 ROI للمستأجر | J45: =D45/D43
A47: 💡 جرّب · غيّر القيم في الخلايا الصفراء وشوف كيف تتغير النتائج لحظياً · ROI > 100% يعني المستأجر سيوافق بالتأكيد
...

Sheet حاسبة ROI
A1: درب · حاسبة العائد على الاستثمار (ROI) لـ تانكي 💎
A2: هل يستحق برنامج تانكي الاستثمار؟ حساب شامل للعائد على درب
A4: 💸 الاستثمار · التكاليف السنوية على درب
A5: البند | B5: الفئة | C5: السنة 1 | D5: السنة 2 | E5: السنة 3 | F5: السنة 4 | G5: السنة 5 | H5: الإجمالي 5 سنوات | I5: % من الإجمالي
A6: 💻 تطوير التطبيق | B6: استثمار أولي | C6: 800000 | D6: 200000 | E6: 150000 | F6: 150000 | G6: 150000 | H6: =SUM(C6:G6) | I6: =H6/H13
A7: 🤝 شراكة Dsquares | B7: تشغيلي | C7: 1370000 | D7: 850000 | E7: 870000 | F7: 890000 | G7: 920000 | H7: =SUM(C7:G7) | I7: =H7/H13
A8: 📣 التسويق والإعلانات | B8: تشغيلي | C8: 1500000 | D8: 1200000 | E8: 1000000 | F8: 1000000 | G8: 1000000 | H8: =SUM(C8:G8) | I8: =H8/H13
A9: 👥 فريق الولاء | B9: تشغيلي | C9: 2780000 | D9: 3500000 | E9: 4000000 | F9: 4500000 | G9: 5000000 | H9: =SUM(C9:G9) | I9: =H9/H13
A10: 🎁 كلفة النقاط للعملاء | B10: تشغيلي | C10: 2270000 | D10: 2680000 | E10: 3100000 | F10: 3520000 | G10: 3930000 | H10: =SUM(C10:G10) | I10: =H10/H13
A11: 🛠️ التكامل مع المستأجرين | B11: تشغيلي | C11: 0 | D11: 500000 | E11: 750000 | F11: 1000000 | G11: 1200000 | H11: =SUM(C11:G11) | I11: =H11/H13
A12: 🔧 الصيانة والدعم | B12: تشغيلي | C12: 200000 | D12: 400000 | E12: 600000 | F12: 800000 | G12: 1000000 | H12: =SUM(C12:G12) | I12: =H12/H13
A13: 📊 إجمالي التكاليف | C13: =SUM(C6:C12) | D13: =SUM(D6:D12) | E13: =SUM(E6:E12) | F13: =SUM(F6:F12) | G13: =SUM(G6:G12) | H13: =SUM(C13:G13) | I13: 100%
A15: 💰 العائد · الإيرادات الإضافية المتوقعة
A16: مصدر العائد | B16: الفئة | C16: السنة 1 | D16: السنة 2 | E16: السنة 3 | F16: السنة 4 | G16: السنة 5 | H16: الإجمالي | I16: % من الإجمالي
A17: ⛽ زيادة مبيعات الوقود (+8%) | B17: تشغيلي | C17: 8000000 | D17: 12000000 | E17: 16000000 | F17: 20000000 | G17: 24000000 | H17: =SUM(C17:G17) | I17: =H17/H23
A18: 🤝 عمولة من المستأجرين | B18: تشغيلي | C18: 0 | D18: 1200000 | E18: 2500000 | F18: 4000000 | G18: 6000000 | H18: =SUM(C18:G18) | I18: =H18/H23
A19: 🎯 جذب عملاء جدد | B19: تشغيلي | C19: 1500000 | D19: 3000000 | E19: 4500000 | F19: 6000000 | G19: 7500000 | H19: =SUM(C19:G19) | I19: =H19/H23
A20: 📊 توفير في التسويق التقليدي | B20: توفير | C20: 800000 | D20: 1500000 | E20: 2000000 | F20: 2500000 | G20: 3000000 | H20: =SUM(C20:G20) | I20: =H20/H23
A21: 🚀 نمو المحطات (انتشار العلامة) | B21: استراتيجي | C21: 500000 | D21: 1500000 | E21: 3000000 | F21: 5000000 | G21: 8000000 | H21: =SUM(C21:G21) | I21: =H21/H23
A22: 💎 بيع البيانات والتحليلات | B22: إضافي | C22: 0 | D22: 200000 | E22: 500000 | F22: 1000000 | G22: 1500000 | H22: =SUM(C22:G22) | I22: =H22/H23
A23: 📊 إجمالي الإيرادات | C23: =SUM(C17:C22) | D23: =SUM(D17:D22) | E23: =SUM(E17:E22) | F23: =SUM(F17:F22) | G23: =SUM(G17:G22) | H23: =SUM(C23:G23) | I23: 100%
A25: 📈 تحليل ROI السنوي
A26: البند | B26: الفئة | C26: السنة 1 | D26: السنة 2 | E26: السنة 3 | F26: السنة 4 | G26: السنة 5 | H26: الإجمالي | I26: النسبة
A27: 💰 إجمالي الإيرادات | C27: =C23 | D27: =D23 | E27: =E23 | F27: =F23 | G27: =G23 | H27: =SUM(C27:G27) | I27: إيرادات
A28: 💸 إجمالي التكاليف | C28: =C13 | D28: =D13 | E28: =E13 | F28: =F13 | G28: =G13 | H28: =SUM(C28:G28) | I28: تكاليف
A29: 💎 صافي الربح | C29: =C27-C28 | D29: =D27-D28 | E29: =E27-E28 | F29: =F27-F28 | G29: =G27-G28 | H29: =SUM(C29:G29) | I29: ربح
A30: 🎯 ROI % | C30: =IFERROR(C29/C28, 0) | D30: =IFERROR(D29/D28, 0) | E30: =IFERROR(E29/E28, 0) | F30: =IFERROR(F29/F28, 0) | G30: =IFERROR(G29/G28, 0) | H30: =H29/H28 | I30: ROI
A32: ⚖️ نقطة التعادل والتقييم النهائي
A33: 🎯 ROI الإجمالي (5 سنوات) | C33: 💰 صافي الربح (5 سنوات) | F33: ⚖️ نقطة التعادل | I33: ✅ التوصية
A34: =H30 | C34: =H29 | F34: =IF(C29>=0,"السنة 1",IF(SUM(C29:D29)>=0,"السنة 2",IF(SUM(C29:E29)>=0,"السنة 3",IF(SUM(C29:F29)>=0,"السنة 4",IF(SUM(C29:G29)>=0,"السنة 5","بعد 5 سنوات"))))) | I34: =IF(H30>1,"⭐ مشروع ممتاز",IF(H30>0.5,"✅ مربح",IF(H30>0,"🟡 مقبول","🔴 إعادة نظر")))
A36: 📝 ملاحظات وافتراضات
A37: 💡 زيادة مبيعات الوقود +8% بناءً على دراسات عالمية لبرامج الولاء (شل · BP · Caltex)
A38: 💡 تكلفة فريق الولاء تشمل: لويالتي ليد + 3 مطورين + PM + 2 شراكات + محلل بيانات
A39: 💡 عمولة المستأجرين تبدأ من السنة 2 (مع إطلاق المرحلة 2 من خطة التوسع)
A40: 💡 توفير التسويق التقليدي: انتقال 30% من الميزانية للقنوات الرقمية بفعالية أعلى
A41: 💡 جذب عملاء جدد: 5% من عملاء المنافسين خلال 5 سنوات (تحفظي)
A42: 💡 الأرقام لا تشمل القيمة الاستراتيجية غير المباشرة (تحسين العلامة التجارية، البيانات الكبيرة، إلخ)
A44: درب · حاسبة ROI · 2026

Sheet مقارنة السيناريوهات
A1: درب · مقارنة 6 سيناريوهات جنباً إلى جنب 📊
A2: السيناريو الحالي يعكس قيم شيت السيناريوهات · باقي السيناريوهات ثابتة للمقارنة
A4: 🆚 جدول المقارنة الشامل
A5: المعيار | B5: 🔴 ساسكو | C5: 🟢 محافظ | D5: ⭐ الحالي | E5: 🟢 معتدل | F5: 🟡 جذاب | G5: 🔴 سخي | H5: 💡 التوصية
A6: قيمة النقطة | B6: 100 | C6: 20000 | D6: =السيناريوهات!C6 | E6: 10000 | F6: 10000 | G6: 10000 | H6: =IF(D6=10000,"✅ موصى به",IF(D6<10000,"🟡 سخي",IF(D6<=20000,"⚠️ متحفظ","🔴 بخيل")))
A7: معدل كسب الأبيض | B7: 0.43 | C7: 50 | D7: =السيناريوهات!C7 | E7: 100 | F7: 150 | G7: 200 | H7: =IF(D7<75,"⚠️ منخفض",IF(D7<=125,"✅ مثالي",IF(D7<=175,"⚠️ مرتفع","🔴 جداً مرتفع")))
A8: معدل كسب الفضي | B8: 0.43 | C8: 75 | D8: =السيناريوهات!C8 | E8: 150 | F8: 200 | G8: 250 | H8: =IF(D8<125,"⚠️ منخفض",IF(D8<=175,"✅ مثالي","⚠️ مرتفع"))
A9: معدل كسب البرتقالي | B9: 0.43 | C9: 100 | D9: =السيناريوهات!C9 | E9: 200 | F9: 250 | G9: 300 | H9: =IF(D9<175,"⚠️ منخفض",IF(D9<=225,"✅ مثالي","⚠️ مرتفع"))
A10: كاش باك الأبيض % | B10: 0.0043 | C10: 0.0025 | D10: =السيناريوهات!C7/السيناريوهات!C6 | E10: 0.01 | F10: 0.015 | G10: 0.02 | H10: =IF(D10<0.005,"🔴 ضعيف",IF(D10<=0.012,"✅ مثالي",IF(D10<=0.018,"⚠️ سخي","🔴 مكلف")))
A11: كاش باك الفضي % | B11: 0.0043 | C11: 0.00375 | D11: =السيناريوهات!C8/السيناريوهات!C6 | E11: 0.015 | F11: 0.02 | G11: 0.025 | H11: =IF(D11<0.01,"⚠️ ضعيف",IF(D11<=0.018,"✅ مثالي","⚠️ سخي"))
A12: كاش باك البرتقالي % | B12: 0.0043 | C12: 0.005 | D12: =السيناريوهات!C9/السيناريوهات!C6 | E12: 0.02 | F12: 0.025 | G12: 0.03 | H12: =IF(D12<0.015,"⚠️ ضعيف",IF(D12<=0.025,"✅ مثالي","⚠️ سخي"))
A13: تكلفة درب (هللة/ريال) | B13: 0.43 | C13: 0.5 | D13: =السيناريوهات!C10 | E13: 1 | F13: 1.5 | G13: 2 | H13: =IF(D13<=1,"✅ مستدام",IF(D13<=1.5,"⚠️ مقبول","🔴 مكلف"))
A15: 🎯 التقييم الإجمالي | B15: ضعيف | C15: آمن | D15: =IF(D10>=0.008,IF(D10<=0.012,"⭐ مثالي",IF(D10<=0.018,"جيد","مكلف")),"ضعيف") | E15: متوازن | F15: سخي | G15: مكلف جداً
A17: 💰 الأثر المالي السنوي على درب (مليون ريال) - افتراض 230 محطة × 80,000 لتر × 12
A18: البند | B18: ساسكو | C18: محافظ | D18: ⭐ الحالي | E18: معتدل | F18: جذاب | G18: سخي | H18: مقارنة
A19: تكلفة سنوية (الأبيض) | B19: =B10*514.5*0.7 | C19: =C10*514.5*0.7 | D19: =D10*514.5*0.7 | E19: =E10*514.5*0.7 | F19: =F10*514.5*0.7 | G19: =G10*514.5*0.7 | H19: =G19-D19
A21: 💡 العمود ⭐ الحالي يعكس قيم شيت السيناريوهات وقت فتح الملف · غيّر القيم في السيناريوهات وارجع هنا لتشوف الفرق
A23: درب · مقارنة السيناريوهات · 2026

Sheet قيمة النقطة
A1: درب · حساب قيمة النقطة بالتفصيل
A2: أمثلة عملية لأنواع مختلفة من العملاء
A4: 🧮 المعادلات الأساسية
A5: المعادلة | B5: الصيغة | C5: النتيجة | D5: الوحدة
A6: قيمة 1 نقطة (ريال) | B6: 1 / 10,000 | C6: =1/السيناريوهات!C6 | D6: ريال
A7: قيمة 1 نقطة (هللة) | B7: (1/10K)×100 | C7: =(1/السيناريوهات!C6)*100 | D7: هللة
A8: نقاط ساسكو لكل ريال | B8: لتر/ريال | C8: =1/السيناريوهات!C11 | D8: نقطة
A9: نقاط درب الأبيض/ريال | B9: 100 | C9: =السيناريوهات!C7 | D9: نقطة
A10: نقاط درب الفضي/ريال | B10: 150 | C10: =السيناريوهات!C8 | D10: نقطة
A11: نقاط درب البرتقالي/ريال | B11: 200 | C11: =السيناريوهات!C9 | D11: نقطة
A12: الكاش باك الأبيض | B12: 100÷10K | C12: =السيناريوهات!C7/السيناريوهات!C6 | D12: %
A13: الكاش باك الفضي | B13: 150÷10K | C13: =السيناريوهات!C8/السيناريوهات!C6 | D13: %
A14: الكاش باك البرتقالي | B14: 200÷10K | C14: =السيناريوهات!C9/السيناريوهات!C6 | D14: %
A16: 📊 أمثلة عملية للعملاء
A17: ملف العميل | B17: إنفاق/شهر | C17: إنفاق/سنة | D17: المستوى | E17: النقاط/سنة | F17: القيمة | G17: الكاش باك | H17: vs ساسكو
A18: 🏠 خفيف | B18: 500 | C18: =B18*12 | D18: =IF(C18<السيناريوهات!$C$16,"🤍 أبيض",IF(C18<السيناريوهات!$C$17,"🩶 فضي","🟠 برتقالي")) | E18: =C18*IF(D18="🤍 أبيض",السيناريوهات!$C$7,IF(D18="🩶 فضي",السيناريوهات!$C$8,السيناريوهات!$C$9)) | F18: =E18/السيناريوهات!$C$6 | G18: =F18/C18 | H18: =G18/0.0043
A19: 🚗 متوسط | B19: 1500 | C19: =B19*12 | D19: =IF(C19<السيناريوهات!$C$16,"🤍 أبيض",IF(C19<السيناريوهات!$C$17,"🩶 فضي","🟠 برتقالي")) | E19: =C19*IF(D19="🤍 أبيض",السيناريوهات!$C$7,IF(D19="🩶 فضي",السيناريوهات!$C$8,السيناريوهات!$C$9)) | F19: =E19/السيناريوهات!$C$6 | G19: =F19/C19 | H19: =G19/0.0043
A20: 🚙 نشط | B20: 2500 | C20: =B20*12 | D20: =IF(C20<السيناريوهات!$C$16,"🤍 أبيض",IF(C20<السيناريوهات!$C$17,"🩶 فضي","🟠 برتقالي")) | E20: =C20*IF(D20="🤍 أبيض",السيناريوهات!$C$7,IF(D20="🩶 فضي",السيناريوهات!$C$8,السيناريوهات!$C$9)) | F20: =E20/السيناريوهات!$C$6 | G20: =F20/C20 | H20: =G20/0.0043
A21: 🏢 أعمال | B21: 5000 | C21: =B21*12 | D21: =IF(C21<السيناريوهات!$C$16,"🤍 أبيض",IF(C21<السيناريوهات!$C$17,"🩶 فضي","🟠 برتقالي")) | E21: =C21*IF(D21="🤍 أبيض",السيناريوهات!$C$7,IF(D21="🩶 فضي",السيناريوهات!$C$8,السيناريوهات!$C$9)) | F21: =E21/السيناريوهات!$C$6 | G21: =F21/C21 | H21: =G21/0.0043

Sheet المستويات الثلاثة
A1: درب · المستويات الثلاثة
A2: هيكل المستويات + الكسب + المنافع
A4: 🎯 هيكل المستويات
A5: المستوى | B5: معدل الكسب | C5: الحد الأدنى | D5: الكاش باك | E5: هدية الترحيب
A6: 🤍 المستوى الأبيض | B6: =السيناريوهات!C7 | C6: 0 | D6: =السيناريوهات!C7/السيناريوهات!C6 | E6: 5000
A7: 🩶 المستوى الفضي | B7: =السيناريوهات!C8 | C7: =السيناريوهات!C16 | D7: =السيناريوهات!C8/السيناريوهات!C6 | E7: 10000
A8: 🟠 المستوى البرتقالي | B8: =السيناريوهات!C9 | C8: =السيناريوهات!C17+1 | D8: =السيناريوهات!C9/السيناريوهات!C6 | E8: 20000
A10: 🎁 المنافع الإضافية
A11: الميزة | B11: 🤍 الأبيض | C11: 🩶 الفضي | D11: 🟠 البرتقالي | E11: ملاحظة
A12: نقاط مضاعفة في الأعياد | B12: ❌ | C12: 🎯 1.5× | D12: 🎯 2× | E12: تحفيز للمناسبات
A13: دعوة لفعاليات درب | B13: ❌ | C13: ✅ | D13: ✅✅ VIP | E13: تجربة حصرية
A14: خصومات الشركاء | B14: 5% | C14: 10% | D14: 15% | E14: قيمة إضافية
A15: أولوية الدعم الفني | B15: عادي | C15: سريع | D15: فوري | E15: خدمة العملاء
A16: إهداء النقاط للعائلة | B16: ❌ | C16: ✅ محدود | D16: ✅ بلا حدود | E16: مشاركة المنفعة
A17: تجميد الحساب | B17: ❌ | C17: ❌ | D17: ✅ مرة/سنة | E17: مرونة في الإجازات
A19: ⚙️ قواعد الترقية والتنزيل
A20: 🔼 الترقية: تلقائية فور تجاوز الحد الأدنى للمستوى التالي
A21: 🔽 التنزيل: بعد 12 شهر من عدم الوصول للحد الأدنى
A22: 📅 المراجعة: 31 ديسمبر من كل سنة · يحتسب آخر 12 شهر
A23: 🎯 فترة سماح: 30 يوم بعد التنزيل لاستعادة المستوى
A24: 💯 النقاط لا تنتهي · باقية حتى لو تغيّر المستوى

Sheet تكلفة المحطات
A1: درب · تكلفة الولاء على كل نوع محطة
A2: حساب الجدوى الاقتصادية لكل نموذج
A4: 📊 التفاصيل لكل نوع محطة
A5: البند | B5: محطة تشغيل | C5: محطة استثمار | D5: محطة امتياز | E5: الفرق | F5: الجدوى | G5: الملاحظة
A6: هامش/لتر (هللة) | B6: =السيناريوهات!C26 | C6: =السيناريوهات!C27 | D6: =السيناريوهات!C28
A7: هامش/ريال (هللة) | B7: =B6/السيناريوهات!$C$11 | C7: =C6/السيناريوهات!$C$11 | D7: =D6/السيناريوهات!$C$11
A8: تكلفة الولاء/ريال (هللة) | B8: =السيناريوهات!$C$10 | C8: =السيناريوهات!$C$10 | D8: =السيناريوهات!$C$10
A9: مساهمة درب % | B9: 1 | C9: 0.5 | D9: =السيناريوهات!C29
A10: تكلفة درب/ريال (هللة) | B10: =B8*B9 | C10: =C8*C9 | D10: =D8*D9
A11: صافي هامش المالك/ريال | B11: =B7 | C11: =C7-(C8*(1-C9)) | D11: =D7-(D8*(1-D9))
A12: الجدوى الاقتصادية | B12: =IF(B11>0.5,"✅ مربح",IF(B11>0,"⚠️ هامش ضيق","🔴 خسارة")) | C12: =IF(C11>0.5,"✅ مربح",IF(C11>0,"⚠️ هامش ضيق","🔴 خسارة")) | D12: =IF(D11>0.5,"✅ مربح",IF(D11>0,"⚠️ هامش ضيق","🔴 خسارة"))

Sheet التحصيل من الامتياز
A1: درب · آلية التحصيل من محطات الامتياز
A2: حساب الفاتورة الشهرية لكل محطة امتياز بناءً على المبيعات
A4: ⚙️ الآلية
A5: 1 | B5: نهاية كل شهر | C5: النظام يحسب إجمالي اللترات لكل محطة
A6: 2 | B6: حساب المساهمة | C6: اللترات × سعر اللتر × 0.5 هللة = المستحق
A7: 3 | B7: إصدار الفاتورة | C7: فاتورة إلكترونية تلقائية في اليوم 1
A8: 4 | B8: مهلة السداد | C8: 15 يوم من تاريخ الفاتورة
A9: 5 | B9: الغرامة | C9: 1% أسبوعياً + إيقاف بعد 30 يوم
A11: 📋 محاكاة 10 محطات امتياز نموذجية
A12: # | B12: الكود | C12: المدينة | D12: لتر/شهر | E12: الإنفاق (ريال) | F12: مساهمة المالك | G12: مساهمة درب
A13: 1 | B13: AMT-001 | C13: الرياض | D13: 95000 | E13: =D13*السيناريوهات!$C$11 | F13: =E13*السيناريوهات!$C$10*السيناريوهات!$C$30/100 | G13: =E13*السيناريوهات!$C$10*السيناريوهات!$C$29/100
A14: 2 | B14: AMT-002 | C14: جدة | D14: 82000 | E14: =D14*السيناريوهات!$C$11 | F14: =E14*السيناريوهات!$C$10*السيناريوهات!$C$30/100 | G14: =E14*السيناريوهات!$C$10*السيناريوهات!$C$29/100
A15: 3 | B15: AMT-003 | C15: مكة | D15: 78000 | E15: =D15*السيناريوهات!$C$11 | F15: =E15*السيناريوهات!$C$10*السيناريوهات!$C$30/100 | G15: =E15*السيناريوهات!$C$10*السيناريوهات!$C$29/100
A16: 4 | B16: AMT-004 | C16: الدمام | D16: 88000 | E16: =D16*السيناريوهات!$C$11 | F16: =E16*السيناريوهات!$C$10*السيناريوهات!$C$30/100 | G16: =E16*السيناريوهات!$C$10*السيناريوهات!$C$29/100
A17: 5 | B17: AMT-005 | C17: الطائف | D17: 65000 | E17: =D17*السيناريوهات!$C$11 | F17: =E17*السيناريوهات!$C$10*السيناريوهات!$C$30/100 | G17: =E17*السيناريوهات!$C$10*السيناريوهات!$C$29/100
A18: 6 | B18: AMT-006 | C18: تبوك | D18: 58000 | E18: =D18*السيناريوهات!$C$11 | F18: =E18*السيناريوهات!$C$10*السيناريوهات!$C$30/100 | G18: =E18*السيناريوهات!$C$10*السيناريوهات!$C$29/100
A19: 7 | B19: AMT-007 | C19: حائل | D19: 52000 | E19: =D19*السيناريوهات!$C$11 | F19: =E19*السيناريوهات!$C$10*السيناريوهات!$C$30/100 | G19: =E19*السيناريوهات!$C$10*السيناريوهات!$C$29/100
A20: 8 | B20: AMT-008 | C20: بريدة | D20: 71000 | E20: =D20*السيناريوهات!$C$11 | F20: =E20*السيناريوهات!$C$10*السيناريوهات!$C$30/100 | G20: =E20*السيناريوهات!$C$10*السيناريوهات!$C$29/100
A21: 9 | B21: AMT-009 | C21: أبها | D21: 68000 | E21: =D21*السيناريوهات!$C$11 | F21: =E21*السيناريوهات!$C$10*السيناريوهات!$C$30/100 | G21: =E21*السيناريوهات!$C$10*السيناريوهات!$C$29/100
A22: 10 | B22: AMT-010 | C22: جازان | D22: 49000 | E22: =D22*السيناريوهات!$C$11 | F22: =E22*السيناريوهات!$C$10*السيناريوهات!$C$30/100 | G22: =E22*السيناريوهات!$C$10*السيناريوهات!$C$29/100
A23: 📊 الإجمالي الشهري | D23: =SUM(D13:D22) | E23: =SUM(E13:E22) | F23: =SUM(F13:F22) | G23: =SUM(G13:G22)
A24: 📅 الإجمالي السنوي | D24: =D23*12 | E24: =E23*12 | F24: =F23*12 | G24: =G23*12

Sheet التوقعات السنوية
A1: درب · التوقعات المالية على 5 سنوات
A2: بناءً على نمو محطات درب من 173 إلى 250
A4: 🏗️ نمو المحطات السنوي
A5: نوع المحطة | B5: 2026 | C5: 2027 | D5: 2028 | E5: 2029 | F5: 2030 | G5: النمو
A6: 🏢 تشغيل | B6: 30 | C6: 35 | D6: 42 | E6: 50 | F6: 58 | G6: =(F6-B6)/B6
A7: 💼 استثمار | B7: 70 | C7: 80 | D7: 88 | E7: 95 | F7: 100 | G7: =(F7-B7)/B7
A8: 🤝 امتياز | B8: 73 | C8: 90 | D8: 105 | E8: 120 | F8: 135 | G8: =(F8-B8)/B8
A9: 📊 الإجمالي | B9: =SUM(B6:B8) | C9: =SUM(C6:C8) | D9: =SUM(D6:D8) | E9: =SUM(E6:E8) | F9: =SUM(F6:F8) | G9: =(F9-B9)/B9
A11: 💰 التكلفة السنوية على درب (مليون ريال)
A12: نوع المحطة | B12: 2026 | C12: 2027 | D12: 2028 | E12: 2029 | F12: 2030 | G12: النمو
A13: تشغيل (100%) | B13: =B6*السيناريوهات!$C$31*12*السيناريوهات!$C$11*السيناريوهات!$C$10/100/1000000 | C13: =C6*السيناريوهات!$C$31*12*السيناريوهات!$C$11*السيناريوهات!$C$10/100/1000000 | D13: =D6*السيناريوهات!$C$31*12*السيناريوهات!$C$11*السيناريوهات!$C$10/100/1000000 | E13: =E6*السيناريوهات!$C$31*12*السيناريوهات!$C$11*السيناريوهات!$C$10/100/1000000 | F13: =F6*السيناريوهات!$C$31*12*السيناريوهات!$C$11*السيناريوهات!$C$10/100/1000000 | G13: =(F13-B13)/B13
A14: استثمار (50%) | B14: =B7*السيناريوهات!$C$31*12*السيناريوهات!$C$11*السيناريوهات!$C$10*0.5/100/1000000 | C14: =C7*السيناريوهات!$C$31*12*السيناريوهات!$C$11*السيناريوهات!$C$10*0.5/100/1000000 | D14: =D7*السيناريوهات!$C$31*12*السيناريوهات!$C$11*السيناريوهات!$C$10*0.5/100/1000000 | E14: =E7*السيناريوهات!$C$31*12*السيناريوهات!$C$11*السيناريوهات!$C$10*0.5/100/1000000 | F14: =F7*السيناريوهات!$C$31*12*السيناريوهات!$C$11*السيناريوهات!$C$10*0.5/100/1000000 | G14: =(F14-B14)/B14
A15: امتياز (50%) | B15: =B8*السيناريوهات!$C$31*12*السيناريوهات!$C$11*السيناريوهات!$C$10*السيناريوهات!$C$29/100/1000000 | C15: =C8*السيناريوهات!$C$31*12*السيناريوهات!$C$11*السيناريوهات!$C$10*السيناريوهات!$C$29/100/1000000 | D15: =D8*السيناريوهات!$C$31*12*السيناريوهات!$C$11*السيناريوهات!$C$10*السيناريوهات!$C$29/100/1000000 | E15: =E8*السيناريوهات!$C$31*12*السيناريوهات!$C$11*السيناريوهات!$C$10*السيناريوهات!$C$29/100/1000000 | F15: =F8*السيناريوهات!$C$31*12*السيناريوهات!$C$11*السيناريوهات!$C$10*السيناريوهات!$C$29/100/1000000 | G15: =(F15-B15)/B15
A16: 📊 الإجمالي | B16: =SUM(B13:B15) | C16: =SUM(C13:C15) | D16: =SUM(D13:D15) | E16: =SUM(E13:E15) | F16: =SUM(F13:F15) | G16: =(F16-B16)/B16
A17: =" 💎 إجمالي 5 سنوات على درب: "&TEXT(SUM(B16:F16),"0.00")&" مليون ريال"

Sheet الاقتصاد الموسّع
A1: درب · محرك الاقتصاد الموسّع — الديزل والشركاء (معادلات حيّة)
A2: كل القيم أدناه معادلات تشير لخلايا ورقة السيناريوهات — غيّر هناك وتتحدث هنا
A4: ⛽ الديزل
A5: البند | B5: القيمة | C5: الوحدة
A6: هامش الديزل/لتر | B6: =السيناريوهات!C37 | C6: هللة/لتر
A7: هامش الديزل % | B7: =السيناريوهات!C37/(السيناريوهات!C36*100) | C7: %
A8: كسب الديزل | B8: =السيناريوهات!C38 | C8: نقطة/ريال
A9: كاش باك الديزل % | B9: =السيناريوهات!C38/السيناريوهات!C6 | C9: %
A10: تكلفة درب على الديزل | B10: =السيناريوهات!C38/السيناريوهات!C6*100 | C10: هللة/ريال
A11: صافي هامش درب على الديزل | B11: =السيناريوهات!C37/السيناريوهات!C36-(السيناريوهات!C38/السيناريوهات!C6*100) | C11: هللة/ريال
A12: الجدوى | B12: =IF(B11>0.5,"✅ مربح",IF(B11>0,"⚠️ هامش ضيق","🔴 خسارة"))
A14: ☕ الشركاء (كافيه/مطعم)
A15: البند | B15: القيمة | C15: الوحدة
A16: كسب العميل عند الشريك | B16: =السيناريوهات!C39 | C16: نقطة/ريال
A17: كاش باك العميل % | B17: =السيناريوهات!C39/السيناريوهات!C6 | C17: %
A18: تكلفة درب (الشريك يموّل) | B18: =0 | C18: هللة/ريال
A19: مساهمة الشريك لدرب | B19: =السيناريوهات!C40 | C19: هللة/ريال
A20: صافي لدرب من الشريك | B20: =السيناريوهات!C40-B18 | C20: هللة/ريال
A22: 🔬 أثر الريال على درب: وقود مقابل شريك
A23: البند | B23: ريال بنزين | C23: ريال شريك
A24: دخل/ربح درب (هللة) | B24: =السيناريوهات!C26/السيناريوهات!C11 | C24: =السيناريوهات!C40
A25: تكلفة الولاء على درب (هللة) | B25: =السيناريوهات!C7/السيناريوهات!C6*100 | C25: =0
A26: الصافي على درب (هللة/ريال) | B26: =B24-B25 | C26: =C24-C25
A27: الخلاصة | B27: =IF(B26>0,"✅ تكلفة احتفاظ","🔴 خسارة") | C27: =IF(C26>0,"✅ ربح صافٍ","—")
A29: 💡 الوقود يجذب (هامش رفيع) والشركاء يموّلون ويربّحون — أولوية درب: توقيع الشركاء

Sheet قنوات الاستبدال
A1: درب · قنوات استبدال النقاط — التكلفة على درب لكل قناة (معادلات حيّة)
A3: إجمالي القيمة المستبدلة سنوياً (ريال) | C3: 1000000
A5: القناة | B5: من يموّلها | C5: النسبة % | D5: تكلفة درب/ريال % | E5: القيمة المستبدلة | F5: تكلفة درب
A6: ⛽ خصم بنزين | B6: درب | C6: 0.3 | D6: 1 | E6: =$C$3*C6 | F6: =E6*D6
A7: 🛍️ عروض المستأجرين | B7: المستأجر | C7: 0.35 | D7: 0 | E7: =$C$3*C7 | F7: =E7*D7
A8: 🎁 شركات خارجية (جرير/أمازون/الفرسان) | B8: درب (خصم جملة) | C8: 0.2 | D8: 0.97 | E8: =$C$3*C8 | F8: =E8*D8
A9: 📱 كرت شحن | B9: درب (عمولة المشغّل) | C9: 0.15 | D9: 0.95 | E9: =$C$3*C9 | F9: =E9*D9
A10: 📊 الإجمالي | C10: =SUM(C6:C9) | E10: =SUM(E6:E9) | F10: =SUM(F6:F9)
A12: متوسط تكلفة الريال المستبدل | C12: =F10/E10
A13: التوفير مقابل الكل-بنزين | C13: =$C$3-F10
A14: تحقق مجموع النسب | C14: =IF(C10=1,"✅ 100%","⚠️ راجع النسب")
A16: 💡 وجّه الاستبدال نحو عروض المستأجرين (تكلفتها صفر) بدل خصم البنزين

Sheet نموذج المحفظة
A1: درب · نموذج المحفظة المموّلة بالكامل (Escrow) — معادلات حيّة
A2: كل مُصدِر يودع نسبته على مبيعاته هو · النقاط واجهة فوق محفظة بالريال
A4: 📥 تغذية المحفظة
A5: المصدر | B5: قيمة الشراء (﷼) | C5: نسبة الإيداع % | D5: المودَع (﷼)
A6: ⛽ بنزين (درب) | B6: 600 | C6: 0.5 | D6: =B6*C6/100
A7: ☕ كافيه | B7: 200 | C7: 4 | D7: =B7*C7/100
A8: 🍔 مطعم | B8: 150 | C8: 3 | D8: =B8*C8/100
A9: 🛒 سوبرماركت | B9: 400 | C9: 1 | D9: =B9*C9/100
A10: 📊 إجمالي التغذية | D10: =SUM(D6:D9)
A12: رصيد المحفظة (﷼) | C12: =D10
A13: يُعرض للعميل كنقاط | C13: =C12*السيناريوهات!C6
A15: 🔁 محاكاة استبدال
A16: يُسحب من المحفظة (﷼) | C16: 10
A17: يضيف التاجر تنافساً (﷼) | C17: 3
A18: يحصل العميل (﷼) | C18: =C16+C17
A19: القيمة لكل ريال مسحوب | C19: =C18/C16
A20: الرصيد بعد الاستبدال (﷼) | C20: =C12-C16
A22: 🕳️ الأموال الخاملة (Breakage)
A23: نسبة الخمول % | C23: 12
A24: مدة الصلاحية (شهر) | C24: 24
A25: المتوقع خامل (﷼) | C25: =C12*C23/100
A26: المتوقع استبداله فعلاً (﷼) | C26: =C12-C25
A28: 🔒 النظام لا يخسر: كل ريال يُستبدل كان مودَعاً مسبقاً · لا أحد يموّل وعود غيره
