Workbook

Sheet الاستراتيجية
B2: درب · الاستراتيجية والركائز 2026 — قطاع المحطات والعقار
B4: الركيزة (5 سنوات) | C4: الوصف | D4: مستهدف 2026
B5: النمو | C5: التوسع في المواقع وزيادة الوصول وتنمية الإيراد.
B6: التوسع في المواقع | C6: افتتاح وتشغيل محطات جديدة. | D6: التشغيل 85 · الامتياز 150 محطة
B7: الامتياز والعقود | C7: تنمية الإيراد عبر الامتياز والاستثمار. | D7: الامتياز 167 · الاستثمار 190 عقد
B8: زيادة وصول العملاء | C8: رفع المبيعات والتغطية. | D8: 718.8M لتر · 13 منطقة
B9: الابتكار | C9: مشاريع جديدة وتحول تقني وهوية وتانكي.
B10: التحول التقني وتانكي | C10: أتمتة 164 محطة · D365 · تطبيق تانكي (التسويق). | D10: أتمتة 90% · تانكي تصاعدي
B11: الاستدامة | C11: جودة التشغيل وتجربة العميل والموظفين.
B12: جودة التشغيل وتجربة العميل | C12: جاهزية وأمن سيبراني ورضا. | D12: جاهزية 99% · CSAT 90%
B13: الاستثمار في الموظفين | C13: التوطين والتدريب والاستبقاء. | D13: 6 دورات · استبقاء 90%
B15: الخارطة التنفيذية — المشاريع
B16: المشروع | C16: الركيزة | D16: عدد المؤشرات | E16: الأداء (حي)
B17: التوسع في المواقع | C17: النمو | D17: =COUNTIF('سجل المؤشرات'!$M$4:$M$146,"التوسع في المواقع") | E17: =IFERROR(AVERAGEIFS('سجل المؤشرات'!$AB$4:$AB$146,'سجل المؤشرات'!$M$4:$M$146,"التوسع في المواقع"),"—")
B18: الامتياز التجاري | C18: النمو | D18: =COUNTIF('سجل المؤشرات'!$M$4:$M$146,"الامتياز التجاري") | E18: =IFERROR(AVERAGEIFS('سجل المؤشرات'!$AB$4:$AB$146,'سجل المؤشرات'!$M$4:$M$146,"الامتياز التجاري"),"—")
B19: زيادة وصول العملاء | C19: النمو | D19: =COUNTIF('سجل المؤشرات'!$M$4:$M$146,"زيادة وصول العملاء") | E19: =IFERROR(AVERAGEIFS('سجل المؤشرات'!$AB$4:$AB$146,'سجل المؤشرات'!$M$4:$M$146,"زيادة وصول العملاء"),"—")
B20: إطلاق مشاريع جديدة | C20: الابتكار | D20: =COUNTIF('سجل المؤشرات'!$M$4:$M$146,"إطلاق مشاريع جديدة") | E20: =IFERROR(AVERAGEIFS('سجل المؤشرات'!$AB$4:$AB$146,'سجل المؤشرات'!$M$4:$M$146,"إطلاق مشاريع جديدة"),"—")
B21: تطوير التصاميم والهوية | C21: الابتكار | D21: =COUNTIF('سجل المؤشرات'!$M$4:$M$146,"تطوير التصاميم والهوية") | E21: =IFERROR(AVERAGEIFS('سجل المؤشرات'!$AB$4:$AB$146,'سجل المؤشرات'!$M$4:$M$146,"تطوير التصاميم والهوية"),"—")
B22: التحول التقني | C22: الابتكار | D22: =COUNTIF('سجل المؤشرات'!$M$4:$M$146,"التحول التقني") | E22: =IFERROR(AVERAGEIFS('سجل المؤشرات'!$AB$4:$AB$146,'سجل المؤشرات'!$M$4:$M$146,"التحول التقني"),"—")
B23: ساحات درب | C23: الابتكار | D23: =COUNTIF('سجل المؤشرات'!$M$4:$M$146,"ساحات درب") | E23: =IFERROR(AVERAGEIFS('سجل المؤشرات'!$AB$4:$AB$146,'سجل المؤشرات'!$M$4:$M$146,"ساحات درب"),"—")
B24: تطبيق «تانكي» | C24: الابتكار | D24: =COUNTIF('سجل المؤشرات'!$M$4:$M$146,"تطبيق «تانكي»") | E24: =IFERROR(AVERAGEIFS('سجل المؤشرات'!$AB$4:$AB$146,'سجل المؤشرات'!$M$4:$M$146,"تطبيق «تانكي»"),"—")
B25: تعزيز تجربة العملاء | C25: الاستدامة | D25: =COUNTIF('سجل المؤشرات'!$M$4:$M$146,"تعزيز تجربة العملاء") | E25: =IFERROR(AVERAGEIFS('سجل المؤشرات'!$AB$4:$AB$146,'سجل المؤشرات'!$M$4:$M$146,"تعزيز تجربة العملاء"),"—")
B26: جودة التشغيل | C26: الاستدامة | D26: =COUNTIF('سجل المؤشرات'!$M$4:$M$146,"جودة التشغيل") | E26: =IFERROR(AVERAGEIFS('سجل المؤشرات'!$AB$4:$AB$146,'سجل المؤشرات'!$M$4:$M$146,"جودة التشغيل"),"—")
B27: منظومة التأجير | C27: الاستدامة | D27: =COUNTIF('سجل المؤشرات'!$M$4:$M$146,"منظومة التأجير") | E27: =IFERROR(AVERAGEIFS('سجل المؤشرات'!$AB$4:$AB$146,'سجل المؤشرات'!$M$4:$M$146,"منظومة التأجير"),"—")
B28: الاستثمار في الموظفين | C28: الاستدامة | D28: =COUNTIF('سجل المؤشرات'!$M$4:$M$146,"الاستثمار في الموظفين") | E28: =IFERROR(AVERAGEIFS('سجل المؤشرات'!$AB$4:$AB$146,'سجل المؤشرات'!$M$4:$M$146,"الاستثمار في الموظفين"),"—")

Sheet اللوحة الموجزة
B2: اللوحة الموجزة — تجميع حي من سجل المؤشرات
B4: الإنجاز العام | C4: ✅ محقق | D4: 🟡 قريب | E4: 🔴 تحت الهدف
B5: =IFERROR(AVERAGE('سجل المؤشرات'!$AB$4:$AB$146),0) | C5: =COUNTIF('سجل المؤشرات'!$AC$4:$AC$146,"✅ محقق") | D5: =COUNTIF('سجل المؤشرات'!$AC$4:$AC$146,"🟡 قريب") | E5: =COUNTIF('سجل المؤشرات'!$AC$4:$AC$146,"🔴 تحت الهدف")
B7: الأداء حسب الإدارة | F7: الأداء حسب الركيزة
B8: الإدارة | C8: الأداء | D8: عدد المؤشرات | F8: الركيزة | G8: الأداء
B9: الإدارة التنفيذية | C9: =IFERROR(AVERAGEIFS('سجل المؤشرات'!$AB$4:$AB$146,'سجل المؤشرات'!$B$4:$B$146,"الإدارة التنفيذية"),"—") | D9: =COUNTIF('سجل المؤشرات'!$B$4:$B$146,"الإدارة التنفيذية") | F9: النمو | G9: =IFERROR(AVERAGEIFS('سجل المؤشرات'!$AB$4:$AB$146,'سجل المؤشرات'!$L$4:$L$146,"النمو"),"—")
B10: الامتياز التجاري | C10: =IFERROR(AVERAGEIFS('سجل المؤشرات'!$AB$4:$AB$146,'سجل المؤشرات'!$B$4:$B$146,"الامتياز التجاري"),"—") | D10: =COUNTIF('سجل المؤشرات'!$B$4:$B$146,"الامتياز التجاري") | F10: الابتكار | G10: =IFERROR(AVERAGEIFS('سجل المؤشرات'!$AB$4:$AB$146,'سجل المؤشرات'!$L$4:$L$146,"الابتكار"),"—")
B11: التشغيل والمحطات | C11: =IFERROR(AVERAGEIFS('سجل المؤشرات'!$AB$4:$AB$146,'سجل المؤشرات'!$B$4:$B$146,"التشغيل والمحطات"),"—") | D11: =COUNTIF('سجل المؤشرات'!$B$4:$B$146,"التشغيل والمحطات") | F11: الاستدامة | G11: =IFERROR(AVERAGEIFS('سجل المؤشرات'!$AB$4:$AB$146,'سجل المؤشرات'!$L$4:$L$146,"الاستدامة"),"—")
B12: الاستثمار | C12: =IFERROR(AVERAGEIFS('سجل المؤشرات'!$AB$4:$AB$146,'سجل المؤشرات'!$B$4:$B$146,"الاستثمار"),"—") | D12: =COUNTIF('سجل المؤشرات'!$B$4:$B$146,"الاستثمار")
B13: العقار | C13: =IFERROR(AVERAGEIFS('سجل المؤشرات'!$AB$4:$AB$146,'سجل المؤشرات'!$B$4:$B$146,"العقار"),"—") | D13: =COUNTIF('سجل المؤشرات'!$B$4:$B$146,"العقار") | F13: الأداء حسب منظور BSC
B14: التقنية الرقمية | C14: =IFERROR(AVERAGEIFS('سجل المؤشرات'!$AB$4:$AB$146,'سجل المؤشرات'!$B$4:$B$146,"التقنية الرقمية"),"—") | D14: =COUNTIF('سجل المؤشرات'!$B$4:$B$146,"التقنية الرقمية") | F14: مالي | G14: =IFERROR(AVERAGEIFS('سجل المؤشرات'!$AB$4:$AB$146,'سجل المؤشرات'!$N$4:$N$146,"مالي"),"—")
B15: الموارد البشرية | C15: =IFERROR(AVERAGEIFS('سجل المؤشرات'!$AB$4:$AB$146,'سجل المؤشرات'!$B$4:$B$146,"الموارد البشرية"),"—") | D15: =COUNTIF('سجل المؤشرات'!$B$4:$B$146,"الموارد البشرية") | F15: العملاء | G15: =IFERROR(AVERAGEIFS('سجل المؤشرات'!$AB$4:$AB$146,'سجل المؤشرات'!$N$4:$N$146,"العملاء"),"—")
B16: التسويق | C16: =IFERROR(AVERAGEIFS('سجل المؤشرات'!$AB$4:$AB$146,'سجل المؤشرات'!$B$4:$B$146,"التسويق"),"—") | D16: =COUNTIF('سجل المؤشرات'!$B$4:$B$146,"التسويق") | F16: العمليات الداخلية | G16: =IFERROR(AVERAGEIFS('سجل المؤشرات'!$AB$4:$AB$146,'سجل المؤشرات'!$N$4:$N$146,"العمليات الداخلية"),"—")
F17: التعلّم والنمو | G17: =IFERROR(AVERAGEIFS('سجل المؤشرات'!$AB$4:$AB$146,'سجل المؤشرات'!$N$4:$N$146,"التعلّم والنمو"),"—")

Sheet سجل المؤشرات
A1: درب · سجل مؤشرات الأداء الموحّد 2026 — كل المؤشرات والمستهدفات والمشاريع والاستراتيجية
A2: 🟩 الأشهر = إدخال · YTD ونسبة التحقيق والحالة دلّات حقيقية تُحسب تلقائياً · قيم التقنية والتسويق مُعبّأة فعلياً
A3: # | B3: الإدارة | C3: المحور | D3: المؤشر | E3: الوحدة | F3: القطبية | G3: التجميع | H3: الأولوية | I3: الوزن % | J3: المستهدف | K3: نص المستهدف | L3: الركيزة | M3: المشروع | N3: منظور BSC | O3: يناير | P3: فبراير | Q3: مارس | R3: أبريل | S3: مايو | T3: يونيو | U3: يوليو | V3: أغسطس | W3: سبتمبر | X3: أكتوبر | Y3: نوفمبر | Z3: ديسمبر | AA3: YTD | AB3: نسبة التحقيق | AC3: الحالة
A4: 1 | B4: الإدارة التنفيذية | C4: النمو | D4: إجمالي المحطات المشغّلة — الشركة (تراكمي) | E4: محطة | F4: ↑ | G4: LAST | H4: 🔴 رئيسي | I4: 0.11538 | J4: 235 | K4: ≥ 235 محطة | L4: النمو | M4: التوسع في المواقع | N4: العمليات الداخلية | AA4: =IF($G4="SUM",IF(COUNT($O4:$Z4)=0,"",SUM($O4:$Z4)),IF($G4="AVG",IFERROR(AVERAGE($O4:$Z4),""),IF($G4="LAST",IFERROR(LOOKUP(2,1/($O4:$Z4<>""),$O4:$Z4),""),""))) | AB4: =IF($J4="","",IF($AA4="","",IF($J4=0,IF($AA4<=0,1,0),IF($F4="↓",IFERROR($J4/$AA4,0),IFERROR($AA4/$J4,0))))) | AC4: =IF($AB4="","—",IF($AB4>=1,"✅ محقق",IF($AB4>=0.85,"🟡 قريب","🔴 تحت الهدف")))
A5: 2 | B5: الإدارة التنفيذية | C5: النمو | D5: إجمالي العقود الجديدة — الشركة | E5: عقد | F5: ↑ | G5: SUM | H5: 🔴 رئيسي | I5: 0.11538 | J5: 357 | K5: 357 عقد | L5: النمو | M5: الامتياز التجاري | N5: العمليات الداخلية | AA5: =IF($G5="SUM",IF(COUNT($O5:$Z5)=0,"",SUM($O5:$Z5)),IF($G5="AVG",IFERROR(AVERAGE($O5:$Z5),""),IF($G5="LAST",IFERROR(LOOKUP(2,1/($O5:$Z5<>""),$O5:$Z5),""),""))) | AB5: =IF($J5="","",IF($AA5="","",IF($J5=0,IF($AA5<=0,1,0),IF($F5="↓",IFERROR($J5/$AA5,0),IFERROR($AA5/$J5,0))))) | AC5: =IF($AB5="","—",IF($AB5>=1,"✅ محقق",IF($AB5>=0.85,"🟡 قريب","🔴 تحت الهدف")))
A6: 3 | B6: الإدارة التنفيذية | C6: النمو | D6: إجمالي إيرادات الشركة السنوية | E6: ر.س | F6: ↑ | G6: SUM | H6: 🔴 رئيسي | I6: 0.11538 | K6: تصاعدي مستمر | L6: النمو | M6: زيادة وصول العملاء | N6: مالي | AA6: =IF($G6="SUM",IF(COUNT($O6:$Z6)=0,"",SUM($O6:$Z6)),IF($G6="AVG",IFERROR(AVERAGE($O6:$Z6),""),IF($G6="LAST",IFERROR(LOOKUP(2,1/($O6:$Z6<>""),$O6:$Z6),""),""))) | AB6: =IF($J6="","",IF($AA6="","",IF($J6=0,IF($AA6<=0,1,0),IF($F6="↓",IFERROR($J6/$AA6,0),IFERROR($AA6/$J6,0))))) | AC6: =IF($AB6="","—",IF($AB6>=1,"✅ محقق",IF($AB6>=0.85,"🟡 قريب","🔴 تحت الهدف")))
A7: 4 | B7: الإدارة التنفيذية | C7: النمو | D7: نسبة نمو إيرادات الشركة (سنوي) | E7: % | F7: ↑ | G7: AVG | H7: 🔴 رئيسي | I7: 0.11538 | K7: مستهدف تنفيذي | L7: النمو | M7: زيادة وصول العملاء | N7: مالي | AA7: =IF($G7="SUM",IF(COUNT($O7:$Z7)=0,"",SUM($O7:$Z7)),IF($G7="AVG",IFERROR(AVERAGE($O7:$Z7),""),IF($G7="LAST",IFERROR(LOOKUP(2,1/($O7:$Z7<>""),$O7:$Z7),""),""))) | AB7: =IF($J7="","",IF($AA7="","",IF($J7=0,IF($AA7<=0,1,0),IF($F7="↓",IFERROR($J7/$AA7,0),IFERROR($AA7/$J7,0))))) | AC7: =IF($AB7="","—",IF($AB7>=1,"✅ محقق",IF($AB7>=0.85,"🟡 قريب","🔴 تحت الهدف")))
A8: 5 | B8: الإدارة التنفيذية | C8: الابتكار | D8: نسبة إنجاز مشاريع الخارطة التنفيذية | E8: % | F8: ↑ | G8: LAST | H8: 🟠 مهم | I8: 0.07692 | J8: 1 | K8: 100% | L8: الابتكار | M8: إطلاق مشاريع جديدة | N8: العمليات الداخلية | AA8: =IF($G8="SUM",IF(COUNT($O8:$Z8)=0,"",SUM($O8:$Z8)),IF($G8="AVG",IFERROR(AVERAGE($O8:$Z8),""),IF($G8="LAST",IFERROR(LOOKUP(2,1/($O8:$Z8<>""),$O8:$Z8),""),""))) | AB8: =IF($J8="","",IF($AA8="","",IF($J8=0,IF($AA8<=0,1,0),IF($F8="↓",IFERROR($J8/$AA8,0),IFERROR($AA8/$J8,0))))) | AC8: =IF($AB8="","—",IF($AB8>=1,"✅ محقق",IF($AB8>=0.85,"🟡 قريب","🔴 تحت الهدف")))
A9: 6 | B9: الإدارة التنفيذية | C9: الابتكار | D9: نسبة التحول الرقمي على مستوى الشركة | E9: % | F9: ↑ | G9: LAST | H9: 🟠 مهم | I9: 0.07692 | J9: 0.9 | K9: ≥ 90% | L9: الابتكار | M9: التحول التقني | N9: التعلّم والنمو | AA9: =IF($G9="SUM",IF(COUNT($O9:$Z9)=0,"",SUM($O9:$Z9)),IF($G9="AVG",IFERROR(AVERAGE($O9:$Z9),""),IF($G9="LAST",IFERROR(LOOKUP(2,1/($O9:$Z9<>""),$O9:$Z9),""),""))) | AB9: =IF($J9="","",IF($AA9="","",IF($J9=0,IF($AA9<=0,1,0),IF($F9="↓",IFERROR($J9/$AA9,0),IFERROR($AA9/$J9,0))))) | AC9: =IF($AB9="","—",IF($AB9>=1,"✅ محقق",IF($AB9>=0.85,"🟡 قريب","🔴 تحت الهدف")))
A10: 7 | B10: الإدارة التنفيذية | C10: الاستدامة | D10: مؤشر رضا العملاء العام (الشركة) | E10: % | F10: ↑ | G10: AVG | H10: 🔴 رئيسي | I10: 0.11538 | J10: 0.9 | K10: ≥ 90% | L10: الاستدامة | M10: تعزيز تجربة العملاء | N10: العملاء | AA10: =IF($G10="SUM",IF(COUNT($O10:$Z10)=0,"",SUM($O10:$Z10)),IF($G10="AVG",IFERROR(AVERAGE($O10:$Z10),""),IF($G10="LAST",IFERROR(LOOKUP(2,1/($O10:$Z10<>""),$O10:$Z10),""),""))) | AB10: =IF($J10="","",IF($AA10="","",IF($J10=0,IF($AA10<=0,1,0),IF($F10="↓",IFERROR($J10/$AA10,0),IFERROR($AA10/$J10,0))))) | AC10: =IF($AB10="","—",IF($AB10>=1,"✅ محقق",IF($AB10>=0.85,"🟡 قريب","🔴 تحت الهدف")))
A11: 8 | B11: الإدارة التنفيذية | C11: الاستدامة | D11: مؤشر رضا الموظفين العام (eNPS) | E11: نقطة | F11: ↑ | G11: AVG | H11: 🔴 رئيسي | I11: 0.11538 | J11: 30 | K11: ≥ 30 | L11: الاستدامة | M11: الاستثمار في الموظفين | N11: التعلّم والنمو | AA11: =IF($G11="SUM",IF(COUNT($O11:$Z11)=0,"",SUM($O11:$Z11)),IF($G11="AVG",IFERROR(AVERAGE($O11:$Z11),""),IF($G11="LAST",IFERROR(LOOKUP(2,1/($O11:$Z11<>""),$O11:$Z11),""),""))) | AB11: =IF($J11="","",IF($AA11="","",IF($J11=0,IF($AA11<=0,1,0),IF($F11="↓",IFERROR($J11/$AA11,0),IFERROR($AA11/$J11,0))))) | AC11: =IF($AB11="","—",IF($AB11>=1,"✅ محقق",IF($AB11>=0.85,"🟡 قريب","🔴 تحت الهدف")))
A12: 9 | B12: الإدارة التنفيذية | C12: الاستدامة | D12: نسبة تحقيق المستهدفات الاستراتيجية العامة | E12: % | F12: ↑ | G12: AVG | H12: 🟠 مهم | I12: 0.07692 | J12: 1 | K12: 100% | L12: الاستدامة | M12: جودة التشغيل | N12: العمليات الداخلية | AA12: =IF($G12="SUM",IF(COUNT($O12:$Z12)=0,"",SUM($O12:$Z12)),IF($G12="AVG",IFERROR(AVERAGE($O12:$Z12),""),IF($G12="LAST",IFERROR(LOOKUP(2,1/($O12:$Z12<>""),$O12:$Z12),""),""))) | AB12: =IF($J12="","",IF($AA12="","",IF($J12=0,IF($AA12<=0,1,0),IF($F12="↓",IFERROR($J12/$AA12,0),IFERROR($AA12/$J12,0))))) | AC12: =IF($AB12="","—",IF($AB12>=1,"✅ محقق",IF($AB12>=0.85,"🟡 قريب","🔴 تحت الهدف")))
A13: 10 | B13: الإدارة التنفيذية | C13: النمو | D13: الالتزام بمعايير وزارة الطاقة (تغطية 13 منطقة) | E13: % | F13: ↑ | G13: LAST | H13: 🟠 مهم | I13: 0.07692 | J13: 1 | K13: 100% | L13: النمو | M13: التوسع في المواقع | N13: العمليات الداخلية | AA13: =IF($G13="SUM",IF(COUNT($O13:$Z13)=0,"",SUM($O13:$Z13)),IF($G13="AVG",IFERROR(AVERAGE($O13:$Z13),""),IF($G13="LAST",IFERROR(LOOKUP(2,1/($O13:$Z13<>""),$O13:$Z13),""),""))) | AB13: =IF($J13="","",IF($AA13="","",IF($J13=0,IF($AA13<=0,1,0),IF($F13="↓",IFERROR($J13/$AA13,0),IFERROR($AA13/$J13,0))))) | AC13: =IF($AB13="","—",IF($AB13>=1,"✅ محقق",IF($AB13>=0.85,"🟡 قريب","🔴 تحت الهدف")))
A14: 11 | B14: الامتياز التجاري | C14: النمو والتوسع | D14: عدد محطات الامتياز المشغّلة (تراكمي) | E14: محطة | F14: ↑ | G14: LAST | H14: 🔴 رئيسي | I14: 0.03371 | J14: 150 | K14: 150 محطة | L14: النمو | M14: التوسع في المواقع | N14: العمليات الداخلية | AA14: =IF($G14="SUM",IF(COUNT($O14:$Z14)=0,"",SUM($O14:$Z14)),IF($G14="AVG",IFERROR(AVERAGE($O14:$Z14),""),IF($G14="LAST",IFERROR(LOOKUP(2,1/($O14:$Z14<>""),$O14:$Z14),""),""))) | AB14: =IF($J14="","",IF($AA14="","",IF($J14=0,IF($AA14<=0,1,0),IF($F14="↓",IFERROR($J14/$AA14,0),IFERROR($AA14/$J14,0))))) | AC14: =IF($AB14="","—",IF($AB14>=1,"✅ محقق",IF($AB14>=0.85,"🟡 قريب","🔴 تحت الهدف")))
A15: 12 | B15: الامتياز التجاري | C15: النمو والتوسع | D15: عدد عقود الامتياز الجديدة الموقّعة | E15: عقد | F15: ↑ | G15: SUM | H15: 🔴 رئيسي | I15: 0.03371 | J15: 167 | K15: 167 عقد | L15: النمو | M15: الامتياز التجاري | N15: العمليات الداخلية | AA15: =IF($G15="SUM",IF(COUNT($O15:$Z15)=0,"",SUM($O15:$Z15)),IF($G15="AVG",IFERROR(AVERAGE($O15:$Z15),""),IF($G15="LAST",IFERROR(LOOKUP(2,1/($O15:$Z15<>""),$O15:$Z15),""),""))) | AB15: =IF($J15="","",IF($AA15="","",IF($J15=0,IF($AA15<=0,1,0),IF($F15="↓",IFERROR($J15/$AA15,0),IFERROR($AA15/$J15,0))))) | AC15: =IF($AB15="","—",IF($AB15>=1,"✅ محقق",IF($AB15>=0.85,"🟡 قريب","🔴 تحت الهدف")))
A16: 13 | B16: الامتياز التجاري | C16: المبيعات والأداء التجاري | D16: إجمالي مبيعات وقود محطات الامتياز | E16: لتر | F16: ↑ | G16: SUM | H16: 🔴 رئيسي | I16: 0.03371 | J16: 718838077 | K16: 718.8M لتر | L16: النمو | M16: زيادة وصول العملاء | N16: مالي | AA16: =IF($G16="SUM",IF(COUNT($O16:$Z16)=0,"",SUM($O16:$Z16)),IF($G16="AVG",IFERROR(AVERAGE($O16:$Z16),""),IF($G16="LAST",IFERROR(LOOKUP(2,1/($O16:$Z16<>""),$O16:$Z16),""),""))) | AB16: =IF($J16="","",IF($AA16="","",IF($J16=0,IF($AA16<=0,1,0),IF($F16="↓",IFERROR($J16/$AA16,0),IFERROR($AA16/$J16,0))))) | AC16: =IF($AB16="","—",IF($AB16>=1,"✅ محقق",IF($AB16>=0.85,"🟡 قريب","🔴 تحت الهدف")))
A17: 14 | B17: الامتياز التجاري | C17: المبيعات والأداء التجاري | D17: نسبة المحطات التي حققت مستهدف المبيعات | E17: % | F17: ↑ | G17: AVG | H17: 🔴 رئيسي | I17: 0.03371 | J17: 0.9 | K17: 90%+ | L17: النمو | M17: زيادة وصول العملاء | N17: مالي | AA17: =IF($G17="SUM",IF(COUNT($O17:$Z17)=0,"",SUM($O17:$Z17)),IF($G17="AVG",IFERROR(AVERAGE($O17:$Z17),""),IF($G17="LAST",IFERROR(LOOKUP(2,1/($O17:$Z17<>""),$O17:$Z17),""),""))) | AB17: =IF($J17="","",IF($AA17="","",IF($J17=0,IF($AA17<=0,1,0),IF($F17="↓",IFERROR($J17/$AA17,0),IFERROR($AA17/$J17,0))))) | AC17: =IF($AB17="","—",IF($AB17>=1,"✅ محقق",IF($AB17>=0.85,"🟡 قريب","🔴 تحت الهدف")))
A18: 15 | B18: الامتياز التجاري | C18: المبيعات والأداء التجاري | D18: متوسط مبيعات المحطة الواحدة شهرياً | E18: لتر/محطة | F18: ↑ | G18: AVG | H18: 🔴 رئيسي | I18: 0.03371 | K18: +10% نمو شهري | L18: النمو | M18: زيادة وصول العملاء | N18: مالي | AA18: =IF($G18="SUM",IF(COUNT($O18:$Z18)=0,"",SUM($O18:$Z18)),IF($G18="AVG",IFERROR(AVERAGE($O18:$Z18),""),IF($G18="LAST",IFERROR(LOOKUP(2,1/($O18:$Z18<>""),$O18:$Z18),""),""))) | AB18: =IF($J18="","",IF($AA18="","",IF($J18=0,IF($AA18<=0,1,0),IF($F18="↓",IFERROR($J18/$AA18,0),IFERROR($AA18/$J18,0))))) | AC18: =IF($AB18="","—",IF($AB18>=1,"✅ محقق",IF($AB18>=0.85,"🟡 قريب","🔴 تحت الهدف")))
A19: 16 | B19: الامتياز التجاري | C19: المبيعات والأداء التجاري | D19: نسبة تأجير وحدات الامتياز | E19: % | F19: ↑ | G19: AVG | H19: 🟠 مهم | I19: 0.02247 | J19: 0.7 | K19: 70% | L19: الاستدامة | M19: منظومة التأجير | N19: العمليات الداخلية | AA19: =IF($G19="SUM",IF(COUNT($O19:$Z19)=0,"",SUM($O19:$Z19)),IF($G19="AVG",IFERROR(AVERAGE($O19:$Z19),""),IF($G19="LAST",IFERROR(LOOKUP(2,1/($O19:$Z19<>""),$O19:$Z19),""),""))) | AB19: =IF($J19="","",IF($AA19="","",IF($J19=0,IF($AA19<=0,1,0),IF($F19="↓",IFERROR($J19/$AA19,0),IFERROR($AA19/$J19,0))))) | AC19: =IF($AB19="","—",IF($AB19>=1,"✅ محقق",IF($AB19>=0.85,"🟡 قريب","🔴 تحت الهدف")))
A20: 17 | B20: الامتياز التجاري | C20: الأداء المالي | D20: إجمالي إيرادات إدارة الامتياز | E20: ر.س | F20: ↑ | G20: SUM | H20: 🔴 رئيسي | I20: 0.03371 | K20: تصاعدي مستمر | L20: النمو | M20: الامتياز التجاري | N20: مالي | AA20: =IF($G20="SUM",IF(COUNT($O20:$Z20)=0,"",SUM($O20:$Z20)),IF($G20="AVG",IFERROR(AVERAGE($O20:$Z20),""),IF($G20="LAST",IFERROR(LOOKUP(2,1/($O20:$Z20<>""),$O20:$Z20),""),""))) | AB20: =IF($J20="","",IF($AA20="","",IF($J20=0,IF($AA20<=0,1,0),IF($F20="↓",IFERROR($J20/$AA20,0),IFERROR($AA20/$J20,0))))) | AC20: =IF($AB20="","—",IF($AB20>=1,"✅ محقق",IF($AB20>=0.85,"🟡 قريب","🔴 تحت الهدف")))
A21: 18 | B21: الامتياز التجاري | C21: الأداء المالي | D21: رفع هامش الربحية للامتياز | E21: هللة/لتر | F21: ↑ | G21: AVG | H21: 🟠 مهم | I21: 0.02247 | J21: 1.8 | K21: +1.8 هللة/لتر | L21: النمو | M21: الامتياز التجاري | N21: مالي | AA21: =IF($G21="SUM",IF(COUNT($O21:$Z21)=0,"",SUM($O21:$Z21)),IF($G21="AVG",IFERROR(AVERAGE($O21:$Z21),""),IF($G21="LAST",IFERROR(LOOKUP(2,1/($O21:$Z21<>""),$O21:$Z21),""),""))) | AB21: =IF($J21="","",IF($AA21="","",IF($J21=0,IF($AA21<=0,1,0),IF($F21="↓",IFERROR($J21/$AA21,0),IFERROR($AA21/$J21,0))))) | AC21: =IF($AB21="","—",IF($AB21>=1,"✅ محقق",IF($AB21>=0.85,"🟡 قريب","🔴 تحت الهدف")))
A22: 19 | B22: الامتياز التجاري | C22: الأداء المالي | D22: نسبة التحصيل المالي من شركاء الامتياز | E22: % | F22: ↑ | G22: AVG | H22: 🔴 رئيسي | I22: 0.03371 | J22: 0.95 | K22: 95%+ | L22: الاستدامة | M22: جودة التشغيل | N22: مالي | AA22: =IF($G22="SUM",IF(COUNT($O22:$Z22)=0,"",SUM($O22:$Z22)),IF($G22="AVG",IFERROR(AVERAGE($O22:$Z22),""),IF($G22="LAST",IFERROR(LOOKUP(2,1/($O22:$Z22<>""),$O22:$Z22),""),""))) | AB22: =IF($J22="","",IF($AA22="","",IF($J22=0,IF($AA22<=0,1,0),IF($F22="↓",IFERROR($J22/$AA22,0),IFERROR($AA22/$J22,0))))) | AC22: =IF($AB22="","—",IF($AB22>=1,"✅ محقق",IF($AB22>=0.85,"🟡 قريب","🔴 تحت الهدف")))
A23: 20 | B23: الامتياز التجاري | C23: الأداء المالي | D23: متوسط أيام التحصيل (DSO) | E23: يوم | F23: ↓ | G23: AVG | H23: 🔴 رئيسي | I23: 0.03371 | J23: 30 | K23: ≤ 30 يوم | L23: الاستدامة | M23: جودة التشغيل | N23: مالي | AA23: =IF($G23="SUM",IF(COUNT($O23:$Z23)=0,"",SUM($O23:$Z23)),IF($G23="AVG",IFERROR(AVERAGE($O23:$Z23),""),IF($G23="LAST",IFERROR(LOOKUP(2,1/($O23:$Z23<>""),$O23:$Z23),""),""))) | AB23: =IF($J23="","",IF($AA23="","",IF($J23=0,IF($AA23<=0,1,0),IF($F23="↓",IFERROR($J23/$AA23,0),IFERROR($AA23/$J23,0))))) | AC23: =IF($AB23="","—",IF($AB23>=1,"✅ محقق",IF($AB23>=0.85,"🟡 قريب","🔴 تحت الهدف")))
A24: 21 | B24: الامتياز التجاري | C24: الأداء المالي | D24: إجمالي المستحقات المتأخرة (+30 يوم) | E24: ر.س | F24: ↓ | G24: LAST | H24: 🟠 مهم | I24: 0.02247 | K24: تراجع مستمر | L24: الاستدامة | M24: جودة التشغيل | N24: مالي | AA24: =IF($G24="SUM",IF(COUNT($O24:$Z24)=0,"",SUM($O24:$Z24)),IF($G24="AVG",IFERROR(AVERAGE($O24:$Z24),""),IF($G24="LAST",IFERROR(LOOKUP(2,1/($O24:$Z24<>""),$O24:$Z24),""),""))) | AB24: =IF($J24="","",IF($AA24="","",IF($J24=0,IF($AA24<=0,1,0),IF($F24="↓",IFERROR($J24/$AA24,0),IFERROR($AA24/$J24,0))))) | AC24: =IF($AB24="","—",IF($AB24>=1,"✅ محقق",IF($AB24>=0.85,"🟡 قريب","🔴 تحت الهدف")))
A25: 22 | B25: الامتياز التجاري | C25: الأداء المالي | D25: نسبة الشركاء الملتزمين بمواعيد السداد | E25: % | F25: ↑ | G25: AVG | H25: 🟠 مهم | I25: 0.02247 | J25: 0.9 | K25: 90%+ | L25: الاستدامة | M25: جودة التشغيل | N25: مالي | AA25: =IF($G25="SUM",IF(COUNT($O25:$Z25)=0,"",SUM($O25:$Z25)),IF($G25="AVG",IFERROR(AVERAGE($O25:$Z25),""),IF($G25="LAST",IFERROR(LOOKUP(2,1/($O25:$Z25<>""),$O25:$Z25),""),""))) | AB25: =IF($J25="","",IF($AA25="","",IF($J25=0,IF($AA25<=0,1,0),IF($F25="↓",IFERROR($J25/$AA25,0),IFERROR($AA25/$J25,0))))) | AC25: =IF($AB25="","—",IF($AB25>=1,"✅ محقق",IF($AB25>=0.85,"🟡 قريب","🔴 تحت الهدف")))
A26: 23 | B26: الامتياز التجاري | C26: الأداء المالي | D26: معدل دوران رأس المال (أيام الدورة) | E26: يوم | F26: ↓ | G26: AVG | H26: 🟠 مهم | I26: 0.02247 | J26: 5 | K26: ≤ 5 أيام | L26: الاستدامة | M26: جودة التشغيل | N26: مالي | AA26: =IF($G26="SUM",IF(COUNT($O26:$Z26)=0,"",SUM($O26:$Z26)),IF($G26="AVG",IFERROR(AVERAGE($O26:$Z26),""),IF($G26="LAST",IFERROR(LOOKUP(2,1/($O26:$Z26<>""),$O26:$Z26),""),""))) | AB26: =IF($J26="","",IF($AA26="","",IF($J26=0,IF($AA26<=0,1,0),IF($F26="↓",IFERROR($J26/$AA26,0),IFERROR($AA26/$J26,0))))) | AC26: =IF($AB26="","—",IF($AB26>=1,"✅ محقق",IF($AB26>=0.85,"🟡 قريب","🔴 تحت الهدف")))
A27: 24 | B27: الامتياز التجاري | C27: التشغيل والجودة | D27: نسبة جاهزية محطات الامتياز (صفر انقطاع) | E27: % | F27: ↑ | G27: AVG | H27: 🔴 رئيسي | I27: 0.03371 | J27: 0.99 | K27: 99%+ | L27: الاستدامة | M27: جودة التشغيل | N27: العمليات الداخلية | AA27: =IF($G27="SUM",IF(COUNT($O27:$Z27)=0,"",SUM($O27:$Z27)),IF($G27="AVG",IFERROR(AVERAGE($O27:$Z27),""),IF($G27="LAST",IFERROR(LOOKUP(2,1/($O27:$Z27<>""),$O27:$Z27),""),""))) | AB27: =IF($J27="","",IF($AA27="","",IF($J27=0,IF($AA27<=0,1,0),IF($F27="↓",IFERROR($J27/$AA27,0),IFERROR($AA27/$J27,0))))) | AC27: =IF($AB27="","—",IF($AB27>=1,"✅ محقق",IF($AB27>=0.85,"🟡 قريب","🔴 تحت الهدف")))
A28: 25 | B28: الامتياز التجاري | C28: التشغيل والجودة | D28: عدد حالات انقطاع الوقود الموثّقة | E28: حالة | F28: ↓ | G28: SUM | H28: 🟠 مهم | I28: 0.02247 | J28: 0 | K28: 0 حالة | L28: الاستدامة | M28: جودة التشغيل | N28: العمليات الداخلية | AA28: =IF($G28="SUM",IF(COUNT($O28:$Z28)=0,"",SUM($O28:$Z28)),IF($G28="AVG",IFERROR(AVERAGE($O28:$Z28),""),IF($G28="LAST",IFERROR(LOOKUP(2,1/($O28:$Z28<>""),$O28:$Z28),""),""))) | AB28: =IF($J28="","",IF($AA28="","",IF($J28=0,IF($AA28<=0,1,0),IF($F28="↓",IFERROR($J28/$AA28,0),IFERROR($AA28/$J28,0))))) | AC28: =IF($AB28="","—",IF($AB28>=1,"✅ محقق",IF($AB28>=0.85,"🟡 قريب","🔴 تحت الهدف")))
A29: 26 | B29: الامتياز التجاري | C29: التشغيل والجودة | D29: نسبة إغلاق ملاحظات الجودة الميدانية | E29: % | F29: ↑ | G29: AVG | H29: 🟠 مهم | I29: 0.02247 | J29: 0.95 | K29: 95%+ | L29: الاستدامة | M29: جودة التشغيل | N29: العمليات الداخلية | AA29: =IF($G29="SUM",IF(COUNT($O29:$Z29)=0,"",SUM($O29:$Z29)),IF($G29="AVG",IFERROR(AVERAGE($O29:$Z29),""),IF($G29="LAST",IFERROR(LOOKUP(2,1/($O29:$Z29<>""),$O29:$Z29),""),""))) | AB29: =IF($J29="","",IF($AA29="","",IF($J29=0,IF($AA29<=0,1,0),IF($F29="↓",IFERROR($J29/$AA29,0),IFERROR($AA29/$J29,0))))) | AC29: =IF($AB29="","—",IF($AB29>=1,"✅ محقق",IF($AB29>=0.85,"🟡 قريب","🔴 تحت الهدف")))
A30: 27 | B30: الامتياز التجاري | C30: التشغيل والجودة | D30: متوسط درجة تقييم جودة المحطة (قائمة التحقق) | E30: درجة/100 | F30: ↑ | G30: AVG | H30: 🔴 رئيسي | I30: 0.03371 | J30: 85 | K30: 85+ | L30: الاستدامة | M30: جودة التشغيل | N30: العمليات الداخلية | AA30: =IF($G30="SUM",IF(COUNT($O30:$Z30)=0,"",SUM($O30:$Z30)),IF($G30="AVG",IFERROR(AVERAGE($O30:$Z30),""),IF($G30="LAST",IFERROR(LOOKUP(2,1/($O30:$Z30<>""),$O30:$Z30),""),""))) | AB30: =IF($J30="","",IF($AA30="","",IF($J30=0,IF($AA30<=0,1,0),IF($F30="↓",IFERROR($J30/$AA30,0),IFERROR($AA30/$J30,0))))) | AC30: =IF($AB30="","—",IF($AB30>=1,"✅ محقق",IF($AB30>=0.85,"🟡 قريب","🔴 تحت الهدف")))
A31: 28 | B31: الامتياز التجاري | C31: التشغيل والجودة | D31: نسبة تنفيذ الزيارات الميدانية المجدولة | E31: % | F31: ↑ | G31: AVG | H31: 🟠 مهم | I31: 0.02247 | J31: 1 | K31: 100% | L31: الاستدامة | M31: جودة التشغيل | N31: العمليات الداخلية | AA31: =IF($G31="SUM",IF(COUNT($O31:$Z31)=0,"",SUM($O31:$Z31)),IF($G31="AVG",IFERROR(AVERAGE($O31:$Z31),""),IF($G31="LAST",IFERROR(LOOKUP(2,1/($O31:$Z31<>""),$O31:$Z31),""),""))) | AB31: =IF($J31="","",IF($AA31="","",IF($J31=0,IF($AA31<=0,1,0),IF($F31="↓",IFERROR($J31/$AA31,0),IFERROR($AA31/$J31,0))))) | AC31: =IF($AB31="","—",IF($AB31>=1,"✅ محقق",IF($AB31>=0.85,"🟡 قريب","🔴 تحت الهدف")))
A32: 29 | B32: الامتياز التجاري | C32: التشغيل والجودة | D32: نسبة المحطات المستوفية لمعايير السلامة | E32: % | F32: ↑ | G32: AVG | H32: 🔴 رئيسي | I32: 0.03371 | J32: 1 | K32: 100% | L32: الاستدامة | M32: جودة التشغيل | N32: العمليات الداخلية | AA32: =IF($G32="SUM",IF(COUNT($O32:$Z32)=0,"",SUM($O32:$Z32)),IF($G32="AVG",IFERROR(AVERAGE($O32:$Z32),""),IF($G32="LAST",IFERROR(LOOKUP(2,1/($O32:$Z32<>""),$O32:$Z32),""),""))) | AB32: =IF($J32="","",IF($AA32="","",IF($J32=0,IF($AA32<=0,1,0),IF($F32="↓",IFERROR($J32/$AA32,0),IFERROR($AA32/$J32,0))))) | AC32: =IF($AB32="","—",IF($AB32>=1,"✅ محقق",IF($AB32>=0.85,"🟡 قريب","🔴 تحت الهدف")))
A33: 30 | B33: الامتياز التجاري | C33: التشغيل والجودة | D33: متوسط وقت معالجة البلاغات التشغيلية | E33: ساعة | F33: ↓ | G33: AVG | H33: 🟠 مهم | I33: 0.02247 | J33: 24 | K33: ≤ 24 ساعة | L33: الاستدامة | M33: جودة التشغيل | N33: العمليات الداخلية | AA33: =IF($G33="SUM",IF(COUNT($O33:$Z33)=0,"",SUM($O33:$Z33)),IF($G33="AVG",IFERROR(AVERAGE($O33:$Z33),""),IF($G33="LAST",IFERROR(LOOKUP(2,1/($O33:$Z33<>""),$O33:$Z33),""),""))) | AB33: =IF($J33="","",IF($AA33="","",IF($J33=0,IF($AA33<=0,1,0),IF($F33="↓",IFERROR($J33/$AA33,0),IFERROR($AA33/$J33,0))))) | AC33: =IF($AB33="","—",IF($AB33>=1,"✅ محقق",IF($AB33>=0.85,"🟡 قريب","🔴 تحت الهدف")))
A34: 31 | B34: الامتياز التجاري | C34: التشغيل والجودة | D34: نسبة أتمتة محطات الامتياز | E34: % | F34: ↑ | G34: LAST | H34: 🔴 رئيسي | I34: 0.03371 | J34: 0.9 | K34: 90% | L34: الابتكار | M34: التحول التقني | N34: التعلّم والنمو | AA34: =IF($G34="SUM",IF(COUNT($O34:$Z34)=0,"",SUM($O34:$Z34)),IF($G34="AVG",IFERROR(AVERAGE($O34:$Z34),""),IF($G34="LAST",IFERROR(LOOKUP(2,1/($O34:$Z34<>""),$O34:$Z34),""),""))) | AB34: =IF($J34="","",IF($AA34="","",IF($J34=0,IF($AA34<=0,1,0),IF($F34="↓",IFERROR($J34/$AA34,0),IFERROR($AA34/$J34,0))))) | AC34: =IF($AB34="","—",IF($AB34>=1,"✅ محقق",IF($AB34>=0.85,"🟡 قريب","🔴 تحت الهدف")))
A35: 32 | B35: الامتياز التجاري | C35: التشغيل والجودة | D35: نسبة تطبيق المعيار الشامل داخل المحطات | E35: % | F35: ↑ | G35: LAST | H35: 🟡 متابعة | I35: 0.01124 | J35: 0.3 | K35: 30% | L35: الابتكار | M35: التحول التقني | N35: العمليات الداخلية | AA35: =IF($G35="SUM",IF(COUNT($O35:$Z35)=0,"",SUM($O35:$Z35)),IF($G35="AVG",IFERROR(AVERAGE($O35:$Z35),""),IF($G35="LAST",IFERROR(LOOKUP(2,1/($O35:$Z35<>""),$O35:$Z35),""),""))) | AB35: =IF($J35="","",IF($AA35="","",IF($J35=0,IF($AA35<=0,1,0),IF($F35="↓",IFERROR($J35/$AA35,0),IFERROR($AA35/$J35,0))))) | AC35: =IF($AB35="","—",IF($AB35>=1,"✅ محقق",IF($AB35>=0.85,"🟡 قريب","🔴 تحت الهدف")))
A36: 33 | B36: الامتياز التجاري | C36: الهوية والتسويق | D36: نسبة التزام المحطات بالهوية المؤسسية | E36: % | F36: ↑ | G36: LAST | H36: 🔴 رئيسي | I36: 0.03371 | J36: 0.55 | K36: 55% | L36: الابتكار | M36: تطوير التصاميم والهوية | N36: التعلّم والنمو | AA36: =IF($G36="SUM",IF(COUNT($O36:$Z36)=0,"",SUM($O36:$Z36)),IF($G36="AVG",IFERROR(AVERAGE($O36:$Z36),""),IF($G36="LAST",IFERROR(LOOKUP(2,1/($O36:$Z36<>""),$O36:$Z36),""),""))) | AB36: =IF($J36="","",IF($AA36="","",IF($J36=0,IF($AA36<=0,1,0),IF($F36="↓",IFERROR($J36/$AA36,0),IFERROR($AA36/$J36,0))))) | AC36: =IF($AB36="","—",IF($AB36>=1,"✅ محقق",IF($AB36>=0.85,"🟡 قريب","🔴 تحت الهدف")))
... A43: 40 | B43: الامتياز التجاري | C43: تجربة العملاء والشركاء | D43: نسبة حل الشكاوى خلال المدة المحددة | E43: % | F43: ↑ | G43: AVG | H43: 🟠 مهم | I43: 0.02247 | J43: 0.95 | K43: 95%+ | L43: الاستدامة | M43: تعزيز تجربة العملاء | N43: العملاء | AA43: =IF($G43="SUM",IF(COUNT($O43:$Z43)=0,"",SUM($O43:$Z43)),IF($G43="AVG",IFERROR(AVERAGE($O43:$Z43),""),IF($G43="LAST",IFERROR(LOOKUP(2,1/($O43:$Z43<>""),$O43:$Z43),""),""))) | AB43: =IF($J43="","",IF($AA43="","",IF($J43=0,IF($AA43<=0,1,0),IF($F43="↓",IFERROR($J43/$AA43,0),IFERROR($AA43/$J43,0))))) | AC43: =IF($AB43="","—",IF($AB43>=1,"✅ محقق",IF($AB43>=0.85,"🟡 قريب","🔴 تحت الهدف")))
A44: 41 | B44: الامتياز التجاري | C44: تجربة العملاء والشركاء | D44: نسبة انخفاض الشكاوى التشغيلية والإدارية | E44: % | F44: ↑ | G44: AVG | H44: 🟠 مهم | I44: 0.02247 | K44: -30% | L44: الاستدامة | M44: تعزيز تجربة العملاء | N44: العملاء | AA44: =IF($G44="SUM",IF(COUNT($O44:$Z44)=0,"",SUM($O44:$Z44)),IF($G44="AVG",IFERROR(AVERAGE($O44:$Z44),""),IF($G44="LAST",IFERROR(LOOKUP(2,1/($O44:$Z44<>""),$O44:$Z44),""),""))) | AB44: =IF($J44="","",IF($AA44="","",IF($J44=0,IF($AA44<=0,1,0),IF($F44="↓",IFERROR($J44/$AA44,0),IFERROR($AA44/$J44,0))))) | AC44: =IF($AB44="","—",IF($AB44>=1,"✅ محقق",IF($AB44>=0.85,"🟡 قريب","🔴 تحت الهدف")))
A45: 42 | B45: الامتياز التجاري | C45: استدامة الشراكة والامتثال | D45: نسبة استدامة أصحاب الامتياز (Retention) | E45: % | F45: ↑ | G45: LAST | H45: 🟠 مهم | I45: 0.02247 | J45: 0.9 | K45: 90% | L45: الاستدامة | M45: تعزيز تجربة العملاء | N45: العمليات الداخلية | AA45: =IF($G45="SUM",IF(COUNT($O45:$Z45)=0,"",SUM($O45:$Z45)),IF($G45="AVG",IFERROR(AVERAGE($O45:$Z45),""),IF($G45="LAST",IFERROR(LOOKUP(2,1/($O45:$Z45<>""),$O45:$Z45),""),""))) | AB45: =IF($J45="","",IF($AA45="","",IF($J45=0,IF($AA45<=0,1,0),IF($F45="↓",IFERROR($J45/$AA45,0),IFERROR($AA45/$J45,0))))) | AC45: =IF($AB45="","—",IF($AB45>=1,"✅ محقق",IF($AB45>=0.85,"🟡 قريب","🔴 تحت الهدف")))
A46: 43 | B46: الامتياز التجاري | C46: استدامة الشراكة والامتثال | D46: نسبة زيادة عدد أصحاب الامتياز | E46: % | F46: ↑ | G46: LAST | H46: 🟠 مهم | I46: 0.02247 | J46: 1 | K46: 100% نمو | L46: الاستدامة | M46: تعزيز تجربة العملاء | N46: العمليات الداخلية | AA46: =IF($G46="SUM",IF(COUNT($O46:$Z46)=0,"",SUM($O46:$Z46)),IF($G46="AVG",IFERROR(AVERAGE($O46:$Z46),""),IF($G46="LAST",IFERROR(LOOKUP(2,1/($O46:$Z46<>""),$O46:$Z46),""),""))) | AB46: =IF($J46="","",IF($AA46="","",IF($J46=0,IF($AA46<=0,1,0),IF($F46="↓",IFERROR($J46/$AA46,0),IFERROR($AA46/$J46,0))))) | AC46: =IF($AB46="","—",IF($AB46>=1,"✅ محقق",IF($AB46>=0.85,"🟡 قريب","🔴 تحت الهدف")))
...
