Workbook

Sheet دليل الاستخدام
B2: درب · المنظومة الاستراتيجية لمؤشرات الأداء 2026 — قطاع المحطات والعقار
B4: 🧭 الفكرة — ملف واحد يتدرّج من فوق لتحت: الاستراتيجية ← لوحة الإدارة التنفيذية ← مؤشرات كل إدارة ← تقييم كل موظف. كل المؤشرات تغذّي نفس اللوحة تلقائياً.
B5: 🟩 خلايا الإدخال — الخلايا الخضراء فقط قابلة للتعديل — يدخل فيها المسؤول أرقامه الشهرية. باقي الخلايا (المؤشر/المستهدف/المعادلة) مقفولة ومحمية.
B6: 🔢 المعادلات — نسبة التحقيق وYTD والحالة والدرجات تُحسب آلياً بمعادلات حقيقية. لا تُكتب يدوياً.
B7: 🔒 الحماية — كل شيت محمي بكلمة مرور: darb2026 — لفك الحماية مؤقتاً للتعديل على الهيكل: مراجعة ← حماية الورقة ← أدخل كلمة المرور.
B8: 👤 الصلاحيات — عند التوزيع: كل موظف/مسؤول يُمنح صلاحية الإدخال على نطاق خلاياه الخضراء فقط (Allow Edit Ranges في Excel / صلاحيات الورقة في SharePoint). الهيكل والمستهدفات تبقى مقفولة للجميع.
B9: 📊 الحالة — ✅ محقق = 100%+ | 🟡 قريب = 85%–99% | 🔴 تحت الهدف = أقل من 85% | — = بانتظار إدخال / مستهدف وصفي.
B10: 🏢 الإدارات — هذا الإصدار يحتوي نموذج إدارة الامتياز التجاري كاملاً. الإدارات الأخرى (التشغيل، الاستثمار، العقار) تُضاف لنفس الملف وتغذّي نفس اللوحة التنفيذية.

Sheet الاستراتيجية
B2: ركائز واستراتيجية درب 2026 — قطاع المحطات والعقار
B4: الركيزة / الهدف | C4: الوصف | D4: المستهدف الرقمي 2026
B5: النمو | C5: التوسع في المواقع وزيادة الوصول للعملاء وتنمية الإيرادات.
B6: التوسع في المواقع | C6: افتتاح وتشغيل محطات جديدة. | D6: التشغيل: 85 محطة · الامتياز: 150 محطة
B7: الامتياز والعقود | C7: تنمية الإيرادات عبر الامتياز والاستثمار. | D7: الامتياز: 167 عقد · الاستثمار: 190 عقد
B8: زيادة وصول العملاء | C8: رفع المبيعات والتغطية الجغرافية. | D8: 718.8M لتر · 13 منطقة · 59 مدينة
B9: الابتكار | C9: مشاريع جديدة وتحول تقني وتطوير الهوية.
B10: الهوية والتصاميم | C10: تطبيق الهوية المؤسسية في المحطات. | D10: التزام 55% بالهوية
B11: التحول التقني وساحات درب | C11: أتمتة المحطات وتطوير ساحات درب وتطبيق تانكي. | D11: أتمتة 90% · تأجير ساحة درب ≥80%
B12: الاستدامة | C12: جودة التشغيل وتجربة العميل والاستثمار في الموظفين.
B13: تجربة العملاء | C13: رفع الرضا وجودة التجربة. | D13: قوقل ≥4.5–4.7 · CSAT ≥90%
B14: جودة التشغيل | C14: كفاءة وجودة عمليات المحطات. | D14: جاهزية 99% · سلامة 100%
B15: منظومة التأجير (العقار) | C15: الإشغال والتحصيل واستدامة المستأجرين. | D15: إشغال ≥60% · 246 علامة · تحصيل 95%+
B16: الاستثمار في الموظفين | C16: التطوير والاستبقاء. | D16: استبقاء الشركاء 90%+

Sheet الخارطة التنفيذية
A1: الخارطة التنفيذية 2026 — مشاريع الشركة وربطها بالمؤشرات (قطاع المحطات والعقار)
A2: المصدر: «رؤية وأهداف 2026» — سحور درب · التغطية: ✅ مرتبط 🟡 جزئي 🔴 فجوة · أداء المؤشرات يُحسب آلياً من المؤشرات المرتبطة
A3: # | B3: الركيزة | C3: المشروع | D3: الإدارة المسؤولة | E3: المؤشرات المرتبطة | F3: التغطية | G3: أداء المؤشرات (مباشر)
A4: 1 | B4: النمو | C4: التوسع في المواقع | D4: التشغيل + الامتياز + الاستثمار | E4: محطات الامتياز المشغّلة (150) · تشغيل 85 محطة · 190 عقد استثماري | F4: ✅ مرتبط | G4: =IF(COUNTIFS('الامتياز · المؤشرات'!$Y$4:$Y$39,"التوسع في المواقع")=0,"—",IFERROR(AVERAGEIFS('الامتياز · المؤشرات'!$V$4:$V$39,'الامتياز · المؤشرات'!$Y$4:$Y$39,"التوسع في المواقع"),"—"))
A5: 2 | C5: الامتياز التجاري | D5: الامتياز التجاري | E5: عقود الامتياز الجديدة (167) · إجمالي مبيعات الوقود | F5: ✅ مرتبط | G5: =IF(COUNTIFS('الامتياز · المؤشرات'!$Y$4:$Y$39,"الامتياز التجاري")=0,"—",IFERROR(AVERAGEIFS('الامتياز · المؤشرات'!$V$4:$V$39,'الامتياز · المؤشرات'!$Y$4:$Y$39,"الامتياز التجاري"),"—"))
A6: 3 | C6: زيادة وصول العملاء | D6: الامتياز + التسويق | E6: إجمالي مبيعات الوقود (718.8M) · تغطية 13 منطقة | F6: ✅ مرتبط | G6: =IF(COUNTIFS('الامتياز · المؤشرات'!$Y$4:$Y$39,"زيادة وصول العملاء")=0,"—",IFERROR(AVERAGEIFS('الامتياز · المؤشرات'!$V$4:$V$39,'الامتياز · المؤشرات'!$Y$4:$Y$39,"زيادة وصول العملاء"),"—"))
A7: 4 | B7: الابتكار | C7: إطلاق مشاريع جديدة | D7: غير محددة — مقترح: الاستثمار/التطوير | E7: — لا يوجد مؤشر مخصص — | F7: 🔴 فجوة | G7: =IF(COUNTIFS('الامتياز · المؤشرات'!$Y$4:$Y$39,"إطلاق مشاريع جديدة")=0,"—",IFERROR(AVERAGEIFS('الامتياز · المؤشرات'!$V$4:$V$39,'الامتياز · المؤشرات'!$Y$4:$Y$39,"إطلاق مشاريع جديدة"),"—"))
A8: 5 | C8: تطوير التصاميم والهوية | D8: غير محددة — مقترح: التسويق والعلامة | E8: نسبة التزام المحطات بالهوية (55%) فقط | F8: 🟡 مرتبط جزئياً | G8: =IF(COUNTIFS('الامتياز · المؤشرات'!$Y$4:$Y$39,"تطوير التصاميم والهوية")=0,"—",IFERROR(AVERAGEIFS('الامتياز · المؤشرات'!$V$4:$V$39,'الامتياز · المؤشرات'!$Y$4:$Y$39,"تطوير التصاميم والهوية"),"—"))
A9: 6 | C9: التحول التقني | D9: غير محددة — مقترح: تقنية المعلومات | E9: أتمتة المحطات (90%) · المعيار الشامل (30%) | F9: 🟡 مرتبط جزئياً | G9: =IF(COUNTIFS('الامتياز · المؤشرات'!$Y$4:$Y$39,"التحول التقني")=0,"—",IFERROR(AVERAGEIFS('الامتياز · المؤشرات'!$V$4:$V$39,'الامتياز · المؤشرات'!$Y$4:$Y$39,"التحول التقني"),"—"))
A10: 7 | C10: ساحات درب | D10: العقار | E10: تأجير ساحة درب (≥80%) · 6 علامات جديدة | F10: ✅ مرتبط | G10: =IF(COUNTIFS('الامتياز · المؤشرات'!$Y$4:$Y$39,"ساحات درب")=0,"—",IFERROR(AVERAGEIFS('الامتياز · المؤشرات'!$V$4:$V$39,'الامتياز · المؤشرات'!$Y$4:$Y$39,"ساحات درب"),"—"))
A11: 8 | C11: تطبيق «تانكي» | D11: غير محددة | E11: — لا يوجد مؤشر ولا إدارة مسؤولة — | F11: 🔴 فجوة | G11: =IF(COUNTIFS('الامتياز · المؤشرات'!$Y$4:$Y$39,"تطبيق «تانكي»")=0,"—",IFERROR(AVERAGEIFS('الامتياز · المؤشرات'!$V$4:$V$39,'الامتياز · المؤشرات'!$Y$4:$Y$39,"تطبيق «تانكي»"),"—"))
A12: 9 | B12: الاستدامة | C12: تعزيز تجربة العملاء | D12: الامتياز + التشغيل | E12: CSAT (90%) · تقييم قوقل (4.5+) · حل الشكاوى | F12: ✅ مرتبط | G12: =IF(COUNTIFS('الامتياز · المؤشرات'!$Y$4:$Y$39,"تعزيز تجربة العملاء")=0,"—",IFERROR(AVERAGEIFS('الامتياز · المؤشرات'!$V$4:$V$39,'الامتياز · المؤشرات'!$Y$4:$Y$39,"تعزيز تجربة العملاء"),"—"))
A13: 10 | C13: جودة التشغيل | D13: التشغيل + الامتياز | E13: جاهزية 99% · السلامة 100% · 15 مؤشر تشغيلي | F13: ✅ مرتبط | G13: =IF(COUNTIFS('الامتياز · المؤشرات'!$Y$4:$Y$39,"جودة التشغيل")=0,"—",IFERROR(AVERAGEIFS('الامتياز · المؤشرات'!$V$4:$V$39,'الامتياز · المؤشرات'!$Y$4:$Y$39,"جودة التشغيل"),"—"))
A14: 11 | C14: منظومة التأجير | D14: العقار | E14: الإشغال (≥60%) · 68 وحدة/شهر · التحصيل (95%+) | F14: ✅ مرتبط | G14: =IF(COUNTIFS('الامتياز · المؤشرات'!$Y$4:$Y$39,"منظومة التأجير")=0,"—",IFERROR(AVERAGEIFS('الامتياز · المؤشرات'!$V$4:$V$39,'الامتياز · المؤشرات'!$Y$4:$Y$39,"منظومة التأجير"),"—"))
A15: 12 | C15: الاستثمار في الموظفين | D15: غير محددة — مقترح: الموارد البشرية | E15: — لا يوجد مؤشر لتطوير/استبقاء الموظفين — | F15: 🔴 فجوة | G15: =IF(COUNTIFS('الامتياز · المؤشرات'!$Y$4:$Y$39,"الاستثمار في الموظفين")=0,"—",IFERROR(AVERAGEIFS('الامتياز · المؤشرات'!$V$4:$V$39,'الامتياز · المؤشرات'!$Y$4:$Y$39,"الاستثمار في الموظفين"),"—"))
B17: ⚠️ ملخص الفجوات — مشاريع تحتاج مؤشراً أو إدارة مسؤولة
B18: 🔴 تطبيق «تانكي» — لا مؤشر ولا إدارة مسؤولة (منتج رقمي بلا مالك).
B19: 🔴 الاستثمار في الموظفين — لا مؤشر موظفين ولا إدارة موارد بشرية ضمن الملفات.
B20: 🔴 إطلاق مشاريع جديدة — مبادرة بلا مؤشر مخصص ولا مالك واضح.
B21: 🟡 التحول التقني — مغطّى جزئياً بالأتمتة فقط؛ بلا إدارة تقنية مالكة.
B22: 🟡 تطوير التصاميم والهوية — مغطّى بمؤشر التزام الهوية فقط؛ بلا إدارة تسويق/علامة.

Sheet لوحة الإدارة التنفيذية
B2: درب · لوحة الإدارة التنفيذية 2026 — المحطات والعقار
B4: مؤشر الإنجاز العام (الامتياز) | D4: ✅ محقق | E4: 🟡 قريب | F4: 🔴 تحت الهدف | H4: الأداء حسب الركائز (5 سنوات)
B5: =IFERROR(AVERAGE('الامتياز · المؤشرات'!$V$4:$V$39),0) | D5: =COUNTIF('الامتياز · المؤشرات'!$W$4:$W$39,"✅ محقق") | E5: =COUNTIF('الامتياز · المؤشرات'!$W$4:$W$39,"🟡 قريب") | F5: =COUNTIF('الامتياز · المؤشرات'!$W$4:$W$39,"🔴 تحت الهدف") | H5: الركيزة | I5: الإنجاز | J5: الحالة
H6: النمو | I6: =IFERROR(AVERAGEIFS('الامتياز · المؤشرات'!$V$4:$V$39,'الامتياز · المؤشرات'!$X$4:$X$39,"النمو"),"—") | J6: =IF(ISNUMBER(I6),IF(I6>=1,"✅",IF(I6>=0.85,"🟡","🔴")),"—")
H7: الابتكار | I7: =IFERROR(AVERAGEIFS('الامتياز · المؤشرات'!$V$4:$V$39,'الامتياز · المؤشرات'!$X$4:$X$39,"الابتكار"),"—") | J7: =IF(ISNUMBER(I7),IF(I7>=1,"✅",IF(I7>=0.85,"🟡","🔴")),"—")
B8: الأداء حسب المحور — إدارة الامتياز | H8: الاستدامة | I8: =IFERROR(AVERAGEIFS('الامتياز · المؤشرات'!$V$4:$V$39,'الامتياز · المؤشرات'!$X$4:$X$39,"الاستدامة"),"—") | J8: =IF(ISNUMBER(I8),IF(I8>=1,"✅",IF(I8>=0.85,"🟡","🔴")),"—")
B9: المحور | C9: نسبة التحقيق | D9: الحالة
B10: النمو والتوسع | C10: =IFERROR(AVERAGEIFS('الامتياز · المؤشرات'!$V$4:$V$39,'الامتياز · المؤشرات'!$B$4:$B$39,"النمو والتوسع"),0) | D10: =IF(C10>=1,"✅ محقق",IF(C10>=0.85,"🟡 قريب","🔴 تحت الهدف"))
B11: المبيعات والأداء التجاري | C11: =IFERROR(AVERAGEIFS('الامتياز · المؤشرات'!$V$4:$V$39,'الامتياز · المؤشرات'!$B$4:$B$39,"المبيعات والأداء التجاري"),0) | D11: =IF(C11>=1,"✅ محقق",IF(C11>=0.85,"🟡 قريب","🔴 تحت الهدف"))
B12: الأداء المالي | C12: =IFERROR(AVERAGEIFS('الامتياز · المؤشرات'!$V$4:$V$39,'الامتياز · المؤشرات'!$B$4:$B$39,"الأداء المالي"),0) | D12: =IF(C12>=1,"✅ محقق",IF(C12>=0.85,"🟡 قريب","🔴 تحت الهدف"))
B13: التشغيل والجودة | C13: =IFERROR(AVERAGEIFS('الامتياز · المؤشرات'!$V$4:$V$39,'الامتياز · المؤشرات'!$B$4:$B$39,"التشغيل والجودة"),0) | D13: =IF(C13>=1,"✅ محقق",IF(C13>=0.85,"🟡 قريب","🔴 تحت الهدف"))
B14: الهوية والتسويق | C14: =IFERROR(AVERAGEIFS('الامتياز · المؤشرات'!$V$4:$V$39,'الامتياز · المؤشرات'!$B$4:$B$39,"الهوية والتسويق"),0) | D14: =IF(C14>=1,"✅ محقق",IF(C14>=0.85,"🟡 قريب","🔴 تحت الهدف"))
B15: التوسع الإقليمي | C15: =IFERROR(AVERAGEIFS('الامتياز · المؤشرات'!$V$4:$V$39,'الامتياز · المؤشرات'!$B$4:$B$39,"التوسع الإقليمي"),0) | D15: =IF(C15>=1,"✅ محقق",IF(C15>=0.85,"🟡 قريب","🔴 تحت الهدف"))
B16: تجربة العملاء والشركاء | C16: =IFERROR(AVERAGEIFS('الامتياز · المؤشرات'!$V$4:$V$39,'الامتياز · المؤشرات'!$B$4:$B$39,"تجربة العملاء والشركاء"),0) | D16: =IF(C16>=1,"✅ محقق",IF(C16>=0.85,"🟡 قريب","🔴 تحت الهدف"))
B17: استدامة الشراكة والامتثال | C17: =IFERROR(AVERAGEIFS('الامتياز · المؤشرات'!$V$4:$V$39,'الامتياز · المؤشرات'!$B$4:$B$39,"استدامة الشراكة والامتثال"),0) | D17: =IF(C17>=1,"✅ محقق",IF(C17>=0.85,"🟡 قريب","🔴 تحت الهدف"))
B19: نظرة الإدارات (تغذي نفس الملف)
B20: الإدارة | C20: الإنجاز | D20: الحالة
B21: الامتياز التجاري والمبيعات | C21: =IFERROR(AVERAGE('الامتياز · المؤشرات'!$V$4:$V$39),0) | D21: =IF(C21>=1,"✅ محقق",IF(C21>=0.85,"🟡 قريب","🔴 تحت الهدف"))
B22: التشغيل والمحطات | C22: قيد الإضافة | D22: —
B23: الاستثمار | C23: قيد الإضافة | D23: —
B24: العقار | C24: قيد الإضافة | D24: —

Sheet الامتياز · المؤشرات
A1: إدارة الامتياز التجاري والمبيعات · مؤشرات الأداء 2026 (36 مؤشر / 8 محاور)
A2: 🟩 الخلايا الخضراء = إدخال شهري للمسؤول · باقي الأعمدة محسوبة/مقفولة · كل مؤشر يغذّي ركيزته ومشروعه تلقائياً
A3: # | B3: المحور | C3: المؤشر | D3: الوحدة | E3: القطبية | F3: التجميع | G3: المستهدف | H3: نص المستهدف | I3: يناير | J3: فبراير | K3: مارس | L3: أبريل | M3: مايو | N3: يونيو | O3: يوليو | P3: أغسطس | Q3: سبتمبر | R3: أكتوبر | S3: نوفمبر | T3: ديسمبر | U3: YTD | V3: نسبة التحقيق | W3: الحالة | X3: الركيزة (5س) | Y3: المشروع (الخارطة)
A4: 1 | B4: النمو والتوسع | C4: عدد محطات الامتياز المشغّلة (تراكمي) | D4: محطة | E4: ↑ | F4: LAST | G4: 150 | H4: 150 محطة | U4: =IF($F4="SUM",IF(COUNT($I4:$T4)=0,"",SUM($I4:$T4)),IF($F4="AVG",IFERROR(AVERAGE($I4:$T4),""),IF($F4="LAST",IFERROR(LOOKUP(2,1/($I4:$T4<>""),$I4:$T4),""),""))) | V4: =IF($G4="","",IF($U4="","",IF($G4=0,IF($U4<=0,1,0),IF($E4="↓",IFERROR($G4/$U4,0),IFERROR($U4/$G4,0))))) | W4: =IF($V4="","—",IF($V4>=1,"✅ محقق",IF($V4>=0.85,"🟡 قريب","🔴 تحت الهدف"))) | X4: النمو | Y4: التوسع في المواقع
A5: 2 | B5: النمو والتوسع | C5: عدد عقود الامتياز الجديدة الموقّعة | D5: عقد | E5: ↑ | F5: SUM | G5: 167 | H5: 167 عقد | U5: =IF($F5="SUM",IF(COUNT($I5:$T5)=0,"",SUM($I5:$T5)),IF($F5="AVG",IFERROR(AVERAGE($I5:$T5),""),IF($F5="LAST",IFERROR(LOOKUP(2,1/($I5:$T5<>""),$I5:$T5),""),""))) | V5: =IF($G5="","",IF($U5="","",IF($G5=0,IF($U5<=0,1,0),IF($E5="↓",IFERROR($G5/$U5,0),IFERROR($U5/$G5,0))))) | W5: =IF($V5="","—",IF($V5>=1,"✅ محقق",IF($V5>=0.85,"🟡 قريب","🔴 تحت الهدف"))) | X5: النمو | Y5: الامتياز التجاري
A6: 3 | B6: المبيعات والأداء التجاري | C6: إجمالي مبيعات وقود محطات الامتياز | D6: لتر | E6: ↑ | F6: SUM | G6: 718838077 | H6: 718.8M لتر | U6: =IF($F6="SUM",IF(COUNT($I6:$T6)=0,"",SUM($I6:$T6)),IF($F6="AVG",IFERROR(AVERAGE($I6:$T6),""),IF($F6="LAST",IFERROR(LOOKUP(2,1/($I6:$T6<>""),$I6:$T6),""),""))) | V6: =IF($G6="","",IF($U6="","",IF($G6=0,IF($U6<=0,1,0),IF($E6="↓",IFERROR($G6/$U6,0),IFERROR($U6/$G6,0))))) | W6: =IF($V6="","—",IF($V6>=1,"✅ محقق",IF($V6>=0.85,"🟡 قريب","🔴 تحت الهدف"))) | X6: النمو | Y6: زيادة وصول العملاء
A7: 4 | B7: المبيعات والأداء التجاري | C7: نسبة المحطات التي حققت مستهدف المبيعات | D7: % | E7: ↑ | F7: AVG | G7: 0.9 | H7: 90%+ | U7: =IF($F7="SUM",IF(COUNT($I7:$T7)=0,"",SUM($I7:$T7)),IF($F7="AVG",IFERROR(AVERAGE($I7:$T7),""),IF($F7="LAST",IFERROR(LOOKUP(2,1/($I7:$T7<>""),$I7:$T7),""),""))) | V7: =IF($G7="","",IF($U7="","",IF($G7=0,IF($U7<=0,1,0),IF($E7="↓",IFERROR($G7/$U7,0),IFERROR($U7/$G7,0))))) | W7: =IF($V7="","—",IF($V7>=1,"✅ محقق",IF($V7>=0.85,"🟡 قريب","🔴 تحت الهدف"))) | X7: النمو | Y7: زيادة وصول العملاء
A8: 5 | B8: المبيعات والأداء التجاري | C8: متوسط مبيعات المحطة الواحدة شهرياً | D8: لتر/محطة | E8: ↑ | F8: AVG | H8: +10% نمو شهري | U8: =IF($F8="SUM",IF(COUNT($I8:$T8)=0,"",SUM($I8:$T8)),IF($F8="AVG",IFERROR(AVERAGE($I8:$T8),""),IF($F8="LAST",IFERROR(LOOKUP(2,1/($I8:$T8<>""),$I8:$T8),""),""))) | V8: =IF($G8="","",IF($U8="","",IF($G8=0,IF($U8<=0,1,0),IF($E8="↓",IFERROR($G8/$U8,0),IFERROR($U8/$G8,0))))) | W8: =IF($V8="","—",IF($V8>=1,"✅ محقق",IF($V8>=0.85,"🟡 قريب","🔴 تحت الهدف"))) | X8: النمو | Y8: زيادة وصول العملاء
A9: 6 | B9: المبيعات والأداء التجاري | C9: نسبة تأجير وحدات الامتياز | D9: % | E9: ↑ | F9: AVG | G9: 0.7 | H9: 70% | U9: =IF($F9="SUM",IF(COUNT($I9:$T9)=0,"",SUM($I9:$T9)),IF($F9="AVG",IFERROR(AVERAGE($I9:$T9),""),IF($F9="LAST",IFERROR(LOOKUP(2,1/($I9:$T9<>""),$I9:$T9),""),""))) | V9: =IF($G9="","",IF($U9="","",IF($G9=0,IF($U9<=0,1,0),IF($E9="↓",IFERROR($G9/$U9,0),IFERROR($U9/$G9,0))))) | W9: =IF($V9="","—",IF($V9>=1,"✅ محقق",IF($V9>=0.85,"🟡 قريب","🔴 تحت الهدف"))) | X9: الاستدامة | Y9: منظومة التأجير
A10: 7 | B10: الأداء المالي | C10: إجمالي إيرادات إدارة الامتياز | D10: ر.س | E10: ↑ | F10: SUM | H10: تصاعدي مستمر | U10: =IF($F10="SUM",IF(COUNT($I10:$T10)=0,"",SUM($I10:$T10)),IF($F10="AVG",IFERROR(AVERAGE($I10:$T10),""),IF($F10="LAST",IFERROR(LOOKUP(2,1/($I10:$T10<>""),$I10:$T10),""),""))) | V10: =IF($G10="","",IF($U10="","",IF($G10=0,IF($U10<=0,1,0),IF($E10="↓",IFERROR($G10/$U10,0),IFERROR($U10/$G10,0))))) | W10: =IF($V10="","—",IF($V10>=1,"✅ محقق",IF($V10>=0.85,"🟡 قريب","🔴 تحت الهدف"))) | X10: النمو | Y10: الامتياز التجاري
A11: 8 | B11: الأداء المالي | C11: رفع هامش الربحية للامتياز | D11: هللة/لتر | E11: ↑ | F11: AVG | G11: 1.8 | H11: +1.8 هللة/لتر | U11: =IF($F11="SUM",IF(COUNT($I11:$T11)=0,"",SUM($I11:$T11)),IF($F11="AVG",IFERROR(AVERAGE($I11:$T11),""),IF($F11="LAST",IFERROR(LOOKUP(2,1/($I11:$T11<>""),$I11:$T11),""),""))) | V11: =IF($G11="","",IF($U11="","",IF($G11=0,IF($U11<=0,1,0),IF($E11="↓",IFERROR($G11/$U11,0),IFERROR($U11/$G11,0))))) | W11: =IF($V11="","—",IF($V11>=1,"✅ محقق",IF($V11>=0.85,"🟡 قريب","🔴 تحت الهدف"))) | X11: النمو | Y11: الامتياز التجاري
A12: 9 | B12: الأداء المالي | C12: نسبة التحصيل المالي من شركاء الامتياز | D12: % | E12: ↑ | F12: AVG | G12: 0.95 | H12: 95%+ | U12: =IF($F12="SUM",IF(COUNT($I12:$T12)=0,"",SUM($I12:$T12)),IF($F12="AVG",IFERROR(AVERAGE($I12:$T12),""),IF($F12="LAST",IFERROR(LOOKUP(2,1/($I12:$T12<>""),$I12:$T12),""),""))) | V12: =IF($G12="","",IF($U12="","",IF($G12=0,IF($U12<=0,1,0),IF($E12="↓",IFERROR($G12/$U12,0),IFERROR($U12/$G12,0))))) | W12: =IF($V12="","—",IF($V12>=1,"✅ محقق",IF($V12>=0.85,"🟡 قريب","🔴 تحت الهدف"))) | X12: الاستدامة | Y12: جودة التشغيل
A13: 10 | B13: الأداء المالي | C13: متوسط أيام التحصيل (DSO) | D13: يوم | E13: ↓ | F13: AVG | G13: 30 | H13: ≤ 30 يوم | U13: =IF($F13="SUM",IF(COUNT($I13:$T13)=0,"",SUM($I13:$T13)),IF($F13="AVG",IFERROR(AVERAGE($I13:$T13),""),IF($F13="LAST",IFERROR(LOOKUP(2,1/($I13:$T13<>""),$I13:$T13),""),""))) | V13: =IF($G13="","",IF($U13="","",IF($G13=0,IF($U13<=0,1,0),IF($E13="↓",IFERROR($G13/$U13,0),IFERROR($U13/$G13,0))))) | W13: =IF($V13="","—",IF($V13>=1,"✅ محقق",IF($V13>=0.85,"🟡 قريب","🔴 تحت الهدف"))) | X13: الاستدامة | Y13: جودة التشغيل
A14: 11 | B14: الأداء المالي | C14: إجمالي المستحقات المتأخرة (+30 يوم) | D14: ر.س | E14: ↓ | F14: LAST | H14: تراجع مستمر | U14: =IF($F14="SUM",IF(COUNT($I14:$T14)=0,"",SUM($I14:$T14)),IF($F14="AVG",IFERROR(AVERAGE($I14:$T14),""),IF($F14="LAST",IFERROR(LOOKUP(2,1/($I14:$T14<>""),$I14:$T14),""),""))) | V14: =IF($G14="","",IF($U14="","",IF($G14=0,IF($U14<=0,1,0),IF($E14="↓",IFERROR($G14/$U14,0),IFERROR($U14/$G14,0))))) | W14: =IF($V14="","—",IF($V14>=1,"✅ محقق",IF($V14>=0.85,"🟡 قريب","🔴 تحت الهدف"))) | X14: الاستدامة | Y14: جودة التشغيل
A15: 12 | B15: الأداء المالي | C15: نسبة الشركاء الملتزمين بمواعيد السداد | D15: % | E15: ↑ | F15: AVG | G15: 0.9 | H15: 90%+ | U15: =IF($F15="SUM",IF(COUNT($I15:$T15)=0,"",SUM($I15:$T15)),IF($F15="AVG",IFERROR(AVERAGE($I15:$T15),""),IF($F15="LAST",IFERROR(LOOKUP(2,1/($I15:$T15<>""),$I15:$T15),""),""))) | V15: =IF($G15="","",IF($U15="","",IF($G15=0,IF($U15<=0,1,0),IF($E15="↓",IFERROR($G15/$U15,0),IFERROR($U15/$G15,0))))) | W15: =IF($V15="","—",IF($V15>=1,"✅ محقق",IF($V15>=0.85,"🟡 قريب","🔴 تحت الهدف"))) | X15: الاستدامة | Y15: جودة التشغيل
A16: 13 | B16: الأداء المالي | C16: معدل دوران رأس المال (أيام الدورة) | D16: يوم | E16: ↓ | F16: AVG | G16: 5 | H16: ≤ 5 أيام | U16: =IF($F16="SUM",IF(COUNT($I16:$T16)=0,"",SUM($I16:$T16)),IF($F16="AVG",IFERROR(AVERAGE($I16:$T16),""),IF($F16="LAST",IFERROR(LOOKUP(2,1/($I16:$T16<>""),$I16:$T16),""),""))) | V16: =IF($G16="","",IF($U16="","",IF($G16=0,IF($U16<=0,1,0),IF($E16="↓",IFERROR($G16/$U16,0),IFERROR($U16/$G16,0))))) | W16: =IF($V16="","—",IF($V16>=1,"✅ محقق",IF($V16>=0.85,"🟡 قريب","🔴 تحت الهدف"))) | X16: الاستدامة | Y16: جودة التشغيل
A17: 14 | B17: التشغيل والجودة | C17: نسبة جاهزية محطات الامتياز (صفر انقطاع) | D17: % | E17: ↑ | F17: AVG | G17: 0.99 | H17: 99%+ | U17: =IF($F17="SUM",IF(COUNT($I17:$T17)=0,"",SUM($I17:$T17)),IF($F17="AVG",IFERROR(AVERAGE($I17:$T17),""),IF($F17="LAST",IFERROR(LOOKUP(2,1/($I17:$T17<>""),$I17:$T17),""),""))) | V17: =IF($G17="","",IF($U17="","",IF($G17=0,IF($U17<=0,1,0),IF($E17="↓",IFERROR($G17/$U17,0),IFERROR($U17/$G17,0))))) | W17: =IF($V17="","—",IF($V17>=1,"✅ محقق",IF($V17>=0.85,"🟡 قريب","🔴 تحت الهدف"))) | X17: الاستدامة | Y17: جودة التشغيل
A18: 15 | B18: التشغيل والجودة | C18: عدد حالات انقطاع الوقود الموثّقة | D18: حالة | E18: ↓ | F18: SUM | G18: 0 | H18: 0 حالة | U18: =IF($F18="SUM",IF(COUNT($I18:$T18)=0,"",SUM($I18:$T18)),IF($F18="AVG",IFERROR(AVERAGE($I18:$T18),""),IF($F18="LAST",IFERROR(LOOKUP(2,1/($I18:$T18<>""),$I18:$T18),""),""))) | V18: =IF($G18="","",IF($U18="","",IF($G18=0,IF($U18<=0,1,0),IF($E18="↓",IFERROR($G18/$U18,0),IFERROR($U18/$G18,0))))) | W18: =IF($V18="","—",IF($V18>=1,"✅ محقق",IF($V18>=0.85,"🟡 قريب","🔴 تحت الهدف"))) | X18: الاستدامة | Y18: جودة التشغيل
A19: 16 | B19: التشغيل والجودة | C19: نسبة إغلاق ملاحظات الجودة الميدانية | D19: % | E19: ↑ | F19: AVG | G19: 0.95 | H19: 95%+ | U19: =IF($F19="SUM",IF(COUNT($I19:$T19)=0,"",SUM($I19:$T19)),IF($F19="AVG",IFERROR(AVERAGE($I19:$T19),""),IF($F19="LAST",IFERROR(LOOKUP(2,1/($I19:$T19<>""),$I19:$T19),""),""))) | V19: =IF($G19="","",IF($U19="","",IF($G19=0,IF($U19<=0,1,0),IF($E19="↓",IFERROR($G19/$U19,0),IFERROR($U19/$G19,0))))) | W19: =IF($V19="","—",IF($V19>=1,"✅ محقق",IF($V19>=0.85,"🟡 قريب","🔴 تحت الهدف"))) | X19: الاستدامة | Y19: جودة التشغيل
A20: 17 | B20: التشغيل والجودة | C20: متوسط درجة تقييم جودة المحطة (قائمة التحقق) | D20: درجة/100 | E20: ↑ | F20: AVG | G20: 85 | H20: 85+ | U20: =IF($F20="SUM",IF(COUNT($I20:$T20)=0,"",SUM($I20:$T20)),IF($F20="AVG",IFERROR(AVERAGE($I20:$T20),""),IF($F20="LAST",IFERROR(LOOKUP(2,1/($I20:$T20<>""),$I20:$T20),""),""))) | V20: =IF($G20="","",IF($U20="","",IF($G20=0,IF($U20<=0,1,0),IF($E20="↓",IFERROR($G20/$U20,0),IFERROR($U20/$G20,0))))) | W20: =IF($V20="","—",IF($V20>=1,"✅ محقق",IF($V20>=0.85,"🟡 قريب","🔴 تحت الهدف"))) | X20: الاستدامة | Y20: جودة التشغيل
A21: 18 | B21: التشغيل والجودة | C21: نسبة تنفيذ الزيارات الميدانية المجدولة | D21: % | E21: ↑ | F21: AVG | G21: 1 | H21: 100% | U21: =IF($F21="SUM",IF(COUNT($I21:$T21)=0,"",SUM($I21:$T21)),IF($F21="AVG",IFERROR(AVERAGE($I21:$T21),""),IF($F21="LAST",IFERROR(LOOKUP(2,1/($I21:$T21<>""),$I21:$T21),""),""))) | V21: =IF($G21="","",IF($U21="","",IF($G21=0,IF($U21<=0,1,0),IF($E21="↓",IFERROR($G21/$U21,0),IFERROR($U21/$G21,0))))) | W21: =IF($V21="","—",IF($V21>=1,"✅ محقق",IF($V21>=0.85,"🟡 قريب","🔴 تحت الهدف"))) | X21: الاستدامة | Y21: جودة التشغيل
A22: 19 | B22: التشغيل والجودة | C22: نسبة المحطات المستوفية لمعايير السلامة | D22: % | E22: ↑ | F22: AVG | G22: 1 | H22: 100% | U22: =IF($F22="SUM",IF(COUNT($I22:$T22)=0,"",SUM($I22:$T22)),IF($F22="AVG",IFERROR(AVERAGE($I22:$T22),""),IF($F22="LAST",IFERROR(LOOKUP(2,1/($I22:$T22<>""),$I22:$T22),""),""))) | V22: =IF($G22="","",IF($U22="","",IF($G22=0,IF($U22<=0,1,0),IF($E22="↓",IFERROR($G22/$U22,0),IFERROR($U22/$G22,0))))) | W22: =IF($V22="","—",IF($V22>=1,"✅ محقق",IF($V22>=0.85,"🟡 قريب","🔴 تحت الهدف"))) | X22: الاستدامة | Y22: جودة التشغيل
A23: 20 | B23: التشغيل والجودة | C23: متوسط وقت معالجة البلاغات التشغيلية | D23: ساعة | E23: ↓ | F23: AVG | G23: 24 | H23: ≤ 24 ساعة | U23: =IF($F23="SUM",IF(COUNT($I23:$T23)=0,"",SUM($I23:$T23)),IF($F23="AVG",IFERROR(AVERAGE($I23:$T23),""),IF($F23="LAST",IFERROR(LOOKUP(2,1/($I23:$T23<>""),$I23:$T23),""),""))) | V23: =IF($G23="","",IF($U23="","",IF($G23=0,IF($U23<=0,1,0),IF($E23="↓",IFERROR($G23/$U23,0),IFERROR($U23/$G23,0))))) | W23: =IF($V23="","—",IF($V23>=1,"✅ محقق",IF($V23>=0.85,"🟡 قريب","🔴 تحت الهدف"))) | X23: الاستدامة | Y23: جودة التشغيل
A24: 21 | B24: التشغيل والجودة | C24: نسبة أتمتة محطات الامتياز | D24: % | E24: ↑ | F24: LAST | G24: 0.9 | H24: 90% | U24: =IF($F24="SUM",IF(COUNT($I24:$T24)=0,"",SUM($I24:$T24)),IF($F24="AVG",IFERROR(AVERAGE($I24:$T24),""),IF($F24="LAST",IFERROR(LOOKUP(2,1/($I24:$T24<>""),$I24:$T24),""),""))) | V24: =IF($G24="","",IF($U24="","",IF($G24=0,IF($U24<=0,1,0),IF($E24="↓",IFERROR($G24/$U24,0),IFERROR($U24/$G24,0))))) | W24: =IF($V24="","—",IF($V24>=1,"✅ محقق",IF($V24>=0.85,"🟡 قريب","🔴 تحت الهدف"))) | X24: الابتكار | Y24: التحول التقني
A25: 22 | B25: التشغيل والجودة | C25: نسبة تطبيق المعيار الشامل داخل المحطات | D25: % | E25: ↑ | F25: LAST | G25: 0.3 | H25: 30% | U25: =IF($F25="SUM",IF(COUNT($I25:$T25)=0,"",SUM($I25:$T25)),IF($F25="AVG",IFERROR(AVERAGE($I25:$T25),""),IF($F25="LAST",IFERROR(LOOKUP(2,1/($I25:$T25<>""),$I25:$T25),""),""))) | V25: =IF($G25="","",IF($U25="","",IF($G25=0,IF($U25<=0,1,0),IF($E25="↓",IFERROR($G25/$U25,0),IFERROR($U25/$G25,0))))) | W25: =IF($V25="","—",IF($V25>=1,"✅ محقق",IF($V25>=0.85,"🟡 قريب","🔴 تحت الهدف"))) | X25: الابتكار | Y25: التحول التقني
A26: 23 | B26: الهوية والتسويق | C26: نسبة التزام المحطات بالهوية المؤسسية | D26: % | E26: ↑ | F26: LAST | G26: 0.55 | H26: 55% | U26: =IF($F26="SUM",IF(COUNT($I26:$T26)=0,"",SUM($I26:$T26)),IF($F26="AVG",IFERROR(AVERAGE($I26:$T26),""),IF($F26="LAST",IFERROR(LOOKUP(2,1/($I26:$T26<>""),$I26:$T26),""),""))) | V26: =IF($G26="","",IF($U26="","",IF($G26=0,IF($U26<=0,1,0),IF($E26="↓",IFERROR($G26/$U26,0),IFERROR($U26/$G26,0))))) | W26: =IF($V26="","—",IF($V26>=1,"✅ محقق",IF($V26>=0.85,"🟡 قريب","🔴 تحت الهدف"))) | X26: الابتكار | Y26: تطوير التصاميم والهوية
... A33: 30 | B33: تجربة العملاء والشركاء | C33: نسبة حل الشكاوى خلال المدة المحددة | D33: % | E33: ↑ | F33: AVG | G33: 0.95 | H33: 95%+ | U33: =IF($F33="SUM",IF(COUNT($I33:$T33)=0,"",SUM($I33:$T33)),IF($F33="AVG",IFERROR(AVERAGE($I33:$T33),""),IF($F33="LAST",IFERROR(LOOKUP(2,1/($I33:$T33<>""),$I33:$T33),""),""))) | V33: =IF($G33="","",IF($U33="","",IF($G33=0,IF($U33<=0,1,0),IF($E33="↓",IFERROR($G33/$U33,0),IFERROR($U33/$G33,0))))) | W33: =IF($V33="","—",IF($V33>=1,"✅ محقق",IF($V33>=0.85,"🟡 قريب","🔴 تحت الهدف"))) | X33: الاستدامة | Y33: تعزيز تجربة العملاء
A34: 31 | B34: تجربة العملاء والشركاء | C34: نسبة انخفاض الشكاوى التشغيلية والإدارية | D34: % | E34: ↑ | F34: AVG | H34: -30% | U34: =IF($F34="SUM",IF(COUNT($I34:$T34)=0,"",SUM($I34:$T34)),IF($F34="AVG",IFERROR(AVERAGE($I34:$T34),""),IF($F34="LAST",IFERROR(LOOKUP(2,1/($I34:$T34<>""),$I34:$T34),""),""))) | V34: =IF($G34="","",IF($U34="","",IF($G34=0,IF($U34<=0,1,0),IF($E34="↓",IFERROR($G34/$U34,0),IFERROR($U34/$G34,0))))) | W34: =IF($V34="","—",IF($V34>=1,"✅ محقق",IF($V34>=0.85,"🟡 قريب","🔴 تحت الهدف"))) | X34: الاستدامة | Y34: تعزيز تجربة العملاء
A35: 32 | B35: استدامة الشراكة والامتثال | C35: نسبة استدامة أصحاب الامتياز (Retention) | D35: % | E35: ↑ | F35: LAST | G35: 0.9 | H35: 90% | U35: =IF($F35="SUM",IF(COUNT($I35:$T35)=0,"",SUM($I35:$T35)),IF($F35="AVG",IFERROR(AVERAGE($I35:$T35),""),IF($F35="LAST",IFERROR(LOOKUP(2,1/($I35:$T35<>""),$I35:$T35),""),""))) | V35: =IF($G35="","",IF($U35="","",IF($G35=0,IF($U35<=0,1,0),IF($E35="↓",IFERROR($G35/$U35,0),IFERROR($U35/$G35,0))))) | W35: =IF($V35="","—",IF($V35>=1,"✅ محقق",IF($V35>=0.85,"🟡 قريب","🔴 تحت الهدف"))) | X35: الاستدامة | Y35: تعزيز تجربة العملاء
A36: 33 | B36: استدامة الشراكة والامتثال | C36: نسبة زيادة عدد أصحاب الامتياز | D36: % | E36: ↑ | F36: LAST | G36: 1 | H36: 100% نمو | U36: =IF($F36="SUM",IF(COUNT($I36:$T36)=0,"",SUM($I36:$T36)),IF($F36="AVG",IFERROR(AVERAGE($I36:$T36),""),IF($F36="LAST",IFERROR(LOOKUP(2,1/($I36:$T36<>""),$I36:$T36),""),""))) | V36: =IF($G36="","",IF($U36="","",IF($G36=0,IF($U36<=0,1,0),IF($E36="↓",IFERROR($G36/$U36,0),IFERROR($U36/$G36,0))))) | W36: =IF($V36="","—",IF($V36>=1,"✅ محقق",IF($V36>=0.85,"🟡 قريب","🔴 تحت الهدف"))) | X36: الاستدامة | Y36: تعزيز تجربة العملاء
A37: 34 | B37: استدامة الشراكة والامتثال | C37: نسبة اكتمال المستندات النظامية قبل التوقيع | D37: % | E37: ↑ | F37: AVG | G37: 1 | H37: 100% | U37: =IF($F37="SUM",IF(COUNT($I37:$T37)=0,"",SUM($I37:$T37)),IF($F37="AVG",IFERROR(AVERAGE($I37:$T37),""),IF($F37="LAST",IFERROR(LOOKUP(2,1/($I37:$T37<>""),$I37:$T37),""),""))) | V37: =IF($G37="","",IF($U37="","",IF($G37=0,IF($U37<=0,1,0),IF($E37="↓",IFERROR($G37/$U37,0),IFERROR($U37/$G37,0))))) | W37: =IF($V37="","—",IF($V37>=1,"✅ محقق",IF($V37>=0.85,"🟡 قريب","🔴 تحت الهدف"))) | X37: الاستدامة | Y37: جودة التشغيل
A38: 35 | B38: استدامة الشراكة والامتثال | C38: متوسط مدة إغلاق عقد الامتياز | D38: أسبوع | E38: ↓ | F38: AVG | G38: 1 | H38: ≤ أسبوع | U38: =IF($F38="SUM",IF(COUNT($I38:$T38)=0,"",SUM($I38:$T38)),IF($F38="AVG",IFERROR(AVERAGE($I38:$T38),""),IF($F38="LAST",IFERROR(LOOKUP(2,1/($I38:$T38<>""),$I38:$T38),""),""))) | V38: =IF($G38="","",IF($U38="","",IF($G38=0,IF($U38<=0,1,0),IF($E38="↓",IFERROR($G38/$U38,0),IFERROR($U38/$G38,0))))) | W38: =IF($V38="","—",IF($V38>=1,"✅ محقق",IF($V38>=0.85,"🟡 قريب","🔴 تحت الهدف"))) | X38: النمو | Y38: الامتياز التجاري
A39: 36 | B39: استدامة الشراكة والامتثال | C39: نسبة إنجاز التقارير الدورية في موعدها | D39: % | E39: ↑ | F39: AVG | G39: 1 | H39: 100% | U39: =IF($F39="SUM",IF(COUNT($I39:$T39)=0,"",SUM($I39:$T39)),IF($F39="AVG",IFERROR(AVERAGE($I39:$T39),""),IF($F39="LAST",IFERROR(LOOKUP(2,1/($I39:$T39<>""),$I39:$T39),""),""))) | V39: =IF($G39="","",IF($U39="","",IF($G39=0,IF($U39<=0,1,0),IF($E39="↓",IFERROR($G39/$U39,0),IFERROR($U39/$G39,0))))) | W39: =IF($V39="","—",IF($V39>=1,"✅ محقق",IF($V39>=0.85,"🟡 قريب","🔴 تحت الهدف"))) | X39: الاستدامة | Y39: جودة التشغيل

Sheet الامتياز · الموظفون
B2: إدارة الامتياز · مؤشرات كل موظف (مرجع الربط)
B4: علاء عزت — أخصائي امتياز — عقود واستقطاب · 5 مؤشر
B5: ●/○ | C5: المؤشر | D5: الأولوية
B6: ● | C6: عدد عقود الامتياز الجديدة الموقّعة | D6: 🔴 رئيسي
B7: ● | C7: عدد محطات الامتياز المشغّلة (تراكمي) | D7: 🔴 رئيسي
B8: ● | C8: نسبة تحويل الفرص إلى عقود موقّعة | D8: 🔴 رئيسي
B9: ● | C9: إجمالي مبيعات وقود محطات الامتياز | D9: 🔴 رئيسي
B10: ● | C10: نسبة استدامة أصحاب الامتياز | D10: 🔴 رئيسي
B12: أنس أبو طوق — مراقب ميداني — هوية وبنية تحتية · 5 مؤشر
B13: ●/○ | C13: المؤشر | D13: الأولوية
B14: ● | C14: نسبة جاهزية محطات الامتياز | D14: 🔴 رئيسي
B15: ● | C15: نسبة إغلاق ملاحظات الجودة الميدانية | D15: 🔴 رئيسي
B16: ● | C16: متوسط درجة تقييم جودة المحطة | D16: 🔴 رئيسي
B17: ● | C17: نسبة المحطات المستوفية لمعايير السلامة | D17: 🔴 رئيسي
B18: ● | C18: نسبة التزام المحطات بالهوية المؤسسية | D18: 🔴 رئيسي
B20: حمدي عبد الجليل — أخصائي امتياز — زيارات واستقطاب · 4 مؤشر
B21: ●/○ | C21: المؤشر | D21: الأولوية
B22: ● | C22: نسبة تنفيذ الزيارات الميدانية المجدولة | D22: 🔴 رئيسي
B23: ○ | C23: عدد عقود الامتياز الجديدة الموقّعة | D23: 🔴 رئيسي
B24: ○ | C24: متوسط درجة تقييم جودة المحطة | D24: 🔴 رئيسي
B25: ● | C25: نسبة مبيعات المنتجات غير البترولية | D25: 🟡 متابعة
B27: رغد الجندي — أخصائية امتياز — تسويق ومالية · 5 مؤشر
B28: ●/○ | C28: المؤشر | D28: الأولوية
B29: ● | C29: إجمالي إيرادات إدارة الامتياز | D29: 🔴 رئيسي
B30: ● | C30: نسبة التحصيل المالي من شركاء الامتياز | D30: 🔴 رئيسي
B31: ● | C31: متوسط تقييم المحطات على خرائط قوقل | D31: 🔴 رئيسي
B32: ● | C32: نسبة الشركاء الملتزمين بمواعيد السداد | D32: 🟠 مهم
B33: ● | C33: عدد الحملات التسويقية الميدانية | D33: 🟠 مهم
B35: إدريس الوائلي — أخصائي امتياز — تقارير وتنسيق مالي · 4 مؤشر
B36: ●/○ | C36: المؤشر | D36: الأولوية
B37: ● | C37: متوسط أيام التحصيل (DSO) | D37: 🟠 مهم
B38: ● | C38: إجمالي المستحقات المتأخرة (+30 يوم) | D38: 🟠 مهم
B39: ● | C39: نسبة إنجاز التقارير الدورية في موعدها | D39: 🟠 مهم
B40: ○ | C40: عدد محطات الامتياز المشغّلة | D40: 🔴 رئيسي
B42: أحمد رمضان — أخصائي امتياز — Dynamics ومتابعة نظام · 2 مؤشر
B43: ●/○ | C43: المؤشر | D43: الأولوية
B44: ○ | C44: نسبة اكتمال المستندات النظامية قبل التوقيع | D44: 🟠 مهم
B45: ○ | C45: نسبة إنجاز التقارير الدورية في موعدها | D45: 🟠 مهم
B47: عبدالسلام الوالي — أخصائي امتياز — عمليات ومخزون · 3 مؤشر
B48: ●/○ | C48: المؤشر | D48: الأولوية
...

Sheet الامتياز · مدير الإدارة
A1: إدارة الامتياز التجاري · نموذج تقييم الأداء — مدير إدارة الامتياز التجاري
A2: الكود: FM-01 · فترة القياس: ربع سنوي · 🟩 أدخل «نسبة التحقيق» فقط — الدرجة تُحسب تلقائياً
A3: اسم الموظف: | D3: القسم: الامتياز التجاري
A4: المدير المباشر: | D4: الربع / السنة:
A5: تاريخ التقييم: | D5: حالة التقييم:
A6: # | B6: مؤشر الأداء | C6: الوزن % | D6: المستهدف | E6: نسبة التحقيق | F6: الدرجة المحققة | G6: ملاحظات
A7: 1 | B7: عدد محطات الامتياز الجديدة | C7: 0.15 | D7: 100%+ من المحطات المستهدفة | F7: =C7*MIN(E7,1)
A8: 2 | B8: إجمالي مبيعات محطات الامتياز | C8: 0.15 | D8: 100%+ من مستهدف المبيعات الربعي | F8: =C8*MIN(E8,1)
A9: 3 | B9: استمرارية تزويد الوقود | C9: 0.1 | D9: 0 حالات انقطاع | F9: =C9*MIN(E9,1)
A10: 4 | B10: نسبة التحصيل المالي | C10: 0.15 | D10: 100%+ من المستحقات الربعية | F10: =C10*MIN(E10,1)
A11: 5 | B11: الالتزام بالهوية المؤسسية | C11: 0.15 | D11: 70%+ من المحطات ملتزمة | F11: =C11*MIN(E11,1)
A12: 6 | B12: انخفاض عدد الشكاوى | C12: 0.1 | D12: خفض 20%+ مقارنة بالربع السابق | F12: =C12*MIN(E12,1)
A13: 7 | B13: تقييمات خرائط قوقل | C13: 0.1 | D13: 4.7 – 5 | F13: =C13*MIN(E13,1)
A14: 8 | B14: انتظام وجودة التقارير | C14: 0.1 | D14: 100% في موعدها | F14: =C14*MIN(E14,1)
B15: المجموع الكلي | C15: =SUM(C7:C14) | E15: الدرجة: | F15: =SUM(F7:F14)
B16: التقدير | C16: =IF(F15>=0.9,"ممتاز",IF(F15>=0.8,"جيد جداً",IF(F15>=0.7,"جيد",IF(F15>=0.6,"مقبول","ضعيف"))))
B18: سلّم التقييم
B19: ممتاز | C19: 90% – 100% | D19: تجاوز المستهدف
B20: جيد جداً | C20: 80% – 89% | D20: حقق المستهدف تقريباً
B21: جيد | C21: 70% – 79% | D21: حقق معظم المستهدفات
B22: مقبول | C22: 60% – 69% | D22: يحتاج تحسين
B23: ضعيف | C23: أقل من 60% | D23: يحتاج خطة تطوير

Sheet الامتياز · مسؤول الامتياز
A1: إدارة الامتياز التجاري · نموذج تقييم الأداء — مسؤول الامتياز التجاري
A2: الكود: FM-02 · فترة القياس: ربع سنوي · 🟩 أدخل «نسبة التحقيق» فقط — الدرجة تُحسب تلقائياً
A3: اسم الموظف: | D3: القسم: الامتياز التجاري
A4: المدير المباشر: | D4: الربع / السنة:
A5: تاريخ التقييم: | D5: حالة التقييم:
A6: # | B6: مؤشر الأداء | C6: الوزن % | D6: المستهدف | E6: نسبة التحقيق | F6: الدرجة المحققة | G6: ملاحظات
A7: 1 | B7: المتابعة مع عملاء الامتياز | C7: 0.3 | D7: متابعة مستمرة 100% | F7: =C7*MIN(E7,1)
A8: 2 | B8: عدم انقطاع المحطات من الوقود | C8: 0.35 | D8: 0 حالات انقطاع | F8: =C8*MIN(E8,1)
A9: 3 | B9: متابعة طلبات وتوريد الوقود | C9: 0.1 | D9: 100% متابعة يومية | F9: =C9*MIN(E9,1)
A10: 4 | B10: إجمالي مبيعات المحطات | C10: 0.1 | D10: تحقيق هدف المبيعات | F10: =C10*MIN(E10,1)
A11: 5 | B11: التحصيل المالي | C11: 0.1 | D11: 100% خلال الربع | F11: =C11*MIN(E11,1)
A12: 6 | B12: التقارير الدورية الشاملة | C12: 0.05 | D12: 100% في مواعيدها | F12: =C12*MIN(E12,1)
B13: المجموع الكلي | C13: =SUM(C7:C12) | E13: الدرجة: | F13: =SUM(F7:F12)
B14: التقدير | C14: =IF(F13>=0.9,"ممتاز",IF(F13>=0.8,"جيد جداً",IF(F13>=0.7,"جيد",IF(F13>=0.6,"مقبول","ضعيف"))))
B16: سلّم التقييم
B17: ممتاز | C17: 90% – 100% | D17: تجاوز المستهدف
B18: جيد جداً | C18: 80% – 89% | D18: حقق المستهدف تقريباً
B19: جيد | C19: 70% – 79% | D19: حقق معظم المستهدفات
B20: مقبول | C20: 60% – 69% | D20: يحتاج تحسين
B21: ضعيف | C21: أقل من 60% | D21: يحتاج خطة تطوير

Sheet الامتياز · المراقب الميداني
A1: إدارة الامتياز التجاري · نموذج تقييم الأداء — المراقب الميداني
A2: الكود: FM-03 · فترة القياس: ربع سنوي · 🟩 أدخل «نسبة التحقيق» فقط — الدرجة تُحسب تلقائياً
A3: اسم الموظف: | D3: القسم: الامتياز التجاري
A4: المدير المباشر: | D4: الربع / السنة:
A5: تاريخ التقييم: | D5: حالة التقييم:
A6: # | B6: مؤشر الأداء | C6: الوزن % | D6: المستهدف | E6: نسبة التحقيق | F6: الدرجة المحققة | G6: ملاحظات
A7: 1 | B7: عدد الزيارات الميدانية المنفذة | C7: 0.3 | D7: 100% من الزيارات المجدولة | F7: =C7*MIN(E7,1)
A8: 2 | B8: متابعة تطبيق الهوية المؤسسية | C8: 0.2 | D8: 100% دون ملاحظات متكررة | F8: =C8*MIN(E8,1)
A9: 3 | B9: تقارير الجودة الميدانية والـChecklist | C9: 0.2 | D9: 100% رفع التقارير | F9: =C9*MIN(E9,1)
A10: 4 | B10: متابعة العلامات التجارية | C10: 0.1 | D10: 100% حسب الجدول | F10: =C10*MIN(E10,1)
A11: 5 | B11: تطبيق معايير السلامة الميدانية | C11: 0.1 | D11: 100% | F11: =C11*MIN(E11,1)
A12: 6 | B12: متابعة الشكاوى وإغلاقها | C12: 0.1 | D12: الاستجابة خلال 24 ساعة | F12: =C12*MIN(E12,1)
B13: المجموع الكلي | C13: =SUM(C7:C12) | E13: الدرجة: | F13: =SUM(F7:F12)
B14: التقدير | C14: =IF(F13>=0.9,"ممتاز",IF(F13>=0.8,"جيد جداً",IF(F13>=0.7,"جيد",IF(F13>=0.6,"مقبول","ضعيف"))))
B16: سلّم التقييم
B17: ممتاز | C17: 90% – 100% | D17: تجاوز المستهدف
B18: جيد جداً | C18: 80% – 89% | D18: حقق المستهدف تقريباً
B19: جيد | C19: 70% – 79% | D19: حقق معظم المستهدفات
B20: مقبول | C20: 60% – 69% | D20: يحتاج تحسين
B21: ضعيف | C21: أقل من 60% | D21: يحتاج خطة تطوير

Sheet الامتياز · مسؤول التعاقدات
A1: إدارة الامتياز التجاري · نموذج تقييم الأداء — مسؤول التعاقدات
A2: الكود: FM-04 · فترة القياس: ربع سنوي · 🟩 أدخل «نسبة التحقيق» فقط — الدرجة تُحسب تلقائياً
A3: اسم الموظف: | D3: القسم: الامتياز التجاري
A4: المدير المباشر: | D4: الربع / السنة:
A5: تاريخ التقييم: | D5: حالة التقييم:
A6: # | B6: مؤشر الأداء | C6: الوزن % | D6: المستهدف | E6: نسبة التحقيق | F6: الدرجة المحققة | G6: ملاحظات
A7: 1 | B7: جودة التفاوض مع العملاء | C7: 0.2 | D7: 98% توافق مع المستهدفات | F7: =C7*MIN(E7,1)
A8: 2 | B8: اكتمال المستندات النظامية قبل التوقيع | C8: 0.15 | D8: 100% | F8: =C8*MIN(E8,1)
A9: 3 | B9: سرعة إنجاز إجراءات العقد | C9: 0.3 | D9: خلال يومي عمل 100% | F9: =C9*MIN(E9,1)
A10: 4 | B10: أرشفة العقود الإلكترونية | C10: 0.1 | D10: خلال 48 ساعة 100% | F10: =C10*MIN(E10,1)
A11: 5 | B11: متابعة تنفيذ بنود العقد | C11: 0.1 | D11: 100% | F11: =C11*MIN(E11,1)
A12: 6 | B12: مدى رضا العملاء | C12: 0.1 | D12: 95% رضا | F12: =C12*MIN(E12,1)
A13: 7 | B13: تحديث قاعدة بيانات العملاء | C13: 0.05 | D13: 100% دوري | F13: =C13*MIN(E13,1)
B14: المجموع الكلي | C14: =SUM(C7:C13) | E14: الدرجة: | F14: =SUM(F7:F13)
B15: التقدير | C15: =IF(F14>=0.9,"ممتاز",IF(F14>=0.8,"جيد جداً",IF(F14>=0.7,"جيد",IF(F14>=0.6,"مقبول","ضعيف"))))
B17: سلّم التقييم
B18: ممتاز | C18: 90% – 100% | D18: تجاوز المستهدف
B19: جيد جداً | C19: 80% – 89% | D19: حقق المستهدف تقريباً
B20: جيد | C20: 70% – 79% | D20: حقق معظم المستهدفات
B21: مقبول | C21: 60% – 69% | D21: يحتاج تحسين
B22: ضعيف | C22: أقل من 60% | D22: يحتاج خطة تطوير

Sheet الامتياز · الموظف الإداري
A1: إدارة الامتياز التجاري · نموذج تقييم الأداء — الموظف الإداري
A2: الكود: FM-05 · فترة القياس: ربع سنوي · 🟩 أدخل «نسبة التحقيق» فقط — الدرجة تُحسب تلقائياً
A3: اسم الموظف: | D3: القسم: الامتياز التجاري
A4: المدير المباشر: | D4: الربع / السنة:
A5: تاريخ التقييم: | D5: حالة التقييم:
A6: # | B6: مؤشر الأداء | C6: الوزن % | D6: المستهدف | E6: نسبة التحقيق | F6: الدرجة المحققة | G6: ملاحظات
A7: 1 | B7: دقة وسرعة إعداد التقارير الدورية | C7: 0.3 | D7: 100% في الوقت المحدد | F7: =C7*MIN(E7,1)
A8: 2 | B8: متابعة الشكاوى وحالات العملاء | C8: 0.3 | D8: 100% حتى الإغلاق | F8: =C8*MIN(E8,1)
A9: 3 | B9: متابعة عمولات تأجير الوحدات | C9: 0.2 | D9: 100% | F9: =C9*MIN(E9,1)
A10: 4 | B10: تحديث بيانات العملاء والمحطات | C10: 0.1 | D10: 100% دقة | F10: =C10*MIN(E10,1)
A11: 5 | B11: إعداد المراسلات الرسمية | C11: 0.1 | D11: 100% في الوقت المحدد | F11: =C11*MIN(E11,1)
B12: المجموع الكلي | C12: =SUM(C7:C11) | E12: الدرجة: | F12: =SUM(F7:F11)
B13: التقدير | C13: =IF(F12>=0.9,"ممتاز",IF(F12>=0.8,"جيد جداً",IF(F12>=0.7,"جيد",IF(F12>=0.6,"مقبول","ضعيف"))))
B15: سلّم التقييم
B16: ممتاز | C16: 90% – 100% | D16: تجاوز المستهدف
B17: جيد جداً | C17: 80% – 89% | D17: حقق المستهدف تقريباً
B18: جيد | C18: 70% – 79% | D18: حقق معظم المستهدفات
B19: مقبول | C19: 60% – 69% | D19: يحتاج تحسين
B20: ضعيف | C20: أقل من 60% | D20: يحتاج خطة تطوير
