Workbook

Sheet تقرير المجلس
B2: تقرير الأداء التنفيذي — مجلس الإدارة · درب 2026
B4: الإنجاز العام الموزون | C4: ✅ محقق | D4: 🟡 قريب | E4: 🔴 تحت الهدف
B5: ='اللوحة الموجزة'!B5 | C5: ='اللوحة الموجزة'!C5 | D5: ='اللوحة الموجزة'!D5 | E5: ='اللوحة الموجزة'!E5
B7: الأداء حسب الركيزة | D7: أبرز 5 انحرافات
B8: النمو | C8: =IFERROR(AVERAGEIFS('قاعدة المؤشرات'!$G$2:$G$223,'قاعدة المؤشرات'!$D$2:$D$223,"النمو"),"—") | D8: معدل التفاعل (Engagement) | F8: 0
B9: الابتكار | C9: =IFERROR(AVERAGEIFS('قاعدة المؤشرات'!$G$2:$G$223,'قاعدة المؤشرات'!$D$2:$D$223,"الابتكار"),"—") | D9: عدد المعارض بالسنة | F9: 0
B10: الاستدامة | C10: =IFERROR(AVERAGEIFS('قاعدة المؤشرات'!$G$2:$G$223,'قاعدة المؤشرات'!$D$2:$D$223,"الاستدامة"),"—") | D10: اتفاقيات استراتيجية | F10: 0
D11: عملاء تجاريون جدد | F11: 0.005
D12: الوصول الكلي (Total Reach) | F12: 0.1
B14: أعلى 5 مخاطر مؤسسية (الأثر × الاحتمال)
B15: تقلّب أسعار الوقود وضغط الهامش | E15: 4×5=20 | F15: 🔴 عالي
B16: تأخّر مشاريع التحول الرقمي | E16: 4×4=16 | F16: 🔴 عالي
B17: اختراق/انقطاع الأنظمة الرقمية | E17: 3×5=15 | F17: 🔴 عالي
B18: تعثّر تحصيل المستحقات | E18: 3×4=12 | F18: 🟠 متوسط
B19: ضغط السيولة والتدفق النقدي | E19: 3×4=12 | F19: 🟠 متوسط
B21: يُحدَّث آلياً من اللوحة الموجزة وتحليل الانحراف وسجل المخاطر · سرّي — لأعضاء المجلس

Sheet أهم المؤشرات (Top 5)
A1: أهم 5 مؤشرات رئيسية لكل إدارة — لوحة المتابعة التنفيذية (قيَم حيّة مرتبطة بأوراق الإدارات)
A2: # | B2: المؤشر | C2: المستهدف | D2: المُحقَّق | E2: نسبة التحقيق | F2: الحالة | G2: الوزن
A3: ▾ الإدارة التنفيذية · وزن الإدارة 0%
A4: 1 | B4: ='الإدارة التنفيذية'!C5 | C4: ='الإدارة التنفيذية'!I5 | D4: ='الإدارة التنفيذية'!M5 | E4: ='الإدارة التنفيذية'!N5 | F4: ='الإدارة التنفيذية'!O5 | G4: ='الإدارة التنفيذية'!G5
A5: 2 | B5: ='الإدارة التنفيذية'!C6 | C5: ='الإدارة التنفيذية'!I6 | D5: ='الإدارة التنفيذية'!M6 | E5: ='الإدارة التنفيذية'!N6 | F5: ='الإدارة التنفيذية'!O6 | G5: ='الإدارة التنفيذية'!G6
A6: 3 | B6: ='الإدارة التنفيذية'!C7 | C6: ='الإدارة التنفيذية'!I7 | D6: ='الإدارة التنفيذية'!M7 | E6: ='الإدارة التنفيذية'!N7 | F6: ='الإدارة التنفيذية'!O7 | G6: ='الإدارة التنفيذية'!G7
A7: 4 | B7: ='الإدارة التنفيذية'!C12 | C7: ='الإدارة التنفيذية'!I12 | D7: ='الإدارة التنفيذية'!M12 | E7: ='الإدارة التنفيذية'!N12 | F7: ='الإدارة التنفيذية'!O12 | G7: ='الإدارة التنفيذية'!G12
A8: 5 | B8: ='الإدارة التنفيذية'!C13 | C8: ='الإدارة التنفيذية'!I13 | D8: ='الإدارة التنفيذية'!M13 | E8: ='الإدارة التنفيذية'!N13 | F8: ='الإدارة التنفيذية'!O13 | G8: ='الإدارة التنفيذية'!G13
A9: ▾ الامتياز التجاري · وزن الإدارة 14%
A10: 1 | B10: ='الامتياز التجاري'!C5 | C10: ='الامتياز التجاري'!I5 | D10: ='الامتياز التجاري'!M5 | E10: ='الامتياز التجاري'!N5 | F10: ='الامتياز التجاري'!O5 | G10: ='الامتياز التجاري'!G5
A11: 2 | B11: ='الامتياز التجاري'!C6 | C11: ='الامتياز التجاري'!I6 | D11: ='الامتياز التجاري'!M6 | E11: ='الامتياز التجاري'!N6 | F11: ='الامتياز التجاري'!O6 | G11: ='الامتياز التجاري'!G6
A12: 3 | B12: ='الامتياز التجاري'!C8 | C12: ='الامتياز التجاري'!I8 | D12: ='الامتياز التجاري'!M8 | E12: ='الامتياز التجاري'!N8 | F12: ='الامتياز التجاري'!O8 | G12: ='الامتياز التجاري'!G8
A13: 4 | B13: ='الامتياز التجاري'!C11 | C13: ='الامتياز التجاري'!I11 | D13: ='الامتياز التجاري'!M11 | E13: ='الامتياز التجاري'!N11 | F13: ='الامتياز التجاري'!O11 | G13: ='الامتياز التجاري'!G11
A14: 5 | B14: ='الامتياز التجاري'!C13 | C14: ='الامتياز التجاري'!I13 | D14: ='الامتياز التجاري'!M13 | E14: ='الامتياز التجاري'!N13 | F14: ='الامتياز التجاري'!O13 | G14: ='الامتياز التجاري'!G13
A15: ▾ التشغيل والمحطات · وزن الإدارة 12%
A16: 1 | B16: ='التشغيل والمحطات'!C4 | C16: ='التشغيل والمحطات'!I4 | D16: ='التشغيل والمحطات'!M4 | E16: ='التشغيل والمحطات'!N4 | F16: ='التشغيل والمحطات'!O4 | G16: ='التشغيل والمحطات'!G4
A17: 2 | B17: ='التشغيل والمحطات'!C6 | C17: ='التشغيل والمحطات'!I6 | D17: ='التشغيل والمحطات'!M6 | E17: ='التشغيل والمحطات'!N6 | F17: ='التشغيل والمحطات'!O6 | G17: ='التشغيل والمحطات'!G6
A18: 3 | B18: ='التشغيل والمحطات'!C7 | C18: ='التشغيل والمحطات'!I7 | D18: ='التشغيل والمحطات'!M7 | E18: ='التشغيل والمحطات'!N7 | F18: ='التشغيل والمحطات'!O7 | G18: ='التشغيل والمحطات'!G7
A19: 4 | B19: ='التشغيل والمحطات'!C8 | C19: ='التشغيل والمحطات'!I8 | D19: ='التشغيل والمحطات'!M8 | E19: ='التشغيل والمحطات'!N8 | F19: ='التشغيل والمحطات'!O8 | G19: ='التشغيل والمحطات'!G8
A20: 5 | B20: ='التشغيل والمحطات'!C9 | C20: ='التشغيل والمحطات'!I9 | D20: ='التشغيل والمحطات'!M9 | E20: ='التشغيل والمحطات'!N9 | F20: ='التشغيل والمحطات'!O9 | G20: ='التشغيل والمحطات'!G9
A21: ▾ الاستثمار · وزن الإدارة 11%
A22: 1 | B22: ='الاستثمار'!C5 | C22: ='الاستثمار'!I5 | D22: ='الاستثمار'!M5 | E22: ='الاستثمار'!N5 | F22: ='الاستثمار'!O5 | G22: ='الاستثمار'!G5
A23: 2 | B23: ='الاستثمار'!C6 | C23: ='الاستثمار'!I6 | D23: ='الاستثمار'!M6 | E23: ='الاستثمار'!N6 | F23: ='الاستثمار'!O6 | G23: ='الاستثمار'!G6
A24: 3 | B24: ='الاستثمار'!C7 | C24: ='الاستثمار'!I7 | D24: ='الاستثمار'!M7 | E24: ='الاستثمار'!N7 | F24: ='الاستثمار'!O7 | G24: ='الاستثمار'!G7
A25: 4 | B25: ='الاستثمار'!C8 | C25: ='الاستثمار'!I8 | D25: ='الاستثمار'!M8 | E25: ='الاستثمار'!N8 | F25: ='الاستثمار'!O8 | G25: ='الاستثمار'!G8
A26: 5 | B26: ='الاستثمار'!C9 | C26: ='الاستثمار'!I9 | D26: ='الاستثمار'!M9 | E26: ='الاستثمار'!N9 | F26: ='الاستثمار'!O9 | G26: ='الاستثمار'!G9
A27: ▾ العقار · وزن الإدارة 9%
A28: 1 | B28: ='العقار'!C5 | C28: ='العقار'!I5 | D28: ='العقار'!M5 | E28: ='العقار'!N5 | F28: ='العقار'!O5 | G28: ='العقار'!G5
A29: 2 | B29: ='العقار'!C6 | C29: ='العقار'!I6 | D29: ='العقار'!M6 | E29: ='العقار'!N6 | F29: ='العقار'!O6 | G29: ='العقار'!G6
A30: 3 | B30: ='العقار'!C7 | C30: ='العقار'!I7 | D30: ='العقار'!M7 | E30: ='العقار'!N7 | F30: ='العقار'!O7 | G30: ='العقار'!G7
A31: 4 | B31: ='العقار'!C9 | C31: ='العقار'!I9 | D31: ='العقار'!M9 | E31: ='العقار'!N9 | F31: ='العقار'!O9 | G31: ='العقار'!G9
A32: 5 | B32: ='العقار'!C12 | C32: ='العقار'!I12 | D32: ='العقار'!M12 | E32: ='العقار'!N12 | F32: ='العقار'!O12 | G32: ='العقار'!G12
A33: ▾ إدارة المشاريع · وزن الإدارة 8%
A34: 1 | B34: ='إدارة المشاريع'!C5 | C34: ='إدارة المشاريع'!I5 | D34: ='إدارة المشاريع'!M5 | E34: ='إدارة المشاريع'!N5 | F34: ='إدارة المشاريع'!O5 | G34: ='إدارة المشاريع'!G5
A35: 2 | B35: ='إدارة المشاريع'!C6 | C35: ='إدارة المشاريع'!I6 | D35: ='إدارة المشاريع'!M6 | E35: ='إدارة المشاريع'!N6 | F35: ='إدارة المشاريع'!O6 | G35: ='إدارة المشاريع'!G6
A36: 3 | B36: ='إدارة المشاريع'!C7 | C36: ='إدارة المشاريع'!I7 | D36: ='إدارة المشاريع'!M7 | E36: ='إدارة المشاريع'!N7 | F36: ='إدارة المشاريع'!O7 | G36: ='إدارة المشاريع'!G7
A37: 4 | B37: ='إدارة المشاريع'!C10 | C37: ='إدارة المشاريع'!I10 | D37: ='إدارة المشاريع'!M10 | E37: ='إدارة المشاريع'!N10 | F37: ='إدارة المشاريع'!O10 | G37: ='إدارة المشاريع'!G10
A38: 5 | B38: ='إدارة المشاريع'!C14 | C38: ='إدارة المشاريع'!I14 | D38: ='إدارة المشاريع'!M14 | E38: ='إدارة المشاريع'!N14 | F38: ='إدارة المشاريع'!O14 | G38: ='إدارة المشاريع'!G14
A39: ▾ سلاسل الإمداد · وزن الإدارة 10%
A40: 1 | B40: ='سلاسل الإمداد'!C5 | C40: ='سلاسل الإمداد'!I5 | D40: ='سلاسل الإمداد'!M5 | E40: ='سلاسل الإمداد'!N5 | F40: ='سلاسل الإمداد'!O5 | G40: ='سلاسل الإمداد'!G5
...

Sheet المؤشرات الجامعة
A1: المؤشرات الجامعة — مؤشر واحد لكل محور (متوسط موزون حيّ) + كشف الأضعف لمنع خداع المتوسطات · لا يُحسب في الإجمالي
A2: # | B2: الإدارة | C2: المحور (مؤشر جامع) | D2: عدد المؤشرات | E2: نسبة التحقيق (موزون) | F2: الحالة | G2: أدنى نسبة تفصيلية | H2: عدد تحت الهدف | I2: المؤشرات التفصيلية المشمولة
A3: 1 | B3: الإدارة التنفيذية | C3: النمو | D3: 4 | E3: =IFERROR(SUMIFS('قاعدة المؤشرات'!$J$2:$J$223,'قاعدة المؤشرات'!$B$2:$B$223,"الإدارة التنفيذية",'قاعدة المؤشرات'!$L$2:$L$223,"النمو")/SUMIFS('قاعدة المؤشرات'!$K$2:$K$223,'قاعدة المؤشرات'!$B$2:$B$223,"الإدارة التنفيذية",'قاعدة المؤشرات'!$L$2:$L$223,"النمو"),"") | F3: =IF($E3="","⏳ بانتظار هدف",IF($E3>=1,"✅ محقق",IF($E3>=0.85,"🟡 قريب","🔴 تحت الهدف"))) | G3: =IF($E3="","",MINIFS('قاعدة المؤشرات'!$G$2:$G$223,'قاعدة المؤشرات'!$B$2:$B$223,"الإدارة التنفيذية",'قاعدة المؤشرات'!$L$2:$L$223,"النمو")) | H3: =COUNTIFS('قاعدة المؤشرات'!$H$2:$H$223,"🔴 تحت الهدف",'قاعدة المؤشرات'!$B$2:$B$223,"الإدارة التنفيذية",'قاعدة المؤشرات'!$L$2:$L$223,"النمو") | I3: إجمالي المحطات المشغّلة — الشركة (تراكمي) · إجمالي العقود الجديدة — الشركة · نسبة نمو إيرادات الشركة (سنوي) · الالتزام بمعايير وزارة الطاقة (تغطية 13 منطقة)
A4: 2 | B4: الإدارة التنفيذية | C4: الابتكار | D4: 2 | E4: =IFERROR(SUMIFS('قاعدة المؤشرات'!$J$2:$J$223,'قاعدة المؤشرات'!$B$2:$B$223,"الإدارة التنفيذية",'قاعدة المؤشرات'!$L$2:$L$223,"الابتكار")/SUMIFS('قاعدة المؤشرات'!$K$2:$K$223,'قاعدة المؤشرات'!$B$2:$B$223,"الإدارة التنفيذية",'قاعدة المؤشرات'!$L$2:$L$223,"الابتكار"),"") | F4: =IF($E4="","⏳ بانتظار هدف",IF($E4>=1,"✅ محقق",IF($E4>=0.85,"🟡 قريب","🔴 تحت الهدف"))) | G4: =IF($E4="","",MINIFS('قاعدة المؤشرات'!$G$2:$G$223,'قاعدة المؤشرات'!$B$2:$B$223,"الإدارة التنفيذية",'قاعدة المؤشرات'!$L$2:$L$223,"الابتكار")) | H4: =COUNTIFS('قاعدة المؤشرات'!$H$2:$H$223,"🔴 تحت الهدف",'قاعدة المؤشرات'!$B$2:$B$223,"الإدارة التنفيذية",'قاعدة المؤشرات'!$L$2:$L$223,"الابتكار") | I4: نسبة إنجاز مشاريع الخارطة التنفيذية · نسبة التحول الرقمي على مستوى الشركة
A5: 3 | B5: الإدارة التنفيذية | C5: الاستدامة | D5: 3 | E5: =IFERROR(SUMIFS('قاعدة المؤشرات'!$J$2:$J$223,'قاعدة المؤشرات'!$B$2:$B$223,"الإدارة التنفيذية",'قاعدة المؤشرات'!$L$2:$L$223,"الاستدامة")/SUMIFS('قاعدة المؤشرات'!$K$2:$K$223,'قاعدة المؤشرات'!$B$2:$B$223,"الإدارة التنفيذية",'قاعدة المؤشرات'!$L$2:$L$223,"الاستدامة"),"") | F5: =IF($E5="","⏳ بانتظار هدف",IF($E5>=1,"✅ محقق",IF($E5>=0.85,"🟡 قريب","🔴 تحت الهدف"))) | G5: =IF($E5="","",MINIFS('قاعدة المؤشرات'!$G$2:$G$223,'قاعدة المؤشرات'!$B$2:$B$223,"الإدارة التنفيذية",'قاعدة المؤشرات'!$L$2:$L$223,"الاستدامة")) | H5: =COUNTIFS('قاعدة المؤشرات'!$H$2:$H$223,"🔴 تحت الهدف",'قاعدة المؤشرات'!$B$2:$B$223,"الإدارة التنفيذية",'قاعدة المؤشرات'!$L$2:$L$223,"الاستدامة") | I5: مؤشر رضا العملاء العام (الشركة) · مؤشر رضا الموظفين العام (eNPS) · نسبة تحقيق المستهدفات الاستراتيجية العامة
A6: 4 | B6: الإدارة التنفيذية | C6: الحوكمة | D6: 1 | E6: =IFERROR(SUMIFS('قاعدة المؤشرات'!$J$2:$J$223,'قاعدة المؤشرات'!$B$2:$B$223,"الإدارة التنفيذية",'قاعدة المؤشرات'!$L$2:$L$223,"الحوكمة")/SUMIFS('قاعدة المؤشرات'!$K$2:$K$223,'قاعدة المؤشرات'!$B$2:$B$223,"الإدارة التنفيذية",'قاعدة المؤشرات'!$L$2:$L$223,"الحوكمة"),"") | F6: =IF($E6="","⏳ بانتظار هدف",IF($E6>=1,"✅ محقق",IF($E6>=0.85,"🟡 قريب","🔴 تحت الهدف"))) | G6: =IF($E6="","",MINIFS('قاعدة المؤشرات'!$G$2:$G$223,'قاعدة المؤشرات'!$B$2:$B$223,"الإدارة التنفيذية",'قاعدة المؤشرات'!$L$2:$L$223,"الحوكمة")) | H6: =COUNTIFS('قاعدة المؤشرات'!$H$2:$H$223,"🔴 تحت الهدف",'قاعدة المؤشرات'!$B$2:$B$223,"الإدارة التنفيذية",'قاعدة المؤشرات'!$L$2:$L$223,"الحوكمة") | I6: نسبة الالتزام بإطار الحوكمة المؤسسية والامتثال التنظيمي
A7: 5 | B7: الامتياز التجاري | C7: النمو والتوسع | D7: 2 | E7: =IFERROR(SUMIFS('قاعدة المؤشرات'!$J$2:$J$223,'قاعدة المؤشرات'!$B$2:$B$223,"الامتياز التجاري",'قاعدة المؤشرات'!$L$2:$L$223,"النمو والتوسع")/SUMIFS('قاعدة المؤشرات'!$K$2:$K$223,'قاعدة المؤشرات'!$B$2:$B$223,"الامتياز التجاري",'قاعدة المؤشرات'!$L$2:$L$223,"النمو والتوسع"),"") | F7: =IF($E7="","⏳ بانتظار هدف",IF($E7>=1,"✅ محقق",IF($E7>=0.85,"🟡 قريب","🔴 تحت الهدف"))) | G7: =IF($E7="","",MINIFS('قاعدة المؤشرات'!$G$2:$G$223,'قاعدة المؤشرات'!$B$2:$B$223,"الامتياز التجاري",'قاعدة المؤشرات'!$L$2:$L$223,"النمو والتوسع")) | H7: =COUNTIFS('قاعدة المؤشرات'!$H$2:$H$223,"🔴 تحت الهدف",'قاعدة المؤشرات'!$B$2:$B$223,"الامتياز التجاري",'قاعدة المؤشرات'!$L$2:$L$223,"النمو والتوسع") | I7: عدد محطات الامتياز المشغّلة (تراكمي) · عدد عقود الامتياز الجديدة الموقّعة
A8: 6 | B8: الامتياز التجاري | C8: المبيعات والأداء التجاري | D8: 2 | E8: =IFERROR(SUMIFS('قاعدة المؤشرات'!$J$2:$J$223,'قاعدة المؤشرات'!$B$2:$B$223,"الامتياز التجاري",'قاعدة المؤشرات'!$L$2:$L$223,"المبيعات والأداء التجاري")/SUMIFS('قاعدة المؤشرات'!$K$2:$K$223,'قاعدة المؤشرات'!$B$2:$B$223,"الامتياز التجاري",'قاعدة المؤشرات'!$L$2:$L$223,"المبيعات والأداء التجاري"),"") | F8: =IF($E8="","⏳ بانتظار هدف",IF($E8>=1,"✅ محقق",IF($E8>=0.85,"🟡 قريب","🔴 تحت الهدف"))) | G8: =IF($E8="","",MINIFS('قاعدة المؤشرات'!$G$2:$G$223,'قاعدة المؤشرات'!$B$2:$B$223,"الامتياز التجاري",'قاعدة المؤشرات'!$L$2:$L$223,"المبيعات والأداء التجاري")) | H8: =COUNTIFS('قاعدة المؤشرات'!$H$2:$H$223,"🔴 تحت الهدف",'قاعدة المؤشرات'!$B$2:$B$223,"الامتياز التجاري",'قاعدة المؤشرات'!$L$2:$L$223,"المبيعات والأداء التجاري") | I8: إجمالي مبيعات وقود محطات الامتياز · نسبة تأجير وحدات الامتياز
A9: 7 | B9: الامتياز التجاري | C9: الأداء المالي | D9: 8 | E9: =IFERROR(SUMIFS('قاعدة المؤشرات'!$J$2:$J$223,'قاعدة المؤشرات'!$B$2:$B$223,"الامتياز التجاري",'قاعدة المؤشرات'!$L$2:$L$223,"الأداء المالي")/SUMIFS('قاعدة المؤشرات'!$K$2:$K$223,'قاعدة المؤشرات'!$B$2:$B$223,"الامتياز التجاري",'قاعدة المؤشرات'!$L$2:$L$223,"الأداء المالي"),"") | F9: =IF($E9="","⏳ بانتظار هدف",IF($E9>=1,"✅ محقق",IF($E9>=0.85,"🟡 قريب","🔴 تحت الهدف"))) | G9: =IF($E9="","",MINIFS('قاعدة المؤشرات'!$G$2:$G$223,'قاعدة المؤشرات'!$B$2:$B$223,"الامتياز التجاري",'قاعدة المؤشرات'!$L$2:$L$223,"الأداء المالي")) | H9: =COUNTIFS('قاعدة المؤشرات'!$H$2:$H$223,"🔴 تحت الهدف",'قاعدة المؤشرات'!$B$2:$B$223,"الامتياز التجاري",'قاعدة المؤشرات'!$L$2:$L$223,"الأداء المالي") | I9: إجمالي إيرادات إدارة الامتياز · رفع هامش الربحية للامتياز · نسبة التحصيل المالي من شركاء الامتياز · متوسط أيام تحصيل شركاء الامتياز (DSO) · إجمالي المستحقات المتأخرة (+30 يوم) · نسبة الشركاء الملتزمين بمواعيد السداد · معدل دوران رأس المال (أيام الدورة) · نسبة التحصيل خلال 5 أيام عمل
A10: 8 | B10: الامتياز التجاري | C10: التشغيل والجودة | D10: 9 | E10: =IFERROR(SUMIFS('قاعدة المؤشرات'!$J$2:$J$223,'قاعدة المؤشرات'!$B$2:$B$223,"الامتياز التجاري",'قاعدة المؤشرات'!$L$2:$L$223,"التشغيل والجودة")/SUMIFS('قاعدة المؤشرات'!$K$2:$K$223,'قاعدة المؤشرات'!$B$2:$B$223,"الامتياز التجاري",'قاعدة المؤشرات'!$L$2:$L$223,"التشغيل والجودة"),"") | F10: =IF($E10="","⏳ بانتظار هدف",IF($E10>=1,"✅ محقق",IF($E10>=0.85,"🟡 قريب","🔴 تحت الهدف"))) | G10: =IF($E10="","",MINIFS('قاعدة المؤشرات'!$G$2:$G$223,'قاعدة المؤشرات'!$B$2:$B$223,"الامتياز التجاري",'قاعدة المؤشرات'!$L$2:$L$223,"التشغيل والجودة")) | H10: =COUNTIFS('قاعدة المؤشرات'!$H$2:$H$223,"🔴 تحت الهدف",'قاعدة المؤشرات'!$B$2:$B$223,"الامتياز التجاري",'قاعدة المؤشرات'!$L$2:$L$223,"التشغيل والجودة") | I10: نسبة جاهزية محطات الامتياز (صفر انقطاع) · عدد حالات انقطاع الوقود الموثّقة · نسبة إغلاق ملاحظات الجودة الميدانية · متوسط درجة تقييم جودة المحطة (قائمة التحقق) · نسبة تنفيذ الزيارات الميدانية المجدولة · نسبة المحطات المستوفية لمعايير السلامة · متوسط وقت معالجة البلاغات التشغيلية · نسبة أتمتة محطات الامتياز · نسبة تطبيق المعيار الشامل داخل المحطات
A11: 9 | B11: الامتياز التجاري | C11: الهوية والتسويق | D11: 1 | E11: =IFERROR(SUMIFS('قاعدة المؤشرات'!$J$2:$J$223,'قاعدة المؤشرات'!$B$2:$B$223,"الامتياز التجاري",'قاعدة المؤشرات'!$L$2:$L$223,"الهوية والتسويق")/SUMIFS('قاعدة المؤشرات'!$K$2:$K$223,'قاعدة المؤشرات'!$B$2:$B$223,"الامتياز التجاري",'قاعدة المؤشرات'!$L$2:$L$223,"الهوية والتسويق"),"") | F11: =IF($E11="","⏳ بانتظار هدف",IF($E11>=1,"✅ محقق",IF($E11>=0.85,"🟡 قريب","🔴 تحت الهدف"))) | G11: =IF($E11="","",MINIFS('قاعدة المؤشرات'!$G$2:$G$223,'قاعدة المؤشرات'!$B$2:$B$223,"الامتياز التجاري",'قاعدة المؤشرات'!$L$2:$L$223,"الهوية والتسويق")) | H11: =COUNTIFS('قاعدة المؤشرات'!$H$2:$H$223,"🔴 تحت الهدف",'قاعدة المؤشرات'!$B$2:$B$223,"الامتياز التجاري",'قاعدة المؤشرات'!$L$2:$L$223,"الهوية والتسويق") | I11: نسبة التزام المحطات بالهوية المؤسسية
A12: 10 | B12: الامتياز التجاري | C12: تجربة العملاء والشركاء | D12: 4 | E12: =IFERROR(SUMIFS('قاعدة المؤشرات'!$J$2:$J$223,'قاعدة المؤشرات'!$B$2:$B$223,"الامتياز التجاري",'قاعدة المؤشرات'!$L$2:$L$223,"تجربة العملاء والشركاء")/SUMIFS('قاعدة المؤشرات'!$K$2:$K$223,'قاعدة المؤشرات'!$B$2:$B$223,"الامتياز التجاري",'قاعدة المؤشرات'!$L$2:$L$223,"تجربة العملاء والشركاء"),"") | F12: =IF($E12="","⏳ بانتظار هدف",IF($E12>=1,"✅ محقق",IF($E12>=0.85,"🟡 قريب","🔴 تحت الهدف"))) | G12: =IF($E12="","",MINIFS('قاعدة المؤشرات'!$G$2:$G$223,'قاعدة المؤشرات'!$B$2:$B$223,"الامتياز التجاري",'قاعدة المؤشرات'!$L$2:$L$223,"تجربة العملاء والشركاء")) | H12: =COUNTIFS('قاعدة المؤشرات'!$H$2:$H$223,"🔴 تحت الهدف",'قاعدة المؤشرات'!$B$2:$B$223,"الامتياز التجاري",'قاعدة المؤشرات'!$L$2:$L$223,"تجربة العملاء والشركاء") | I12: متوسط تقييم المحطات على خرائط قوقل · معدل رضا شركاء الامتياز (CSAT) · نسبة حل الشكاوى خلال المدة المحددة · نسبة انخفاض الشكاوى التشغيلية والإدارية
A13: 11 | B13: الامتياز التجاري | C13: استدامة الشراكة والامتثال | D13: 3 | E13: =IFERROR(SUMIFS('قاعدة المؤشرات'!$J$2:$J$223,'قاعدة المؤشرات'!$B$2:$B$223,"الامتياز التجاري",'قاعدة المؤشرات'!$L$2:$L$223,"استدامة الشراكة والامتثال")/SUMIFS('قاعدة المؤشرات'!$K$2:$K$223,'قاعدة المؤشرات'!$B$2:$B$223,"الامتياز التجاري",'قاعدة المؤشرات'!$L$2:$L$223,"استدامة الشراكة والامتثال"),"") | F13: =IF($E13="","⏳ بانتظار هدف",IF($E13>=1,"✅ محقق",IF($E13>=0.85,"🟡 قريب","🔴 تحت الهدف"))) | G13: =IF($E13="","",MINIFS('قاعدة المؤشرات'!$G$2:$G$223,'قاعدة المؤشرات'!$B$2:$B$223,"الامتياز التجاري",'قاعدة المؤشرات'!$L$2:$L$223,"استدامة الشراكة والامتثال")) | H13: =COUNTIFS('قاعدة المؤشرات'!$H$2:$H$223,"🔴 تحت الهدف",'قاعدة المؤشرات'!$B$2:$B$223,"الامتياز التجاري",'قاعدة المؤشرات'!$L$2:$L$223,"استدامة الشراكة والامتثال") | I13: نسبة استدامة أصحاب الامتياز (Retention) · نسبة زيادة عدد أصحاب الامتياز · متوسط مدة إغلاق عقد الامتياز
A14: 12 | B14: التشغيل والمحطات | C14: النمو | D14: 1 | E14: =IFERROR(SUMIFS('قاعدة المؤشرات'!$J$2:$J$223,'قاعدة المؤشرات'!$B$2:$B$223,"التشغيل والمحطات",'قاعدة المؤشرات'!$L$2:$L$223,"النمو")/SUMIFS('قاعدة المؤشرات'!$K$2:$K$223,'قاعدة المؤشرات'!$B$2:$B$223,"التشغيل والمحطات",'قاعدة المؤشرات'!$L$2:$L$223,"النمو"),"") | F14: =IF($E14="","⏳ بانتظار هدف",IF($E14>=1,"✅ محقق",IF($E14>=0.85,"🟡 قريب","🔴 تحت الهدف"))) | G14: =IF($E14="","",MINIFS('قاعدة المؤشرات'!$G$2:$G$223,'قاعدة المؤشرات'!$B$2:$B$223,"التشغيل والمحطات",'قاعدة المؤشرات'!$L$2:$L$223,"النمو")) | H14: =COUNTIFS('قاعدة المؤشرات'!$H$2:$H$223,"🔴 تحت الهدف",'قاعدة المؤشرات'!$B$2:$B$223,"التشغيل والمحطات",'قاعدة المؤشرات'!$L$2:$L$223,"النمو") | I14: عدد المحطات المشغّلة (تراكمي)
A15: 13 | B15: التشغيل والمحطات | C15: الربحية | D15: 4 | E15: =IFERROR(SUMIFS('قاعدة المؤشرات'!$J$2:$J$223,'قاعدة المؤشرات'!$B$2:$B$223,"التشغيل والمحطات",'قاعدة المؤشرات'!$L$2:$L$223,"الربحية")/SUMIFS('قاعدة المؤشرات'!$K$2:$K$223,'قاعدة المؤشرات'!$B$2:$B$223,"التشغيل والمحطات",'قاعدة المؤشرات'!$L$2:$L$223,"الربحية"),"") | F15: =IF($E15="","⏳ بانتظار هدف",IF($E15>=1,"✅ محقق",IF($E15>=0.85,"🟡 قريب","🔴 تحت الهدف"))) | G15: =IF($E15="","",MINIFS('قاعدة المؤشرات'!$G$2:$G$223,'قاعدة المؤشرات'!$B$2:$B$223,"التشغيل والمحطات",'قاعدة المؤشرات'!$L$2:$L$223,"الربحية")) | H15: =COUNTIFS('قاعدة المؤشرات'!$H$2:$H$223,"🔴 تحت الهدف",'قاعدة المؤشرات'!$B$2:$B$223,"التشغيل والمحطات",'قاعدة المؤشرات'!$L$2:$L$223,"الربحية") | I15: نمو مبيعات بنزين 91 مقارنة بالعام السابق · نمو مبيعات بنزين 95 مقارنة بالعام السابق · نمو مبيعات بنزين 98 مقارنة بالعام السابق · نمو مبيعات الديزل مقارنة بالعام السابق
A16: 14 | B16: التشغيل والمحطات | C16: حماية الإيراد | D16: 2 | E16: =IFERROR(SUMIFS('قاعدة المؤشرات'!$J$2:$J$223,'قاعدة المؤشرات'!$B$2:$B$223,"التشغيل والمحطات",'قاعدة المؤشرات'!$L$2:$L$223,"حماية الإيراد")/SUMIFS('قاعدة المؤشرات'!$K$2:$K$223,'قاعدة المؤشرات'!$B$2:$B$223,"التشغيل والمحطات",'قاعدة المؤشرات'!$L$2:$L$223,"حماية الإيراد"),"") | F16: =IF($E16="","⏳ بانتظار هدف",IF($E16>=1,"✅ محقق",IF($E16>=0.85,"🟡 قريب","🔴 تحت الهدف"))) | G16: =IF($E16="","",MINIFS('قاعدة المؤشرات'!$G$2:$G$223,'قاعدة المؤشرات'!$B$2:$B$223,"التشغيل والمحطات",'قاعدة المؤشرات'!$L$2:$L$223,"حماية الإيراد")) | H16: =COUNTIFS('قاعدة المؤشرات'!$H$2:$H$223,"🔴 تحت الهدف",'قاعدة المؤشرات'!$B$2:$B$223,"التشغيل والمحطات",'قاعدة المؤشرات'!$L$2:$L$223,"حماية الإيراد") | I16: نسبة جاهزية المحطة الشاملة (Uptime) · نسبة المضخات العاملة
A17: 15 | B17: التشغيل والمحطات | C17: ضغط التكلفة | D17: 1 | E17: =IFERROR(SUMIFS('قاعدة المؤشرات'!$J$2:$J$223,'قاعدة المؤشرات'!$B$2:$B$223,"التشغيل والمحطات",'قاعدة المؤشرات'!$L$2:$L$223,"ضغط التكلفة")/SUMIFS('قاعدة المؤشرات'!$K$2:$K$223,'قاعدة المؤشرات'!$B$2:$B$223,"التشغيل والمحطات",'قاعدة المؤشرات'!$L$2:$L$223,"ضغط التكلفة"),"") | F17: =IF($E17="","⏳ بانتظار هدف",IF($E17>=1,"✅ محقق",IF($E17>=0.85,"🟡 قريب","🔴 تحت الهدف"))) | G17: =IF($E17="","",MINIFS('قاعدة المؤشرات'!$G$2:$G$223,'قاعدة المؤشرات'!$B$2:$B$223,"التشغيل والمحطات",'قاعدة المؤشرات'!$L$2:$L$223,"ضغط التكلفة")) | H17: =COUNTIFS('قاعدة المؤشرات'!$H$2:$H$223,"🔴 تحت الهدف",'قاعدة المؤشرات'!$B$2:$B$223,"التشغيل والمحطات",'قاعدة المؤشرات'!$L$2:$L$223,"ضغط التكلفة") | I17: تكلفة التشغيل لكل لتر مباع
A18: 16 | B18: التشغيل والمحطات | C18: حماية الأصول | D18: 1 | E18: =IFERROR(SUMIFS('قاعدة المؤشرات'!$J$2:$J$223,'قاعدة المؤشرات'!$B$2:$B$223,"التشغيل والمحطات",'قاعدة المؤشرات'!$L$2:$L$223,"حماية الأصول")/SUMIFS('قاعدة المؤشرات'!$K$2:$K$223,'قاعدة المؤشرات'!$B$2:$B$223,"التشغيل والمحطات",'قاعدة المؤشرات'!$L$2:$L$223,"حماية الأصول"),"") | F18: =IF($E18="","⏳ بانتظار هدف",IF($E18>=1,"✅ محقق",IF($E18>=0.85,"🟡 قريب","🔴 تحت الهدف"))) | G18: =IF($E18="","",MINIFS('قاعدة المؤشرات'!$G$2:$G$223,'قاعدة المؤشرات'!$B$2:$B$223,"التشغيل والمحطات",'قاعدة المؤشرات'!$L$2:$L$223,"حماية الأصول")) | H18: =COUNTIFS('قاعدة المؤشرات'!$H$2:$H$223,"🔴 تحت الهدف",'قاعدة المؤشرات'!$B$2:$B$223,"التشغيل والمحطات",'قاعدة المؤشرات'!$L$2:$L$223,"حماية الأصول") | I18: نسبة الصيانة الوقائية المنفذة في موعدها
A19: 17 | B19: التشغيل والمحطات | C19: تجربة العميل | D19: 5 | E19: =IFERROR(SUMIFS('قاعدة المؤشرات'!$J$2:$J$223,'قاعدة المؤشرات'!$B$2:$B$223,"التشغيل والمحطات",'قاعدة المؤشرات'!$L$2:$L$223,"تجربة العميل")/SUMIFS('قاعدة المؤشرات'!$K$2:$K$223,'قاعدة المؤشرات'!$B$2:$B$223,"التشغيل والمحطات",'قاعدة المؤشرات'!$L$2:$L$223,"تجربة العميل"),"") | F19: =IF($E19="","⏳ بانتظار هدف",IF($E19>=1,"✅ محقق",IF($E19>=0.85,"🟡 قريب","🔴 تحت الهدف"))) | G19: =IF($E19="","",MINIFS('قاعدة المؤشرات'!$G$2:$G$223,'قاعدة المؤشرات'!$B$2:$B$223,"التشغيل والمحطات",'قاعدة المؤشرات'!$L$2:$L$223,"تجربة العميل")) | H19: =COUNTIFS('قاعدة المؤشرات'!$H$2:$H$223,"🔴 تحت الهدف",'قاعدة المؤشرات'!$B$2:$B$223,"التشغيل والمحطات",'قاعدة المؤشرات'!$L$2:$L$223,"تجربة العميل") | I19: نسبة انخفاض الشكاوى مقارنة بالشهر السابق · تقييم Google Maps للمحطات · سرعة تعبئة الوقود · دقة التعبئة بدون أخطاء · تطبيق المعيار الشامل في المحطات
A20: 18 | B20: التشغيل والمحطات | C20: السلامة | D20: 1 | E20: =IFERROR(SUMIFS('قاعدة المؤشرات'!$J$2:$J$223,'قاعدة المؤشرات'!$B$2:$B$223,"التشغيل والمحطات",'قاعدة المؤشرات'!$L$2:$L$223,"السلامة")/SUMIFS('قاعدة المؤشرات'!$K$2:$K$223,'قاعدة المؤشرات'!$B$2:$B$223,"التشغيل والمحطات",'قاعدة المؤشرات'!$L$2:$L$223,"السلامة"),"") | F20: =IF($E20="","⏳ بانتظار هدف",IF($E20>=1,"✅ محقق",IF($E20>=0.85,"🟡 قريب","🔴 تحت الهدف"))) | G20: =IF($E20="","",MINIFS('قاعدة المؤشرات'!$G$2:$G$223,'قاعدة المؤشرات'!$B$2:$B$223,"التشغيل والمحطات",'قاعدة المؤشرات'!$L$2:$L$223,"السلامة")) | H20: =COUNTIFS('قاعدة المؤشرات'!$H$2:$H$223,"🔴 تحت الهدف",'قاعدة المؤشرات'!$B$2:$B$223,"التشغيل والمحطات",'قاعدة المؤشرات'!$L$2:$L$223,"السلامة") | I20: الالتزام بمعايير السلامة داخل المحطة
A21: 19 | B21: التشغيل والمحطات | C21: البيئة | D21: 1 | E21: =IFERROR(SUMIFS('قاعدة المؤشرات'!$J$2:$J$223,'قاعدة المؤشرات'!$B$2:$B$223,"التشغيل والمحطات",'قاعدة المؤشرات'!$L$2:$L$223,"البيئة")/SUMIFS('قاعدة المؤشرات'!$K$2:$K$223,'قاعدة المؤشرات'!$B$2:$B$223,"التشغيل والمحطات",'قاعدة المؤشرات'!$L$2:$L$223,"البيئة"),"") | F21: =IF($E21="","⏳ بانتظار هدف",IF($E21>=1,"✅ محقق",IF($E21>=0.85,"🟡 قريب","🔴 تحت الهدف"))) | G21: =IF($E21="","",MINIFS('قاعدة المؤشرات'!$G$2:$G$223,'قاعدة المؤشرات'!$B$2:$B$223,"التشغيل والمحطات",'قاعدة المؤشرات'!$L$2:$L$223,"البيئة")) | H21: =COUNTIFS('قاعدة المؤشرات'!$H$2:$H$223,"🔴 تحت الهدف",'قاعدة المؤشرات'!$B$2:$B$223,"التشغيل والمحطات",'قاعدة المؤشرات'!$L$2:$L$223,"البيئة") | I21: التشجير داخل المحطة (معيار الوزارة)
A22: 20 | B22: الاستثمار | C22: نمو المحفظة | D22: 7 | E22: =IFERROR(SUMIFS('قاعدة المؤشرات'!$J$2:$J$223,'قاعدة المؤشرات'!$B$2:$B$223,"الاستثمار",'قاعدة المؤشرات'!$L$2:$L$223,"نمو المحفظة")/SUMIFS('قاعدة المؤشرات'!$K$2:$K$223,'قاعدة المؤشرات'!$B$2:$B$223,"الاستثمار",'قاعدة المؤشرات'!$L$2:$L$223,"نمو المحفظة"),"") | F22: =IF($E22="","⏳ بانتظار هدف",IF($E22>=1,"✅ محقق",IF($E22>=0.85,"🟡 قريب","🔴 تحت الهدف"))) | G22: =IF($E22="","",MINIFS('قاعدة المؤشرات'!$G$2:$G$223,'قاعدة المؤشرات'!$B$2:$B$223,"الاستثمار",'قاعدة المؤشرات'!$L$2:$L$223,"نمو المحفظة")) | H22: =COUNTIFS('قاعدة المؤشرات'!$H$2:$H$223,"🔴 تحت الهدف",'قاعدة المؤشرات'!$B$2:$B$223,"الاستثمار",'قاعدة المؤشرات'!$L$2:$L$223,"نمو المحفظة") | I22: إجمالي عقود الاستثمار الجديدة (جميع النماذج) · عقود الاستثمار العادي الجديدة · عقود الاستحواذ الجديدة · المحطات المستحوَذ عليها المشغّلة (تراكمي) · عقود تأجير الأرض الجديدة · عقود إيجار المحطة الجديدة · عقود تشغيل المحطة الجديدة
A23: 21 | B23: الاستثمار | C23: الربحية وجودة الموقع | D23: 3 | E23: =IFERROR(SUMIFS('قاعدة المؤشرات'!$J$2:$J$223,'قاعدة المؤشرات'!$B$2:$B$223,"الاستثمار",'قاعدة المؤشرات'!$L$2:$L$223,"الربحية وجودة الموقع")/SUMIFS('قاعدة المؤشرات'!$K$2:$K$223,'قاعدة المؤشرات'!$B$2:$B$223,"الاستثمار",'قاعدة المؤشرات'!$L$2:$L$223,"الربحية وجودة الموقع"),"") | F23: =IF($E23="","⏳ بانتظار هدف",IF($E23>=1,"✅ محقق",IF($E23>=0.85,"🟡 قريب","🔴 تحت الهدف"))) | G23: =IF($E23="","",MINIFS('قاعدة المؤشرات'!$G$2:$G$223,'قاعدة المؤشرات'!$B$2:$B$223,"الاستثمار",'قاعدة المؤشرات'!$L$2:$L$223,"الربحية وجودة الموقع")) | H23: =COUNTIFS('قاعدة المؤشرات'!$H$2:$H$223,"🔴 تحت الهدف",'قاعدة المؤشرات'!$B$2:$B$223,"الاستثمار",'قاعدة المؤشرات'!$L$2:$L$223,"الربحية وجودة الموقع") | I23: نسبة المواقع المعتمدة ذات العائد المجدي · متوسط فترة استرداد رأس المال · متوسط قيمة عقد الإيجار السنوي (أرض)
A24: 22 | B24: الاستثمار | C24: التوسع الإقليمي | D24: 4 | E24: =IFERROR(SUMIFS('قاعدة المؤشرات'!$J$2:$J$223,'قاعدة المؤشرات'!$B$2:$B$223,"الاستثمار",'قاعدة المؤشرات'!$L$2:$L$223,"التوسع الإقليمي")/SUMIFS('قاعدة المؤشرات'!$K$2:$K$223,'قاعدة المؤشرات'!$B$2:$B$223,"الاستثمار",'قاعدة المؤشرات'!$L$2:$L$223,"التوسع الإقليمي"),"") | F24: =IF($E24="","⏳ بانتظار هدف",IF($E24>=1,"✅ محقق",IF($E24>=0.85,"🟡 قريب","🔴 تحت الهدف"))) | G24: =IF($E24="","",MINIFS('قاعدة المؤشرات'!$G$2:$G$223,'قاعدة المؤشرات'!$B$2:$B$223,"الاستثمار",'قاعدة المؤشرات'!$L$2:$L$223,"التوسع الإقليمي")) | H24: =COUNTIFS('قاعدة المؤشرات'!$H$2:$H$223,"🔴 تحت الهدف",'قاعدة المؤشرات'!$B$2:$B$223,"الاستثمار",'قاعدة المؤشرات'!$L$2:$L$223,"التوسع الإقليمي") | I24: نسبة العقود التي تغطي المناطق الـ13 · نسبة العقود خارج المدن الرئيسية · نسبة العقود في الـ12 مدينة الرئيسية · نسبة العقود على الطرق الإقليمية
A25: 23 | B25: الاستثمار | C25: كفاءة الدورة | D25: 3 | E25: =IFERROR(SUMIFS('قاعدة المؤشرات'!$J$2:$J$223,'قاعدة المؤشرات'!$B$2:$B$223,"الاستثمار",'قاعدة المؤشرات'!$L$2:$L$223,"كفاءة الدورة")/SUMIFS('قاعدة المؤشرات'!$K$2:$K$223,'قاعدة المؤشرات'!$B$2:$B$223,"الاستثمار",'قاعدة المؤشرات'!$L$2:$L$223,"كفاءة الدورة"),"") | F25: =IF($E25="","⏳ بانتظار هدف",IF($E25>=1,"✅ محقق",IF($E25>=0.85,"🟡 قريب","🔴 تحت الهدف"))) | G25: =IF($E25="","",MINIFS('قاعدة المؤشرات'!$G$2:$G$223,'قاعدة المؤشرات'!$B$2:$B$223,"الاستثمار",'قاعدة المؤشرات'!$L$2:$L$223,"كفاءة الدورة")) | H25: =COUNTIFS('قاعدة المؤشرات'!$H$2:$H$223,"🔴 تحت الهدف",'قاعدة المؤشرات'!$B$2:$B$223,"الاستثمار",'قاعدة المؤشرات'!$L$2:$L$223,"كفاءة الدورة") | I25: متوسط مدة إغلاق عقد الاستثمار · نسبة العقود المتحوّلة لمحطات مشغّلة · نسبة تخفيض إيجار المواقع عالية التكاليف
A26: 24 | B26: الاستثمار | C26: الامتثال | D26: 2 | E26: =IFERROR(SUMIFS('قاعدة المؤشرات'!$J$2:$J$223,'قاعدة المؤشرات'!$B$2:$B$223,"الاستثمار",'قاعدة المؤشرات'!$L$2:$L$223,"الامتثال")/SUMIFS('قاعدة المؤشرات'!$K$2:$K$223,'قاعدة المؤشرات'!$B$2:$B$223,"الاستثمار",'قاعدة المؤشرات'!$L$2:$L$223,"الامتثال"),"") | F26: =IF($E26="","⏳ بانتظار هدف",IF($E26>=1,"✅ محقق",IF($E26>=0.85,"🟡 قريب","🔴 تحت الهدف"))) | G26: =IF($E26="","",MINIFS('قاعدة المؤشرات'!$G$2:$G$223,'قاعدة المؤشرات'!$B$2:$B$223,"الاستثمار",'قاعدة المؤشرات'!$L$2:$L$223,"الامتثال")) | H26: =COUNTIFS('قاعدة المؤشرات'!$H$2:$H$223,"🔴 تحت الهدف",'قاعدة المؤشرات'!$B$2:$B$223,"الاستثمار",'قاعدة المؤشرات'!$L$2:$L$223,"الامتثال") | I26: نسبة اكتمال المستندات النظامية قبل التوقيع · نسبة العقود المؤرشفة إلكترونياً خلال 48 ساعة
A27: 25 | B27: الاستثمار | C27: جودة التعاقد | D27: 5 | E27: =IFERROR(SUMIFS('قاعدة المؤشرات'!$J$2:$J$223,'قاعدة المؤشرات'!$B$2:$B$223,"الاستثمار",'قاعدة المؤشرات'!$L$2:$L$223,"جودة التعاقد")/SUMIFS('قاعدة المؤشرات'!$K$2:$K$223,'قاعدة المؤشرات'!$B$2:$B$223,"الاستثمار",'قاعدة المؤشرات'!$L$2:$L$223,"جودة التعاقد"),"") | F27: =IF($E27="","⏳ بانتظار هدف",IF($E27>=1,"✅ محقق",IF($E27>=0.85,"🟡 قريب","🔴 تحت الهدف"))) | G27: =IF($E27="","",MINIFS('قاعدة المؤشرات'!$G$2:$G$223,'قاعدة المؤشرات'!$B$2:$B$223,"الاستثمار",'قاعدة المؤشرات'!$L$2:$L$223,"جودة التعاقد")) | H27: =COUNTIFS('قاعدة المؤشرات'!$H$2:$H$223,"🔴 تحت الهدف",'قاعدة المؤشرات'!$B$2:$B$223,"الاستثمار",'قاعدة المؤشرات'!$L$2:$L$223,"جودة التعاقد") | I27: جودة التفاوض مع المستثمرين · سرعة إنجاز إجراءات التعاقد · مدى رضا المستثمرين وشركاء الاستثمار · نسبة اكتمال أرشفة ملفات العملاء · نسبة إنجاز التقارير الدورية في موعدها
A28: 26 | B28: العقار | C28: الإدارة | D28: 3 | E28: =IFERROR(SUMIFS('قاعدة المؤشرات'!$J$2:$J$223,'قاعدة المؤشرات'!$B$2:$B$223,"العقار",'قاعدة المؤشرات'!$L$2:$L$223,"الإدارة")/SUMIFS('قاعدة المؤشرات'!$K$2:$K$223,'قاعدة المؤشرات'!$B$2:$B$223,"العقار",'قاعدة المؤشرات'!$L$2:$L$223,"الإدارة"),"") | F28: =IF($E28="","⏳ بانتظار هدف",IF($E28>=1,"✅ محقق",IF($E28>=0.85,"🟡 قريب","🔴 تحت الهدف"))) | G28: =IF($E28="","",MINIFS('قاعدة المؤشرات'!$G$2:$G$223,'قاعدة المؤشرات'!$B$2:$B$223,"العقار",'قاعدة المؤشرات'!$L$2:$L$223,"الإدارة")) | H28: =COUNTIFS('قاعدة المؤشرات'!$H$2:$H$223,"🔴 تحت الهدف",'قاعدة المؤشرات'!$B$2:$B$223,"العقار",'قاعدة المؤشرات'!$L$2:$L$223,"الإدارة") | I28: نمو الإيرادات الإيجارية · نسبة الالتزام بالعقود · نسبة تحصيل الإيجارات
A29: 27 | B29: العقار | C29: التأجير | D29: 5 | E29: =IFERROR(SUMIFS('قاعدة المؤشرات'!$J$2:$J$223,'قاعدة المؤشرات'!$B$2:$B$223,"العقار",'قاعدة المؤشرات'!$L$2:$L$223,"التأجير")/SUMIFS('قاعدة المؤشرات'!$K$2:$K$223,'قاعدة المؤشرات'!$B$2:$B$223,"العقار",'قاعدة المؤشرات'!$L$2:$L$223,"التأجير"),"") | F29: =IF($E29="","⏳ بانتظار هدف",IF($E29>=1,"✅ محقق",IF($E29>=0.85,"🟡 قريب","🔴 تحت الهدف"))) | G29: =IF($E29="","",MINIFS('قاعدة المؤشرات'!$G$2:$G$223,'قاعدة المؤشرات'!$B$2:$B$223,"العقار",'قاعدة المؤشرات'!$L$2:$L$223,"التأجير")) | H29: =COUNTIFS('قاعدة المؤشرات'!$H$2:$H$223,"🔴 تحت الهدف",'قاعدة المؤشرات'!$B$2:$B$223,"العقار",'قاعدة المؤشرات'!$L$2:$L$223,"التأجير") | I29: نسبة الإشغال · الوحدات المؤجَّرة شهرياً · العملاء المحتملون (LEADS) · معدل التحويل · زيادة عدد العلامات التجارية
A30: 28 | B30: العقار | C30: الإبداع والتكامل | D30: 3 | E30: =IFERROR(SUMIFS('قاعدة المؤشرات'!$J$2:$J$223,'قاعدة المؤشرات'!$B$2:$B$223,"العقار",'قاعدة المؤشرات'!$L$2:$L$223,"الإبداع والتكامل")/SUMIFS('قاعدة المؤشرات'!$K$2:$K$223,'قاعدة المؤشرات'!$B$2:$B$223,"العقار",'قاعدة المؤشرات'!$L$2:$L$223,"الإبداع والتكامل"),"") | F30: =IF($E30="","⏳ بانتظار هدف",IF($E30>=1,"✅ محقق",IF($E30>=0.85,"🟡 قريب","🔴 تحت الهدف"))) | G30: =IF($E30="","",MINIFS('قاعدة المؤشرات'!$G$2:$G$223,'قاعدة المؤشرات'!$B$2:$B$223,"العقار",'قاعدة المؤشرات'!$L$2:$L$223,"الإبداع والتكامل")) | H30: =COUNTIFS('قاعدة المؤشرات'!$H$2:$H$223,"🔴 تحت الهدف",'قاعدة المؤشرات'!$B$2:$B$223,"العقار",'قاعدة المؤشرات'!$L$2:$L$223,"الإبداع والتكامل") | I30: نسبة تأجير ساحة درب · علامات تجارية جديدة (ساحة درب) · الشراكات الاستراتيجية
A31: 29 | B31: العقار | C31: إدارة الأملاك | D31: 1 | E31: =IFERROR(SUMIFS('قاعدة المؤشرات'!$J$2:$J$223,'قاعدة المؤشرات'!$B$2:$B$223,"العقار",'قاعدة المؤشرات'!$L$2:$L$223,"إدارة الأملاك")/SUMIFS('قاعدة المؤشرات'!$K$2:$K$223,'قاعدة المؤشرات'!$B$2:$B$223,"العقار",'قاعدة المؤشرات'!$L$2:$L$223,"إدارة الأملاك"),"") | F31: =IF($E31="","⏳ بانتظار هدف",IF($E31>=1,"✅ محقق",IF($E31>=0.85,"🟡 قريب","🔴 تحت الهدف"))) | G31: =IF($E31="","",MINIFS('قاعدة المؤشرات'!$G$2:$G$223,'قاعدة المؤشرات'!$B$2:$B$223,"العقار",'قاعدة المؤشرات'!$L$2:$L$223,"إدارة الأملاك")) | H31: =COUNTIFS('قاعدة المؤشرات'!$H$2:$H$223,"🔴 تحت الهدف",'قاعدة المؤشرات'!$B$2:$B$223,"العقار",'قاعدة المؤشرات'!$L$2:$L$223,"إدارة الأملاك") | I31: نسبة تجديد العقود
A32: 30 | B32: العقار | C32: تنسيق المشاريع | D32: 2 | E32: =IFERROR(SUMIFS('قاعدة المؤشرات'!$J$2:$J$223,'قاعدة المؤشرات'!$B$2:$B$223,"العقار",'قاعدة المؤشرات'!$L$2:$L$223,"تنسيق المشاريع")/SUMIFS('قاعدة المؤشرات'!$K$2:$K$223,'قاعدة المؤشرات'!$B$2:$B$223,"العقار",'قاعدة المؤشرات'!$L$2:$L$223,"تنسيق المشاريع"),"") | F32: =IF($E32="","⏳ بانتظار هدف",IF($E32>=1,"✅ محقق",IF($E32>=0.85,"🟡 قريب","🔴 تحت الهدف"))) | G32: =IF($E32="","",MINIFS('قاعدة المؤشرات'!$G$2:$G$223,'قاعدة المؤشرات'!$B$2:$B$223,"العقار",'قاعدة المؤشرات'!$L$2:$L$223,"تنسيق المشاريع")) | H32: =COUNTIFS('قاعدة المؤشرات'!$H$2:$H$223,"🔴 تحت الهدف",'قاعدة المؤشرات'!$B$2:$B$223,"العقار",'قاعدة المؤشرات'!$L$2:$L$223,"تنسيق المشاريع") | I32: متوسط زمن تسليم الوحدة · نسبة إغلاق الطلبات خلال 3 أسابيع
A33: 31 | B33: العقار | C33: الجودة والاستدامة | D33: 2 | E33: =IFERROR(SUMIFS('قاعدة المؤشرات'!$J$2:$J$223,'قاعدة المؤشرات'!$B$2:$B$223,"العقار",'قاعدة المؤشرات'!$L$2:$L$223,"الجودة والاستدامة")/SUMIFS('قاعدة المؤشرات'!$K$2:$K$223,'قاعدة المؤشرات'!$B$2:$B$223,"العقار",'قاعدة المؤشرات'!$L$2:$L$223,"الجودة والاستدامة"),"") | F33: =IF($E33="","⏳ بانتظار هدف",IF($E33>=1,"✅ محقق",IF($E33>=0.85,"🟡 قريب","🔴 تحت الهدف"))) | G33: =IF($E33="","",MINIFS('قاعدة المؤشرات'!$G$2:$G$223,'قاعدة المؤشرات'!$B$2:$B$223,"العقار",'قاعدة المؤشرات'!$L$2:$L$223,"الجودة والاستدامة")) | H33: =COUNTIFS('قاعدة المؤشرات'!$H$2:$H$223,"🔴 تحت الهدف",'قاعدة المؤشرات'!$B$2:$B$223,"العقار",'قاعدة المؤشرات'!$L$2:$L$223,"الجودة والاستدامة") | I33: استدامة المستأجرين (لم يُنهَ مبكراً) · معدل رضا المستأجرين (استبيان ربعي)
A34: 32 | B34: إدارة المشاريع | C34: تسليم محطات الشركة | D34: 4 | E34: =IFERROR(SUMIFS('قاعدة المؤشرات'!$J$2:$J$223,'قاعدة المؤشرات'!$B$2:$B$223,"إدارة المشاريع",'قاعدة المؤشرات'!$L$2:$L$223,"تسليم محطات الشركة")/SUMIFS('قاعدة المؤشرات'!$K$2:$K$223,'قاعدة المؤشرات'!$B$2:$B$223,"إدارة المشاريع",'قاعدة المؤشرات'!$L$2:$L$223,"تسليم محطات الشركة"),"") | F34: =IF($E34="","⏳ بانتظار هدف",IF($E34>=1,"✅ محقق",IF($E34>=0.85,"🟡 قريب","🔴 تحت الهدف"))) | G34: =IF($E34="","",MINIFS('قاعدة المؤشرات'!$G$2:$G$223,'قاعدة المؤشرات'!$B$2:$B$223,"إدارة المشاريع",'قاعدة المؤشرات'!$L$2:$L$223,"تسليم محطات الشركة")) | H34: =COUNTIFS('قاعدة المؤشرات'!$H$2:$H$223,"🔴 تحت الهدف",'قاعدة المؤشرات'!$B$2:$B$223,"إدارة المشاريع",'قاعدة المؤشرات'!$L$2:$L$223,"تسليم محطات الشركة") | I34: عدد محطات الشركة المُسلَّمة · نسبة إنجاز محفظة مشاريع التوسع · نسبة تسليم المحطات في الموعد المخطط · نسبة المشاريع المنفّذة ضمن الميزانية
A35: 33 | B35: إدارة المشاريع | C35: الإشراف على الامتياز | D35: 4 | E35: =IFERROR(SUMIFS('قاعدة المؤشرات'!$J$2:$J$223,'قاعدة المؤشرات'!$B$2:$B$223,"إدارة المشاريع",'قاعدة المؤشرات'!$L$2:$L$223,"الإشراف على الامتياز")/SUMIFS('قاعدة المؤشرات'!$K$2:$K$223,'قاعدة المؤشرات'!$B$2:$B$223,"إدارة المشاريع",'قاعدة المؤشرات'!$L$2:$L$223,"الإشراف على الامتياز"),"") | F35: =IF($E35="","⏳ بانتظار هدف",IF($E35>=1,"✅ محقق",IF($E35>=0.85,"🟡 قريب","🔴 تحت الهدف"))) | G35: =IF($E35="","",MINIFS('قاعدة المؤشرات'!$G$2:$G$223,'قاعدة المؤشرات'!$B$2:$B$223,"إدارة المشاريع",'قاعدة المؤشرات'!$L$2:$L$223,"الإشراف على الامتياز")) | H35: =COUNTIFS('قاعدة المؤشرات'!$H$2:$H$223,"🔴 تحت الهدف",'قاعدة المؤشرات'!$B$2:$B$223,"إدارة المشاريع",'قاعدة المؤشرات'!$L$2:$L$223,"الإشراف على الامتياز") | I35: عدد محطات الامتياز المُسلَّمة بالهوية · نسبة تنفيذ زيارات الإشراف المجدولة · نسبة التزام المطوّرين بالجدول الزمني · نسبة إغلاق ملاحظات الجودة على المطوّرين
A36: 34 | B36: إدارة المشاريع | C36: إجمالي التسليم | D36: 1 | E36: =IFERROR(SUMIFS('قاعدة المؤشرات'!$J$2:$J$223,'قاعدة المؤشرات'!$B$2:$B$223,"إدارة المشاريع",'قاعدة المؤشرات'!$L$2:$L$223,"إجمالي التسليم")/SUMIFS('قاعدة المؤشرات'!$K$2:$K$223,'قاعدة المؤشرات'!$B$2:$B$223,"إدارة المشاريع",'قاعدة المؤشرات'!$L$2:$L$223,"إجمالي التسليم"),"") | F36: =IF($E36="","⏳ بانتظار هدف",IF($E36>=1,"✅ محقق",IF($E36>=0.85,"🟡 قريب","🔴 تحت الهدف"))) | G36: =IF($E36="","",MINIFS('قاعدة المؤشرات'!$G$2:$G$223,'قاعدة المؤشرات'!$B$2:$B$223,"إدارة المشاريع",'قاعدة المؤشرات'!$L$2:$L$223,"إجمالي التسليم")) | H36: =COUNTIFS('قاعدة المؤشرات'!$H$2:$H$223,"🔴 تحت الهدف",'قاعدة المؤشرات'!$B$2:$B$223,"إدارة المشاريع",'قاعدة المؤشرات'!$L$2:$L$223,"إجمالي التسليم") | I36: إجمالي المحطات المُسلَّمة بالهوية (شركة + امتياز)
A37: 35 | B37: إدارة المشاريع | C37: الجودة والمقاولون | D37: 3 | E37: =IFERROR(SUMIFS('قاعدة المؤشرات'!$J$2:$J$223,'قاعدة المؤشرات'!$B$2:$B$223,"إدارة المشاريع",'قاعدة المؤشرات'!$L$2:$L$223,"الجودة والمقاولون")/SUMIFS('قاعدة المؤشرات'!$K$2:$K$223,'قاعدة المؤشرات'!$B$2:$B$223,"إدارة المشاريع",'قاعدة المؤشرات'!$L$2:$L$223,"الجودة والمقاولون"),"") | F37: =IF($E37="","⏳ بانتظار هدف",IF($E37>=1,"✅ محقق",IF($E37>=0.85,"🟡 قريب","🔴 تحت الهدف"))) | G37: =IF($E37="","",MINIFS('قاعدة المؤشرات'!$G$2:$G$223,'قاعدة المؤشرات'!$B$2:$B$223,"إدارة المشاريع",'قاعدة المؤشرات'!$L$2:$L$223,"الجودة والمقاولون")) | H37: =COUNTIFS('قاعدة المؤشرات'!$H$2:$H$223,"🔴 تحت الهدف",'قاعدة المؤشرات'!$B$2:$B$223,"إدارة المشاريع",'قاعدة المؤشرات'!$L$2:$L$223,"الجودة والمقاولون") | I37: نسبة المشاريع الخالية من مخالفات الجودة · عدد مخالفات المقاولين (سنوي) · نسبة التزام المقاولين بمعايير السلامة
A38: 36 | B38: إدارة المشاريع | C38: الالتزام بالخطة | D38: 2 | E38: =IFERROR(SUMIFS('قاعدة المؤشرات'!$J$2:$J$223,'قاعدة المؤشرات'!$B$2:$B$223,"إدارة المشاريع",'قاعدة المؤشرات'!$L$2:$L$223,"الالتزام بالخطة")/SUMIFS('قاعدة المؤشرات'!$K$2:$K$223,'قاعدة المؤشرات'!$B$2:$B$223,"إدارة المشاريع",'قاعدة المؤشرات'!$L$2:$L$223,"الالتزام بالخطة"),"") | F38: =IF($E38="","⏳ بانتظار هدف",IF($E38>=1,"✅ محقق",IF($E38>=0.85,"🟡 قريب","🔴 تحت الهدف"))) | G38: =IF($E38="","",MINIFS('قاعدة المؤشرات'!$G$2:$G$223,'قاعدة المؤشرات'!$B$2:$B$223,"إدارة المشاريع",'قاعدة المؤشرات'!$L$2:$L$223,"الالتزام بالخطة")) | H38: =COUNTIFS('قاعدة المؤشرات'!$H$2:$H$223,"🔴 تحت الهدف",'قاعدة المؤشرات'!$B$2:$B$223,"إدارة المشاريع",'قاعدة المؤشرات'!$L$2:$L$223,"الالتزام بالخطة") | I38: نسبة الالتزام بالميزانية المعتمدة · نسبة الالتزام بالجدول الزمني العام
A39: 37 | B39: إدارة المشاريع | C39: التصاميم وأوامر التغيير | D39: 1 | E39: =IFERROR(SUMIFS('قاعدة المؤشرات'!$J$2:$J$223,'قاعدة المؤشرات'!$B$2:$B$223,"إدارة المشاريع",'قاعدة المؤشرات'!$L$2:$L$223,"التصاميم وأوامر التغيير")/SUMIFS('قاعدة المؤشرات'!$K$2:$K$223,'قاعدة المؤشرات'!$B$2:$B$223,"إدارة المشاريع",'قاعدة المؤشرات'!$L$2:$L$223,"التصاميم وأوامر التغيير"),"") | F39: =IF($E39="","⏳ بانتظار هدف",IF($E39>=1,"✅ محقق",IF($E39>=0.85,"🟡 قريب","🔴 تحت الهدف"))) | G39: =IF($E39="","",MINIFS('قاعدة المؤشرات'!$G$2:$G$223,'قاعدة المؤشرات'!$B$2:$B$223,"إدارة المشاريع",'قاعدة المؤشرات'!$L$2:$L$223,"التصاميم وأوامر التغيير")) | H39: =COUNTIFS('قاعدة المؤشرات'!$H$2:$H$223,"🔴 تحت الهدف",'قاعدة المؤشرات'!$B$2:$B$223,"إدارة المشاريع",'قاعدة المؤشرات'!$L$2:$L$223,"التصاميم وأوامر التغيير") | I39: متوسط مدة إغلاق قائمة الملاحظات النهائية
A40: 38 | B40: سلاسل الإمداد | C40: خدمة العميل والتوفّر | D40: 2 | E40: =IFERROR(SUMIFS('قاعدة المؤشرات'!$J$2:$J$223,'قاعدة المؤشرات'!$B$2:$B$223,"سلاسل الإمداد",'قاعدة المؤشرات'!$L$2:$L$223,"خدمة العميل والتوفّر")/SUMIFS('قاعدة المؤشرات'!$K$2:$K$223,'قاعدة المؤشرات'!$B$2:$B$223,"سلاسل الإمداد",'قاعدة المؤشرات'!$L$2:$L$223,"خدمة العميل والتوفّر"),"") | F40: =IF($E40="","⏳ بانتظار هدف",IF($E40>=1,"✅ محقق",IF($E40>=0.85,"🟡 قريب","🔴 تحت الهدف"))) | G40: =IF($E40="","",MINIFS('قاعدة المؤشرات'!$G$2:$G$223,'قاعدة المؤشرات'!$B$2:$B$223,"سلاسل الإمداد",'قاعدة المؤشرات'!$L$2:$L$223,"خدمة العميل والتوفّر")) | H40: =COUNTIFS('قاعدة المؤشرات'!$H$2:$H$223,"🔴 تحت الهدف",'قاعدة المؤشرات'!$B$2:$B$223,"سلاسل الإمداد",'قاعدة المؤشرات'!$L$2:$L$223,"خدمة العميل والتوفّر") | I40: نسبة تلبية طلبات المحطات من الوقود Fill Rate · عدد انقطاعات التوريد المؤثرة شهريًا
...

Sheet الاستراتيجية والمستهدفات
B2: درب · الاستراتيجية ومستهدفات 2026 — قطاع المحطات والعقار
B4: الركيزة (5 سنوات) / الهدف | C4: الوصف | D4: مستهدف 2026
B5: النمو | C5: التوسع في المواقع وزيادة الوصول وتنمية الإيراد.
B6: التوسع في المواقع | C6: افتتاح وتشغيل محطات جديدة. | D6: التشغيل 85 · الامتياز 150 محطة
B7: الامتياز والعقود | C7: تنمية الإيراد عبر الامتياز والاستثمار. | D7: الامتياز 167 · الاستثمار 190 عقد
B8: زيادة وصول العملاء | C8: رفع المبيعات والتغطية الجغرافية. | D8: 718.8M لتر · 13 منطقة · 59 مدينة
B9: الابتكار | C9: مشاريع جديدة وتحول تقني وهوية وتانكي.
B10: التحول التقني | C10: أتمتة 164 محطة · D365 · جاهزية الأنظمة. | D10: أتمتة 90% · جاهزية 99%
B11: ساحات درب وتانكي | C11: تشغيل ساحات درب ونمو تطبيق تانكي (التسويق). | D11: تأجير ساحة ≥80% · تانكي تصاعدي
B12: الاستدامة | C12: جودة التشغيل وتجربة العميل والموظفين.
B13: تجربة العميل وجودة التشغيل | C13: رضا وأمن سيبراني وجاهزية. | D13: CSAT 90% · جاهزية 99%
B14: منظومة التأجير | C14: الإشغال والتحصيل واستدامة المستأجرين. | D14: إشغال ≥60% · 246 علامة
B15: الاستثمار في الموظفين | C15: التوطين والتدريب والاستبقاء. | D15: 6 دورات · استبقاء 90% · سعودة
B17: الخارطة التنفيذية — المشاريع (أداء حي)
B18: المشروع | C18: الركيزة | D18: عدد المؤشرات | E18: الأداء (حي)
B19: التوسع في المواقع | C19: النمو | D19: =COUNTIF('قاعدة المؤشرات'!$E$2:$E$223,"التوسع في المواقع") | E19: =IFERROR(AVERAGEIFS('قاعدة المؤشرات'!$G$2:$G$223,'قاعدة المؤشرات'!$E$2:$E$223,"التوسع في المواقع"),"—")
B20: الامتياز التجاري | C20: النمو | D20: =COUNTIF('قاعدة المؤشرات'!$E$2:$E$223,"الامتياز التجاري") | E20: =IFERROR(AVERAGEIFS('قاعدة المؤشرات'!$G$2:$G$223,'قاعدة المؤشرات'!$E$2:$E$223,"الامتياز التجاري"),"—")
B21: زيادة وصول العملاء | C21: النمو | D21: =COUNTIF('قاعدة المؤشرات'!$E$2:$E$223,"زيادة وصول العملاء") | E21: =IFERROR(AVERAGEIFS('قاعدة المؤشرات'!$G$2:$G$223,'قاعدة المؤشرات'!$E$2:$E$223,"زيادة وصول العملاء"),"—")
B22: إطلاق مشاريع جديدة | C22: الابتكار | D22: =COUNTIF('قاعدة المؤشرات'!$E$2:$E$223,"إطلاق مشاريع جديدة") | E22: =IFERROR(AVERAGEIFS('قاعدة المؤشرات'!$G$2:$G$223,'قاعدة المؤشرات'!$E$2:$E$223,"إطلاق مشاريع جديدة"),"—")
B23: تطوير التصاميم والهوية | C23: الابتكار | D23: =COUNTIF('قاعدة المؤشرات'!$E$2:$E$223,"تطوير التصاميم والهوية") | E23: =IFERROR(AVERAGEIFS('قاعدة المؤشرات'!$G$2:$G$223,'قاعدة المؤشرات'!$E$2:$E$223,"تطوير التصاميم والهوية"),"—")
B24: التحول التقني | C24: الابتكار | D24: =COUNTIF('قاعدة المؤشرات'!$E$2:$E$223,"التحول التقني") | E24: =IFERROR(AVERAGEIFS('قاعدة المؤشرات'!$G$2:$G$223,'قاعدة المؤشرات'!$E$2:$E$223,"التحول التقني"),"—")
B25: ساحات درب | C25: الابتكار | D25: =COUNTIF('قاعدة المؤشرات'!$E$2:$E$223,"ساحات درب") | E25: =IFERROR(AVERAGEIFS('قاعدة المؤشرات'!$G$2:$G$223,'قاعدة المؤشرات'!$E$2:$E$223,"ساحات درب"),"—")
B26: تطبيق «تانكي» | C26: الابتكار | D26: =COUNTIF('قاعدة المؤشرات'!$E$2:$E$223,"تطبيق «تانكي»") | E26: =IFERROR(AVERAGEIFS('قاعدة المؤشرات'!$G$2:$G$223,'قاعدة المؤشرات'!$E$2:$E$223,"تطبيق «تانكي»"),"—")
B27: تعزيز تجربة العملاء | C27: الاستدامة | D27: =COUNTIF('قاعدة المؤشرات'!$E$2:$E$223,"تعزيز تجربة العملاء") | E27: =IFERROR(AVERAGEIFS('قاعدة المؤشرات'!$G$2:$G$223,'قاعدة المؤشرات'!$E$2:$E$223,"تعزيز تجربة العملاء"),"—")
B28: جودة التشغيل | C28: الاستدامة | D28: =COUNTIF('قاعدة المؤشرات'!$E$2:$E$223,"جودة التشغيل") | E28: =IFERROR(AVERAGEIFS('قاعدة المؤشرات'!$G$2:$G$223,'قاعدة المؤشرات'!$E$2:$E$223,"جودة التشغيل"),"—")
B29: منظومة التأجير | C29: الاستدامة | D29: =COUNTIF('قاعدة المؤشرات'!$E$2:$E$223,"منظومة التأجير") | E29: =IFERROR(AVERAGEIFS('قاعدة المؤشرات'!$G$2:$G$223,'قاعدة المؤشرات'!$E$2:$E$223,"منظومة التأجير"),"—")
B30: الاستثمار في الموظفين | C30: الاستدامة | D30: =COUNTIF('قاعدة المؤشرات'!$E$2:$E$223,"الاستثمار في الموظفين") | E30: =IFERROR(AVERAGEIFS('قاعدة المؤشرات'!$G$2:$G$223,'قاعدة المؤشرات'!$E$2:$E$223,"الاستثمار في الموظفين"),"—")

Sheet الخريطة الاستراتيجية
B2: الخريطة الاستراتيجية — علاقات السبب والأثر (Balanced Scorecard) · الأداء حي
B4: ⬆ المنظور المالي — القيمة للمساهمين
B5: النمو · الربحية · التدفّق النقدي والتحصيل
B6: =IFERROR(AVERAGEIFS('قاعدة المؤشرات'!$G$2:$G$223,'قاعدة المؤشرات'!$F$2:$F$223,"مالي"),"—")
C7: ⬆ | E7: ⬆ | G7: ⬆ | I7: ⬆ | K7: ⬆
B8: المنظور — العملاء
B9: زيادة وصول العملاء | E9: تعزيز تجربة العملاء | H9: تطبيق تانكي والولاء
B10: =IFERROR(AVERAGEIFS('قاعدة المؤشرات'!$G$2:$G$223,'قاعدة المؤشرات'!$E$2:$E$223,"زيادة وصول العملاء"),"—") | E10: =IFERROR(AVERAGEIFS('قاعدة المؤشرات'!$G$2:$G$223,'قاعدة المؤشرات'!$E$2:$E$223,"تعزيز تجربة العملاء"),"—") | H10: =IFERROR(AVERAGEIFS('قاعدة المؤشرات'!$G$2:$G$223,'قاعدة المؤشرات'!$E$2:$E$223,"تطبيق «تانكي»"),"—")
C11: ⬆ | E11: ⬆ | G11: ⬆ | I11: ⬆ | K11: ⬆
B12: المنظور — العمليات الداخلية
B13: التوسع في المواقع | D13: الامتياز التجاري | F13: منظومة التأجير | H13: ساحات درب | J13: جودة التشغيل
B14: =IFERROR(AVERAGEIFS('قاعدة المؤشرات'!$G$2:$G$223,'قاعدة المؤشرات'!$E$2:$E$223,"التوسع في المواقع"),"—") | D14: =IFERROR(AVERAGEIFS('قاعدة المؤشرات'!$G$2:$G$223,'قاعدة المؤشرات'!$E$2:$E$223,"الامتياز التجاري"),"—") | F14: =IFERROR(AVERAGEIFS('قاعدة المؤشرات'!$G$2:$G$223,'قاعدة المؤشرات'!$E$2:$E$223,"منظومة التأجير"),"—") | H14: =IFERROR(AVERAGEIFS('قاعدة المؤشرات'!$G$2:$G$223,'قاعدة المؤشرات'!$E$2:$E$223,"ساحات درب"),"—") | J14: =IFERROR(AVERAGEIFS('قاعدة المؤشرات'!$G$2:$G$223,'قاعدة المؤشرات'!$E$2:$E$223,"جودة التشغيل"),"—")
C15: ⬆ | E15: ⬆ | G15: ⬆ | I15: ⬆ | K15: ⬆
B16: المنظور — التعلّم والنمو (الأساس الممكِّن)
B17: الاستثمار في الموظفين | D17: التحول التقني | F17: إطلاق مشاريع جديدة | H17: التصاميم والهوية
B18: =IFERROR(AVERAGEIFS('قاعدة المؤشرات'!$G$2:$G$223,'قاعدة المؤشرات'!$E$2:$E$223,"الاستثمار في الموظفين"),"—") | D18: =IFERROR(AVERAGEIFS('قاعدة المؤشرات'!$G$2:$G$223,'قاعدة المؤشرات'!$E$2:$E$223,"التحول التقني"),"—") | F18: =IFERROR(AVERAGEIFS('قاعدة المؤشرات'!$G$2:$G$223,'قاعدة المؤشرات'!$E$2:$E$223,"إطلاق مشاريع جديدة"),"—") | H18: =IFERROR(AVERAGEIFS('قاعدة المؤشرات'!$G$2:$G$223,'قاعدة المؤشرات'!$E$2:$E$223,"تطوير التصاميم والهوية"),"—")
B19: القراءة من الأسفل للأعلى: تطوير الكوادر والتقنية ⟵ يُمكّن العمليات ⟵ يخلق قيمة للعملاء ⟵ يُنتج النتائج المالية

Sheet اللوحة الموجزة
B2: اللوحة الموجزة — إنجاز موزون (وزن المؤشر × وزن الإدارة) · سقف 100%
B4: الإنجاز العام (موزون) | C4: ✅ محقق | D4: 🟡 قريب | E4: 🔴 تحت الهدف
B5: =IFERROR(SUMPRODUCT(I9:I22,H9:H22)/SUMPRODUCT(I9:I22,J9:J22),0) | C5: =COUNTIFS('قاعدة المؤشرات'!$H$2:$H$223,"✅ محقق",'قاعدة المؤشرات'!$B$2:$B$223,"<>الإدارة التنفيذية") | D5: =COUNTIFS('قاعدة المؤشرات'!$H$2:$H$223,"🟡 قريب",'قاعدة المؤشرات'!$B$2:$B$223,"<>الإدارة التنفيذية") | E5: =COUNTIFS('قاعدة المؤشرات'!$H$2:$H$223,"🔴 تحت الهدف",'قاعدة المؤشرات'!$B$2:$B$223,"<>الإدارة التنفيذية")
B7: الأداء حسب الإدارة (موزون) | D7: حسب الركيزة
B8: الإدارة | C8: الأداء | D8: الركيزة | E8: الأداء
B9: الإدارة التنفيذية | C9: =IFERROR(SUMIF('قاعدة المؤشرات'!$B$2:$B$223,"الإدارة التنفيذية",'قاعدة المؤشرات'!$J$2:$J$223)/SUMIF('قاعدة المؤشرات'!$B$2:$B$223,"الإدارة التنفيذية",'قاعدة المؤشرات'!$K$2:$K$223),"—") | D9: النمو | E9: =IFERROR(AVERAGEIFS('قاعدة المؤشرات'!$G$2:$G$223,'قاعدة المؤشرات'!$D$2:$D$223,"النمو"),"—") | H9: =IFERROR(SUMIF('قاعدة المؤشرات'!$B$2:$B$223,"الإدارة التنفيذية",'قاعدة المؤشرات'!$J$2:$J$223)/SUMIF('قاعدة المؤشرات'!$B$2:$B$223,"الإدارة التنفيذية",'قاعدة المؤشرات'!$K$2:$K$223),0) | I9: 0 | J9: =IF(SUMIF('قاعدة المؤشرات'!$B$2:$B$223,"الإدارة التنفيذية",'قاعدة المؤشرات'!$K$2:$K$223)=0,0,1)
B10: الامتياز التجاري | C10: =IFERROR(SUMIF('قاعدة المؤشرات'!$B$2:$B$223,"الامتياز التجاري",'قاعدة المؤشرات'!$J$2:$J$223)/SUMIF('قاعدة المؤشرات'!$B$2:$B$223,"الامتياز التجاري",'قاعدة المؤشرات'!$K$2:$K$223),"—") | D10: الابتكار | E10: =IFERROR(AVERAGEIFS('قاعدة المؤشرات'!$G$2:$G$223,'قاعدة المؤشرات'!$D$2:$D$223,"الابتكار"),"—") | H10: =IFERROR(SUMIF('قاعدة المؤشرات'!$B$2:$B$223,"الامتياز التجاري",'قاعدة المؤشرات'!$J$2:$J$223)/SUMIF('قاعدة المؤشرات'!$B$2:$B$223,"الامتياز التجاري",'قاعدة المؤشرات'!$K$2:$K$223),0) | I10: 0.14 | J10: =IF(SUMIF('قاعدة المؤشرات'!$B$2:$B$223,"الامتياز التجاري",'قاعدة المؤشرات'!$K$2:$K$223)=0,0,1)
B11: التشغيل والمحطات | C11: =IFERROR(SUMIF('قاعدة المؤشرات'!$B$2:$B$223,"التشغيل والمحطات",'قاعدة المؤشرات'!$J$2:$J$223)/SUMIF('قاعدة المؤشرات'!$B$2:$B$223,"التشغيل والمحطات",'قاعدة المؤشرات'!$K$2:$K$223),"—") | D11: الاستدامة | E11: =IFERROR(AVERAGEIFS('قاعدة المؤشرات'!$G$2:$G$223,'قاعدة المؤشرات'!$D$2:$D$223,"الاستدامة"),"—") | H11: =IFERROR(SUMIF('قاعدة المؤشرات'!$B$2:$B$223,"التشغيل والمحطات",'قاعدة المؤشرات'!$J$2:$J$223)/SUMIF('قاعدة المؤشرات'!$B$2:$B$223,"التشغيل والمحطات",'قاعدة المؤشرات'!$K$2:$K$223),0) | I11: 0.12 | J11: =IF(SUMIF('قاعدة المؤشرات'!$B$2:$B$223,"التشغيل والمحطات",'قاعدة المؤشرات'!$K$2:$K$223)=0,0,1)
B12: الاستثمار | C12: =IFERROR(SUMIF('قاعدة المؤشرات'!$B$2:$B$223,"الاستثمار",'قاعدة المؤشرات'!$J$2:$J$223)/SUMIF('قاعدة المؤشرات'!$B$2:$B$223,"الاستثمار",'قاعدة المؤشرات'!$K$2:$K$223),"—") | H12: =IFERROR(SUMIF('قاعدة المؤشرات'!$B$2:$B$223,"الاستثمار",'قاعدة المؤشرات'!$J$2:$J$223)/SUMIF('قاعدة المؤشرات'!$B$2:$B$223,"الاستثمار",'قاعدة المؤشرات'!$K$2:$K$223),0) | I12: 0.11 | J12: =IF(SUMIF('قاعدة المؤشرات'!$B$2:$B$223,"الاستثمار",'قاعدة المؤشرات'!$K$2:$K$223)=0,0,1)
B13: العقار | C13: =IFERROR(SUMIF('قاعدة المؤشرات'!$B$2:$B$223,"العقار",'قاعدة المؤشرات'!$J$2:$J$223)/SUMIF('قاعدة المؤشرات'!$B$2:$B$223,"العقار",'قاعدة المؤشرات'!$K$2:$K$223),"—") | D13: حسب منظور BSC | H13: =IFERROR(SUMIF('قاعدة المؤشرات'!$B$2:$B$223,"العقار",'قاعدة المؤشرات'!$J$2:$J$223)/SUMIF('قاعدة المؤشرات'!$B$2:$B$223,"العقار",'قاعدة المؤشرات'!$K$2:$K$223),0) | I13: 0.09 | J13: =IF(SUMIF('قاعدة المؤشرات'!$B$2:$B$223,"العقار",'قاعدة المؤشرات'!$K$2:$K$223)=0,0,1)
B14: إدارة المشاريع | C14: =IFERROR(SUMIF('قاعدة المؤشرات'!$B$2:$B$223,"إدارة المشاريع",'قاعدة المؤشرات'!$J$2:$J$223)/SUMIF('قاعدة المؤشرات'!$B$2:$B$223,"إدارة المشاريع",'قاعدة المؤشرات'!$K$2:$K$223),"—") | D14: مالي | E14: =IFERROR(AVERAGEIFS('قاعدة المؤشرات'!$G$2:$G$223,'قاعدة المؤشرات'!$F$2:$F$223,"مالي"),"—") | H14: =IFERROR(SUMIF('قاعدة المؤشرات'!$B$2:$B$223,"إدارة المشاريع",'قاعدة المؤشرات'!$J$2:$J$223)/SUMIF('قاعدة المؤشرات'!$B$2:$B$223,"إدارة المشاريع",'قاعدة المؤشرات'!$K$2:$K$223),0) | I14: 0.08 | J14: =IF(SUMIF('قاعدة المؤشرات'!$B$2:$B$223,"إدارة المشاريع",'قاعدة المؤشرات'!$K$2:$K$223)=0,0,1)
B15: سلاسل الإمداد | C15: =IFERROR(SUMIF('قاعدة المؤشرات'!$B$2:$B$223,"سلاسل الإمداد",'قاعدة المؤشرات'!$J$2:$J$223)/SUMIF('قاعدة المؤشرات'!$B$2:$B$223,"سلاسل الإمداد",'قاعدة المؤشرات'!$K$2:$K$223),"—") | D15: العملاء | E15: =IFERROR(AVERAGEIFS('قاعدة المؤشرات'!$G$2:$G$223,'قاعدة المؤشرات'!$F$2:$F$223,"العملاء"),"—") | H15: =IFERROR(SUMIF('قاعدة المؤشرات'!$B$2:$B$223,"سلاسل الإمداد",'قاعدة المؤشرات'!$J$2:$J$223)/SUMIF('قاعدة المؤشرات'!$B$2:$B$223,"سلاسل الإمداد",'قاعدة المؤشرات'!$K$2:$K$223),0) | I15: 0.1 | J15: =IF(SUMIF('قاعدة المؤشرات'!$B$2:$B$223,"سلاسل الإمداد",'قاعدة المؤشرات'!$K$2:$K$223)=0,0,1)
B16: الصيانة والأتمتة | C16: =IFERROR(SUMIF('قاعدة المؤشرات'!$B$2:$B$223,"الصيانة والأتمتة",'قاعدة المؤشرات'!$J$2:$J$223)/SUMIF('قاعدة المؤشرات'!$B$2:$B$223,"الصيانة والأتمتة",'قاعدة المؤشرات'!$K$2:$K$223),"—") | D16: العمليات الداخلية | E16: =IFERROR(AVERAGEIFS('قاعدة المؤشرات'!$G$2:$G$223,'قاعدة المؤشرات'!$F$2:$F$223,"العمليات الداخلية"),"—") | H16: =IFERROR(SUMIF('قاعدة المؤشرات'!$B$2:$B$223,"الصيانة والأتمتة",'قاعدة المؤشرات'!$J$2:$J$223)/SUMIF('قاعدة المؤشرات'!$B$2:$B$223,"الصيانة والأتمتة",'قاعدة المؤشرات'!$K$2:$K$223),0) | I16: 0.07 | J16: =IF(SUMIF('قاعدة المؤشرات'!$B$2:$B$223,"الصيانة والأتمتة",'قاعدة المؤشرات'!$K$2:$K$223)=0,0,1)
B17: التقنية الرقمية | C17: =IFERROR(SUMIF('قاعدة المؤشرات'!$B$2:$B$223,"التقنية الرقمية",'قاعدة المؤشرات'!$J$2:$J$223)/SUMIF('قاعدة المؤشرات'!$B$2:$B$223,"التقنية الرقمية",'قاعدة المؤشرات'!$K$2:$K$223),"—") | D17: التعلّم والنمو | E17: =IFERROR(AVERAGEIFS('قاعدة المؤشرات'!$G$2:$G$223,'قاعدة المؤشرات'!$F$2:$F$223,"التعلّم والنمو"),"—") | H17: =IFERROR(SUMIF('قاعدة المؤشرات'!$B$2:$B$223,"التقنية الرقمية",'قاعدة المؤشرات'!$J$2:$J$223)/SUMIF('قاعدة المؤشرات'!$B$2:$B$223,"التقنية الرقمية",'قاعدة المؤشرات'!$K$2:$K$223),0) | I17: 0.04 | J17: =IF(SUMIF('قاعدة المؤشرات'!$B$2:$B$223,"التقنية الرقمية",'قاعدة المؤشرات'!$K$2:$K$223)=0,0,1)
B18: الموارد البشرية | C18: =IFERROR(SUMIF('قاعدة المؤشرات'!$B$2:$B$223,"الموارد البشرية",'قاعدة المؤشرات'!$J$2:$J$223)/SUMIF('قاعدة المؤشرات'!$B$2:$B$223,"الموارد البشرية",'قاعدة المؤشرات'!$K$2:$K$223),"—") | H18: =IFERROR(SUMIF('قاعدة المؤشرات'!$B$2:$B$223,"الموارد البشرية",'قاعدة المؤشرات'!$J$2:$J$223)/SUMIF('قاعدة المؤشرات'!$B$2:$B$223,"الموارد البشرية",'قاعدة المؤشرات'!$K$2:$K$223),0) | I18: 0.04 | J18: =IF(SUMIF('قاعدة المؤشرات'!$B$2:$B$223,"الموارد البشرية",'قاعدة المؤشرات'!$K$2:$K$223)=0,0,1)
B19: التسويق | C19: =IFERROR(SUMIF('قاعدة المؤشرات'!$B$2:$B$223,"التسويق",'قاعدة المؤشرات'!$J$2:$J$223)/SUMIF('قاعدة المؤشرات'!$B$2:$B$223,"التسويق",'قاعدة المؤشرات'!$K$2:$K$223),"—") | H19: =IFERROR(SUMIF('قاعدة المؤشرات'!$B$2:$B$223,"التسويق",'قاعدة المؤشرات'!$J$2:$J$223)/SUMIF('قاعدة المؤشرات'!$B$2:$B$223,"التسويق",'قاعدة المؤشرات'!$K$2:$K$223),0) | I19: 0.05 | J19: =IF(SUMIF('قاعدة المؤشرات'!$B$2:$B$223,"التسويق",'قاعدة المؤشرات'!$K$2:$K$223)=0,0,1)
B20: الجودة | C20: =IFERROR(SUMIF('قاعدة المؤشرات'!$B$2:$B$223,"الجودة",'قاعدة المؤشرات'!$J$2:$J$223)/SUMIF('قاعدة المؤشرات'!$B$2:$B$223,"الجودة",'قاعدة المؤشرات'!$K$2:$K$223),"—") | H20: =IFERROR(SUMIF('قاعدة المؤشرات'!$B$2:$B$223,"الجودة",'قاعدة المؤشرات'!$J$2:$J$223)/SUMIF('قاعدة المؤشرات'!$B$2:$B$223,"الجودة",'قاعدة المؤشرات'!$K$2:$K$223),0) | I20: 0.05 | J20: =IF(SUMIF('قاعدة المؤشرات'!$B$2:$B$223,"الجودة",'قاعدة المؤشرات'!$K$2:$K$223)=0,0,1)
B21: الإدارة القانونية | C21: =IFERROR(SUMIF('قاعدة المؤشرات'!$B$2:$B$223,"الإدارة القانونية",'قاعدة المؤشرات'!$J$2:$J$223)/SUMIF('قاعدة المؤشرات'!$B$2:$B$223,"الإدارة القانونية",'قاعدة المؤشرات'!$K$2:$K$223),"—") | H21: =IFERROR(SUMIF('قاعدة المؤشرات'!$B$2:$B$223,"الإدارة القانونية",'قاعدة المؤشرات'!$J$2:$J$223)/SUMIF('قاعدة المؤشرات'!$B$2:$B$223,"الإدارة القانونية",'قاعدة المؤشرات'!$K$2:$K$223),0) | I21: 0.03 | J21: =IF(SUMIF('قاعدة المؤشرات'!$B$2:$B$223,"الإدارة القانونية",'قاعدة المؤشرات'!$K$2:$K$223)=0,0,1)
B22: الإدارة المالية | C22: =IFERROR(SUMIF('قاعدة المؤشرات'!$B$2:$B$223,"الإدارة المالية",'قاعدة المؤشرات'!$J$2:$J$223)/SUMIF('قاعدة المؤشرات'!$B$2:$B$223,"الإدارة المالية",'قاعدة المؤشرات'!$K$2:$K$223),"—") | H22: =IFERROR(SUMIF('قاعدة المؤشرات'!$B$2:$B$223,"الإدارة المالية",'قاعدة المؤشرات'!$J$2:$J$223)/SUMIF('قاعدة المؤشرات'!$B$2:$B$223,"الإدارة المالية",'قاعدة المؤشرات'!$K$2:$K$223),0) | I22: 0.08 | J22: =IF(SUMIF('قاعدة المؤشرات'!$B$2:$B$223,"الإدارة المالية",'قاعدة المؤشرات'!$K$2:$K$223)=0,0,1)

Sheet تحليل الانحراف
A1: تحليل الانحراف — المؤشرات دون المستهدف مع السبب والإجراء (تقرير الاستثناءات)
A2: # | B2: الإدارة | C2: المؤشر | D2: المُحقَّق | E2: المستهدف | F2: نسبة التحقيق | G2: الفجوة | H2: التنبؤ | I2: الحالة | J2: السبب | K2: الإجراء التصحيحي | L2: المالك | M2: الموعد
A3: 1 | B3: التسويق | C3: معدل التفاعل (Engagement) | D3: 0 | E3: 0.5 | F3: 0 | G3: 1 | H3: 0 | I3: 🔴 تحت الهدف | J3: انحراف جوهري — أولوية عاجلة. | K3: إجراء تصحيحي خلال 30 يوماً. | L3: مدير التسويق
A4: 2 | B4: التسويق | C4: عدد المعارض بالسنة | D4: 0 | E4: 3 | F4: 0 | G4: 1 | H4: 0 | I4: 🔴 تحت الهدف | J4: انحراف جوهري — أولوية عاجلة. | K4: إجراء تصحيحي خلال 30 يوماً. | L4: مدير التسويق
A5: 3 | B5: التسويق | C5: اتفاقيات استراتيجية | D5: 0 | E5: 3 | F5: 0 | G5: 1 | H5: 0 | I5: 🔴 تحت الهدف | J5: انحراف جوهري — أولوية عاجلة. | K5: إجراء تصحيحي خلال 30 يوماً. | L5: مدير التسويق
A6: 4 | B6: التسويق | C6: عملاء تجاريون جدد | D6: 1 | E6: 200 | F6: 0.005 | G6: 0.995 | H6: 2 | I6: 🔴 تحت الهدف | J6: انحراف جوهري — أولوية عاجلة. | K6: إجراء تصحيحي خلال 30 يوماً. | L6: مدير التسويق
A7: 5 | B7: التسويق | C7: الوصول الكلي (Total Reach) | D7: 5000000 | E7: 50000000 | F7: 0.1 | G7: 0.9 | H7: 5000000 | I7: 🔴 تحت الهدف | J7: انحراف جوهري — أولوية عاجلة. | K7: إجراء تصحيحي خلال 30 يوماً. | L7: مدير التسويق
A8: 6 | B8: التسويق | C8: نسبة التزام الهوية البصرية | D8: 0.1 | E8: 1 | F8: 0.1 | G8: 0.9 | H8: 0.1 | I8: 🔴 تحت الهدف | J8: انحراف جوهري — أولوية عاجلة. | K8: إجراء تصحيحي خلال 30 يوماً. | L8: مدير التسويق
A9: 7 | B9: التسويق | C9: نسبة المبيعات لكل حملة | D9: 0.16 | E9: 1 | F9: 0.16 | G9: 0.84 | H9: 0.16 | I9: 🔴 تحت الهدف | J9: انحراف جوهري — أولوية عاجلة. | K9: إجراء تصحيحي خلال 30 يوماً. | L9: مدير التسويق
A10: 8 | B10: التسويق | C10: وصول العلاقات العامة (PR) | D10: 1500000 | E10: 7000000 | F10: 0.21428571 | G10: 0.78571429 | H10: 1500000 | I10: 🔴 تحت الهدف | J10: انحراف جوهري — أولوية عاجلة. | K10: إجراء تصحيحي خلال 30 يوماً. | L10: مدير التسويق
A11: 9 | B11: التسويق | C11: حملات تسويقية منجزة | D11: 11 | E11: 48 | F11: 0.22916667 | G11: 0.77083333 | H11: 22 | I11: 🔴 تحت الهدف | J11: انحراف جوهري — أولوية عاجلة. | K11: إجراء تصحيحي خلال 30 يوماً. | L11: مدير التسويق
A12: 10 | B12: التسويق | C12: إجمالي المتابعين (كل المنصات) | D12: 253000 | E12: 380000 | F12: 0.66578947 | G12: 0.33421053 | H12: 253000 | I12: 🔴 تحت الهدف | J12: انحراف جوهري — أولوية عاجلة. | K12: إجراء تصحيحي خلال 30 يوماً. | L12: مدير التسويق
A13: 11 | B13: التسويق | C13: تحويل الفرص إلى عقود | D13: 0.17 | E13: 0.25 | F13: 0.68 | G13: 0.32 | H13: 0.17 | I13: 🔴 تحت الهدف | J13: انحراف جوهري — أولوية عاجلة. | K13: إجراء تصحيحي خلال 30 يوماً. | L13: مدير التسويق
A14: 12 | B14: التسويق | C14: معدل خفض الشكاوى | D14: 0.21 | E14: 0.3 | F14: 0.7 | G14: 0.3 | H14: 0.21 | I14: 🔴 تحت الهدف | J14: انحراف جوهري — أولوية عاجلة. | K14: إجراء تصحيحي خلال 30 يوماً. | L14: مدير التسويق
... A169: 167 | B169: الامتياز التجاري | C169: نسبة تطبيق المعيار الشامل داخل المحطات | D169: 0.299 | E169: 0.3 | F169: 0.99666667 | G169: 0.0033333333 | H169: 0.299 | I169: 🟡 قريب | J169: فجوة محدودة — متابعة. | K169: متابعة أسبوعية لإغلاق الفجوة. | L169: مدير الامتياز

Sheet التتبّع الشهري
A1: التتبّع الشهري — أدخل رقم كل شهر · «المُحقَّق» ونسبة التحقيق والحالة والوتيرة تُحسب تلقائياً
A2: 🟩 خلايا الأشهر للإدخال · تراكمي=مجموع الأشهر · معدل=متوسط المُدخل · لقطة=آخر شهر · الوتيرة: 🟢 على المسار / 🟠 متأخّر مقابل المتوقّع
A3: # | B3: الإدارة | C3: المؤشر | D3: الدورية | E3: التجميع | F3: القطبية | G3: المستهدف | H3: يناير | I3: فبراير | J3: مارس | K3: أبريل | L3: مايو | M3: يونيو | N3: يوليو | O3: أغسطس | P3: سبتمبر | Q3: أكتوبر | R3: نوفمبر | S3: ديسمبر | T3: المُحقَّق (تراكمي) | U3: نسبة التحقيق | V3: الحالة | W3: المتوقّع حتى الآن | X3: الوتيرة
A4: 1 | B4: الإدارة التنفيذية | C4: إجمالي المحطات المشغّلة — الشركة (تراكمي) | D4: شهري | E4: لقطة | F4: ↑ | G4: 235 | T4: =IFERROR(LOOKUP(2,1/($H4:$S4<>""),$H4:$S4),"") | U4: =IF($G4="","",IF($T4="","",MIN(1,IF($G4=0,IF($T4<=0,1,0),IF($F4="↓",IFERROR($G4/$T4,0),IFERROR($T4/$G4,0)))))) | V4: =IF($U4="","⏳ بانتظار هدف",IF($U4>=1.0,"✅ محقق",IF($U4>=0.85,"🟡 قريب","🔴 تحت الهدف"))) | W4: =IF($G4="","",$G4) | X4: =IF($U4="","—",IF($U4>=0.85,"🟢 على المسار","🟠 متأخّر"))
A5: 2 | B5: الإدارة التنفيذية | C5: إجمالي العقود الجديدة — الشركة | D5: شهري | E5: تراكمي | F5: ↑ | G5: 357 | T5: =IF(COUNT($H5:$S5)=0,"",SUM($H5:$S5)) | U5: =IF($G5="","",IF($T5="","",MIN(1,IF($G5=0,IF($T5<=0,1,0),IF($F5="↓",IFERROR($G5/$T5,0),IFERROR($T5/$G5,0)))))) | V5: =IF($U5="","⏳ بانتظار هدف",IF($U5>=1.0,"✅ محقق",IF($U5>=0.85,"🟡 قريب","🔴 تحت الهدف"))) | W5: =IF($G5="","",$G5*COUNT($H5:$S5)/12) | X5: =IF($U5="","—",IF($U5>=COUNT($H5:$S5)/12,"🟢 على المسار","🟠 متأخّر"))
A6: 3 | B6: الإدارة التنفيذية | C6: نسبة نمو إيرادات الشركة (سنوي) | D6: شهري | E6: معدل | F6: ↑ | G6: 0.15 | T6: =IF(COUNT($H6:$S6)=0,"",SUM($H6:$S6)/COUNT($H6:$S6)) | U6: =IF($G6="","",IF($T6="","",MIN(1,IF($G6=0,IF($T6<=0,1,0),IF($F6="↓",IFERROR($G6/$T6,0),IFERROR($T6/$G6,0)))))) | V6: =IF($U6="","⏳ بانتظار هدف",IF($U6>=1.0,"✅ محقق",IF($U6>=0.85,"🟡 قريب","🔴 تحت الهدف"))) | W6: =IF($G6="","",$G6) | X6: =IF($U6="","—",IF($U6>=0.85,"🟢 على المسار","🟠 متأخّر"))
A7: 4 | B7: الإدارة التنفيذية | C7: نسبة إنجاز مشاريع الخارطة التنفيذية | D7: شهري | E7: لقطة | F7: ↑ | G7: 1 | T7: =IFERROR(LOOKUP(2,1/($H7:$S7<>""),$H7:$S7),"") | U7: =IF($G7="","",IF($T7="","",MIN(1,IF($G7=0,IF($T7<=0,1,0),IF($F7="↓",IFERROR($G7/$T7,0),IFERROR($T7/$G7,0)))))) | V7: =IF($U7="","⏳ بانتظار هدف",IF($U7>=1.0,"✅ محقق",IF($U7>=0.85,"🟡 قريب","🔴 تحت الهدف"))) | W7: =IF($G7="","",$G7) | X7: =IF($U7="","—",IF($U7>=0.85,"🟢 على المسار","🟠 متأخّر"))
A8: 5 | B8: الإدارة التنفيذية | C8: نسبة التحول الرقمي على مستوى الشركة | D8: شهري | E8: لقطة | F8: ↑ | G8: 0.9 | T8: =IFERROR(LOOKUP(2,1/($H8:$S8<>""),$H8:$S8),"") | U8: =IF($G8="","",IF($T8="","",MIN(1,IF($G8=0,IF($T8<=0,1,0),IF($F8="↓",IFERROR($G8/$T8,0),IFERROR($T8/$G8,0)))))) | V8: =IF($U8="","⏳ بانتظار هدف",IF($U8>=1.0,"✅ محقق",IF($U8>=0.85,"🟡 قريب","🔴 تحت الهدف"))) | W8: =IF($G8="","",$G8) | X8: =IF($U8="","—",IF($U8>=0.85,"🟢 على المسار","🟠 متأخّر"))
