Workbook

Sheet 📋 بيانات المحطات
A2: 📋 بيانات المحطات وهوامش العقود — المدخلات الرئيسية
A3: ① عبِّئ هذا الشيت أولاً — كل الشيتات الأخرى تحسب نفسها | الخلايا الزرقاء = مدخلات يدوية
A5: معلومات المحطة الأساسية | H5: هوامش العقد (هللة/لتر) — من عقد كل محطة
A6: # | B6: اسم المحطة | C6: الكود | D6: الفئة | E6: الحالة | F6: المشرف الميداني | G6: عدد المضخات | H6: هامش 91 هل/ل | I6: هامش 95 هل/ل | J6: هامش 98 هل/ل | K6: هامش ديزل هل/ل
A7: 1 | B7: جبل النور | C7: MK 001 | D7: الفئة | E7: الحالة | F7: المشرف | G7: عدد المضخات | H7: هامش 91 (هللة/لتر) | I7: هامش 95 (هللة/لتر) | J7: هامش 98 (هللة/لتر) | K7: هامش ديزل (هللة/لتر)
A8: 1 | B8: المعيصم | C8: MK002 | D8: تشغيل مباشر | E8: نشطة | F8: المشرف الأول
A9: 2 | B9: العوالي | C9: MK003 | D9: تشغيل مباشر | E9: نشطة | F9: المشرف الأول
A10: 3 | B10: عاصفة الصحراء | C10: MK004 | D10: تشغيل مباشر | E10: نشطة | F10: المشرف الأول
A11: 4 | B11: الشيباني | C11: MK005 | D11: تشغيل مباشر | E11: نشطة | F11: المشرف الأول
A12: 5 | B12: جنوب الطائف | C12: MK006 | D12: تشغيل مباشر | E12: نشطة | F12: المشرف الأول
A13: 6 | B13: جنوب الحسينية | C13: MK008 | D13: تشغيل مباشر | E13: نشطة | F13: المشرف الأول
A14: 7 | B14: جدة النسيم | C14: MK015 | D14: تشغيل مباشر | E14: نشطة | F14: المشرف الأول
A15: 8 | B15: الرصيفة | C15: MK016 | D15: تشغيل مباشر | E15: نشطة | F15: المشرف الأول
A16: 9 | B16: عرفات الشوقية | C16: MK017 | D16: تشغيل مباشر | E16: نشطة | F16: المشرف الأول
A17: 10 | B17: الرصيفة مسار | C17: MK018 | D17: تشغيل مباشر | E17: نشطة | F17: المشرف الأول
A18: 11 | B18: عرفات الشرائع | C18: MK019 | D18: تشغيل مباشر | E18: نشطة | F18: المشرف الأول
A19: 12 | B19: ممشى الشوقية | C19: MK020 | D19: تشغيل مباشر | E19: نشطة | F19: المشرف الأول
... A54: 48 | B54: سلطان المطرفي | C54: MK54 | D54: تشغيل مباشر | E54: نشطة | F54: المشرف الثالث
A55: 49 | B55: محطه بن قباس | D55: تشغيل مباشر | E55: نشطة | F55: المشرف الثالث
A56: 50 | B56: محطة مدخل محايل | D56: تشغيل مباشر | E56: نشطة | F56: المشرف الثالث
A57: 51 | B57: الشوقية - سندي | D57: تشغيل مباشر | E57: نشطة | F57: المشرف الثالث
A58: 52 | B58: دوار البلديه احد المسارحه | D58: تشغيل مباشر | E58: نشطة | F58: المشرف الرابع
A59: 53 | B59: الازوري (طريق المطار) | D59: تشغيل مباشر | E59: نشطة | F59: المشرف الرابع
A60: 54 | B60: عبد الله الخريجي | D60: تشغيل مباشر | E60: نشطة | F60: المشرف الرابع

Sheet ⛽ المبيعات الشهرية
A2: ⛽ المبيعات الشهرية — مفصّلة حسب المنتج (لتر)
A3: ② عبِّئ كميات المبيعات بالليتر — الإجماليات تحسب تلقائياً | الخلايا الزرقاء = مدخلات يدوية
A5: # | B5: اسم المحطة | C5: بنزين 91 | O5: بنزين 95 | AA5: بنزين 98 | AM5: ديزل | AY5: الإجمالي الكلي
A6: # | B6: اسم المحطة | C6: ينا | D6: فبر | E6: مار | F6: أبر | G6: ماي | H6: يون | I6: يول | J6: أغس | K6: سبت | L6: أكت | M6: نوف | N6: ديس | O6: ينا | P6: فبر | Q6: مار | R6: أبر | S6: ماي | T6: يون | U6: يول | V6: أغس | W6: سبت | X6: أكت | Y6: نوف | Z6: ديس | AA6: ينا | AB6: فبر | AC6: مار | AD6: أبر | AE6: ماي | AF6: يون | AG6: يول | AH6: أغس | AI6: سبت | AJ6: أكت | AK6: نوف | AL6: ديس | AM6: ينا | AN6: فبر | AO6: مار | AP6: أبر | AQ6: ماي | AR6: يون | AS6: يول | AT6: أغس | AU6: سبت | AV6: أكت | AW6: نوف | AX6: ديس | AY6: إجمالي سنوي | AZ6: متوسط شهري
A7: 1 | B7: ='📋 بيانات المحطات'!B7 -> جبل النور | F7: 244228.38 | R7: 189303.54 | AY7: =SUM(C7:N7)+SUM(O7:Z7)+SUM(AA7:AL7)+SUM(AM7:AX7) -> 433531.92 | AZ7: =IFERROR(AY7/COUNTIF(C7:AN7,">0"),"") -> 216765.96
A8: 2 | B8: ='📋 بيانات المحطات'!B8 -> المعيصم | F8: 1627699.2 | R8: 1524173.8 | AY8: =SUM(C8:N8)+SUM(O8:Z8)+SUM(AA8:AL8)+SUM(AM8:AX8) -> 3151873 | AZ8: =IFERROR(AY8/COUNTIF(C8:AN8,">0"),"") -> 1575936.5
A9: 3 | B9: ='📋 بيانات المحطات'!B9 -> العوالي | F9: 877778.12 | R9: 753002.13 | AP9: 1046930.2 | AY9: =SUM(C9:N9)+SUM(O9:Z9)+SUM(AA9:AL9)+SUM(AM9:AX9) -> 2677710.5 | AZ9: =IFERROR(AY9/COUNTIF(C9:AN9,">0"),"") -> 1338855.2
A10: 4 | B10: ='📋 بيانات المحطات'!B10 -> عاصفة الصحراء | F10: 779495.71 | R10: 633569.37 | AY10: =SUM(C10:N10)+SUM(O10:Z10)+SUM(AA10:AL10)+SUM(AM10:AX10) -> 1413065.1 | AZ10: =IFERROR(AY10/COUNTIF(C10:AN10,">0"),"") -> 706532.54
A11: 5 | B11: ='📋 بيانات المحطات'!B11 -> الشيباني | F11: 593868.81 | R11: 456844.18 | AY11: =SUM(C11:N11)+SUM(O11:Z11)+SUM(AA11:AL11)+SUM(AM11:AX11) -> 1050713 | AZ11: =IFERROR(AY11/COUNTIF(C11:AN11,">0"),"") -> 525356.49
A12: 6 | B12: ='📋 بيانات المحطات'!B12 -> جنوب الطائف | F12: 638840.81 | R12: 402418.29 | AP12: 865387 | AY12: =SUM(C12:N12)+SUM(O12:Z12)+SUM(AA12:AL12)+SUM(AM12:AX12) -> 1906646.1 | AZ12: =IFERROR(AY12/COUNTIF(C12:AN12,">0"),"") -> 953323.05
A13: 7 | B13: ='📋 بيانات المحطات'!B13 -> جنوب الحسينية | F13: 944289.38 | R13: 676583.7 | AD13: 24445.33 | AY13: =SUM(C13:N13)+SUM(O13:Z13)+SUM(AA13:AL13)+SUM(AM13:AX13) -> 1645318.4 | AZ13: =IFERROR(AY13/COUNTIF(C13:AN13,">0"),"") -> 548439.47
A14: 8 | B14: ='📋 بيانات المحطات'!B14 -> جدة النسيم | F14: 487040.71 | R14: 357935.56 | AY14: =SUM(C14:N14)+SUM(O14:Z14)+SUM(AA14:AL14)+SUM(AM14:AX14) -> 844976.27 | AZ14: =IFERROR(AY14/COUNTIF(C14:AN14,">0"),"") -> 422488.14
A15: 9 | B15: ='📋 بيانات المحطات'!B15 -> الرصيفة | F15: 424268.56 | R15: 372044.17 | AY15: =SUM(C15:N15)+SUM(O15:Z15)+SUM(AA15:AL15)+SUM(AM15:AX15) -> 796312.73 | AZ15: =IFERROR(AY15/COUNTIF(C15:AN15,">0"),"") -> 398156.36
A16: 10 | B16: ='📋 بيانات المحطات'!B16 -> عرفات الشوقية | F16: 331403.27 | R16: 197936.52 | AP16: 127925.58 | AY16: =SUM(C16:N16)+SUM(O16:Z16)+SUM(AA16:AL16)+SUM(AM16:AX16) -> 657265.37 | AZ16: =IFERROR(AY16/COUNTIF(C16:AN16,">0"),"") -> 328632.68
A17: 11 | B17: ='📋 بيانات المحطات'!B17 -> الرصيفة مسار | F17: 142934.61 | R17: 143169.3 | AY17: =SUM(C17:N17)+SUM(O17:Z17)+SUM(AA17:AL17)+SUM(AM17:AX17) -> 286103.91 | AZ17: =IFERROR(AY17/COUNTIF(C17:AN17,">0"),"") -> 143051.95
A18: 12 | B18: ='📋 بيانات المحطات'!B18 -> عرفات الشرائع | F18: 432589.4 | R18: 380494.28 | AY18: =SUM(C18:N18)+SUM(O18:Z18)+SUM(AA18:AL18)+SUM(AM18:AX18) -> 813083.68 | AZ18: =IFERROR(AY18/COUNTIF(C18:AN18,">0"),"") -> 406541.84
A19: 13 | B19: ='📋 بيانات المحطات'!B19 -> ممشى الشوقية | F19: 264547.54 | R19: 221745.7 | AP19: 212998.78 | AY19: =SUM(C19:N19)+SUM(O19:Z19)+SUM(AA19:AL19)+SUM(AM19:AX19) -> 699292.02 | AZ19: =IFERROR(AY19/COUNTIF(C19:AN19,">0"),"") -> 349646.01
A20: 14 | B20: ='📋 بيانات المحطات'!B20 -> بطحاء قريش | F20: 270579.71 | R20: 214242.15 | AY20: =SUM(C20:N20)+SUM(O20:Z20)+SUM(AA20:AL20)+SUM(AM20:AX20) -> 484821.86 | AZ20: =IFERROR(AY20/COUNTIF(C20:AN20,">0"),"") -> 242410.93
A21: 15 | B21: ='📋 بيانات المحطات'!B21 -> بن درويش | F21: 259128.86 | R21: 231366.23 | AP21: 24604.87 | AY21: =SUM(C21:N21)+SUM(O21:Z21)+SUM(AA21:AL21)+SUM(AM21:AX21) -> 515099.96 | AZ21: =IFERROR(AY21/COUNTIF(C21:AN21,">0"),"") -> 257549.98
A22: 16 | B22: ='📋 بيانات المحطات'!B22 -> الخرج غرناطة | F22: 325436.36 | R22: 294675.03 | AP22: 67429.4 | AY22: =SUM(C22:N22)+SUM(O22:Z22)+SUM(AA22:AL22)+SUM(AM22:AX22) -> 687540.79 | AZ22: =IFERROR(AY22/COUNTIF(C22:AN22,">0"),"") -> 343770.4
A23: 17 | B23: ='📋 بيانات المحطات'!B23 -> الخرج الحمراء | F23: 588023.07 | R23: 537180.45 | AP23: 127869.36 | AY23: =SUM(C23:N23)+SUM(O23:Z23)+SUM(AA23:AL23)+SUM(AM23:AX23) -> 1253072.9 | AZ23: =IFERROR(AY23/COUNTIF(C23:AN23,">0"),"") -> 626536.44
A24: 18 | B24: ='📋 بيانات المحطات'!B24 -> احلى مساء | F24: 512384.81 | R24: 452211.55 | AP24: 218901.49 | AY24: =SUM(C24:N24)+SUM(O24:Z24)+SUM(AA24:AL24)+SUM(AM24:AX24) -> 1183497.9 | AZ24: =IFERROR(AY24/COUNTIF(C24:AN24,">0"),"") -> 591748.93
A25: 19 | B25: ='📋 بيانات المحطات'!B25 -> الذكرى الخالدة | F25: 183238.23 | R25: 127240.63 | AP25: 88807.98 | AY25: =SUM(C25:N25)+SUM(O25:Z25)+SUM(AA25:AL25)+SUM(AM25:AX25) -> 399286.84 | AZ25: =IFERROR(AY25/COUNTIF(C25:AN25,">0"),"") -> 199643.42
A26: 20 | B26: ='📋 بيانات المحطات'!B26 -> بطحاء قريش 2 | F26: 346640.99 | R26: 203236.36 | AP26: 389400.84 | AY26: =SUM(C26:N26)+SUM(O26:Z26)+SUM(AA26:AL26)+SUM(AM26:AX26) -> 939278.19 | AZ26: =IFERROR(AY26/COUNTIF(C26:AN26,">0"),"") -> 469639.09
A27: 21 | B27: ='📋 بيانات المحطات'!B27 -> أبو وافي | F27: 304706.89 | R27: 269906.26 | AP27: 238542.04 | AY27: =SUM(C27:N27)+SUM(O27:Z27)+SUM(AA27:AL27)+SUM(AM27:AX27) -> 813155.19 | AZ27: =IFERROR(AY27/COUNTIF(C27:AN27,">0"),"") -> 406577.6
A28: 22 | B28: ='📋 بيانات المحطات'!B28 -> الجمعية | F28: 139972.15 | R28: 78795.46 | AP28: 29843.96 | AY28: =SUM(C28:N28)+SUM(O28:Z28)+SUM(AA28:AL28)+SUM(AM28:AX28) -> 248611.57 | AZ28: =IFERROR(AY28/COUNTIF(C28:AN28,">0"),"") -> 124305.78
A29: 23 | B29: ='📋 بيانات المحطات'!B29 -> العريفي | F29: 541745.1 | R29: 401434.57 | AP29: 571750.09 | AY29: =SUM(C29:N29)+SUM(O29:Z29)+SUM(AA29:AL29)+SUM(AM29:AX29) -> 1514929.8 | AZ29: =IFERROR(AY29/COUNTIF(C29:AN29,">0"),"") -> 757464.88
A30: 24 | B30: ='📋 بيانات المحطات'!B30 -> الحليس | F30: 470762.57 | R30: 471510.09 | AP30: 472472.68 | AY30: =SUM(C30:N30)+SUM(O30:Z30)+SUM(AA30:AL30)+SUM(AM30:AX30) -> 1414745.3 | AZ30: =IFERROR(AY30/COUNTIF(C30:AN30,">0"),"") -> 707372.67
A31: 25 | B31: ='📋 بيانات المحطات'!B31 -> القادسية | F31: 89890.92 | R31: 68140.36 | AP31: 54305.82 | AY31: =SUM(C31:N31)+SUM(O31:Z31)+SUM(AA31:AL31)+SUM(AM31:AX31) -> 212337.1 | AZ31: =IFERROR(AY31/COUNTIF(C31:AN31,">0"),"") -> 106168.55
A32: 26 | B32: ='📋 بيانات المحطات'!B32 -> صامطة | F32: 170986.18 | R32: 157208.01 | AP32: 246657.86 | AY32: =SUM(C32:N32)+SUM(O32:Z32)+SUM(AA32:AL32)+SUM(AM32:AX32) -> 574852.05 | AZ32: =IFERROR(AY32/COUNTIF(C32:AN32,">0"),"") -> 287426.03
... A52: 46 | B52: ='📋 بيانات المحطات'!B52 -> الاطاوله الباحة | F52: 77947.64 | R52: 55245.65 | AP52: 12322.2 | AY52: =SUM(C52:N52)+SUM(O52:Z52)+SUM(AA52:AL52)+SUM(AM52:AX52) -> 145515.49 | AZ52: =IFERROR(AY52/COUNTIF(C52:AN52,">0"),"") -> 72757.745
A53: 47 | B53: ='📋 بيانات المحطات'!B53 -> محايل عسير | AY53: =SUM(C53:N53)+SUM(O53:Z53)+SUM(AA53:AL53)+SUM(AM53:AX53) -> 0 | AZ53: =IFERROR(AY53/COUNTIF(C53:AN53,">0"),"")
A54: 48 | B54: ='📋 بيانات المحطات'!B54 -> سلطان المطرفي | F54: 242518.77 | R54: 201595.03 | AP54: 237341.99 | AY54: =SUM(C54:N54)+SUM(O54:Z54)+SUM(AA54:AL54)+SUM(AM54:AX54) -> 681455.79 | AZ54: =IFERROR(AY54/COUNTIF(C54:AN54,">0"),"") -> 340727.9
A55: 49 | B55: ='📋 بيانات المحطات'!B55 -> محطه بن قباس | AY55: =SUM(C55:N55)+SUM(O55:Z55)+SUM(AA55:AL55)+SUM(AM55:AX55) -> 0 | AZ55: =IFERROR(AY55/COUNTIF(C55:AN55,">0"),"")
A56: 50 | B56: ='📋 بيانات المحطات'!B56 -> محطة مدخل محايل | AY56: =SUM(C56:N56)+SUM(O56:Z56)+SUM(AA56:AL56)+SUM(AM56:AX56) -> 0 | AZ56: =IFERROR(AY56/COUNTIF(C56:AN56,">0"),"")
A57: 51 | B57: ='📋 بيانات المحطات'!B57 -> الشوقية - سندي | AY57: =SUM(C57:N57)+SUM(O57:Z57)+SUM(AA57:AL57)+SUM(AM57:AX57) -> 0 | AZ57: =IFERROR(AY57/COUNTIF(C57:AN57,">0"),"")
A58: 52 | B58: ='📋 بيانات المحطات'!B58 -> دوار البلديه احد المسارحه | AY58: =SUM(C58:N58)+SUM(O58:Z58)+SUM(AA58:AL58)+SUM(AM58:AX58) -> 0 | AZ58: =IFERROR(AY58/COUNTIF(C58:AN58,">0"),"")
A59: 53 | B59: ='📋 بيانات المحطات'!B59 -> الازوري (طريق المطار) | AY59: =SUM(C59:N59)+SUM(O59:Z59)+SUM(AA59:AL59)+SUM(AM59:AX59) -> 0 | AZ59: =IFERROR(AY59/COUNTIF(C59:AN59,">0"),"")
A60: 54 | B60: ='📋 بيانات المحطات'!B60 -> عبد الله الخريجي | AY60: =SUM(C60:N60)+SUM(O60:Z60)+SUM(AA60:AL60)+SUM(AM60:AX60) -> 0 | AZ60: =IFERROR(AY60/COUNTIF(C60:AN60,">0"),"")
B61: إجمالي جميع المحطات | C61: =SUM(C7:C60) -> 0 | D61: =SUM(D7:D60) -> 0 | E61: =SUM(E7:E60) -> 0 | F61: =SUM(F7:F60) -> 18505033 | G61: =SUM(G7:G60) -> 0 | H61: =SUM(H7:H60) -> 0 | I61: =SUM(I7:I60) -> 0 | J61: =SUM(J7:J60) -> 0 | ... AY61: =SUM(AY7:AY60) -> 41785055

Sheet 💰 الربحية — محسوبة
A2: 💰 ربحية المنتجات — محسوبة تلقائياً (هامش العقد × المبيعات)
A3: ✅ هذا الشيت يحسب نفسه — لا تعديل مطلوب | الربحية = هامش العقد × المبيعات ÷ 100
A5: # | B5: اسم المحطة | C5: بنزين 91 — الربحية (ريال) | Q5: بنزين 95 — الربحية (ريال) | AE5: بنزين 98 — الربحية (ريال) | AS5: ديزل — الربحية (ريال) | BG5: إجمالي ربحية المحطة
A6: # | B6: اسم المحطة | C6: الهامش هل/ل | D6: ينا | E6: فبر | F6: مار | G6: أبر | H6: ماي | I6: يون | J6: يول | K6: أغس | L6: سبت | M6: أكت | N6: نوف | O6: ديس | P6: إجمالي سنوي | Q6: الهامش هل/ل | R6: ينا | S6: فبر | T6: مار | U6: أبر | V6: ماي | W6: يون | X6: يول | Y6: أغس | Z6: سبت | AA6: أكت | AB6: نوف | AC6: ديس | AD6: إجمالي سنوي | AE6: الهامش هل/ل | AF6: ينا | AG6: فبر | AH6: مار | AI6: أبر | AJ6: ماي | AK6: يون | AL6: يول | AM6: أغس | AN6: سبت | AO6: أكت | AP6: نوف | AQ6: ديس | AR6: إجمالي سنوي | AS6: الهامش هل/ل | AT6: ينا | AU6: فبر | AV6: مار | AW6: أبر | AX6: ماي | AY6: يون | AZ6: يول | BA6: أغس | BB6: سبت | BC6: أكت | BD6: نوف | BE6: ديس | BF6: إجمالي سنوي | BG6: إجمالي كل المنتجات
A7: 1 | B7: ='📋 بيانات المحطات'!B6 -> اسم المحطة | C7: ='📋 بيانات المحطات'!H6 -> هامش 91 هل/ل | D7: =IFERROR(C7*'⛽ المبيعات الشهرية'!C6/100,"") | E7: =IFERROR(C7*'⛽ المبيعات الشهرية'!D6/100,"") | F7: =IFERROR(C7*'⛽ المبيعات الشهرية'!E6/100,"") | G7: =IFERROR(C7*'⛽ المبيعات الشهرية'!F6/100,"") | H7: =IFERROR(C7*'⛽ المبيعات الشهرية'!G6/100,"") | I7: =IFERROR(C7*'⛽ المبيعات الشهرية'!H6/100,"") | J7: =IFERROR(C7*'⛽ المبيعات الشهرية'!I6/100,"") | K7: =IFERROR(C7*'⛽ المبيعات الشهرية'!J6/100,"") | L7: =IFERROR(C7*'⛽ المبيعات الشهرية'!K6/100,"") | M7: =IFERROR(C7*'⛽ المبيعات الشهرية'!L6/100,"") | N7: =IFERROR(C7*'⛽ المبيعات الشهرية'!M6/100,"") | O7: =IFERROR(C7*'⛽ المبيعات الشهرية'!N6/100,"") | P7: =IFERROR(SUM(D7:O7),"") -> 0 | Q7: ='📋 بيانات المحطات'!I6 -> هامش 95 هل/ل | R7: =IFERROR(Q7*'⛽ المبيعات الشهرية'!O6/100,"") | S7: =IFERROR(Q7*'⛽ المبيعات الشهرية'!P6/100,"") | T7: =IFERROR(Q7*'⛽ المبيعات الشهرية'!Q6/100,"") | U7: =IFERROR(Q7*'⛽ المبيعات الشهرية'!R6/100,"") | V7: =IFERROR(Q7*'⛽ المبيعات الشهرية'!S6/100,"") | W7: =IFERROR(Q7*'⛽ المبيعات الشهرية'!T6/100,"") | X7: =IFERROR(Q7*'⛽ المبيعات الشهرية'!U6/100,"") | Y7: =IFERROR(Q7*'⛽ المبيعات الشهرية'!V6/100,"") | Z7: =IFERROR(Q7*'⛽ المبيعات الشهرية'!W6/100,"") | AA7: =IFERROR(Q7*'⛽ المبيعات الشهرية'!X6/100,"") | AB7: =IFERROR(Q7*'⛽ المبيعات الشهرية'!Y6/100,"") | AC7: =IFERROR(Q7*'⛽ المبيعات الشهرية'!Z6/100,"") | AD7: =IFERROR(SUM(R7:AC7),"") -> 0 | AE7: ='📋 بيانات المحطات'!J6 -> هامش 98 هل/ل | AF7: =IFERROR(AE7*'⛽ المبيعات الشهرية'!AA6/100,"") | AG7: =IFERROR(AE7*'⛽ المبيعات الشهرية'!AB6/100,"") | AH7: =IFERROR(AE7*'⛽ المبيعات الشهرية'!AC6/100,"") | AI7: =IFERROR(AE7*'⛽ المبيعات الشهرية'!AD6/100,"") | AJ7: =IFERROR(AE7*'⛽ المبيعات الشهرية'!AE6/100,"") | AK7: =IFERROR(AE7*'⛽ المبيعات الشهرية'!AF6/100,"") | AL7: =IFERROR(AE7*'⛽ المبيعات الشهرية'!AG6/100,"") | AM7: =IFERROR(AE7*'⛽ المبيعات الشهرية'!AH6/100,"") | AN7: =IFERROR(AE7*'⛽ المبيعات الشهرية'!AI6/100,"") | AO7: =IFERROR(AE7*'⛽ المبيعات الشهرية'!AJ6/100,"") | AP7: =IFERROR(AE7*'⛽ المبيعات الشهرية'!AK6/100,"") | AQ7: =IFERROR(AE7*'⛽ المبيعات الشهرية'!AL6/100,"") | AR7: =IFERROR(SUM(AF7:AQ7),"") -> 0 | AS7: ='📋 بيانات المحطات'!K6 -> هامش ديزل هل/ل | AT7: =IFERROR(AS7*'⛽ المبيعات الشهرية'!AM6/100,"") | AU7: =IFERROR(AS7*'⛽ المبيعات الشهرية'!AN6/100,"") | AV7: =IFERROR(AS7*'⛽ المبيعات الشهرية'!AO6/100,"") | AW7: =IFERROR(AS7*'⛽ المبيعات الشهرية'!AP6/100,"") | AX7: =IFERROR(AS7*'⛽ المبيعات الشهرية'!AQ6/100,"") | AY7: =IFERROR(AS7*'⛽ المبيعات الشهرية'!AR6/100,"") | AZ7: =IFERROR(AS7*'⛽ المبيعات الشهرية'!AS6/100,"") | BA7: =IFERROR(AS7*'⛽ المبيعات الشهرية'!AT6/100,"") | BB7: =IFERROR(AS7*'⛽ المبيعات الشهرية'!AU6/100,"") | BC7: =IFERROR(AS7*'⛽ المبيعات الشهرية'!AV6/100,"") | BD7: =IFERROR(AS7*'⛽ المبيعات الشهرية'!AW6/100,"") | BE7: =IFERROR(AS7*'⛽ المبيعات الشهرية'!AX6/100,"") | BF7: =IFERROR(SUM(AT7:BE7),"") -> 0 | BG7: =IFERROR(P7+AD7+AR7+BF7,"") -> 0
A8: 2 | B8: ='📋 بيانات المحطات'!B7 -> جبل النور | C8: ='📋 بيانات المحطات'!H7 -> هامش 91 (هللة/لتر) | D8: =IFERROR(C8*'⛽ المبيعات الشهرية'!C7/100,"") | E8: =IFERROR(C8*'⛽ المبيعات الشهرية'!D7/100,"") | F8: =IFERROR(C8*'⛽ المبيعات الشهرية'!E7/100,"") | G8: =IFERROR(C8*'⛽ المبيعات الشهرية'!F7/100,"") | H8: =IFERROR(C8*'⛽ المبيعات الشهرية'!G7/100,"") | I8: =IFERROR(C8*'⛽ المبيعات الشهرية'!H7/100,"") | J8: =IFERROR(C8*'⛽ المبيعات الشهرية'!I7/100,"") | K8: =IFERROR(C8*'⛽ المبيعات الشهرية'!J7/100,"") | L8: =IFERROR(C8*'⛽ المبيعات الشهرية'!K7/100,"") | M8: =IFERROR(C8*'⛽ المبيعات الشهرية'!L7/100,"") | N8: =IFERROR(C8*'⛽ المبيعات الشهرية'!M7/100,"") | O8: =IFERROR(C8*'⛽ المبيعات الشهرية'!N7/100,"") | P8: =IFERROR(SUM(D8:O8),"") -> 0 | Q8: ='📋 بيانات المحطات'!I7 -> هامش 95 (هللة/لتر) | R8: =IFERROR(Q8*'⛽ المبيعات الشهرية'!O7/100,"") | S8: =IFERROR(Q8*'⛽ المبيعات الشهرية'!P7/100,"") | T8: =IFERROR(Q8*'⛽ المبيعات الشهرية'!Q7/100,"") | U8: =IFERROR(Q8*'⛽ المبيعات الشهرية'!R7/100,"") | V8: =IFERROR(Q8*'⛽ المبيعات الشهرية'!S7/100,"") | W8: =IFERROR(Q8*'⛽ المبيعات الشهرية'!T7/100,"") | X8: =IFERROR(Q8*'⛽ المبيعات الشهرية'!U7/100,"") | Y8: =IFERROR(Q8*'⛽ المبيعات الشهرية'!V7/100,"") | Z8: =IFERROR(Q8*'⛽ المبيعات الشهرية'!W7/100,"") | AA8: =IFERROR(Q8*'⛽ المبيعات الشهرية'!X7/100,"") | AB8: =IFERROR(Q8*'⛽ المبيعات الشهرية'!Y7/100,"") | AC8: =IFERROR(Q8*'⛽ المبيعات الشهرية'!Z7/100,"") | AD8: =IFERROR(SUM(R8:AC8),"") -> 0 | AE8: ='📋 بيانات المحطات'!J7 -> هامش 98 (هللة/لتر) | AF8: =IFERROR(AE8*'⛽ المبيعات الشهرية'!AA7/100,"") | AG8: =IFERROR(AE8*'⛽ المبيعات الشهرية'!AB7/100,"") | AH8: =IFERROR(AE8*'⛽ المبيعات الشهرية'!AC7/100,"") | AI8: =IFERROR(AE8*'⛽ المبيعات الشهرية'!AD7/100,"") | AJ8: =IFERROR(AE8*'⛽ المبيعات الشهرية'!AE7/100,"") | AK8: =IFERROR(AE8*'⛽ المبيعات الشهرية'!AF7/100,"") | AL8: =IFERROR(AE8*'⛽ المبيعات الشهرية'!AG7/100,"") | AM8: =IFERROR(AE8*'⛽ المبيعات الشهرية'!AH7/100,"") | AN8: =IFERROR(AE8*'⛽ المبيعات الشهرية'!AI7/100,"") | AO8: =IFERROR(AE8*'⛽ المبيعات الشهرية'!AJ7/100,"") | AP8: =IFERROR(AE8*'⛽ المبيعات الشهرية'!AK7/100,"") | AQ8: =IFERROR(AE8*'⛽ المبيعات الشهرية'!AL7/100,"") | AR8: =IFERROR(SUM(AF8:AQ8),"") -> 0 | AS8: ='📋 بيانات المحطات'!K7 -> هامش ديزل (هللة/لتر) | AT8: =IFERROR(AS8*'⛽ المبيعات الشهرية'!AM7/100,"") | AU8: =IFERROR(AS8*'⛽ المبيعات الشهرية'!AN7/100,"") | AV8: =IFERROR(AS8*'⛽ المبيعات الشهرية'!AO7/100,"") | AW8: =IFERROR(AS8*'⛽ المبيعات الشهرية'!AP7/100,"") | AX8: =IFERROR(AS8*'⛽ المبيعات الشهرية'!AQ7/100,"") | AY8: =IFERROR(AS8*'⛽ المبيعات الشهرية'!AR7/100,"") | AZ8: =IFERROR(AS8*'⛽ المبيعات الشهرية'!AS7/100,"") | BA8: =IFERROR(AS8*'⛽ المبيعات الشهرية'!AT7/100,"") | BB8: =IFERROR(AS8*'⛽ المبيعات الشهرية'!AU7/100,"") | BC8: =IFERROR(AS8*'⛽ المبيعات الشهرية'!AV7/100,"") | BD8: =IFERROR(AS8*'⛽ المبيعات الشهرية'!AW7/100,"") | BE8: =IFERROR(AS8*'⛽ المبيعات الشهرية'!AX7/100,"") | BF8: =IFERROR(SUM(AT8:BE8),"") -> 0 | BG8: =IFERROR(P8+AD8+AR8+BF8,"") -> 0
A9: 3 | B9: ='📋 بيانات المحطات'!B8 -> المعيصم | C9: ='📋 بيانات المحطات'!H8 -> 0 | D9: =IFERROR(C9*'⛽ المبيعات الشهرية'!C8/100,"") -> 0 | E9: =IFERROR(C9*'⛽ المبيعات الشهرية'!D8/100,"") -> 0 | F9: =IFERROR(C9*'⛽ المبيعات الشهرية'!E8/100,"") -> 0 | G9: =IFERROR(C9*'⛽ المبيعات الشهرية'!F8/100,"") -> 0 | H9: =IFERROR(C9*'⛽ المبيعات الشهرية'!G8/100,"") -> 0 | I9: =IFERROR(C9*'⛽ المبيعات الشهرية'!H8/100,"") -> 0 | J9: =IFERROR(C9*'⛽ المبيعات الشهرية'!I8/100,"") -> 0 | K9: =IFERROR(C9*'⛽ المبيعات الشهرية'!J8/100,"") -> 0 | L9: =IFERROR(C9*'⛽ المبيعات الشهرية'!K8/100,"") -> 0 | M9: =IFERROR(C9*'⛽ المبيعات الشهرية'!L8/100,"") -> 0 | N9: =IFERROR(C9*'⛽ المبيعات الشهرية'!M8/100,"") -> 0 | O9: =IFERROR(C9*'⛽ المبيعات الشهرية'!N8/100,"") -> 0 | P9: =IFERROR(SUM(D9:O9),"") -> 0 | Q9: ='📋 بيانات المحطات'!I8 -> 0 | R9: =IFERROR(Q9*'⛽ المبيعات الشهرية'!O8/100,"") -> 0 | S9: =IFERROR(Q9*'⛽ المبيعات الشهرية'!P8/100,"") -> 0 | T9: =IFERROR(Q9*'⛽ المبيعات الشهرية'!Q8/100,"") -> 0 | U9: =IFERROR(Q9*'⛽ المبيعات الشهرية'!R8/100,"") -> 0 | V9: =IFERROR(Q9*'⛽ المبيعات الشهرية'!S8/100,"") -> 0 | W9: =IFERROR(Q9*'⛽ المبيعات الشهرية'!T8/100,"") -> 0 | X9: =IFERROR(Q9*'⛽ المبيعات الشهرية'!U8/100,"") -> 0 | Y9: =IFERROR(Q9*'⛽ المبيعات الشهرية'!V8/100,"") -> 0 | Z9: =IFERROR(Q9*'⛽ المبيعات الشهرية'!W8/100,"") -> 0 | AA9: =IFERROR(Q9*'⛽ المبيعات الشهرية'!X8/100,"") -> 0 | AB9: =IFERROR(Q9*'⛽ المبيعات الشهرية'!Y8/100,"") -> 0 | AC9: =IFERROR(Q9*'⛽ المبيعات الشهرية'!Z8/100,"") -> 0 | AD9: =IFERROR(SUM(R9:AC9),"") -> 0 | AE9: ='📋 بيانات المحطات'!J8 -> 0 | AF9: =IFERROR(AE9*'⛽ المبيعات الشهرية'!AA8/100,"") -> 0 | AG9: =IFERROR(AE9*'⛽ المبيعات الشهرية'!AB8/100,"") -> 0 | AH9: =IFERROR(AE9*'⛽ المبيعات الشهرية'!AC8/100,"") -> 0 | AI9: =IFERROR(AE9*'⛽ المبيعات الشهرية'!AD8/100,"") -> 0 | AJ9: =IFERROR(AE9*'⛽ المبيعات الشهرية'!AE8/100,"") -> 0 | AK9: =IFERROR(AE9*'⛽ المبيعات الشهرية'!AF8/100,"") -> 0 | AL9: =IFERROR(AE9*'⛽ المبيعات الشهرية'!AG8/100,"") -> 0 | AM9: =IFERROR(AE9*'⛽ المبيعات الشهرية'!AH8/100,"") -> 0 | AN9: =IFERROR(AE9*'⛽ المبيعات الشهرية'!AI8/100,"") -> 0 | AO9: =IFERROR(AE9*'⛽ المبيعات الشهرية'!AJ8/100,"") -> 0 | AP9: =IFERROR(AE9*'⛽ المبيعات الشهرية'!AK8/100,"") -> 0 | AQ9: =IFERROR(AE9*'⛽ المبيعات الشهرية'!AL8/100,"") -> 0 | AR9: =IFERROR(SUM(AF9:AQ9),"") -> 0 | AS9: ='📋 بيانات المحطات'!K8 -> 0 | AT9: =IFERROR(AS9*'⛽ المبيعات الشهرية'!AM8/100,"") -> 0 | AU9: =IFERROR(AS9*'⛽ المبيعات الشهرية'!AN8/100,"") -> 0 | AV9: =IFERROR(AS9*'⛽ المبيعات الشهرية'!AO8/100,"") -> 0 | AW9: =IFERROR(AS9*'⛽ المبيعات الشهرية'!AP8/100,"") -> 0 | AX9: =IFERROR(AS9*'⛽ المبيعات الشهرية'!AQ8/100,"") -> 0 | AY9: =IFERROR(AS9*'⛽ المبيعات الشهرية'!AR8/100,"") -> 0 | AZ9: =IFERROR(AS9*'⛽ المبيعات الشهرية'!AS8/100,"") -> 0 | BA9: =IFERROR(AS9*'⛽ المبيعات الشهرية'!AT8/100,"") -> 0 | BB9: =IFERROR(AS9*'⛽ المبيعات الشهرية'!AU8/100,"") -> 0 | BC9: =IFERROR(AS9*'⛽ المبيعات الشهرية'!AV8/100,"") -> 0 | BD9: =IFERROR(AS9*'⛽ المبيعات الشهرية'!AW8/100,"") -> 0 | BE9: =IFERROR(AS9*'⛽ المبيعات الشهرية'!AX8/100,"") -> 0 | BF9: =IFERROR(SUM(AT9:BE9),"") -> 0 | BG9: =IFERROR(P9+AD9+AR9+BF9,"") -> 0
A10: 4 | B10: ='📋 بيانات المحطات'!B9 -> العوالي | C10: ='📋 بيانات المحطات'!H9 -> 0 | D10: =IFERROR(C10*'⛽ المبيعات الشهرية'!C9/100,"") -> 0 | E10: =IFERROR(C10*'⛽ المبيعات الشهرية'!D9/100,"") -> 0 | F10: =IFERROR(C10*'⛽ المبيعات الشهرية'!E9/100,"") -> 0 | G10: =IFERROR(C10*'⛽ المبيعات الشهرية'!F9/100,"") -> 0 | H10: =IFERROR(C10*'⛽ المبيعات الشهرية'!G9/100,"") -> 0 | I10: =IFERROR(C10*'⛽ المبيعات الشهرية'!H9/100,"") -> 0 | J10: =IFERROR(C10*'⛽ المبيعات الشهرية'!I9/100,"") -> 0 | K10: =IFERROR(C10*'⛽ المبيعات الشهرية'!J9/100,"") -> 0 | L10: =IFERROR(C10*'⛽ المبيعات الشهرية'!K9/100,"") -> 0 | M10: =IFERROR(C10*'⛽ المبيعات الشهرية'!L9/100,"") -> 0 | N10: =IFERROR(C10*'⛽ المبيعات الشهرية'!M9/100,"") -> 0 | O10: =IFERROR(C10*'⛽ المبيعات الشهرية'!N9/100,"") -> 0 | P10: =IFERROR(SUM(D10:O10),"") -> 0 | Q10: ='📋 بيانات المحطات'!I9 -> 0 | R10: =IFERROR(Q10*'⛽ المبيعات الشهرية'!O9/100,"") -> 0 | S10: =IFERROR(Q10*'⛽ المبيعات الشهرية'!P9/100,"") -> 0 | T10: =IFERROR(Q10*'⛽ المبيعات الشهرية'!Q9/100,"") -> 0 | U10: =IFERROR(Q10*'⛽ المبيعات الشهرية'!R9/100,"") -> 0 | V10: =IFERROR(Q10*'⛽ المبيعات الشهرية'!S9/100,"") -> 0 | W10: =IFERROR(Q10*'⛽ المبيعات الشهرية'!T9/100,"") -> 0 | X10: =IFERROR(Q10*'⛽ المبيعات الشهرية'!U9/100,"") -> 0 | Y10: =IFERROR(Q10*'⛽ المبيعات الشهرية'!V9/100,"") -> 0 | Z10: =IFERROR(Q10*'⛽ المبيعات الشهرية'!W9/100,"") -> 0 | AA10: =IFERROR(Q10*'⛽ المبيعات الشهرية'!X9/100,"") -> 0 | AB10: =IFERROR(Q10*'⛽ المبيعات الشهرية'!Y9/100,"") -> 0 | AC10: =IFERROR(Q10*'⛽ المبيعات الشهرية'!Z9/100,"") -> 0 | AD10: =IFERROR(SUM(R10:AC10),"") -> 0 | AE10: ='📋 بيانات المحطات'!J9 -> 0 | AF10: =IFERROR(AE10*'⛽ المبيعات الشهرية'!AA9/100,"") -> 0 | AG10: =IFERROR(AE10*'⛽ المبيعات الشهرية'!AB9/100,"") -> 0 | AH10: =IFERROR(AE10*'⛽ المبيعات الشهرية'!AC9/100,"") -> 0 | AI10: =IFERROR(AE10*'⛽ المبيعات الشهرية'!AD9/100,"") -> 0 | AJ10: =IFERROR(AE10*'⛽ المبيعات الشهرية'!AE9/100,"") -> 0 | AK10: =IFERROR(AE10*'⛽ المبيعات الشهرية'!AF9/100,"") -> 0 | AL10: =IFERROR(AE10*'⛽ المبيعات الشهرية'!AG9/100,"") -> 0 | AM10: =IFERROR(AE10*'⛽ المبيعات الشهرية'!AH9/100,"") -> 0 | AN10: =IFERROR(AE10*'⛽ المبيعات الشهرية'!AI9/100,"") -> 0 | AO10: =IFERROR(AE10*'⛽ المبيعات الشهرية'!AJ9/100,"") -> 0 | AP10: =IFERROR(AE10*'⛽ المبيعات الشهرية'!AK9/100,"") -> 0 | AQ10: =IFERROR(AE10*'⛽ المبيعات الشهرية'!AL9/100,"") -> 0 | AR10: =IFERROR(SUM(AF10:AQ10),"") -> 0 | AS10: ='📋 بيانات المحطات'!K9 -> 0 | AT10: =IFERROR(AS10*'⛽ المبيعات الشهرية'!AM9/100,"") -> 0 | AU10: =IFERROR(AS10*'⛽ المبيعات الشهرية'!AN9/100,"") -> 0 | AV10: =IFERROR(AS10*'⛽ المبيعات الشهرية'!AO9/100,"") -> 0 | AW10: =IFERROR(AS10*'⛽ المبيعات الشهرية'!AP9/100,"") -> 0 | AX10: =IFERROR(AS10*'⛽ المبيعات الشهرية'!AQ9/100,"") -> 0 | AY10: =IFERROR(AS10*'⛽ المبيعات الشهرية'!AR9/100,"") -> 0 | AZ10: =IFERROR(AS10*'⛽ المبيعات الشهرية'!AS9/100,"") -> 0 | BA10: =IFERROR(AS10*'⛽ المبيعات الشهرية'!AT9/100,"") -> 0 | BB10: =IFERROR(AS10*'⛽ المبيعات الشهرية'!AU9/100,"") -> 0 | BC10: =IFERROR(AS10*'⛽ المبيعات الشهرية'!AV9/100,"") -> 0 | BD10: =IFERROR(AS10*'⛽ المبيعات الشهرية'!AW9/100,"") -> 0 | BE10: =IFERROR(AS10*'⛽ المبيعات الشهرية'!AX9/100,"") -> 0 | BF10: =IFERROR(SUM(AT10:BE10),"") -> 0 | BG10: =IFERROR(P10+AD10+AR10+BF10,"") -> 0
A11: 5 | B11: ='📋 بيانات المحطات'!B10 -> عاصفة الصحراء | C11: ='📋 بيانات المحطات'!H10 -> 0 | D11: =IFERROR(C11*'⛽ المبيعات الشهرية'!C10/100,"") -> 0 | E11: =IFERROR(C11*'⛽ المبيعات الشهرية'!D10/100,"") -> 0 | F11: =IFERROR(C11*'⛽ المبيعات الشهرية'!E10/100,"") -> 0 | G11: =IFERROR(C11*'⛽ المبيعات الشهرية'!F10/100,"") -> 0 | H11: =IFERROR(C11*'⛽ المبيعات الشهرية'!G10/100,"") -> 0 | I11: =IFERROR(C11*'⛽ المبيعات الشهرية'!H10/100,"") -> 0 | J11: =IFERROR(C11*'⛽ المبيعات الشهرية'!I10/100,"") -> 0 | K11: =IFERROR(C11*'⛽ المبيعات الشهرية'!J10/100,"") -> 0 | L11: =IFERROR(C11*'⛽ المبيعات الشهرية'!K10/100,"") -> 0 | M11: =IFERROR(C11*'⛽ المبيعات الشهرية'!L10/100,"") -> 0 | N11: =IFERROR(C11*'⛽ المبيعات الشهرية'!M10/100,"") -> 0 | O11: =IFERROR(C11*'⛽ المبيعات الشهرية'!N10/100,"") -> 0 | P11: =IFERROR(SUM(D11:O11),"") -> 0 | Q11: ='📋 بيانات المحطات'!I10 -> 0 | R11: =IFERROR(Q11*'⛽ المبيعات الشهرية'!O10/100,"") -> 0 | S11: =IFERROR(Q11*'⛽ المبيعات الشهرية'!P10/100,"") -> 0 | T11: =IFERROR(Q11*'⛽ المبيعات الشهرية'!Q10/100,"") -> 0 | U11: =IFERROR(Q11*'⛽ المبيعات الشهرية'!R10/100,"") -> 0 | V11: =IFERROR(Q11*'⛽ المبيعات الشهرية'!S10/100,"") -> 0 | W11: =IFERROR(Q11*'⛽ المبيعات الشهرية'!T10/100,"") -> 0 | X11: =IFERROR(Q11*'⛽ المبيعات الشهرية'!U10/100,"") -> 0 | Y11: =IFERROR(Q11*'⛽ المبيعات الشهرية'!V10/100,"") -> 0 | Z11: =IFERROR(Q11*'⛽ المبيعات الشهرية'!W10/100,"") -> 0 | AA11: =IFERROR(Q11*'⛽ المبيعات الشهرية'!X10/100,"") -> 0 | AB11: =IFERROR(Q11*'⛽ المبيعات الشهرية'!Y10/100,"") -> 0 | AC11: =IFERROR(Q11*'⛽ المبيعات الشهرية'!Z10/100,"") -> 0 | AD11: =IFERROR(SUM(R11:AC11),"") -> 0 | AE11: ='📋 بيانات المحطات'!J10 -> 0 | AF11: =IFERROR(AE11*'⛽ المبيعات الشهرية'!AA10/100,"") -> 0 | AG11: =IFERROR(AE11*'⛽ المبيعات الشهرية'!AB10/100,"") -> 0 | AH11: =IFERROR(AE11*'⛽ المبيعات الشهرية'!AC10/100,"") -> 0 | AI11: =IFERROR(AE11*'⛽ المبيعات الشهرية'!AD10/100,"") -> 0 | AJ11: =IFERROR(AE11*'⛽ المبيعات الشهرية'!AE10/100,"") -> 0 | AK11: =IFERROR(AE11*'⛽ المبيعات الشهرية'!AF10/100,"") -> 0 | AL11: =IFERROR(AE11*'⛽ المبيعات الشهرية'!AG10/100,"") -> 0 | AM11: =IFERROR(AE11*'⛽ المبيعات الشهرية'!AH10/100,"") -> 0 | AN11: =IFERROR(AE11*'⛽ المبيعات الشهرية'!AI10/100,"") -> 0 | AO11: =IFERROR(AE11*'⛽ المبيعات الشهرية'!AJ10/100,"") -> 0 | AP11: =IFERROR(AE11*'⛽ المبيعات الشهرية'!AK10/100,"") -> 0 | AQ11: =IFERROR(AE11*'⛽ المبيعات الشهرية'!AL10/100,"") -> 0 | AR11: =IFERROR(SUM(AF11:AQ11),"") -> 0 | AS11: ='📋 بيانات المحطات'!K10 -> 0 | AT11: =IFERROR(AS11*'⛽ المبيعات الشهرية'!AM10/100,"") -> 0 | AU11: =IFERROR(AS11*'⛽ المبيعات الشهرية'!AN10/100,"") -> 0 | AV11: =IFERROR(AS11*'⛽ المبيعات الشهرية'!AO10/100,"") -> 0 | AW11: =IFERROR(AS11*'⛽ المبيعات الشهرية'!AP10/100,"") -> 0 | AX11: =IFERROR(AS11*'⛽ المبيعات الشهرية'!AQ10/100,"") -> 0 | AY11: =IFERROR(AS11*'⛽ المبيعات الشهرية'!AR10/100,"") -> 0 | AZ11: =IFERROR(AS11*'⛽ المبيعات الشهرية'!AS10/100,"") -> 0 | BA11: =IFERROR(AS11*'⛽ المبيعات الشهرية'!AT10/100,"") -> 0 | BB11: =IFERROR(AS11*'⛽ المبيعات الشهرية'!AU10/100,"") -> 0 | BC11: =IFERROR(AS11*'⛽ المبيعات الشهرية'!AV10/100,"") -> 0 | BD11: =IFERROR(AS11*'⛽ المبيعات الشهرية'!AW10/100,"") -> 0 | BE11: =IFERROR(AS11*'⛽ المبيعات الشهرية'!AX10/100,"") -> 0 | BF11: =IFERROR(SUM(AT11:BE11),"") -> 0 | BG11: =IFERROR(P11+AD11+AR11+BF11,"") -> 0
A12: 6 | B12: ='📋 بيانات المحطات'!B11 -> الشيباني | C12: ='📋 بيانات المحطات'!H11 -> 0 | D12: =IFERROR(C12*'⛽ المبيعات الشهرية'!C11/100,"") -> 0 | E12: =IFERROR(C12*'⛽ المبيعات الشهرية'!D11/100,"") -> 0 | F12: =IFERROR(C12*'⛽ المبيعات الشهرية'!E11/100,"") -> 0 | G12: =IFERROR(C12*'⛽ المبيعات الشهرية'!F11/100,"") -> 0 | H12: =IFERROR(C12*'⛽ المبيعات الشهرية'!G11/100,"") -> 0 | I12: =IFERROR(C12*'⛽ المبيعات الشهرية'!H11/100,"") -> 0 | J12: =IFERROR(C12*'⛽ المبيعات الشهرية'!I11/100,"") -> 0 | K12: =IFERROR(C12*'⛽ المبيعات الشهرية'!J11/100,"") -> 0 | L12: =IFERROR(C12*'⛽ المبيعات الشهرية'!K11/100,"") -> 0 | M12: =IFERROR(C12*'⛽ المبيعات الشهرية'!L11/100,"") -> 0 | N12: =IFERROR(C12*'⛽ المبيعات الشهرية'!M11/100,"") -> 0 | O12: =IFERROR(C12*'⛽ المبيعات الشهرية'!N11/100,"") -> 0 | P12: =IFERROR(SUM(D12:O12),"") -> 0 | Q12: ='📋 بيانات المحطات'!I11 -> 0 | R12: =IFERROR(Q12*'⛽ المبيعات الشهرية'!O11/100,"") -> 0 | S12: =IFERROR(Q12*'⛽ المبيعات الشهرية'!P11/100,"") -> 0 | T12: =IFERROR(Q12*'⛽ المبيعات الشهرية'!Q11/100,"") -> 0 | U12: =IFERROR(Q12*'⛽ المبيعات الشهرية'!R11/100,"") -> 0 | V12: =IFERROR(Q12*'⛽ المبيعات الشهرية'!S11/100,"") -> 0 | W12: =IFERROR(Q12*'⛽ المبيعات الشهرية'!T11/100,"") -> 0 | X12: =IFERROR(Q12*'⛽ المبيعات الشهرية'!U11/100,"") -> 0 | Y12: =IFERROR(Q12*'⛽ المبيعات الشهرية'!V11/100,"") -> 0 | Z12: =IFERROR(Q12*'⛽ المبيعات الشهرية'!W11/100,"") -> 0 | AA12: =IFERROR(Q12*'⛽ المبيعات الشهرية'!X11/100,"") -> 0 | AB12: =IFERROR(Q12*'⛽ المبيعات الشهرية'!Y11/100,"") -> 0 | AC12: =IFERROR(Q12*'⛽ المبيعات الشهرية'!Z11/100,"") -> 0 | AD12: =IFERROR(SUM(R12:AC12),"") -> 0 | AE12: ='📋 بيانات المحطات'!J11 -> 0 | AF12: =IFERROR(AE12*'⛽ المبيعات الشهرية'!AA11/100,"") -> 0 | AG12: =IFERROR(AE12*'⛽ المبيعات الشهرية'!AB11/100,"") -> 0 | AH12: =IFERROR(AE12*'⛽ المبيعات الشهرية'!AC11/100,"") -> 0 | AI12: =IFERROR(AE12*'⛽ المبيعات الشهرية'!AD11/100,"") -> 0 | AJ12: =IFERROR(AE12*'⛽ المبيعات الشهرية'!AE11/100,"") -> 0 | AK12: =IFERROR(AE12*'⛽ المبيعات الشهرية'!AF11/100,"") -> 0 | AL12: =IFERROR(AE12*'⛽ المبيعات الشهرية'!AG11/100,"") -> 0 | AM12: =IFERROR(AE12*'⛽ المبيعات الشهرية'!AH11/100,"") -> 0 | AN12: =IFERROR(AE12*'⛽ المبيعات الشهرية'!AI11/100,"") -> 0 | AO12: =IFERROR(AE12*'⛽ المبيعات الشهرية'!AJ11/100,"") -> 0 | AP12: =IFERROR(AE12*'⛽ المبيعات الشهرية'!AK11/100,"") -> 0 | AQ12: =IFERROR(AE12*'⛽ المبيعات الشهرية'!AL11/100,"") -> 0 | AR12: =IFERROR(SUM(AF12:AQ12),"") -> 0 | AS12: ='📋 بيانات المحطات'!K11 -> 0 | AT12: =IFERROR(AS12*'⛽ المبيعات الشهرية'!AM11/100,"") -> 0 | AU12: =IFERROR(AS12*'⛽ المبيعات الشهرية'!AN11/100,"") -> 0 | AV12: =IFERROR(AS12*'⛽ المبيعات الشهرية'!AO11/100,"") -> 0 | AW12: =IFERROR(AS12*'⛽ المبيعات الشهرية'!AP11/100,"") -> 0 | AX12: =IFERROR(AS12*'⛽ المبيعات الشهرية'!AQ11/100,"") -> 0 | AY12: =IFERROR(AS12*'⛽ المبيعات الشهرية'!AR11/100,"") -> 0 | AZ12: =IFERROR(AS12*'⛽ المبيعات الشهرية'!AS11/100,"") -> 0 | BA12: =IFERROR(AS12*'⛽ المبيعات الشهرية'!AT11/100,"") -> 0 | BB12: =IFERROR(AS12*'⛽ المبيعات الشهرية'!AU11/100,"") -> 0 | BC12: =IFERROR(AS12*'⛽ المبيعات الشهرية'!AV11/100,"") -> 0 | BD12: =IFERROR(AS12*'⛽ المبيعات الشهرية'!AW11/100,"") -> 0 | BE12: =IFERROR(AS12*'⛽ المبيعات الشهرية'!AX11/100,"") -> 0 | BF12: =IFERROR(SUM(AT12:BE12),"") -> 0 | BG12: =IFERROR(P12+AD12+AR12+BF12,"") -> 0
A13: 7 | B13: ='📋 بيانات المحطات'!B12 -> جنوب الطائف | C13: ='📋 بيانات المحطات'!H12 -> 0 | D13: =IFERROR(C13*'⛽ المبيعات الشهرية'!C12/100,"") -> 0 | E13: =IFERROR(C13*'⛽ المبيعات الشهرية'!D12/100,"") -> 0 | F13: =IFERROR(C13*'⛽ المبيعات الشهرية'!E12/100,"") -> 0 | G13: =IFERROR(C13*'⛽ المبيعات الشهرية'!F12/100,"") -> 0 | H13: =IFERROR(C13*'⛽ المبيعات الشهرية'!G12/100,"") -> 0 | I13: =IFERROR(C13*'⛽ المبيعات الشهرية'!H12/100,"") -> 0 | J13: =IFERROR(C13*'⛽ المبيعات الشهرية'!I12/100,"") -> 0 | K13: =IFERROR(C13*'⛽ المبيعات الشهرية'!J12/100,"") -> 0 | L13: =IFERROR(C13*'⛽ المبيعات الشهرية'!K12/100,"") -> 0 | M13: =IFERROR(C13*'⛽ المبيعات الشهرية'!L12/100,"") -> 0 | N13: =IFERROR(C13*'⛽ المبيعات الشهرية'!M12/100,"") -> 0 | O13: =IFERROR(C13*'⛽ المبيعات الشهرية'!N12/100,"") -> 0 | P13: =IFERROR(SUM(D13:O13),"") -> 0 | Q13: ='📋 بيانات المحطات'!I12 -> 0 | R13: =IFERROR(Q13*'⛽ المبيعات الشهرية'!O12/100,"") -> 0 | S13: =IFERROR(Q13*'⛽ المبيعات الشهرية'!P12/100,"") -> 0 | T13: =IFERROR(Q13*'⛽ المبيعات الشهرية'!Q12/100,"") -> 0 | U13: =IFERROR(Q13*'⛽ المبيعات الشهرية'!R12/100,"") -> 0 | V13: =IFERROR(Q13*'⛽ المبيعات الشهرية'!S12/100,"") -> 0 | W13: =IFERROR(Q13*'⛽ المبيعات الشهرية'!T12/100,"") -> 0 | X13: =IFERROR(Q13*'⛽ المبيعات الشهرية'!U12/100,"") -> 0 | Y13: =IFERROR(Q13*'⛽ المبيعات الشهرية'!V12/100,"") -> 0 | Z13: =IFERROR(Q13*'⛽ المبيعات الشهرية'!W12/100,"") -> 0 | AA13: =IFERROR(Q13*'⛽ المبيعات الشهرية'!X12/100,"") -> 0 | AB13: =IFERROR(Q13*'⛽ المبيعات الشهرية'!Y12/100,"") -> 0 | AC13: =IFERROR(Q13*'⛽ المبيعات الشهرية'!Z12/100,"") -> 0 | AD13: =IFERROR(SUM(R13:AC13),"") -> 0 | AE13: ='📋 بيانات المحطات'!J12 -> 0 | AF13: =IFERROR(AE13*'⛽ المبيعات الشهرية'!AA12/100,"") -> 0 | AG13: =IFERROR(AE13*'⛽ المبيعات الشهرية'!AB12/100,"") -> 0 | AH13: =IFERROR(AE13*'⛽ المبيعات الشهرية'!AC12/100,"") -> 0 | AI13: =IFERROR(AE13*'⛽ المبيعات الشهرية'!AD12/100,"") -> 0 | AJ13: =IFERROR(AE13*'⛽ المبيعات الشهرية'!AE12/100,"") -> 0 | AK13: =IFERROR(AE13*'⛽ المبيعات الشهرية'!AF12/100,"") -> 0 | AL13: =IFERROR(AE13*'⛽ المبيعات الشهرية'!AG12/100,"") -> 0 | AM13: =IFERROR(AE13*'⛽ المبيعات الشهرية'!AH12/100,"") -> 0 | AN13: =IFERROR(AE13*'⛽ المبيعات الشهرية'!AI12/100,"") -> 0 | AO13: =IFERROR(AE13*'⛽ المبيعات الشهرية'!AJ12/100,"") -> 0 | AP13: =IFERROR(AE13*'⛽ المبيعات الشهرية'!AK12/100,"") -> 0 | AQ13: =IFERROR(AE13*'⛽ المبيعات الشهرية'!AL12/100,"") -> 0 | AR13: =IFERROR(SUM(AF13:AQ13),"") -> 0 | AS13: ='📋 بيانات المحطات'!K12 -> 0 | AT13: =IFERROR(AS13*'⛽ المبيعات الشهرية'!AM12/100,"") -> 0 | AU13: =IFERROR(AS13*'⛽ المبيعات الشهرية'!AN12/100,"") -> 0 | AV13: =IFERROR(AS13*'⛽ المبيعات الشهرية'!AO12/100,"") -> 0 | AW13: =IFERROR(AS13*'⛽ المبيعات الشهرية'!AP12/100,"") -> 0 | AX13: =IFERROR(AS13*'⛽ المبيعات الشهرية'!AQ12/100,"") -> 0 | AY13: =IFERROR(AS13*'⛽ المبيعات الشهرية'!AR12/100,"") -> 0 | AZ13: =IFERROR(AS13*'⛽ المبيعات الشهرية'!AS12/100,"") -> 0 | BA13: =IFERROR(AS13*'⛽ المبيعات الشهرية'!AT12/100,"") -> 0 | BB13: =IFERROR(AS13*'⛽ المبيعات الشهرية'!AU12/100,"") -> 0 | BC13: =IFERROR(AS13*'⛽ المبيعات الشهرية'!AV12/100,"") -> 0 | BD13: =IFERROR(AS13*'⛽ المبيعات الشهرية'!AW12/100,"") -> 0 | BE13: =IFERROR(AS13*'⛽ المبيعات الشهرية'!AX12/100,"") -> 0 | BF13: =IFERROR(SUM(AT13:BE13),"") -> 0 | BG13: =IFERROR(P13+AD13+AR13+BF13,"") -> 0
A14: 8 | B14: ='📋 بيانات المحطات'!B13 -> جنوب الحسينية | C14: ='📋 بيانات المحطات'!H13 -> 0 | D14: =IFERROR(C14*'⛽ المبيعات الشهرية'!C13/100,"") -> 0 | E14: =IFERROR(C14*'⛽ المبيعات الشهرية'!D13/100,"") -> 0 | F14: =IFERROR(C14*'⛽ المبيعات الشهرية'!E13/100,"") -> 0 | G14: =IFERROR(C14*'⛽ المبيعات الشهرية'!F13/100,"") -> 0 | H14: =IFERROR(C14*'⛽ المبيعات الشهرية'!G13/100,"") -> 0 | I14: =IFERROR(C14*'⛽ المبيعات الشهرية'!H13/100,"") -> 0 | J14: =IFERROR(C14*'⛽ المبيعات الشهرية'!I13/100,"") -> 0 | K14: =IFERROR(C14*'⛽ المبيعات الشهرية'!J13/100,"") -> 0 | L14: =IFERROR(C14*'⛽ المبيعات الشهرية'!K13/100,"") -> 0 | M14: =IFERROR(C14*'⛽ المبيعات الشهرية'!L13/100,"") -> 0 | N14: =IFERROR(C14*'⛽ المبيعات الشهرية'!M13/100,"") -> 0 | O14: =IFERROR(C14*'⛽ المبيعات الشهرية'!N13/100,"") -> 0 | P14: =IFERROR(SUM(D14:O14),"") -> 0 | Q14: ='📋 بيانات المحطات'!I13 -> 0 | R14: =IFERROR(Q14*'⛽ المبيعات الشهرية'!O13/100,"") -> 0 | S14: =IFERROR(Q14*'⛽ المبيعات الشهرية'!P13/100,"") -> 0 | T14: =IFERROR(Q14*'⛽ المبيعات الشهرية'!Q13/100,"") -> 0 | U14: =IFERROR(Q14*'⛽ المبيعات الشهرية'!R13/100,"") -> 0 | V14: =IFERROR(Q14*'⛽ المبيعات الشهرية'!S13/100,"") -> 0 | W14: =IFERROR(Q14*'⛽ المبيعات الشهرية'!T13/100,"") -> 0 | X14: =IFERROR(Q14*'⛽ المبيعات الشهرية'!U13/100,"") -> 0 | Y14: =IFERROR(Q14*'⛽ المبيعات الشهرية'!V13/100,"") -> 0 | Z14: =IFERROR(Q14*'⛽ المبيعات الشهرية'!W13/100,"") -> 0 | AA14: =IFERROR(Q14*'⛽ المبيعات الشهرية'!X13/100,"") -> 0 | AB14: =IFERROR(Q14*'⛽ المبيعات الشهرية'!Y13/100,"") -> 0 | AC14: =IFERROR(Q14*'⛽ المبيعات الشهرية'!Z13/100,"") -> 0 | AD14: =IFERROR(SUM(R14:AC14),"") -> 0 | AE14: ='📋 بيانات المحطات'!J13 -> 0 | AF14: =IFERROR(AE14*'⛽ المبيعات الشهرية'!AA13/100,"") -> 0 | AG14: =IFERROR(AE14*'⛽ المبيعات الشهرية'!AB13/100,"") -> 0 | AH14: =IFERROR(AE14*'⛽ المبيعات الشهرية'!AC13/100,"") -> 0 | AI14: =IFERROR(AE14*'⛽ المبيعات الشهرية'!AD13/100,"") -> 0 | AJ14: =IFERROR(AE14*'⛽ المبيعات الشهرية'!AE13/100,"") -> 0 | AK14: =IFERROR(AE14*'⛽ المبيعات الشهرية'!AF13/100,"") -> 0 | AL14: =IFERROR(AE14*'⛽ المبيعات الشهرية'!AG13/100,"") -> 0 | AM14: =IFERROR(AE14*'⛽ المبيعات الشهرية'!AH13/100,"") -> 0 | AN14: =IFERROR(AE14*'⛽ المبيعات الشهرية'!AI13/100,"") -> 0 | AO14: =IFERROR(AE14*'⛽ المبيعات الشهرية'!AJ13/100,"") -> 0 | AP14: =IFERROR(AE14*'⛽ المبيعات الشهرية'!AK13/100,"") -> 0 | AQ14: =IFERROR(AE14*'⛽ المبيعات الشهرية'!AL13/100,"") -> 0 | AR14: =IFERROR(SUM(AF14:AQ14),"") -> 0 | AS14: ='📋 بيانات المحطات'!K13 -> 0 | AT14: =IFERROR(AS14*'⛽ المبيعات الشهرية'!AM13/100,"") -> 0 | AU14: =IFERROR(AS14*'⛽ المبيعات الشهرية'!AN13/100,"") -> 0 | AV14: =IFERROR(AS14*'⛽ المبيعات الشهرية'!AO13/100,"") -> 0 | AW14: =IFERROR(AS14*'⛽ المبيعات الشهرية'!AP13/100,"") -> 0 | AX14: =IFERROR(AS14*'⛽ المبيعات الشهرية'!AQ13/100,"") -> 0 | AY14: =IFERROR(AS14*'⛽ المبيعات الشهرية'!AR13/100,"") -> 0 | AZ14: =IFERROR(AS14*'⛽ المبيعات الشهرية'!AS13/100,"") -> 0 | BA14: =IFERROR(AS14*'⛽ المبيعات الشهرية'!AT13/100,"") -> 0 | BB14: =IFERROR(AS14*'⛽ المبيعات الشهرية'!AU13/100,"") -> 0 | BC14: =IFERROR(AS14*'⛽ المبيعات الشهرية'!AV13/100,"") -> 0 | BD14: =IFERROR(AS14*'⛽ المبيعات الشهرية'!AW13/100,"") -> 0 | BE14: =IFERROR(AS14*'⛽ المبيعات الشهرية'!AX13/100,"") -> 0 | BF14: =IFERROR(SUM(AT14:BE14),"") -> 0 | BG14: =IFERROR(P14+AD14+AR14+BF14,"") -> 0
A15: 9 | B15: ='📋 بيانات المحطات'!B14 -> جدة النسيم | C15: ='📋 بيانات المحطات'!H14 -> 0 | D15: =IFERROR(C15*'⛽ المبيعات الشهرية'!C14/100,"") -> 0 | E15: =IFERROR(C15*'⛽ المبيعات الشهرية'!D14/100,"") -> 0 | F15: =IFERROR(C15*'⛽ المبيعات الشهرية'!E14/100,"") -> 0 | G15: =IFERROR(C15*'⛽ المبيعات الشهرية'!F14/100,"") -> 0 | H15: =IFERROR(C15*'⛽ المبيعات الشهرية'!G14/100,"") -> 0 | I15: =IFERROR(C15*'⛽ المبيعات الشهرية'!H14/100,"") -> 0 | J15: =IFERROR(C15*'⛽ المبيعات الشهرية'!I14/100,"") -> 0 | K15: =IFERROR(C15*'⛽ المبيعات الشهرية'!J14/100,"") -> 0 | L15: =IFERROR(C15*'⛽ المبيعات الشهرية'!K14/100,"") -> 0 | M15: =IFERROR(C15*'⛽ المبيعات الشهرية'!L14/100,"") -> 0 | N15: =IFERROR(C15*'⛽ المبيعات الشهرية'!M14/100,"") -> 0 | O15: =IFERROR(C15*'⛽ المبيعات الشهرية'!N14/100,"") -> 0 | P15: =IFERROR(SUM(D15:O15),"") -> 0 | Q15: ='📋 بيانات المحطات'!I14 -> 0 | R15: =IFERROR(Q15*'⛽ المبيعات الشهرية'!O14/100,"") -> 0 | S15: =IFERROR(Q15*'⛽ المبيعات الشهرية'!P14/100,"") -> 0 | T15: =IFERROR(Q15*'⛽ المبيعات الشهرية'!Q14/100,"") -> 0 | U15: =IFERROR(Q15*'⛽ المبيعات الشهرية'!R14/100,"") -> 0 | V15: =IFERROR(Q15*'⛽ المبيعات الشهرية'!S14/100,"") -> 0 | W15: =IFERROR(Q15*'⛽ المبيعات الشهرية'!T14/100,"") -> 0 | X15: =IFERROR(Q15*'⛽ المبيعات الشهرية'!U14/100,"") -> 0 | Y15: =IFERROR(Q15*'⛽ المبيعات الشهرية'!V14/100,"") -> 0 | Z15: =IFERROR(Q15*'⛽ المبيعات الشهرية'!W14/100,"") -> 0 | AA15: =IFERROR(Q15*'⛽ المبيعات الشهرية'!X14/100,"") -> 0 | AB15: =IFERROR(Q15*'⛽ المبيعات الشهرية'!Y14/100,"") -> 0 | AC15: =IFERROR(Q15*'⛽ المبيعات الشهرية'!Z14/100,"") -> 0 | AD15: =IFERROR(SUM(R15:AC15),"") -> 0 | AE15: ='📋 بيانات المحطات'!J14 -> 0 | AF15: =IFERROR(AE15*'⛽ المبيعات الشهرية'!AA14/100,"") -> 0 | AG15: =IFERROR(AE15*'⛽ المبيعات الشهرية'!AB14/100,"") -> 0 | AH15: =IFERROR(AE15*'⛽ المبيعات الشهرية'!AC14/100,"") -> 0 | AI15: =IFERROR(AE15*'⛽ المبيعات الشهرية'!AD14/100,"") -> 0 | AJ15: =IFERROR(AE15*'⛽ المبيعات الشهرية'!AE14/100,"") -> 0 | AK15: =IFERROR(AE15*'⛽ المبيعات الشهرية'!AF14/100,"") -> 0 | AL15: =IFERROR(AE15*'⛽ المبيعات الشهرية'!AG14/100,"") -> 0 | AM15: =IFERROR(AE15*'⛽ المبيعات الشهرية'!AH14/100,"") -> 0 | AN15: =IFERROR(AE15*'⛽ المبيعات الشهرية'!AI14/100,"") -> 0 | AO15: =IFERROR(AE15*'⛽ المبيعات الشهرية'!AJ14/100,"") -> 0 | AP15: =IFERROR(AE15*'⛽ المبيعات الشهرية'!AK14/100,"") -> 0 | AQ15: =IFERROR(AE15*'⛽ المبيعات الشهرية'!AL14/100,"") -> 0 | AR15: =IFERROR(SUM(AF15:AQ15),"") -> 0 | AS15: ='📋 بيانات المحطات'!K14 -> 0 | AT15: =IFERROR(AS15*'⛽ المبيعات الشهرية'!AM14/100,"") -> 0 | AU15: =IFERROR(AS15*'⛽ المبيعات الشهرية'!AN14/100,"") -> 0 | AV15: =IFERROR(AS15*'⛽ المبيعات الشهرية'!AO14/100,"") -> 0 | AW15: =IFERROR(AS15*'⛽ المبيعات الشهرية'!AP14/100,"") -> 0 | AX15: =IFERROR(AS15*'⛽ المبيعات الشهرية'!AQ14/100,"") -> 0 | AY15: =IFERROR(AS15*'⛽ المبيعات الشهرية'!AR14/100,"") -> 0 | AZ15: =IFERROR(AS15*'⛽ المبيعات الشهرية'!AS14/100,"") -> 0 | BA15: =IFERROR(AS15*'⛽ المبيعات الشهرية'!AT14/100,"") -> 0 | BB15: =IFERROR(AS15*'⛽ المبيعات الشهرية'!AU14/100,"") -> 0 | BC15: =IFERROR(AS15*'⛽ المبيعات الشهرية'!AV14/100,"") -> 0 | BD15: =IFERROR(AS15*'⛽ المبيعات الشهرية'!AW14/100,"") -> 0 | BE15: =IFERROR(AS15*'⛽ المبيعات الشهرية'!AX14/100,"") -> 0 | BF15: =IFERROR(SUM(AT15:BE15),"") -> 0 | BG15: =IFERROR(P15+AD15+AR15+BF15,"") -> 0
A16: 10 | B16: ='📋 بيانات المحطات'!B15 -> الرصيفة | C16: ='📋 بيانات المحطات'!H15 -> 0 | D16: =IFERROR(C16*'⛽ المبيعات الشهرية'!C15/100,"") -> 0 | E16: =IFERROR(C16*'⛽ المبيعات الشهرية'!D15/100,"") -> 0 | F16: =IFERROR(C16*'⛽ المبيعات الشهرية'!E15/100,"") -> 0 | G16: =IFERROR(C16*'⛽ المبيعات الشهرية'!F15/100,"") -> 0 | H16: =IFERROR(C16*'⛽ المبيعات الشهرية'!G15/100,"") -> 0 | I16: =IFERROR(C16*'⛽ المبيعات الشهرية'!H15/100,"") -> 0 | J16: =IFERROR(C16*'⛽ المبيعات الشهرية'!I15/100,"") -> 0 | K16: =IFERROR(C16*'⛽ المبيعات الشهرية'!J15/100,"") -> 0 | L16: =IFERROR(C16*'⛽ المبيعات الشهرية'!K15/100,"") -> 0 | M16: =IFERROR(C16*'⛽ المبيعات الشهرية'!L15/100,"") -> 0 | N16: =IFERROR(C16*'⛽ المبيعات الشهرية'!M15/100,"") -> 0 | O16: =IFERROR(C16*'⛽ المبيعات الشهرية'!N15/100,"") -> 0 | P16: =IFERROR(SUM(D16:O16),"") -> 0 | Q16: ='📋 بيانات المحطات'!I15 -> 0 | R16: =IFERROR(Q16*'⛽ المبيعات الشهرية'!O15/100,"") -> 0 | S16: =IFERROR(Q16*'⛽ المبيعات الشهرية'!P15/100,"") -> 0 | T16: =IFERROR(Q16*'⛽ المبيعات الشهرية'!Q15/100,"") -> 0 | U16: =IFERROR(Q16*'⛽ المبيعات الشهرية'!R15/100,"") -> 0 | V16: =IFERROR(Q16*'⛽ المبيعات الشهرية'!S15/100,"") -> 0 | W16: =IFERROR(Q16*'⛽ المبيعات الشهرية'!T15/100,"") -> 0 | X16: =IFERROR(Q16*'⛽ المبيعات الشهرية'!U15/100,"") -> 0 | Y16: =IFERROR(Q16*'⛽ المبيعات الشهرية'!V15/100,"") -> 0 | Z16: =IFERROR(Q16*'⛽ المبيعات الشهرية'!W15/100,"") -> 0 | AA16: =IFERROR(Q16*'⛽ المبيعات الشهرية'!X15/100,"") -> 0 | AB16: =IFERROR(Q16*'⛽ المبيعات الشهرية'!Y15/100,"") -> 0 | AC16: =IFERROR(Q16*'⛽ المبيعات الشهرية'!Z15/100,"") -> 0 | AD16: =IFERROR(SUM(R16:AC16),"") -> 0 | AE16: ='📋 بيانات المحطات'!J15 -> 0 | AF16: =IFERROR(AE16*'⛽ المبيعات الشهرية'!AA15/100,"") -> 0 | AG16: =IFERROR(AE16*'⛽ المبيعات الشهرية'!AB15/100,"") -> 0 | AH16: =IFERROR(AE16*'⛽ المبيعات الشهرية'!AC15/100,"") -> 0 | AI16: =IFERROR(AE16*'⛽ المبيعات الشهرية'!AD15/100,"") -> 0 | AJ16: =IFERROR(AE16*'⛽ المبيعات الشهرية'!AE15/100,"") -> 0 | AK16: =IFERROR(AE16*'⛽ المبيعات الشهرية'!AF15/100,"") -> 0 | AL16: =IFERROR(AE16*'⛽ المبيعات الشهرية'!AG15/100,"") -> 0 | AM16: =IFERROR(AE16*'⛽ المبيعات الشهرية'!AH15/100,"") -> 0 | AN16: =IFERROR(AE16*'⛽ المبيعات الشهرية'!AI15/100,"") -> 0 | AO16: =IFERROR(AE16*'⛽ المبيعات الشهرية'!AJ15/100,"") -> 0 | AP16: =IFERROR(AE16*'⛽ المبيعات الشهرية'!AK15/100,"") -> 0 | AQ16: =IFERROR(AE16*'⛽ المبيعات الشهرية'!AL15/100,"") -> 0 | AR16: =IFERROR(SUM(AF16:AQ16),"") -> 0 | AS16: ='📋 بيانات المحطات'!K15 -> 0 | AT16: =IFERROR(AS16*'⛽ المبيعات الشهرية'!AM15/100,"") -> 0 | AU16: =IFERROR(AS16*'⛽ المبيعات الشهرية'!AN15/100,"") -> 0 | AV16: =IFERROR(AS16*'⛽ المبيعات الشهرية'!AO15/100,"") -> 0 | AW16: =IFERROR(AS16*'⛽ المبيعات الشهرية'!AP15/100,"") -> 0 | AX16: =IFERROR(AS16*'⛽ المبيعات الشهرية'!AQ15/100,"") -> 0 | AY16: =IFERROR(AS16*'⛽ المبيعات الشهرية'!AR15/100,"") -> 0 | AZ16: =IFERROR(AS16*'⛽ المبيعات الشهرية'!AS15/100,"") -> 0 | BA16: =IFERROR(AS16*'⛽ المبيعات الشهرية'!AT15/100,"") -> 0 | BB16: =IFERROR(AS16*'⛽ المبيعات الشهرية'!AU15/100,"") -> 0 | BC16: =IFERROR(AS16*'⛽ المبيعات الشهرية'!AV15/100,"") -> 0 | BD16: =IFERROR(AS16*'⛽ المبيعات الشهرية'!AW15/100,"") -> 0 | BE16: =IFERROR(AS16*'⛽ المبيعات الشهرية'!AX15/100,"") -> 0 | BF16: =IFERROR(SUM(AT16:BE16),"") -> 0 | BG16: =IFERROR(P16+AD16+AR16+BF16,"") -> 0
A17: 11 | B17: ='📋 بيانات المحطات'!B16 -> عرفات الشوقية | C17: ='📋 بيانات المحطات'!H16 -> 0 | D17: =IFERROR(C17*'⛽ المبيعات الشهرية'!C16/100,"") -> 0 | E17: =IFERROR(C17*'⛽ المبيعات الشهرية'!D16/100,"") -> 0 | F17: =IFERROR(C17*'⛽ المبيعات الشهرية'!E16/100,"") -> 0 | G17: =IFERROR(C17*'⛽ المبيعات الشهرية'!F16/100,"") -> 0 | H17: =IFERROR(C17*'⛽ المبيعات الشهرية'!G16/100,"") -> 0 | I17: =IFERROR(C17*'⛽ المبيعات الشهرية'!H16/100,"") -> 0 | J17: =IFERROR(C17*'⛽ المبيعات الشهرية'!I16/100,"") -> 0 | K17: =IFERROR(C17*'⛽ المبيعات الشهرية'!J16/100,"") -> 0 | L17: =IFERROR(C17*'⛽ المبيعات الشهرية'!K16/100,"") -> 0 | M17: =IFERROR(C17*'⛽ المبيعات الشهرية'!L16/100,"") -> 0 | N17: =IFERROR(C17*'⛽ المبيعات الشهرية'!M16/100,"") -> 0 | O17: =IFERROR(C17*'⛽ المبيعات الشهرية'!N16/100,"") -> 0 | P17: =IFERROR(SUM(D17:O17),"") -> 0 | Q17: ='📋 بيانات المحطات'!I16 -> 0 | R17: =IFERROR(Q17*'⛽ المبيعات الشهرية'!O16/100,"") -> 0 | S17: =IFERROR(Q17*'⛽ المبيعات الشهرية'!P16/100,"") -> 0 | T17: =IFERROR(Q17*'⛽ المبيعات الشهرية'!Q16/100,"") -> 0 | U17: =IFERROR(Q17*'⛽ المبيعات الشهرية'!R16/100,"") -> 0 | V17: =IFERROR(Q17*'⛽ المبيعات الشهرية'!S16/100,"") -> 0 | W17: =IFERROR(Q17*'⛽ المبيعات الشهرية'!T16/100,"") -> 0 | X17: =IFERROR(Q17*'⛽ المبيعات الشهرية'!U16/100,"") -> 0 | Y17: =IFERROR(Q17*'⛽ المبيعات الشهرية'!V16/100,"") -> 0 | Z17: =IFERROR(Q17*'⛽ المبيعات الشهرية'!W16/100,"") -> 0 | AA17: =IFERROR(Q17*'⛽ المبيعات الشهرية'!X16/100,"") -> 0 | AB17: =IFERROR(Q17*'⛽ المبيعات الشهرية'!Y16/100,"") -> 0 | AC17: =IFERROR(Q17*'⛽ المبيعات الشهرية'!Z16/100,"") -> 0 | AD17: =IFERROR(SUM(R17:AC17),"") -> 0 | AE17: ='📋 بيانات المحطات'!J16 -> 0 | AF17: =IFERROR(AE17*'⛽ المبيعات الشهرية'!AA16/100,"") -> 0 | AG17: =IFERROR(AE17*'⛽ المبيعات الشهرية'!AB16/100,"") -> 0 | AH17: =IFERROR(AE17*'⛽ المبيعات الشهرية'!AC16/100,"") -> 0 | AI17: =IFERROR(AE17*'⛽ المبيعات الشهرية'!AD16/100,"") -> 0 | AJ17: =IFERROR(AE17*'⛽ المبيعات الشهرية'!AE16/100,"") -> 0 | AK17: =IFERROR(AE17*'⛽ المبيعات الشهرية'!AF16/100,"") -> 0 | AL17: =IFERROR(AE17*'⛽ المبيعات الشهرية'!AG16/100,"") -> 0 | AM17: =IFERROR(AE17*'⛽ المبيعات الشهرية'!AH16/100,"") -> 0 | AN17: =IFERROR(AE17*'⛽ المبيعات الشهرية'!AI16/100,"") -> 0 | AO17: =IFERROR(AE17*'⛽ المبيعات الشهرية'!AJ16/100,"") -> 0 | AP17: =IFERROR(AE17*'⛽ المبيعات الشهرية'!AK16/100,"") -> 0 | AQ17: =IFERROR(AE17*'⛽ المبيعات الشهرية'!AL16/100,"") -> 0 | AR17: =IFERROR(SUM(AF17:AQ17),"") -> 0 | AS17: ='📋 بيانات المحطات'!K16 -> 0 | AT17: =IFERROR(AS17*'⛽ المبيعات الشهرية'!AM16/100,"") -> 0 | AU17: =IFERROR(AS17*'⛽ المبيعات الشهرية'!AN16/100,"") -> 0 | AV17: =IFERROR(AS17*'⛽ المبيعات الشهرية'!AO16/100,"") -> 0 | AW17: =IFERROR(AS17*'⛽ المبيعات الشهرية'!AP16/100,"") -> 0 | AX17: =IFERROR(AS17*'⛽ المبيعات الشهرية'!AQ16/100,"") -> 0 | AY17: =IFERROR(AS17*'⛽ المبيعات الشهرية'!AR16/100,"") -> 0 | AZ17: =IFERROR(AS17*'⛽ المبيعات الشهرية'!AS16/100,"") -> 0 | BA17: =IFERROR(AS17*'⛽ المبيعات الشهرية'!AT16/100,"") -> 0 | BB17: =IFERROR(AS17*'⛽ المبيعات الشهرية'!AU16/100,"") -> 0 | BC17: =IFERROR(AS17*'⛽ المبيعات الشهرية'!AV16/100,"") -> 0 | BD17: =IFERROR(AS17*'⛽ المبيعات الشهرية'!AW16/100,"") -> 0 | BE17: =IFERROR(AS17*'⛽ المبيعات الشهرية'!AX16/100,"") -> 0 | BF17: =IFERROR(SUM(AT17:BE17),"") -> 0 | BG17: =IFERROR(P17+AD17+AR17+BF17,"") -> 0
A18: 12 | B18: ='📋 بيانات المحطات'!B17 -> الرصيفة مسار | C18: ='📋 بيانات المحطات'!H17 -> 0 | D18: =IFERROR(C18*'⛽ المبيعات الشهرية'!C17/100,"") -> 0 | E18: =IFERROR(C18*'⛽ المبيعات الشهرية'!D17/100,"") -> 0 | F18: =IFERROR(C18*'⛽ المبيعات الشهرية'!E17/100,"") -> 0 | G18: =IFERROR(C18*'⛽ المبيعات الشهرية'!F17/100,"") -> 0 | H18: =IFERROR(C18*'⛽ المبيعات الشهرية'!G17/100,"") -> 0 | I18: =IFERROR(C18*'⛽ المبيعات الشهرية'!H17/100,"") -> 0 | J18: =IFERROR(C18*'⛽ المبيعات الشهرية'!I17/100,"") -> 0 | K18: =IFERROR(C18*'⛽ المبيعات الشهرية'!J17/100,"") -> 0 | L18: =IFERROR(C18*'⛽ المبيعات الشهرية'!K17/100,"") -> 0 | M18: =IFERROR(C18*'⛽ المبيعات الشهرية'!L17/100,"") -> 0 | N18: =IFERROR(C18*'⛽ المبيعات الشهرية'!M17/100,"") -> 0 | O18: =IFERROR(C18*'⛽ المبيعات الشهرية'!N17/100,"") -> 0 | P18: =IFERROR(SUM(D18:O18),"") -> 0 | Q18: ='📋 بيانات المحطات'!I17 -> 0 | R18: =IFERROR(Q18*'⛽ المبيعات الشهرية'!O17/100,"") -> 0 | S18: =IFERROR(Q18*'⛽ المبيعات الشهرية'!P17/100,"") -> 0 | T18: =IFERROR(Q18*'⛽ المبيعات الشهرية'!Q17/100,"") -> 0 | U18: =IFERROR(Q18*'⛽ المبيعات الشهرية'!R17/100,"") -> 0 | V18: =IFERROR(Q18*'⛽ المبيعات الشهرية'!S17/100,"") -> 0 | W18: =IFERROR(Q18*'⛽ المبيعات الشهرية'!T17/100,"") -> 0 | X18: =IFERROR(Q18*'⛽ المبيعات الشهرية'!U17/100,"") -> 0 | Y18: =IFERROR(Q18*'⛽ المبيعات الشهرية'!V17/100,"") -> 0 | Z18: =IFERROR(Q18*'⛽ المبيعات الشهرية'!W17/100,"") -> 0 | AA18: =IFERROR(Q18*'⛽ المبيعات الشهرية'!X17/100,"") -> 0 | AB18: =IFERROR(Q18*'⛽ المبيعات الشهرية'!Y17/100,"") -> 0 | AC18: =IFERROR(Q18*'⛽ المبيعات الشهرية'!Z17/100,"") -> 0 | AD18: =IFERROR(SUM(R18:AC18),"") -> 0 | AE18: ='📋 بيانات المحطات'!J17 -> 0 | AF18: =IFERROR(AE18*'⛽ المبيعات الشهرية'!AA17/100,"") -> 0 | AG18: =IFERROR(AE18*'⛽ المبيعات الشهرية'!AB17/100,"") -> 0 | AH18: =IFERROR(AE18*'⛽ المبيعات الشهرية'!AC17/100,"") -> 0 | AI18: =IFERROR(AE18*'⛽ المبيعات الشهرية'!AD17/100,"") -> 0 | AJ18: =IFERROR(AE18*'⛽ المبيعات الشهرية'!AE17/100,"") -> 0 | AK18: =IFERROR(AE18*'⛽ المبيعات الشهرية'!AF17/100,"") -> 0 | AL18: =IFERROR(AE18*'⛽ المبيعات الشهرية'!AG17/100,"") -> 0 | AM18: =IFERROR(AE18*'⛽ المبيعات الشهرية'!AH17/100,"") -> 0 | AN18: =IFERROR(AE18*'⛽ المبيعات الشهرية'!AI17/100,"") -> 0 | AO18: =IFERROR(AE18*'⛽ المبيعات الشهرية'!AJ17/100,"") -> 0 | AP18: =IFERROR(AE18*'⛽ المبيعات الشهرية'!AK17/100,"") -> 0 | AQ18: =IFERROR(AE18*'⛽ المبيعات الشهرية'!AL17/100,"") -> 0 | AR18: =IFERROR(SUM(AF18:AQ18),"") -> 0 | AS18: ='📋 بيانات المحطات'!K17 -> 0 | AT18: =IFERROR(AS18*'⛽ المبيعات الشهرية'!AM17/100,"") -> 0 | AU18: =IFERROR(AS18*'⛽ المبيعات الشهرية'!AN17/100,"") -> 0 | AV18: =IFERROR(AS18*'⛽ المبيعات الشهرية'!AO17/100,"") -> 0 | AW18: =IFERROR(AS18*'⛽ المبيعات الشهرية'!AP17/100,"") -> 0 | AX18: =IFERROR(AS18*'⛽ المبيعات الشهرية'!AQ17/100,"") -> 0 | AY18: =IFERROR(AS18*'⛽ المبيعات الشهرية'!AR17/100,"") -> 0 | AZ18: =IFERROR(AS18*'⛽ المبيعات الشهرية'!AS17/100,"") -> 0 | BA18: =IFERROR(AS18*'⛽ المبيعات الشهرية'!AT17/100,"") -> 0 | BB18: =IFERROR(AS18*'⛽ المبيعات الشهرية'!AU17/100,"") -> 0 | BC18: =IFERROR(AS18*'⛽ المبيعات الشهرية'!AV17/100,"") -> 0 | BD18: =IFERROR(AS18*'⛽ المبيعات الشهرية'!AW17/100,"") -> 0 | BE18: =IFERROR(AS18*'⛽ المبيعات الشهرية'!AX17/100,"") -> 0 | BF18: =IFERROR(SUM(AT18:BE18),"") -> 0 | BG18: =IFERROR(P18+AD18+AR18+BF18,"") -> 0
... A91: 85 | B91: ='📋 بيانات المحطات'!B90 -> 0 | C91: ='📋 بيانات المحطات'!H90 -> 0 | D91: =IFERROR(C91*'⛽ المبيعات الشهرية'!C90/100,"") -> 0 | E91: =IFERROR(C91*'⛽ المبيعات الشهرية'!D90/100,"") -> 0 | F91: =IFERROR(C91*'⛽ المبيعات الشهرية'!E90/100,"") -> 0 | G91: =IFERROR(C91*'⛽ المبيعات الشهرية'!F90/100,"") -> 0 | H91: =IFERROR(C91*'⛽ المبيعات الشهرية'!G90/100,"") -> 0 | I91: =IFERROR(C91*'⛽ المبيعات الشهرية'!H90/100,"") -> 0 | J91: =IFERROR(C91*'⛽ المبيعات الشهرية'!I90/100,"") -> 0 | K91: =IFERROR(C91*'⛽ المبيعات الشهرية'!J90/100,"") -> 0 | L91: =IFERROR(C91*'⛽ المبيعات الشهرية'!K90/100,"") -> 0 | M91: =IFERROR(C91*'⛽ المبيعات الشهرية'!L90/100,"") -> 0 | N91: =IFERROR(C91*'⛽ المبيعات الشهرية'!M90/100,"") -> 0 | O91: =IFERROR(C91*'⛽ المبيعات الشهرية'!N90/100,"") -> 0 | P91: =IFERROR(SUM(D91:O91),"") -> 0 | Q91: ='📋 بيانات المحطات'!I90 -> 0 | R91: =IFERROR(Q91*'⛽ المبيعات الشهرية'!O90/100,"") -> 0 | S91: =IFERROR(Q91*'⛽ المبيعات الشهرية'!P90/100,"") -> 0 | T91: =IFERROR(Q91*'⛽ المبيعات الشهرية'!Q90/100,"") -> 0 | U91: =IFERROR(Q91*'⛽ المبيعات الشهرية'!R90/100,"") -> 0 | V91: =IFERROR(Q91*'⛽ المبيعات الشهرية'!S90/100,"") -> 0 | W91: =IFERROR(Q91*'⛽ المبيعات الشهرية'!T90/100,"") -> 0 | X91: =IFERROR(Q91*'⛽ المبيعات الشهرية'!U90/100,"") -> 0 | Y91: =IFERROR(Q91*'⛽ المبيعات الشهرية'!V90/100,"") -> 0 | Z91: =IFERROR(Q91*'⛽ المبيعات الشهرية'!W90/100,"") -> 0 | AA91: =IFERROR(Q91*'⛽ المبيعات الشهرية'!X90/100,"") -> 0 | AB91: =IFERROR(Q91*'⛽ المبيعات الشهرية'!Y90/100,"") -> 0 | AC91: =IFERROR(Q91*'⛽ المبيعات الشهرية'!Z90/100,"") -> 0 | AD91: =IFERROR(SUM(R91:AC91),"") -> 0 | AE91: ='📋 بيانات المحطات'!J90 -> 0 | AF91: =IFERROR(AE91*'⛽ المبيعات الشهرية'!AA90/100,"") -> 0 | AG91: =IFERROR(AE91*'⛽ المبيعات الشهرية'!AB90/100,"") -> 0 | AH91: =IFERROR(AE91*'⛽ المبيعات الشهرية'!AC90/100,"") -> 0 | AI91: =IFERROR(AE91*'⛽ المبيعات الشهرية'!AD90/100,"") -> 0 | AJ91: =IFERROR(AE91*'⛽ المبيعات الشهرية'!AE90/100,"") -> 0 | AK91: =IFERROR(AE91*'⛽ المبيعات الشهرية'!AF90/100,"") -> 0 | AL91: =IFERROR(AE91*'⛽ المبيعات الشهرية'!AG90/100,"") -> 0 | AM91: =IFERROR(AE91*'⛽ المبيعات الشهرية'!AH90/100,"") -> 0 | AN91: =IFERROR(AE91*'⛽ المبيعات الشهرية'!AI90/100,"") -> 0 | AO91: =IFERROR(AE91*'⛽ المبيعات الشهرية'!AJ90/100,"") -> 0 | AP91: =IFERROR(AE91*'⛽ المبيعات الشهرية'!AK90/100,"") -> 0 | AQ91: =IFERROR(AE91*'⛽ المبيعات الشهرية'!AL90/100,"") -> 0 | AR91: =IFERROR(SUM(AF91:AQ91),"") -> 0 | AS91: ='📋 بيانات المحطات'!K90 -> 0 | AT91: =IFERROR(AS91*'⛽ المبيعات الشهرية'!AM90/100,"") -> 0 | AU91: =IFERROR(AS91*'⛽ المبيعات الشهرية'!AN90/100,"") -> 0 | AV91: =IFERROR(AS91*'⛽ المبيعات الشهرية'!AO90/100,"") -> 0 | AW91: =IFERROR(AS91*'⛽ المبيعات الشهرية'!AP90/100,"") -> 0 | AX91: =IFERROR(AS91*'⛽ المبيعات الشهرية'!AQ90/100,"") -> 0 | AY91: =IFERROR(AS91*'⛽ المبيعات الشهرية'!AR90/100,"") -> 0 | AZ91: =IFERROR(AS91*'⛽ المبيعات الشهرية'!AS90/100,"") -> 0 | BA91: =IFERROR(AS91*'⛽ المبيعات الشهرية'!AT90/100,"") -> 0 | BB91: =IFERROR(AS91*'⛽ المبيعات الشهرية'!AU90/100,"") -> 0 | BC91: =IFERROR(AS91*'⛽ المبيعات الشهرية'!AV90/100,"") -> 0 | BD91: =IFERROR(AS91*'⛽ المبيعات الشهرية'!AW90/100,"") -> 0 | BE91: =IFERROR(AS91*'⛽ المبيعات الشهرية'!AX90/100,"") -> 0 | BF91: =IFERROR(SUM(AT91:BE91),"") -> 0 | BG91: =IFERROR(P91+AD91+AR91+BF91,"") -> 0
B92: إجمالي جميع المحطات | C92: متوسط | D92: =IFERROR(SUM(D6:D90),"") -> 0 | E92: =IFERROR(SUM(E6:E90),"") -> 0 | F92: =IFERROR(SUM(F6:F90),"") -> 0 | G92: =IFERROR(SUM(G6:G90),"") -> 0 | H92: =IFERROR(SUM(H6:H90),"") -> 0 | I92: =IFERROR(SUM(I6:I90),"") -> 0 | J92: =IFERROR(SUM(J6:J90),"") -> 0 | K92: =IFERROR(SUM(K6:K90),"") -> 0 | ... P92: =IFERROR(SUM(P6:P90),"") -> 0 | Q92: متوسط | R92: =IFERROR(SUM(R6:R90),"") -> 0 | S92: =IFERROR(SUM(S6:S90),"") -> 0 | T92: =IFERROR(SUM(T6:T90),"") -> 0 | U92: =IFERROR(SUM(U6:U90),"") -> 0 | V92: =IFERROR(SUM(V6:V90),"") -> 0 | W92: =IFERROR(SUM(W6:W90),"") -> 0 | X92: =IFERROR(SUM(X6:X90),"") -> 0 | Y92: =IFERROR(SUM(Y6:Y90),"") -> 0 | ... AD92: =IFERROR(SUM(AD6:AD90),"") -> 0 | AE92: متوسط | AF92: =IFERROR(SUM(AF6:AF90),"") -> 0 | AG92: =IFERROR(SUM(AG6:AG90),"") -> 0 | AH92: =IFERROR(SUM(AH6:AH90),"") -> 0 | AI92: =IFERROR(SUM(AI6:AI90),"") -> 0 | AJ92: =IFERROR(SUM(AJ6:AJ90),"") -> 0 | AK92: =IFERROR(SUM(AK6:AK90),"") -> 0 | AL92: =IFERROR(SUM(AL6:AL90),"") -> 0 | AM92: =IFERROR(SUM(AM6:AM90),"") -> 0 | ... AR92: =IFERROR(SUM(AR6:AR90),"") -> 0 | AS92: متوسط | AT92: =IFERROR(SUM(AT6:AT90),"") -> 0 | AU92: =IFERROR(SUM(AU6:AU90),"") -> 0 | AV92: =IFERROR(SUM(AV6:AV90),"") -> 0 | AW92: =IFERROR(SUM(AW6:AW90),"") -> 0 | AX92: =IFERROR(SUM(AX6:AX90),"") -> 0 | AY92: =IFERROR(SUM(AY6:AY90),"") -> 0 | AZ92: =IFERROR(SUM(AZ6:AZ90),"") -> 0 | BA92: =IFERROR(SUM(BA6:BA90),"") -> 0 | ... BG92: =IFERROR(SUM(BG6:BG90),"") -> 0

Sheet 📊 مؤشرات KPI
A2: 📊 مؤشرات KPI — محسوبة تلقائياً من البيانات
A3: ✅ هذا الشيت يتحدث تلقائياً عند أي تغيير في البيانات أو المبيعات أو الهوامش
A5: # | B5: المؤشر | C5: الوحدة | D5: الهدف | E5: يناير | F5: فبراير | G5: مارس | H5: Q1 مجموع | I5: Q2 مجموع | J5: Q3 مجموع | K5: YTD
A6: ◀ 🛢️ ربحية المنتجات (هامش العقد × المبيعات)
A7: 1 | B7: ربحية بنزين 91 — إجمالي جميع المحطات | C7: ريال | D7: تصاعدي | E7: =IFERROR(SUMPRODUCT('📋 بيانات المحطات'!H6:H90,'⛽ المبيعات الشهرية'!C6:C90)/100,"") -> 0 | F7: =IFERROR(SUMPRODUCT('📋 بيانات المحطات'!H6:H90,'⛽ المبيعات الشهرية'!D6:D90)/100,"") -> 0 | G7: =IFERROR(SUMPRODUCT('📋 بيانات المحطات'!H6:H90,'⛽ المبيعات الشهرية'!E6:E90)/100,"") -> 0 | H7: =IFERROR(SUM(E7:G7),"") -> 0 | K7: =IFERROR(SUM('💰 الربحية — محسوبة'!P6:P90),"") -> 0
A8: 2 | B8: ربحية بنزين 95 — إجمالي جميع المحطات | C8: ريال | D8: تصاعدي | E8: =IFERROR(SUMPRODUCT('📋 بيانات المحطات'!I6:I90,'⛽ المبيعات الشهرية'!O6:O90)/100,"") -> 0 | F8: =IFERROR(SUMPRODUCT('📋 بيانات المحطات'!I6:I90,'⛽ المبيعات الشهرية'!P6:P90)/100,"") -> 0 | G8: =IFERROR(SUMPRODUCT('📋 بيانات المحطات'!I6:I90,'⛽ المبيعات الشهرية'!Q6:Q90)/100,"") -> 0 | H8: =IFERROR(SUM(E8:G8),"") -> 0 | K8: =IFERROR(SUM('💰 الربحية — محسوبة'!AD6:AD90),"") -> 0
A9: 3 | B9: ربحية بنزين 98 — إجمالي جميع المحطات | C9: ريال | D9: تصاعدي | E9: =IFERROR(SUMPRODUCT('📋 بيانات المحطات'!J6:J90,'⛽ المبيعات الشهرية'!AA6:AA90)/100,"") -> 0 | F9: =IFERROR(SUMPRODUCT('📋 بيانات المحطات'!J6:J90,'⛽ المبيعات الشهرية'!AB6:AB90)/100,"") -> 0 | G9: =IFERROR(SUMPRODUCT('📋 بيانات المحطات'!J6:J90,'⛽ المبيعات الشهرية'!AC6:AC90)/100,"") -> 0 | H9: =IFERROR(SUM(E9:G9),"") -> 0 | K9: =IFERROR(SUM('💰 الربحية — محسوبة'!AR6:AR90),"") -> 0
A10: 4 | B10: ربحية الديزل — إجمالي جميع المحطات | C10: ريال | D10: تصاعدي | E10: =IFERROR(SUMPRODUCT('📋 بيانات المحطات'!K6:K90,'⛽ المبيعات الشهرية'!AM6:AM90)/100,"") -> 0 | F10: =IFERROR(SUMPRODUCT('📋 بيانات المحطات'!K6:K90,'⛽ المبيعات الشهرية'!AN6:AN90)/100,"") -> 0 | G10: =IFERROR(SUMPRODUCT('📋 بيانات المحطات'!K6:K90,'⛽ المبيعات الشهرية'!AO6:AO90)/100,"") -> 0 | H10: =IFERROR(SUM(E10:G10),"") -> 0 | K10: =IFERROR(SUM('💰 الربحية — محسوبة'!BF6:BF90),"") -> 0
A11: 5 | B11: إجمالي ربحية جميع المنتجات — جميع المحطات | C11: ريال | D11: تصاعدي | H11: =IFERROR(SUM(H7:H10),"") -> 0 | K11: =IFERROR(SUM('💰 الربحية — محسوبة'!BG6:BG90),"") -> 0
A13: ◀ 📦 مؤشرات المبيعات الحجمية (لتر)
A14: 6 | B14: إجمالي مبيعات بنزين 91 (لتر) | C14: لتر | D14: تصاعدي | E14: =IFERROR(SUM('⛽ المبيعات الشهرية'!C6:C90),"") -> 0 | F14: =IFERROR(SUM('⛽ المبيعات الشهرية'!D6:D90),"") -> 0 | G14: =IFERROR(SUM('⛽ المبيعات الشهرية'!E6:E90),"") -> 0 | H14: =IFERROR(SUM(E14:G14),"") -> 0 | K14: =IFERROR(SUM('⛽ المبيعات الشهرية'!C6:N90),"") -> 37010066
A15: 7 | B15: إجمالي مبيعات بنزين 95 (لتر) | C15: لتر | D15: تصاعدي | E15: =IFERROR(SUM('⛽ المبيعات الشهرية'!O6:O90),"") -> 0 | F15: =IFERROR(SUM('⛽ المبيعات الشهرية'!P6:P90),"") -> 0 | G15: =IFERROR(SUM('⛽ المبيعات الشهرية'!Q6:Q90),"") -> 0 | H15: =IFERROR(SUM(E15:G15),"") -> 0 | K15: =IFERROR(SUM('⛽ المبيعات الشهرية'!O6:Z90),"") -> 30691121
A16: 8 | B16: إجمالي مبيعات بنزين 98 (لتر) | C16: لتر | D16: تصاعدي | E16: =IFERROR(SUM('⛽ المبيعات الشهرية'!AA6:AA90),"") -> 0 | F16: =IFERROR(SUM('⛽ المبيعات الشهرية'!AB6:AB90),"") -> 0 | G16: =IFERROR(SUM('⛽ المبيعات الشهرية'!AC6:AC90),"") -> 0 | H16: =IFERROR(SUM(E16:G16),"") -> 0 | K16: =IFERROR(SUM('⛽ المبيعات الشهرية'!AA6:AL90),"") -> 48890.66
A17: 9 | B17: إجمالي مبيعات الديزل (لتر) | C17: لتر | D17: تصاعدي | E17: =IFERROR(SUM('⛽ المبيعات الشهرية'!AM6:AM90),"") -> 0 | F17: =IFERROR(SUM('⛽ المبيعات الشهرية'!AN6:AN90),"") -> 0 | G17: =IFERROR(SUM('⛽ المبيعات الشهرية'!AO6:AO90),"") -> 0 | H17: =IFERROR(SUM(E17:G17),"") -> 0 | K17: =IFERROR(SUM('⛽ المبيعات الشهرية'!AM6:AX90),"") -> 15820032

Sheet أبريل 2026 — يومي
A2: تقرير المبيعات اليومي — أبريل 2026 | إجمالي الوقود (لتر)
A3: 55 محطة | 30 يوم | البيانات من: Daily Sales Report April 2026
A5: # | B5: اسم المحطة | C5: الكود | D5: 01/4 | E5: 02/4 | F5: 03/4 | G5: 04/4 | H5: 05/4 | I5: 06/4 | J5: 07/4 | K5: 08/4 | L5: 09/4 | M5: 10/4 | N5: 11/4 | O5: 12/4 | P5: 13/4 | Q5: 14/4 | R5: 15/4 | S5: 16/4 | T5: 17/4 | U5: 18/4 | V5: 19/4 | W5: 20/4 | X5: 21/4 | Y5: 22/4 | Z5: 23/4 | AA5: 24/4 | AB5: 25/4 | AC5: 26/4 | AD5: 27/4 | AE5: 28/4 | AF5: 29/4 | AG5: 30/4 | AH5: إجمالي أبريل | AI5: متوسط/يوم | AJ5: نسبة 91% | AK5: نسبة 95%
