Workbook

Sheet 📊 ملخص آلي + KPIs
A1: 📊 مؤشرات أداء سلاسل الإمداد 2026
A2: 🎯 13 مؤشر عبر 5 محاور · خطة (يدوي) vs فعلي (آلي) · الانحراف يقارن المتوسطين
A3: 📌 المؤشر | G3: 📅 الأشهر — خطة (يدوي) vs فعلي (آلي)
A4: # | B4: المؤشر | C4: الوحدة | D4: الهدف | E4: النوع | F4: الانحراف | G4: يناير | H4: فبراير | I4: مارس | J4: أبريل | K4: مايو | L4: يونيو | M4: يوليو | N4: أغسطس | O4: سبتمبر | P4: أكتوبر | Q4: نوفمبر | R4: ديسمبر
A5: ◀ 👥 خدمة العميل
A6: 1 | B6: توفر الوقود (1 - نسبة الانقطاع) | C6: % | D6: ≥ 99.5% | E6: خطة | G6: 0.995 | H6: 0.995 | I6: 0.995 | J6: 0.995 | K6: 0.995 | L6: 0.995 | M6: 0.995 | N6: 0.995 | O6: 0.995 | P6: 0.995 | Q6: 0.995 | R6: 0.995
E7: فعلي | F7: =IFERROR(IF(AVERAGE(G6:R6)=0,"",IF(IFERROR(AVERAGEIF(G7:R7,">0",G7:R7),0)>=AVERAGE(G6:R6),"✅ ",IF(IFERROR(AVERAGEIF(G7:R7,">0",G7:R7),0)>=AVERAGE(G6:R6)*0.85,"🟡 ","🔴 "))&TEXT((IFERROR(AVERAGEIF(G7:R7,">0",G7:R7),0)-AVERAGE(G6:R6))/AVERAGE(G6:R6),"+0.0%;-0.0%")),"") | G7: =IFERROR(1-(SUMIFS('🛢️ انقطاعات الوقود'!F5:F104,'🛢️ انقطاعات الوقود'!B5:B104,">="&DATE(2026,1,1),'🛢️ انقطاعات الوقود'!B5:B104,"<"&DATE(2026,1+1,1))/($F$38*DAY(DATE(2026,1+1,1)-1))),1) | H7: =IFERROR(1-(SUMIFS('🛢️ انقطاعات الوقود'!F5:F104,'🛢️ انقطاعات الوقود'!B5:B104,">="&DATE(2026,2,1),'🛢️ انقطاعات الوقود'!B5:B104,"<"&DATE(2026,2+1,1))/($F$38*DAY(DATE(2026,2+1,1)-1))),1) | I7: =IFERROR(1-(SUMIFS('🛢️ انقطاعات الوقود'!F5:F104,'🛢️ انقطاعات الوقود'!B5:B104,">="&DATE(2026,3,1),'🛢️ انقطاعات الوقود'!B5:B104,"<"&DATE(2026,3+1,1))/($F$38*DAY(DATE(2026,3+1,1)-1))),1) | J7: =IFERROR(1-(SUMIFS('🛢️ انقطاعات الوقود'!F5:F104,'🛢️ انقطاعات الوقود'!B5:B104,">="&DATE(2026,4,1),'🛢️ انقطاعات الوقود'!B5:B104,"<"&DATE(2026,4+1,1))/($F$38*DAY(DATE(2026,4+1,1)-1))),1) | K7: =IFERROR(1-(SUMIFS('🛢️ انقطاعات الوقود'!F5:F104,'🛢️ انقطاعات الوقود'!B5:B104,">="&DATE(2026,5,1),'🛢️ انقطاعات الوقود'!B5:B104,"<"&DATE(2026,5+1,1))/($F$38*DAY(DATE(2026,5+1,1)-1))),1) | L7: =IFERROR(1-(SUMIFS('🛢️ انقطاعات الوقود'!F5:F104,'🛢️ انقطاعات الوقود'!B5:B104,">="&DATE(2026,6,1),'🛢️ انقطاعات الوقود'!B5:B104,"<"&DATE(2026,6+1,1))/($F$38*DAY(DATE(2026,6+1,1)-1))),1) | M7: =IFERROR(1-(SUMIFS('🛢️ انقطاعات الوقود'!F5:F104,'🛢️ انقطاعات الوقود'!B5:B104,">="&DATE(2026,7,1),'🛢️ انقطاعات الوقود'!B5:B104,"<"&DATE(2026,7+1,1))/($F$38*DAY(DATE(2026,7+1,1)-1))),1) | N7: =IFERROR(1-(SUMIFS('🛢️ انقطاعات الوقود'!F5:F104,'🛢️ انقطاعات الوقود'!B5:B104,">="&DATE(2026,8,1),'🛢️ انقطاعات الوقود'!B5:B104,"<"&DATE(2026,8+1,1))/($F$38*DAY(DATE(2026,8+1,1)-1))),1) | O7: =IFERROR(1-(SUMIFS('🛢️ انقطاعات الوقود'!F5:F104,'🛢️ انقطاعات الوقود'!B5:B104,">="&DATE(2026,9,1),'🛢️ انقطاعات الوقود'!B5:B104,"<"&DATE(2026,9+1,1))/($F$38*DAY(DATE(2026,9+1,1)-1))),1) | P7: =IFERROR(1-(SUMIFS('🛢️ انقطاعات الوقود'!F5:F104,'🛢️ انقطاعات الوقود'!B5:B104,">="&DATE(2026,10,1),'🛢️ انقطاعات الوقود'!B5:B104,"<"&DATE(2026,10+1,1))/($F$38*DAY(DATE(2026,10+1,1)-1))),1) | Q7: =IFERROR(1-(SUMIFS('🛢️ انقطاعات الوقود'!F5:F104,'🛢️ انقطاعات الوقود'!B5:B104,">="&DATE(2026,11,1),'🛢️ انقطاعات الوقود'!B5:B104,"<"&DATE(2026,11+1,1))/($F$38*DAY(DATE(2026,11+1,1)-1))),1) | R7: =IFERROR(1-(SUMIFS('🛢️ انقطاعات الوقود'!F5:F104,'🛢️ انقطاعات الوقود'!B5:B104,">="&DATE(2026,12,1),'🛢️ انقطاعات الوقود'!B5:B104,"<"&DATE(2026,12+1,1))/($F$38*DAY(DATE(2026,12+1,1)-1))),1)
A8: 2 | B8: عدد الانقطاعات الشهرية | C8: انقطاع | D8: ≤ 5 | E8: خطة | G8: 5 | H8: 5 | I8: 5 | J8: 5 | K8: 5 | L8: 5 | M8: 5 | N8: 5 | O8: 5 | P8: 5 | Q8: 5 | R8: 5
E9: فعلي | F9: =IFERROR(IF(AVERAGE(G8:R8)=0,"",IF(IFERROR(AVERAGEIF(G9:R9,">0",G9:R9),0)<=AVERAGE(G8:R8),"✅ ",IF(IFERROR(AVERAGEIF(G9:R9,">0",G9:R9),0)<=AVERAGE(G8:R8)*1.3,"🟡 ","🔴 "))&TEXT((IFERROR(AVERAGEIF(G9:R9,">0",G9:R9),0)-AVERAGE(G8:R8))/AVERAGE(G8:R8),"+0.0%;-0.0%")),"") | G9: =COUNTIFS('🛢️ انقطاعات الوقود'!B5:B104,">="&DATE(2026,1,1),'🛢️ انقطاعات الوقود'!B5:B104,"<"&DATE(2026,1+1,1)) | H9: =COUNTIFS('🛢️ انقطاعات الوقود'!B5:B104,">="&DATE(2026,2,1),'🛢️ انقطاعات الوقود'!B5:B104,"<"&DATE(2026,2+1,1)) | I9: =COUNTIFS('🛢️ انقطاعات الوقود'!B5:B104,">="&DATE(2026,3,1),'🛢️ انقطاعات الوقود'!B5:B104,"<"&DATE(2026,3+1,1)) | J9: =COUNTIFS('🛢️ انقطاعات الوقود'!B5:B104,">="&DATE(2026,4,1),'🛢️ انقطاعات الوقود'!B5:B104,"<"&DATE(2026,4+1,1)) | K9: =COUNTIFS('🛢️ انقطاعات الوقود'!B5:B104,">="&DATE(2026,5,1),'🛢️ انقطاعات الوقود'!B5:B104,"<"&DATE(2026,5+1,1)) | L9: =COUNTIFS('🛢️ انقطاعات الوقود'!B5:B104,">="&DATE(2026,6,1),'🛢️ انقطاعات الوقود'!B5:B104,"<"&DATE(2026,6+1,1)) | M9: =COUNTIFS('🛢️ انقطاعات الوقود'!B5:B104,">="&DATE(2026,7,1),'🛢️ انقطاعات الوقود'!B5:B104,"<"&DATE(2026,7+1,1)) | N9: =COUNTIFS('🛢️ انقطاعات الوقود'!B5:B104,">="&DATE(2026,8,1),'🛢️ انقطاعات الوقود'!B5:B104,"<"&DATE(2026,8+1,1)) | O9: =COUNTIFS('🛢️ انقطاعات الوقود'!B5:B104,">="&DATE(2026,9,1),'🛢️ انقطاعات الوقود'!B5:B104,"<"&DATE(2026,9+1,1)) | P9: =COUNTIFS('🛢️ انقطاعات الوقود'!B5:B104,">="&DATE(2026,10,1),'🛢️ انقطاعات الوقود'!B5:B104,"<"&DATE(2026,10+1,1)) | Q9: =COUNTIFS('🛢️ انقطاعات الوقود'!B5:B104,">="&DATE(2026,11,1),'🛢️ انقطاعات الوقود'!B5:B104,"<"&DATE(2026,11+1,1)) | R9: =COUNTIFS('🛢️ انقطاعات الوقود'!B5:B104,">="&DATE(2026,12,1),'🛢️ انقطاعات الوقود'!B5:B104,"<"&DATE(2026,12+1,1))
A10: 3 | B10: توفر المواد المخزنية (تسليم ≤ 3 أيام) | C10: % | D10: 100% | E10: خطة | G10: 1 | H10: 1 | I10: 1 | J10: 1 | K10: 1 | L10: 1 | M10: 1 | N10: 1 | O10: 1 | P10: 1 | Q10: 1 | R10: 1
E11: فعلي | F11: =IFERROR(IF(AVERAGE(G10:R10)=0,"",IF(IFERROR(AVERAGEIF(G11:R11,">0",G11:R11),0)>=AVERAGE(G10:R10),"✅ ",IF(IFERROR(AVERAGEIF(G11:R11,">0",G11:R11),0)>=AVERAGE(G10:R10)*0.85,"🟡 ","🔴 "))&TEXT((IFERROR(AVERAGEIF(G11:R11,">0",G11:R11),0)-AVERAGE(G10:R10))/AVERAGE(G10:R10),"+0.0%;-0.0%")),"") | G11: =IFERROR(COUNTIFS('🛒 الطلبات والمشتريات'!C5:C204,">="&DATE(2026,1,1),'🛒 الطلبات والمشتريات'!C5:C204,"<"&DATE(2026,1+1,1),'🛒 الطلبات والمشتريات'!D5:D204,"مواد مخزنية",'🛒 الطلبات والمشتريات'!I5:I204,"*ضمن*")/MAX(1,COUNTIFS('🛒 الطلبات والمشتريات'!C5:C204,">="&DATE(2026,1,1),'🛒 الطلبات والمشتريات'!C5:C204,"<"&DATE(2026,1+1,1),'🛒 الطلبات والمشتريات'!D5:D204,"مواد مخزنية")),0) | H11: =IFERROR(COUNTIFS('🛒 الطلبات والمشتريات'!C5:C204,">="&DATE(2026,2,1),'🛒 الطلبات والمشتريات'!C5:C204,"<"&DATE(2026,2+1,1),'🛒 الطلبات والمشتريات'!D5:D204,"مواد مخزنية",'🛒 الطلبات والمشتريات'!I5:I204,"*ضمن*")/MAX(1,COUNTIFS('🛒 الطلبات والمشتريات'!C5:C204,">="&DATE(2026,2,1),'🛒 الطلبات والمشتريات'!C5:C204,"<"&DATE(2026,2+1,1),'🛒 الطلبات والمشتريات'!D5:D204,"مواد مخزنية")),0) | I11: =IFERROR(COUNTIFS('🛒 الطلبات والمشتريات'!C5:C204,">="&DATE(2026,3,1),'🛒 الطلبات والمشتريات'!C5:C204,"<"&DATE(2026,3+1,1),'🛒 الطلبات والمشتريات'!D5:D204,"مواد مخزنية",'🛒 الطلبات والمشتريات'!I5:I204,"*ضمن*")/MAX(1,COUNTIFS('🛒 الطلبات والمشتريات'!C5:C204,">="&DATE(2026,3,1),'🛒 الطلبات والمشتريات'!C5:C204,"<"&DATE(2026,3+1,1),'🛒 الطلبات والمشتريات'!D5:D204,"مواد مخزنية")),0) | J11: =IFERROR(COUNTIFS('🛒 الطلبات والمشتريات'!C5:C204,">="&DATE(2026,4,1),'🛒 الطلبات والمشتريات'!C5:C204,"<"&DATE(2026,4+1,1),'🛒 الطلبات والمشتريات'!D5:D204,"مواد مخزنية",'🛒 الطلبات والمشتريات'!I5:I204,"*ضمن*")/MAX(1,COUNTIFS('🛒 الطلبات والمشتريات'!C5:C204,">="&DATE(2026,4,1),'🛒 الطلبات والمشتريات'!C5:C204,"<"&DATE(2026,4+1,1),'🛒 الطلبات والمشتريات'!D5:D204,"مواد مخزنية")),0) | K11: =IFERROR(COUNTIFS('🛒 الطلبات والمشتريات'!C5:C204,">="&DATE(2026,5,1),'🛒 الطلبات والمشتريات'!C5:C204,"<"&DATE(2026,5+1,1),'🛒 الطلبات والمشتريات'!D5:D204,"مواد مخزنية",'🛒 الطلبات والمشتريات'!I5:I204,"*ضمن*")/MAX(1,COUNTIFS('🛒 الطلبات والمشتريات'!C5:C204,">="&DATE(2026,5,1),'🛒 الطلبات والمشتريات'!C5:C204,"<"&DATE(2026,5+1,1),'🛒 الطلبات والمشتريات'!D5:D204,"مواد مخزنية")),0) | L11: =IFERROR(COUNTIFS('🛒 الطلبات والمشتريات'!C5:C204,">="&DATE(2026,6,1),'🛒 الطلبات والمشتريات'!C5:C204,"<"&DATE(2026,6+1,1),'🛒 الطلبات والمشتريات'!D5:D204,"مواد مخزنية",'🛒 الطلبات والمشتريات'!I5:I204,"*ضمن*")/MAX(1,COUNTIFS('🛒 الطلبات والمشتريات'!C5:C204,">="&DATE(2026,6,1),'🛒 الطلبات والمشتريات'!C5:C204,"<"&DATE(2026,6+1,1),'🛒 الطلبات والمشتريات'!D5:D204,"مواد مخزنية")),0) | M11: =IFERROR(COUNTIFS('🛒 الطلبات والمشتريات'!C5:C204,">="&DATE(2026,7,1),'🛒 الطلبات والمشتريات'!C5:C204,"<"&DATE(2026,7+1,1),'🛒 الطلبات والمشتريات'!D5:D204,"مواد مخزنية",'🛒 الطلبات والمشتريات'!I5:I204,"*ضمن*")/MAX(1,COUNTIFS('🛒 الطلبات والمشتريات'!C5:C204,">="&DATE(2026,7,1),'🛒 الطلبات والمشتريات'!C5:C204,"<"&DATE(2026,7+1,1),'🛒 الطلبات والمشتريات'!D5:D204,"مواد مخزنية")),0) | N11: =IFERROR(COUNTIFS('🛒 الطلبات والمشتريات'!C5:C204,">="&DATE(2026,8,1),'🛒 الطلبات والمشتريات'!C5:C204,"<"&DATE(2026,8+1,1),'🛒 الطلبات والمشتريات'!D5:D204,"مواد مخزنية",'🛒 الطلبات والمشتريات'!I5:I204,"*ضمن*")/MAX(1,COUNTIFS('🛒 الطلبات والمشتريات'!C5:C204,">="&DATE(2026,8,1),'🛒 الطلبات والمشتريات'!C5:C204,"<"&DATE(2026,8+1,1),'🛒 الطلبات والمشتريات'!D5:D204,"مواد مخزنية")),0) | O11: =IFERROR(COUNTIFS('🛒 الطلبات والمشتريات'!C5:C204,">="&DATE(2026,9,1),'🛒 الطلبات والمشتريات'!C5:C204,"<"&DATE(2026,9+1,1),'🛒 الطلبات والمشتريات'!D5:D204,"مواد مخزنية",'🛒 الطلبات والمشتريات'!I5:I204,"*ضمن*")/MAX(1,COUNTIFS('🛒 الطلبات والمشتريات'!C5:C204,">="&DATE(2026,9,1),'🛒 الطلبات والمشتريات'!C5:C204,"<"&DATE(2026,9+1,1),'🛒 الطلبات والمشتريات'!D5:D204,"مواد مخزنية")),0) | P11: =IFERROR(COUNTIFS('🛒 الطلبات والمشتريات'!C5:C204,">="&DATE(2026,10,1),'🛒 الطلبات والمشتريات'!C5:C204,"<"&DATE(2026,10+1,1),'🛒 الطلبات والمشتريات'!D5:D204,"مواد مخزنية",'🛒 الطلبات والمشتريات'!I5:I204,"*ضمن*")/MAX(1,COUNTIFS('🛒 الطلبات والمشتريات'!C5:C204,">="&DATE(2026,10,1),'🛒 الطلبات والمشتريات'!C5:C204,"<"&DATE(2026,10+1,1),'🛒 الطلبات والمشتريات'!D5:D204,"مواد مخزنية")),0) | Q11: =IFERROR(COUNTIFS('🛒 الطلبات والمشتريات'!C5:C204,">="&DATE(2026,11,1),'🛒 الطلبات والمشتريات'!C5:C204,"<"&DATE(2026,11+1,1),'🛒 الطلبات والمشتريات'!D5:D204,"مواد مخزنية",'🛒 الطلبات والمشتريات'!I5:I204,"*ضمن*")/MAX(1,COUNTIFS('🛒 الطلبات والمشتريات'!C5:C204,">="&DATE(2026,11,1),'🛒 الطلبات والمشتريات'!C5:C204,"<"&DATE(2026,11+1,1),'🛒 الطلبات والمشتريات'!D5:D204,"مواد مخزنية")),0) | R11: =IFERROR(COUNTIFS('🛒 الطلبات والمشتريات'!C5:C204,">="&DATE(2026,12,1),'🛒 الطلبات والمشتريات'!C5:C204,"<"&DATE(2026,12+1,1),'🛒 الطلبات والمشتريات'!D5:D204,"مواد مخزنية",'🛒 الطلبات والمشتريات'!I5:I204,"*ضمن*")/MAX(1,COUNTIFS('🛒 الطلبات والمشتريات'!C5:C204,">="&DATE(2026,12,1),'🛒 الطلبات والمشتريات'!C5:C204,"<"&DATE(2026,12+1,1),'🛒 الطلبات والمشتريات'!D5:D204,"مواد مخزنية")),0)
A12: 4 | B12: إصدار أوامر الشراء (≤ 5 أيام عمل) | C12: % | D12: ≥ 95% | E12: خطة | G12: 0.95 | H12: 0.95 | I12: 0.95 | J12: 0.95 | K12: 0.95 | L12: 0.95 | M12: 0.95 | N12: 0.95 | O12: 0.95 | P12: 0.95 | Q12: 0.95 | R12: 0.95
E13: فعلي | F13: =IFERROR(IF(AVERAGE(G12:R12)=0,"",IF(IFERROR(AVERAGEIF(G13:R13,">0",G13:R13),0)>=AVERAGE(G12:R12),"✅ ",IF(IFERROR(AVERAGEIF(G13:R13,">0",G13:R13),0)>=AVERAGE(G12:R12)*0.85,"🟡 ","🔴 "))&TEXT((IFERROR(AVERAGEIF(G13:R13,">0",G13:R13),0)-AVERAGE(G12:R12))/AVERAGE(G12:R12),"+0.0%;-0.0%")),"") | G13: =IFERROR(COUNTIFS('🛒 الطلبات والمشتريات'!C5:C204,">="&DATE(2026,1,1),'🛒 الطلبات والمشتريات'!C5:C204,"<"&DATE(2026,1+1,1),'🛒 الطلبات والمشتريات'!D5:D204,"أمر شراء",'🛒 الطلبات والمشتريات'!I5:I204,"*ضمن*")/MAX(1,COUNTIFS('🛒 الطلبات والمشتريات'!C5:C204,">="&DATE(2026,1,1),'🛒 الطلبات والمشتريات'!C5:C204,"<"&DATE(2026,1+1,1),'🛒 الطلبات والمشتريات'!D5:D204,"أمر شراء")),0) | H13: =IFERROR(COUNTIFS('🛒 الطلبات والمشتريات'!C5:C204,">="&DATE(2026,2,1),'🛒 الطلبات والمشتريات'!C5:C204,"<"&DATE(2026,2+1,1),'🛒 الطلبات والمشتريات'!D5:D204,"أمر شراء",'🛒 الطلبات والمشتريات'!I5:I204,"*ضمن*")/MAX(1,COUNTIFS('🛒 الطلبات والمشتريات'!C5:C204,">="&DATE(2026,2,1),'🛒 الطلبات والمشتريات'!C5:C204,"<"&DATE(2026,2+1,1),'🛒 الطلبات والمشتريات'!D5:D204,"أمر شراء")),0) | I13: =IFERROR(COUNTIFS('🛒 الطلبات والمشتريات'!C5:C204,">="&DATE(2026,3,1),'🛒 الطلبات والمشتريات'!C5:C204,"<"&DATE(2026,3+1,1),'🛒 الطلبات والمشتريات'!D5:D204,"أمر شراء",'🛒 الطلبات والمشتريات'!I5:I204,"*ضمن*")/MAX(1,COUNTIFS('🛒 الطلبات والمشتريات'!C5:C204,">="&DATE(2026,3,1),'🛒 الطلبات والمشتريات'!C5:C204,"<"&DATE(2026,3+1,1),'🛒 الطلبات والمشتريات'!D5:D204,"أمر شراء")),0) | J13: =IFERROR(COUNTIFS('🛒 الطلبات والمشتريات'!C5:C204,">="&DATE(2026,4,1),'🛒 الطلبات والمشتريات'!C5:C204,"<"&DATE(2026,4+1,1),'🛒 الطلبات والمشتريات'!D5:D204,"أمر شراء",'🛒 الطلبات والمشتريات'!I5:I204,"*ضمن*")/MAX(1,COUNTIFS('🛒 الطلبات والمشتريات'!C5:C204,">="&DATE(2026,4,1),'🛒 الطلبات والمشتريات'!C5:C204,"<"&DATE(2026,4+1,1),'🛒 الطلبات والمشتريات'!D5:D204,"أمر شراء")),0) | K13: =IFERROR(COUNTIFS('🛒 الطلبات والمشتريات'!C5:C204,">="&DATE(2026,5,1),'🛒 الطلبات والمشتريات'!C5:C204,"<"&DATE(2026,5+1,1),'🛒 الطلبات والمشتريات'!D5:D204,"أمر شراء",'🛒 الطلبات والمشتريات'!I5:I204,"*ضمن*")/MAX(1,COUNTIFS('🛒 الطلبات والمشتريات'!C5:C204,">="&DATE(2026,5,1),'🛒 الطلبات والمشتريات'!C5:C204,"<"&DATE(2026,5+1,1),'🛒 الطلبات والمشتريات'!D5:D204,"أمر شراء")),0) | L13: =IFERROR(COUNTIFS('🛒 الطلبات والمشتريات'!C5:C204,">="&DATE(2026,6,1),'🛒 الطلبات والمشتريات'!C5:C204,"<"&DATE(2026,6+1,1),'🛒 الطلبات والمشتريات'!D5:D204,"أمر شراء",'🛒 الطلبات والمشتريات'!I5:I204,"*ضمن*")/MAX(1,COUNTIFS('🛒 الطلبات والمشتريات'!C5:C204,">="&DATE(2026,6,1),'🛒 الطلبات والمشتريات'!C5:C204,"<"&DATE(2026,6+1,1),'🛒 الطلبات والمشتريات'!D5:D204,"أمر شراء")),0) | M13: =IFERROR(COUNTIFS('🛒 الطلبات والمشتريات'!C5:C204,">="&DATE(2026,7,1),'🛒 الطلبات والمشتريات'!C5:C204,"<"&DATE(2026,7+1,1),'🛒 الطلبات والمشتريات'!D5:D204,"أمر شراء",'🛒 الطلبات والمشتريات'!I5:I204,"*ضمن*")/MAX(1,COUNTIFS('🛒 الطلبات والمشتريات'!C5:C204,">="&DATE(2026,7,1),'🛒 الطلبات والمشتريات'!C5:C204,"<"&DATE(2026,7+1,1),'🛒 الطلبات والمشتريات'!D5:D204,"أمر شراء")),0) | N13: =IFERROR(COUNTIFS('🛒 الطلبات والمشتريات'!C5:C204,">="&DATE(2026,8,1),'🛒 الطلبات والمشتريات'!C5:C204,"<"&DATE(2026,8+1,1),'🛒 الطلبات والمشتريات'!D5:D204,"أمر شراء",'🛒 الطلبات والمشتريات'!I5:I204,"*ضمن*")/MAX(1,COUNTIFS('🛒 الطلبات والمشتريات'!C5:C204,">="&DATE(2026,8,1),'🛒 الطلبات والمشتريات'!C5:C204,"<"&DATE(2026,8+1,1),'🛒 الطلبات والمشتريات'!D5:D204,"أمر شراء")),0) | O13: =IFERROR(COUNTIFS('🛒 الطلبات والمشتريات'!C5:C204,">="&DATE(2026,9,1),'🛒 الطلبات والمشتريات'!C5:C204,"<"&DATE(2026,9+1,1),'🛒 الطلبات والمشتريات'!D5:D204,"أمر شراء",'🛒 الطلبات والمشتريات'!I5:I204,"*ضمن*")/MAX(1,COUNTIFS('🛒 الطلبات والمشتريات'!C5:C204,">="&DATE(2026,9,1),'🛒 الطلبات والمشتريات'!C5:C204,"<"&DATE(2026,9+1,1),'🛒 الطلبات والمشتريات'!D5:D204,"أمر شراء")),0) | P13: =IFERROR(COUNTIFS('🛒 الطلبات والمشتريات'!C5:C204,">="&DATE(2026,10,1),'🛒 الطلبات والمشتريات'!C5:C204,"<"&DATE(2026,10+1,1),'🛒 الطلبات والمشتريات'!D5:D204,"أمر شراء",'🛒 الطلبات والمشتريات'!I5:I204,"*ضمن*")/MAX(1,COUNTIFS('🛒 الطلبات والمشتريات'!C5:C204,">="&DATE(2026,10,1),'🛒 الطلبات والمشتريات'!C5:C204,"<"&DATE(2026,10+1,1),'🛒 الطلبات والمشتريات'!D5:D204,"أمر شراء")),0) | Q13: =IFERROR(COUNTIFS('🛒 الطلبات والمشتريات'!C5:C204,">="&DATE(2026,11,1),'🛒 الطلبات والمشتريات'!C5:C204,"<"&DATE(2026,11+1,1),'🛒 الطلبات والمشتريات'!D5:D204,"أمر شراء",'🛒 الطلبات والمشتريات'!I5:I204,"*ضمن*")/MAX(1,COUNTIFS('🛒 الطلبات والمشتريات'!C5:C204,">="&DATE(2026,11,1),'🛒 الطلبات والمشتريات'!C5:C204,"<"&DATE(2026,11+1,1),'🛒 الطلبات والمشتريات'!D5:D204,"أمر شراء")),0) | R13: =IFERROR(COUNTIFS('🛒 الطلبات والمشتريات'!C5:C204,">="&DATE(2026,12,1),'🛒 الطلبات والمشتريات'!C5:C204,"<"&DATE(2026,12+1,1),'🛒 الطلبات والمشتريات'!D5:D204,"أمر شراء",'🛒 الطلبات والمشتريات'!I5:I204,"*ضمن*")/MAX(1,COUNTIFS('🛒 الطلبات والمشتريات'!C5:C204,">="&DATE(2026,12,1),'🛒 الطلبات والمشتريات'!C5:C204,"<"&DATE(2026,12+1,1),'🛒 الطلبات والمشتريات'!D5:D204,"أمر شراء")),0)
A14: 5 | B14: نسبة استيفاء طلبات المحطات (Fill Rate) | C14: % | D14: ≥ 98% | E14: خطة | G14: 0.98 | H14: 0.98 | I14: 0.98 | J14: 0.98 | K14: 0.98 | L14: 0.98 | M14: 0.98 | N14: 0.98 | O14: 0.98 | P14: 0.98 | Q14: 0.98 | R14: 0.98
E15: فعلي | F15: =IFERROR(IF(AVERAGE(G14:R14)=0,"",IF(IFERROR(AVERAGEIF(G15:R15,">0",G15:R15),0)>=AVERAGE(G14:R14),"✅ ",IF(IFERROR(AVERAGEIF(G15:R15,">0",G15:R15),0)>=AVERAGE(G14:R14)*0.85,"🟡 ","🔴 "))&TEXT((IFERROR(AVERAGEIF(G15:R15,">0",G15:R15),0)-AVERAGE(G14:R14))/AVERAGE(G14:R14),"+0.0%;-0.0%")),"") | G15: =IFERROR(COUNTIFS('🛒 الطلبات والمشتريات'!C5:C204,">="&DATE(2026,1,1),'🛒 الطلبات والمشتريات'!C5:C204,"<"&DATE(2026,1+1,1),'🛒 الطلبات والمشتريات'!I5:I204,"*ضمن*")/MAX(1,COUNTIFS('🛒 الطلبات والمشتريات'!C5:C204,">="&DATE(2026,1,1),'🛒 الطلبات والمشتريات'!C5:C204,"<"&DATE(2026,1+1,1))),0) | H15: =IFERROR(COUNTIFS('🛒 الطلبات والمشتريات'!C5:C204,">="&DATE(2026,2,1),'🛒 الطلبات والمشتريات'!C5:C204,"<"&DATE(2026,2+1,1),'🛒 الطلبات والمشتريات'!I5:I204,"*ضمن*")/MAX(1,COUNTIFS('🛒 الطلبات والمشتريات'!C5:C204,">="&DATE(2026,2,1),'🛒 الطلبات والمشتريات'!C5:C204,"<"&DATE(2026,2+1,1))),0) | I15: =IFERROR(COUNTIFS('🛒 الطلبات والمشتريات'!C5:C204,">="&DATE(2026,3,1),'🛒 الطلبات والمشتريات'!C5:C204,"<"&DATE(2026,3+1,1),'🛒 الطلبات والمشتريات'!I5:I204,"*ضمن*")/MAX(1,COUNTIFS('🛒 الطلبات والمشتريات'!C5:C204,">="&DATE(2026,3,1),'🛒 الطلبات والمشتريات'!C5:C204,"<"&DATE(2026,3+1,1))),0) | J15: =IFERROR(COUNTIFS('🛒 الطلبات والمشتريات'!C5:C204,">="&DATE(2026,4,1),'🛒 الطلبات والمشتريات'!C5:C204,"<"&DATE(2026,4+1,1),'🛒 الطلبات والمشتريات'!I5:I204,"*ضمن*")/MAX(1,COUNTIFS('🛒 الطلبات والمشتريات'!C5:C204,">="&DATE(2026,4,1),'🛒 الطلبات والمشتريات'!C5:C204,"<"&DATE(2026,4+1,1))),0) | K15: =IFERROR(COUNTIFS('🛒 الطلبات والمشتريات'!C5:C204,">="&DATE(2026,5,1),'🛒 الطلبات والمشتريات'!C5:C204,"<"&DATE(2026,5+1,1),'🛒 الطلبات والمشتريات'!I5:I204,"*ضمن*")/MAX(1,COUNTIFS('🛒 الطلبات والمشتريات'!C5:C204,">="&DATE(2026,5,1),'🛒 الطلبات والمشتريات'!C5:C204,"<"&DATE(2026,5+1,1))),0) | L15: =IFERROR(COUNTIFS('🛒 الطلبات والمشتريات'!C5:C204,">="&DATE(2026,6,1),'🛒 الطلبات والمشتريات'!C5:C204,"<"&DATE(2026,6+1,1),'🛒 الطلبات والمشتريات'!I5:I204,"*ضمن*")/MAX(1,COUNTIFS('🛒 الطلبات والمشتريات'!C5:C204,">="&DATE(2026,6,1),'🛒 الطلبات والمشتريات'!C5:C204,"<"&DATE(2026,6+1,1))),0) | M15: =IFERROR(COUNTIFS('🛒 الطلبات والمشتريات'!C5:C204,">="&DATE(2026,7,1),'🛒 الطلبات والمشتريات'!C5:C204,"<"&DATE(2026,7+1,1),'🛒 الطلبات والمشتريات'!I5:I204,"*ضمن*")/MAX(1,COUNTIFS('🛒 الطلبات والمشتريات'!C5:C204,">="&DATE(2026,7,1),'🛒 الطلبات والمشتريات'!C5:C204,"<"&DATE(2026,7+1,1))),0) | N15: =IFERROR(COUNTIFS('🛒 الطلبات والمشتريات'!C5:C204,">="&DATE(2026,8,1),'🛒 الطلبات والمشتريات'!C5:C204,"<"&DATE(2026,8+1,1),'🛒 الطلبات والمشتريات'!I5:I204,"*ضمن*")/MAX(1,COUNTIFS('🛒 الطلبات والمشتريات'!C5:C204,">="&DATE(2026,8,1),'🛒 الطلبات والمشتريات'!C5:C204,"<"&DATE(2026,8+1,1))),0) | O15: =IFERROR(COUNTIFS('🛒 الطلبات والمشتريات'!C5:C204,">="&DATE(2026,9,1),'🛒 الطلبات والمشتريات'!C5:C204,"<"&DATE(2026,9+1,1),'🛒 الطلبات والمشتريات'!I5:I204,"*ضمن*")/MAX(1,COUNTIFS('🛒 الطلبات والمشتريات'!C5:C204,">="&DATE(2026,9,1),'🛒 الطلبات والمشتريات'!C5:C204,"<"&DATE(2026,9+1,1))),0) | P15: =IFERROR(COUNTIFS('🛒 الطلبات والمشتريات'!C5:C204,">="&DATE(2026,10,1),'🛒 الطلبات والمشتريات'!C5:C204,"<"&DATE(2026,10+1,1),'🛒 الطلبات والمشتريات'!I5:I204,"*ضمن*")/MAX(1,COUNTIFS('🛒 الطلبات والمشتريات'!C5:C204,">="&DATE(2026,10,1),'🛒 الطلبات والمشتريات'!C5:C204,"<"&DATE(2026,10+1,1))),0) | Q15: =IFERROR(COUNTIFS('🛒 الطلبات والمشتريات'!C5:C204,">="&DATE(2026,11,1),'🛒 الطلبات والمشتريات'!C5:C204,"<"&DATE(2026,11+1,1),'🛒 الطلبات والمشتريات'!I5:I204,"*ضمن*")/MAX(1,COUNTIFS('🛒 الطلبات والمشتريات'!C5:C204,">="&DATE(2026,11,1),'🛒 الطلبات والمشتريات'!C5:C204,"<"&DATE(2026,11+1,1))),0) | R15: =IFERROR(COUNTIFS('🛒 الطلبات والمشتريات'!C5:C204,">="&DATE(2026,12,1),'🛒 الطلبات والمشتريات'!C5:C204,"<"&DATE(2026,12+1,1),'🛒 الطلبات والمشتريات'!I5:I204,"*ضمن*")/MAX(1,COUNTIFS('🛒 الطلبات والمشتريات'!C5:C204,">="&DATE(2026,12,1),'🛒 الطلبات والمشتريات'!C5:C204,"<"&DATE(2026,12+1,1))),0)
A16: ◀ 💰 التكاليف
A17: 6 | B17: فواقد الوقود لكل 33K لتر | C17: لتر | D17: ≤ 100 | E17: خطة | G17: 100 | H17: 100 | I17: 100 | J17: 100 | K17: 100 | L17: 100 | M17: 100 | N17: 100 | O17: 100 | P17: 100 | Q17: 100 | R17: 100
E18: فعلي | F18: =IFERROR(IF(AVERAGE(G17:R17)=0,"",IF(IFERROR(AVERAGEIF(G18:R18,">0",G18:R18),0)<=AVERAGE(G17:R17),"✅ ",IF(IFERROR(AVERAGEIF(G18:R18,">0",G18:R18),0)<=AVERAGE(G17:R17)*1.3,"🟡 ","🔴 "))&TEXT((IFERROR(AVERAGEIF(G18:R18,">0",G18:R18),0)-AVERAGE(G17:R17))/AVERAGE(G17:R17),"+0.0%;-0.0%")),"") | G18: =IFERROR(SUMIFS('💧 الردود والفاقد'!G5:G304,'💧 الردود والفاقد'!B5:B304,">="&DATE(2026,1,1),'💧 الردود والفاقد'!B5:B304,"<"&DATE(2026,1+1,1))/COUNTIFS('💧 الردود والفاقد'!B5:B304,">="&DATE(2026,1,1),'💧 الردود والفاقد'!B5:B304,"<"&DATE(2026,1+1,1)),0) | H18: =IFERROR(SUMIFS('💧 الردود والفاقد'!G5:G304,'💧 الردود والفاقد'!B5:B304,">="&DATE(2026,2,1),'💧 الردود والفاقد'!B5:B304,"<"&DATE(2026,2+1,1))/COUNTIFS('💧 الردود والفاقد'!B5:B304,">="&DATE(2026,2,1),'💧 الردود والفاقد'!B5:B304,"<"&DATE(2026,2+1,1)),0) | I18: =IFERROR(SUMIFS('💧 الردود والفاقد'!G5:G304,'💧 الردود والفاقد'!B5:B304,">="&DATE(2026,3,1),'💧 الردود والفاقد'!B5:B304,"<"&DATE(2026,3+1,1))/COUNTIFS('💧 الردود والفاقد'!B5:B304,">="&DATE(2026,3,1),'💧 الردود والفاقد'!B5:B304,"<"&DATE(2026,3+1,1)),0) | J18: =IFERROR(SUMIFS('💧 الردود والفاقد'!G5:G304,'💧 الردود والفاقد'!B5:B304,">="&DATE(2026,4,1),'💧 الردود والفاقد'!B5:B304,"<"&DATE(2026,4+1,1))/COUNTIFS('💧 الردود والفاقد'!B5:B304,">="&DATE(2026,4,1),'💧 الردود والفاقد'!B5:B304,"<"&DATE(2026,4+1,1)),0) | K18: =IFERROR(SUMIFS('💧 الردود والفاقد'!G5:G304,'💧 الردود والفاقد'!B5:B304,">="&DATE(2026,5,1),'💧 الردود والفاقد'!B5:B304,"<"&DATE(2026,5+1,1))/COUNTIFS('💧 الردود والفاقد'!B5:B304,">="&DATE(2026,5,1),'💧 الردود والفاقد'!B5:B304,"<"&DATE(2026,5+1,1)),0) | L18: =IFERROR(SUMIFS('💧 الردود والفاقد'!G5:G304,'💧 الردود والفاقد'!B5:B304,">="&DATE(2026,6,1),'💧 الردود والفاقد'!B5:B304,"<"&DATE(2026,6+1,1))/COUNTIFS('💧 الردود والفاقد'!B5:B304,">="&DATE(2026,6,1),'💧 الردود والفاقد'!B5:B304,"<"&DATE(2026,6+1,1)),0) | M18: =IFERROR(SUMIFS('💧 الردود والفاقد'!G5:G304,'💧 الردود والفاقد'!B5:B304,">="&DATE(2026,7,1),'💧 الردود والفاقد'!B5:B304,"<"&DATE(2026,7+1,1))/COUNTIFS('💧 الردود والفاقد'!B5:B304,">="&DATE(2026,7,1),'💧 الردود والفاقد'!B5:B304,"<"&DATE(2026,7+1,1)),0) | N18: =IFERROR(SUMIFS('💧 الردود والفاقد'!G5:G304,'💧 الردود والفاقد'!B5:B304,">="&DATE(2026,8,1),'💧 الردود والفاقد'!B5:B304,"<"&DATE(2026,8+1,1))/COUNTIFS('💧 الردود والفاقد'!B5:B304,">="&DATE(2026,8,1),'💧 الردود والفاقد'!B5:B304,"<"&DATE(2026,8+1,1)),0) | O18: =IFERROR(SUMIFS('💧 الردود والفاقد'!G5:G304,'💧 الردود والفاقد'!B5:B304,">="&DATE(2026,9,1),'💧 الردود والفاقد'!B5:B304,"<"&DATE(2026,9+1,1))/COUNTIFS('💧 الردود والفاقد'!B5:B304,">="&DATE(2026,9,1),'💧 الردود والفاقد'!B5:B304,"<"&DATE(2026,9+1,1)),0) | P18: =IFERROR(SUMIFS('💧 الردود والفاقد'!G5:G304,'💧 الردود والفاقد'!B5:B304,">="&DATE(2026,10,1),'💧 الردود والفاقد'!B5:B304,"<"&DATE(2026,10+1,1))/COUNTIFS('💧 الردود والفاقد'!B5:B304,">="&DATE(2026,10,1),'💧 الردود والفاقد'!B5:B304,"<"&DATE(2026,10+1,1)),0) | Q18: =IFERROR(SUMIFS('💧 الردود والفاقد'!G5:G304,'💧 الردود والفاقد'!B5:B304,">="&DATE(2026,11,1),'💧 الردود والفاقد'!B5:B304,"<"&DATE(2026,11+1,1))/COUNTIFS('💧 الردود والفاقد'!B5:B304,">="&DATE(2026,11,1),'💧 الردود والفاقد'!B5:B304,"<"&DATE(2026,11+1,1)),0) | R18: =IFERROR(SUMIFS('💧 الردود والفاقد'!G5:G304,'💧 الردود والفاقد'!B5:B304,">="&DATE(2026,12,1),'💧 الردود والفاقد'!B5:B304,"<"&DATE(2026,12+1,1))/COUNTIFS('💧 الردود والفاقد'!B5:B304,">="&DATE(2026,12,1),'💧 الردود والفاقد'!B5:B304,"<"&DATE(2026,12+1,1)),0)
A19: 7 | B19: نسبة المواد التالفة (يدوي شهرياً) | C19: % | D19: ≤ 2% | E19: خطة | G19: 0.02 | H19: 0.02 | I19: 0.02 | J19: 0.02 | K19: 0.02 | L19: 0.02 | M19: 0.02 | N19: 0.02 | O19: 0.02 | P19: 0.02 | Q19: 0.02 | R19: 0.02
E20: فعلي | F20: =IFERROR(IF(AVERAGE(G19:R19)=0,"",IF(IFERROR(AVERAGEIF(G20:R20,">0",G20:R20),0)<=AVERAGE(G19:R19),"✅ ",IF(IFERROR(AVERAGEIF(G20:R20,">0",G20:R20),0)<=AVERAGE(G19:R19)*1.3,"🟡 ","🔴 "))&TEXT((IFERROR(AVERAGEIF(G20:R20,">0",G20:R20),0)-AVERAGE(G19:R19))/AVERAGE(G19:R19),"+0.0%;-0.0%")),"") | G20: 0 | H20: 0 | I20: 0 | J20: 0 | K20: 0 | L20: 0 | M20: 0 | N20: 0 | O20: 0 | P20: 0 | Q20: 0 | R20: 0
A21: ◀ 🏦 السيولة المالية
A22: 8 | B22: كمية مخزون الوقود (أيام) | C22: يوم | D22: ≤ 3 | E22: خطة | G22: 3 | H22: 3 | I22: 3 | J22: 3 | K22: 3 | L22: 3 | M22: 3 | N22: 3 | O22: 3 | P22: 3 | Q22: 3 | R22: 3
E23: فعلي | F23: =IFERROR(IF(AVERAGE(G22:R22)=0,"",IF(IFERROR(AVERAGEIF(G23:R23,">0",G23:R23),0)<=AVERAGE(G22:R22),"✅ ",IF(IFERROR(AVERAGEIF(G23:R23,">0",G23:R23),0)<=AVERAGE(G22:R22)*1.3,"🟡 ","🔴 "))&TEXT((IFERROR(AVERAGEIF(G23:R23,">0",G23:R23),0)-AVERAGE(G22:R22))/AVERAGE(G22:R22),"+0.0%;-0.0%")),"") | G23: =IFERROR(AVERAGEIFS('📦 المخزون'!I5:I304,'📦 المخزون'!C5:C304,1,'📦 المخزون'!F5:F304,"وقود"),0) | H23: =IFERROR(AVERAGEIFS('📦 المخزون'!I5:I304,'📦 المخزون'!C5:C304,2,'📦 المخزون'!F5:F304,"وقود"),0) | I23: =IFERROR(AVERAGEIFS('📦 المخزون'!I5:I304,'📦 المخزون'!C5:C304,3,'📦 المخزون'!F5:F304,"وقود"),0) | J23: =IFERROR(AVERAGEIFS('📦 المخزون'!I5:I304,'📦 المخزون'!C5:C304,4,'📦 المخزون'!F5:F304,"وقود"),0) | K23: =IFERROR(AVERAGEIFS('📦 المخزون'!I5:I304,'📦 المخزون'!C5:C304,5,'📦 المخزون'!F5:F304,"وقود"),0) | L23: =IFERROR(AVERAGEIFS('📦 المخزون'!I5:I304,'📦 المخزون'!C5:C304,6,'📦 المخزون'!F5:F304,"وقود"),0) | M23: =IFERROR(AVERAGEIFS('📦 المخزون'!I5:I304,'📦 المخزون'!C5:C304,7,'📦 المخزون'!F5:F304,"وقود"),0) | N23: =IFERROR(AVERAGEIFS('📦 المخزون'!I5:I304,'📦 المخزون'!C5:C304,8,'📦 المخزون'!F5:F304,"وقود"),0) | O23: =IFERROR(AVERAGEIFS('📦 المخزون'!I5:I304,'📦 المخزون'!C5:C304,9,'📦 المخزون'!F5:F304,"وقود"),0) | P23: =IFERROR(AVERAGEIFS('📦 المخزون'!I5:I304,'📦 المخزون'!C5:C304,10,'📦 المخزون'!F5:F304,"وقود"),0) | Q23: =IFERROR(AVERAGEIFS('📦 المخزون'!I5:I304,'📦 المخزون'!C5:C304,11,'📦 المخزون'!F5:F304,"وقود"),0) | R23: =IFERROR(AVERAGEIFS('📦 المخزون'!I5:I304,'📦 المخزون'!C5:C304,12,'📦 المخزون'!F5:F304,"وقود"),0)
A24: 9 | B24: معدل دوران المخزون (مرات/شهر) | C24: مرة | D24: ≥ 10 | E24: خطة | G24: 10 | H24: 10 | I24: 10 | J24: 10 | K24: 10 | L24: 10 | M24: 10 | N24: 10 | O24: 10 | P24: 10 | Q24: 10 | R24: 10
E25: فعلي | F25: =IFERROR(IF(AVERAGE(G24:R24)=0,"",IF(IFERROR(AVERAGEIF(G25:R25,">0",G25:R25),0)>=AVERAGE(G24:R24),"✅ ",IF(IFERROR(AVERAGEIF(G25:R25,">0",G25:R25),0)>=AVERAGE(G24:R24)*0.85,"🟡 ","🔴 "))&TEXT((IFERROR(AVERAGEIF(G25:R25,">0",G25:R25),0)-AVERAGE(G24:R24))/AVERAGE(G24:R24),"+0.0%;-0.0%")),"") | G25: =IFERROR(30/AVERAGEIFS('📦 المخزون'!I5:I304,'📦 المخزون'!C5:C304,1,'📦 المخزون'!F5:F304,"وقود"),0) | H25: =IFERROR(30/AVERAGEIFS('📦 المخزون'!I5:I304,'📦 المخزون'!C5:C304,2,'📦 المخزون'!F5:F304,"وقود"),0) | I25: =IFERROR(30/AVERAGEIFS('📦 المخزون'!I5:I304,'📦 المخزون'!C5:C304,3,'📦 المخزون'!F5:F304,"وقود"),0) | J25: =IFERROR(30/AVERAGEIFS('📦 المخزون'!I5:I304,'📦 المخزون'!C5:C304,4,'📦 المخزون'!F5:F304,"وقود"),0) | K25: =IFERROR(30/AVERAGEIFS('📦 المخزون'!I5:I304,'📦 المخزون'!C5:C304,5,'📦 المخزون'!F5:F304,"وقود"),0) | L25: =IFERROR(30/AVERAGEIFS('📦 المخزون'!I5:I304,'📦 المخزون'!C5:C304,6,'📦 المخزون'!F5:F304,"وقود"),0) | M25: =IFERROR(30/AVERAGEIFS('📦 المخزون'!I5:I304,'📦 المخزون'!C5:C304,7,'📦 المخزون'!F5:F304,"وقود"),0) | N25: =IFERROR(30/AVERAGEIFS('📦 المخزون'!I5:I304,'📦 المخزون'!C5:C304,8,'📦 المخزون'!F5:F304,"وقود"),0) | O25: =IFERROR(30/AVERAGEIFS('📦 المخزون'!I5:I304,'📦 المخزون'!C5:C304,9,'📦 المخزون'!F5:F304,"وقود"),0) | P25: =IFERROR(30/AVERAGEIFS('📦 المخزون'!I5:I304,'📦 المخزون'!C5:C304,10,'📦 المخزون'!F5:F304,"وقود"),0) | Q25: =IFERROR(30/AVERAGEIFS('📦 المخزون'!I5:I304,'📦 المخزون'!C5:C304,11,'📦 المخزون'!F5:F304,"وقود"),0) | R25: =IFERROR(30/AVERAGEIFS('📦 المخزون'!I5:I304,'📦 المخزون'!C5:C304,12,'📦 المخزون'!F5:F304,"وقود"),0)
A26: ◀ 🛡️ السلامة والامتثال
A27: 10 | B27: عدد حوادث النقل الشهرية | C27: حادث | D27: 0 | E27: خطة | G27: 0 | H27: 0 | I27: 0 | J27: 0 | K27: 0 | L27: 0 | M27: 0 | N27: 0 | O27: 0 | P27: 0 | Q27: 0 | R27: 0
E28: فعلي | F28: =IFERROR(IF(AVERAGE(G27:R27)=0,"",IF(IFERROR(AVERAGEIF(G28:R28,">0",G28:R28),0)<=AVERAGE(G27:R27),"✅ ",IF(IFERROR(AVERAGEIF(G28:R28,">0",G28:R28),0)<=AVERAGE(G27:R27)*1.3,"🟡 ","🔴 "))&TEXT((IFERROR(AVERAGEIF(G28:R28,">0",G28:R28),0)-AVERAGE(G27:R27))/AVERAGE(G27:R27),"+0.0%;-0.0%")),"") | G28: =COUNTIFS('🚚 النقل والرحلات'!B5:B304,">="&DATE(2026,1,1),'🚚 النقل والرحلات'!B5:B304,"<"&DATE(2026,1+1,1),'🚚 النقل والرحلات'!K5:K304,"<>لا يوجد",'🚚 النقل والرحلات'!K5:K304,"<>") | H28: =COUNTIFS('🚚 النقل والرحلات'!B5:B304,">="&DATE(2026,2,1),'🚚 النقل والرحلات'!B5:B304,"<"&DATE(2026,2+1,1),'🚚 النقل والرحلات'!K5:K304,"<>لا يوجد",'🚚 النقل والرحلات'!K5:K304,"<>") | I28: =COUNTIFS('🚚 النقل والرحلات'!B5:B304,">="&DATE(2026,3,1),'🚚 النقل والرحلات'!B5:B304,"<"&DATE(2026,3+1,1),'🚚 النقل والرحلات'!K5:K304,"<>لا يوجد",'🚚 النقل والرحلات'!K5:K304,"<>") | J28: =COUNTIFS('🚚 النقل والرحلات'!B5:B304,">="&DATE(2026,4,1),'🚚 النقل والرحلات'!B5:B304,"<"&DATE(2026,4+1,1),'🚚 النقل والرحلات'!K5:K304,"<>لا يوجد",'🚚 النقل والرحلات'!K5:K304,"<>") | K28: =COUNTIFS('🚚 النقل والرحلات'!B5:B304,">="&DATE(2026,5,1),'🚚 النقل والرحلات'!B5:B304,"<"&DATE(2026,5+1,1),'🚚 النقل والرحلات'!K5:K304,"<>لا يوجد",'🚚 النقل والرحلات'!K5:K304,"<>") | L28: =COUNTIFS('🚚 النقل والرحلات'!B5:B304,">="&DATE(2026,6,1),'🚚 النقل والرحلات'!B5:B304,"<"&DATE(2026,6+1,1),'🚚 النقل والرحلات'!K5:K304,"<>لا يوجد",'🚚 النقل والرحلات'!K5:K304,"<>") | M28: =COUNTIFS('🚚 النقل والرحلات'!B5:B304,">="&DATE(2026,7,1),'🚚 النقل والرحلات'!B5:B304,"<"&DATE(2026,7+1,1),'🚚 النقل والرحلات'!K5:K304,"<>لا يوجد",'🚚 النقل والرحلات'!K5:K304,"<>") | N28: =COUNTIFS('🚚 النقل والرحلات'!B5:B304,">="&DATE(2026,8,1),'🚚 النقل والرحلات'!B5:B304,"<"&DATE(2026,8+1,1),'🚚 النقل والرحلات'!K5:K304,"<>لا يوجد",'🚚 النقل والرحلات'!K5:K304,"<>") | O28: =COUNTIFS('🚚 النقل والرحلات'!B5:B304,">="&DATE(2026,9,1),'🚚 النقل والرحلات'!B5:B304,"<"&DATE(2026,9+1,1),'🚚 النقل والرحلات'!K5:K304,"<>لا يوجد",'🚚 النقل والرحلات'!K5:K304,"<>") | P28: =COUNTIFS('🚚 النقل والرحلات'!B5:B304,">="&DATE(2026,10,1),'🚚 النقل والرحلات'!B5:B304,"<"&DATE(2026,10+1,1),'🚚 النقل والرحلات'!K5:K304,"<>لا يوجد",'🚚 النقل والرحلات'!K5:K304,"<>") | Q28: =COUNTIFS('🚚 النقل والرحلات'!B5:B304,">="&DATE(2026,11,1),'🚚 النقل والرحلات'!B5:B304,"<"&DATE(2026,11+1,1),'🚚 النقل والرحلات'!K5:K304,"<>لا يوجد",'🚚 النقل والرحلات'!K5:K304,"<>") | R28: =COUNTIFS('🚚 النقل والرحلات'!B5:B304,">="&DATE(2026,12,1),'🚚 النقل والرحلات'!B5:B304,"<"&DATE(2026,12+1,1),'🚚 النقل والرحلات'!K5:K304,"<>لا يوجد",'🚚 النقل والرحلات'!K5:K304,"<>")
A29: 11 | B29: معدل امتثال السائقين (بدون مخالفات) | C29: % | D29: ≥ 95% | E29: خطة | G29: 0.95 | H29: 0.95 | I29: 0.95 | J29: 0.95 | K29: 0.95 | L29: 0.95 | M29: 0.95 | N29: 0.95 | O29: 0.95 | P29: 0.95 | Q29: 0.95 | R29: 0.95
E30: فعلي | F30: =IFERROR(IF(AVERAGE(G29:R29)=0,"",IF(IFERROR(AVERAGEIF(G30:R30,">0",G30:R30),0)>=AVERAGE(G29:R29),"✅ ",IF(IFERROR(AVERAGEIF(G30:R30,">0",G30:R30),0)>=AVERAGE(G29:R29)*0.85,"🟡 ","🔴 "))&TEXT((IFERROR(AVERAGEIF(G30:R30,">0",G30:R30),0)-AVERAGE(G29:R29))/AVERAGE(G29:R29),"+0.0%;-0.0%")),"") | G30: =IFERROR(COUNTIFS('🚚 النقل والرحلات'!B5:B304,">="&DATE(2026,1,1),'🚚 النقل والرحلات'!B5:B304,"<"&DATE(2026,1+1,1),'🚚 النقل والرحلات'!K5:K304,"لا يوجد")/MAX(1,COUNTIFS('🚚 النقل والرحلات'!B5:B304,">="&DATE(2026,1,1),'🚚 النقل والرحلات'!B5:B304,"<"&DATE(2026,1+1,1))),0) | H30: =IFERROR(COUNTIFS('🚚 النقل والرحلات'!B5:B304,">="&DATE(2026,2,1),'🚚 النقل والرحلات'!B5:B304,"<"&DATE(2026,2+1,1),'🚚 النقل والرحلات'!K5:K304,"لا يوجد")/MAX(1,COUNTIFS('🚚 النقل والرحلات'!B5:B304,">="&DATE(2026,2,1),'🚚 النقل والرحلات'!B5:B304,"<"&DATE(2026,2+1,1))),0) | I30: =IFERROR(COUNTIFS('🚚 النقل والرحلات'!B5:B304,">="&DATE(2026,3,1),'🚚 النقل والرحلات'!B5:B304,"<"&DATE(2026,3+1,1),'🚚 النقل والرحلات'!K5:K304,"لا يوجد")/MAX(1,COUNTIFS('🚚 النقل والرحلات'!B5:B304,">="&DATE(2026,3,1),'🚚 النقل والرحلات'!B5:B304,"<"&DATE(2026,3+1,1))),0) | J30: =IFERROR(COUNTIFS('🚚 النقل والرحلات'!B5:B304,">="&DATE(2026,4,1),'🚚 النقل والرحلات'!B5:B304,"<"&DATE(2026,4+1,1),'🚚 النقل والرحلات'!K5:K304,"لا يوجد")/MAX(1,COUNTIFS('🚚 النقل والرحلات'!B5:B304,">="&DATE(2026,4,1),'🚚 النقل والرحلات'!B5:B304,"<"&DATE(2026,4+1,1))),0) | K30: =IFERROR(COUNTIFS('🚚 النقل والرحلات'!B5:B304,">="&DATE(2026,5,1),'🚚 النقل والرحلات'!B5:B304,"<"&DATE(2026,5+1,1),'🚚 النقل والرحلات'!K5:K304,"لا يوجد")/MAX(1,COUNTIFS('🚚 النقل والرحلات'!B5:B304,">="&DATE(2026,5,1),'🚚 النقل والرحلات'!B5:B304,"<"&DATE(2026,5+1,1))),0) | L30: =IFERROR(COUNTIFS('🚚 النقل والرحلات'!B5:B304,">="&DATE(2026,6,1),'🚚 النقل والرحلات'!B5:B304,"<"&DATE(2026,6+1,1),'🚚 النقل والرحلات'!K5:K304,"لا يوجد")/MAX(1,COUNTIFS('🚚 النقل والرحلات'!B5:B304,">="&DATE(2026,6,1),'🚚 النقل والرحلات'!B5:B304,"<"&DATE(2026,6+1,1))),0) | M30: =IFERROR(COUNTIFS('🚚 النقل والرحلات'!B5:B304,">="&DATE(2026,7,1),'🚚 النقل والرحلات'!B5:B304,"<"&DATE(2026,7+1,1),'🚚 النقل والرحلات'!K5:K304,"لا يوجد")/MAX(1,COUNTIFS('🚚 النقل والرحلات'!B5:B304,">="&DATE(2026,7,1),'🚚 النقل والرحلات'!B5:B304,"<"&DATE(2026,7+1,1))),0) | N30: =IFERROR(COUNTIFS('🚚 النقل والرحلات'!B5:B304,">="&DATE(2026,8,1),'🚚 النقل والرحلات'!B5:B304,"<"&DATE(2026,8+1,1),'🚚 النقل والرحلات'!K5:K304,"لا يوجد")/MAX(1,COUNTIFS('🚚 النقل والرحلات'!B5:B304,">="&DATE(2026,8,1),'🚚 النقل والرحلات'!B5:B304,"<"&DATE(2026,8+1,1))),0) | O30: =IFERROR(COUNTIFS('🚚 النقل والرحلات'!B5:B304,">="&DATE(2026,9,1),'🚚 النقل والرحلات'!B5:B304,"<"&DATE(2026,9+1,1),'🚚 النقل والرحلات'!K5:K304,"لا يوجد")/MAX(1,COUNTIFS('🚚 النقل والرحلات'!B5:B304,">="&DATE(2026,9,1),'🚚 النقل والرحلات'!B5:B304,"<"&DATE(2026,9+1,1))),0) | P30: =IFERROR(COUNTIFS('🚚 النقل والرحلات'!B5:B304,">="&DATE(2026,10,1),'🚚 النقل والرحلات'!B5:B304,"<"&DATE(2026,10+1,1),'🚚 النقل والرحلات'!K5:K304,"لا يوجد")/MAX(1,COUNTIFS('🚚 النقل والرحلات'!B5:B304,">="&DATE(2026,10,1),'🚚 النقل والرحلات'!B5:B304,"<"&DATE(2026,10+1,1))),0) | Q30: =IFERROR(COUNTIFS('🚚 النقل والرحلات'!B5:B304,">="&DATE(2026,11,1),'🚚 النقل والرحلات'!B5:B304,"<"&DATE(2026,11+1,1),'🚚 النقل والرحلات'!K5:K304,"لا يوجد")/MAX(1,COUNTIFS('🚚 النقل والرحلات'!B5:B304,">="&DATE(2026,11,1),'🚚 النقل والرحلات'!B5:B304,"<"&DATE(2026,11+1,1))),0) | R30: =IFERROR(COUNTIFS('🚚 النقل والرحلات'!B5:B304,">="&DATE(2026,12,1),'🚚 النقل والرحلات'!B5:B304,"<"&DATE(2026,12+1,1),'🚚 النقل والرحلات'!K5:K304,"لا يوجد")/MAX(1,COUNTIFS('🚚 النقل والرحلات'!B5:B304,">="&DATE(2026,12,1),'🚚 النقل والرحلات'!B5:B304,"<"&DATE(2026,12+1,1))),0)
A31: ◀ ⚙️ الكفاءة التشغيلية
A32: 12 | B32: التزام جدول النقل (On-time) | C32: % | D32: ≥ 95% | E32: خطة | G32: 0.95 | H32: 0.95 | I32: 0.95 | J32: 0.95 | K32: 0.95 | L32: 0.95 | M32: 0.95 | N32: 0.95 | O32: 0.95 | P32: 0.95 | Q32: 0.95 | R32: 0.95
E33: فعلي | F33: =IFERROR(IF(AVERAGE(G32:R32)=0,"",IF(IFERROR(AVERAGEIF(G33:R33,">0",G33:R33),0)>=AVERAGE(G32:R32),"✅ ",IF(IFERROR(AVERAGEIF(G33:R33,">0",G33:R33),0)>=AVERAGE(G32:R32)*0.85,"🟡 ","🔴 "))&TEXT((IFERROR(AVERAGEIF(G33:R33,">0",G33:R33),0)-AVERAGE(G32:R32))/AVERAGE(G32:R32),"+0.0%;-0.0%")),"") | G33: =IFERROR(COUNTIFS('🚚 النقل والرحلات'!B5:B304,">="&DATE(2026,1,1),'🚚 النقل والرحلات'!B5:B304,"<"&DATE(2026,1+1,1),'🚚 النقل والرحلات'!J5:J304,"*في الوقت*")/MAX(1,COUNTIFS('🚚 النقل والرحلات'!B5:B304,">="&DATE(2026,1,1),'🚚 النقل والرحلات'!B5:B304,"<"&DATE(2026,1+1,1))),0) | H33: =IFERROR(COUNTIFS('🚚 النقل والرحلات'!B5:B304,">="&DATE(2026,2,1),'🚚 النقل والرحلات'!B5:B304,"<"&DATE(2026,2+1,1),'🚚 النقل والرحلات'!J5:J304,"*في الوقت*")/MAX(1,COUNTIFS('🚚 النقل والرحلات'!B5:B304,">="&DATE(2026,2,1),'🚚 النقل والرحلات'!B5:B304,"<"&DATE(2026,2+1,1))),0) | I33: =IFERROR(COUNTIFS('🚚 النقل والرحلات'!B5:B304,">="&DATE(2026,3,1),'🚚 النقل والرحلات'!B5:B304,"<"&DATE(2026,3+1,1),'🚚 النقل والرحلات'!J5:J304,"*في الوقت*")/MAX(1,COUNTIFS('🚚 النقل والرحلات'!B5:B304,">="&DATE(2026,3,1),'🚚 النقل والرحلات'!B5:B304,"<"&DATE(2026,3+1,1))),0) | J33: =IFERROR(COUNTIFS('🚚 النقل والرحلات'!B5:B304,">="&DATE(2026,4,1),'🚚 النقل والرحلات'!B5:B304,"<"&DATE(2026,4+1,1),'🚚 النقل والرحلات'!J5:J304,"*في الوقت*")/MAX(1,COUNTIFS('🚚 النقل والرحلات'!B5:B304,">="&DATE(2026,4,1),'🚚 النقل والرحلات'!B5:B304,"<"&DATE(2026,4+1,1))),0) | K33: =IFERROR(COUNTIFS('🚚 النقل والرحلات'!B5:B304,">="&DATE(2026,5,1),'🚚 النقل والرحلات'!B5:B304,"<"&DATE(2026,5+1,1),'🚚 النقل والرحلات'!J5:J304,"*في الوقت*")/MAX(1,COUNTIFS('🚚 النقل والرحلات'!B5:B304,">="&DATE(2026,5,1),'🚚 النقل والرحلات'!B5:B304,"<"&DATE(2026,5+1,1))),0) | L33: =IFERROR(COUNTIFS('🚚 النقل والرحلات'!B5:B304,">="&DATE(2026,6,1),'🚚 النقل والرحلات'!B5:B304,"<"&DATE(2026,6+1,1),'🚚 النقل والرحلات'!J5:J304,"*في الوقت*")/MAX(1,COUNTIFS('🚚 النقل والرحلات'!B5:B304,">="&DATE(2026,6,1),'🚚 النقل والرحلات'!B5:B304,"<"&DATE(2026,6+1,1))),0) | M33: =IFERROR(COUNTIFS('🚚 النقل والرحلات'!B5:B304,">="&DATE(2026,7,1),'🚚 النقل والرحلات'!B5:B304,"<"&DATE(2026,7+1,1),'🚚 النقل والرحلات'!J5:J304,"*في الوقت*")/MAX(1,COUNTIFS('🚚 النقل والرحلات'!B5:B304,">="&DATE(2026,7,1),'🚚 النقل والرحلات'!B5:B304,"<"&DATE(2026,7+1,1))),0) | N33: =IFERROR(COUNTIFS('🚚 النقل والرحلات'!B5:B304,">="&DATE(2026,8,1),'🚚 النقل والرحلات'!B5:B304,"<"&DATE(2026,8+1,1),'🚚 النقل والرحلات'!J5:J304,"*في الوقت*")/MAX(1,COUNTIFS('🚚 النقل والرحلات'!B5:B304,">="&DATE(2026,8,1),'🚚 النقل والرحلات'!B5:B304,"<"&DATE(2026,8+1,1))),0) | O33: =IFERROR(COUNTIFS('🚚 النقل والرحلات'!B5:B304,">="&DATE(2026,9,1),'🚚 النقل والرحلات'!B5:B304,"<"&DATE(2026,9+1,1),'🚚 النقل والرحلات'!J5:J304,"*في الوقت*")/MAX(1,COUNTIFS('🚚 النقل والرحلات'!B5:B304,">="&DATE(2026,9,1),'🚚 النقل والرحلات'!B5:B304,"<"&DATE(2026,9+1,1))),0) | P33: =IFERROR(COUNTIFS('🚚 النقل والرحلات'!B5:B304,">="&DATE(2026,10,1),'🚚 النقل والرحلات'!B5:B304,"<"&DATE(2026,10+1,1),'🚚 النقل والرحلات'!J5:J304,"*في الوقت*")/MAX(1,COUNTIFS('🚚 النقل والرحلات'!B5:B304,">="&DATE(2026,10,1),'🚚 النقل والرحلات'!B5:B304,"<"&DATE(2026,10+1,1))),0) | Q33: =IFERROR(COUNTIFS('🚚 النقل والرحلات'!B5:B304,">="&DATE(2026,11,1),'🚚 النقل والرحلات'!B5:B304,"<"&DATE(2026,11+1,1),'🚚 النقل والرحلات'!J5:J304,"*في الوقت*")/MAX(1,COUNTIFS('🚚 النقل والرحلات'!B5:B304,">="&DATE(2026,11,1),'🚚 النقل والرحلات'!B5:B304,"<"&DATE(2026,11+1,1))),0) | R33: =IFERROR(COUNTIFS('🚚 النقل والرحلات'!B5:B304,">="&DATE(2026,12,1),'🚚 النقل والرحلات'!B5:B304,"<"&DATE(2026,12+1,1),'🚚 النقل والرحلات'!J5:J304,"*في الوقت*")/MAX(1,COUNTIFS('🚚 النقل والرحلات'!B5:B304,">="&DATE(2026,12,1),'🚚 النقل والرحلات'!B5:B304,"<"&DATE(2026,12+1,1))),0)
A34: 13 | B34: نسبة استخدام الأسطول المملوك | C34: % | D34: ≥ 60% | E34: خطة | G34: 0.6 | H34: 0.6 | I34: 0.6 | J34: 0.6 | K34: 0.6 | L34: 0.6 | M34: 0.6 | N34: 0.6 | O34: 0.6 | P34: 0.6 | Q34: 0.6 | R34: 0.6
E35: فعلي | F35: =IFERROR(IF(AVERAGE(G34:R34)=0,"",IF(IFERROR(AVERAGEIF(G35:R35,">0",G35:R35),0)>=AVERAGE(G34:R34),"✅ ",IF(IFERROR(AVERAGEIF(G35:R35,">0",G35:R35),0)>=AVERAGE(G34:R34)*0.85,"🟡 ","🔴 "))&TEXT((IFERROR(AVERAGEIF(G35:R35,">0",G35:R35),0)-AVERAGE(G34:R34))/AVERAGE(G34:R34),"+0.0%;-0.0%")),"") | G35: =IFERROR(COUNTIFS('🚚 النقل والرحلات'!B5:B304,">="&DATE(2026,1,1),'🚚 النقل والرحلات'!B5:B304,"<"&DATE(2026,1+1,1),'🚚 النقل والرحلات'!G5:G304,"مملوك درب")/MAX(1,COUNTIFS('🚚 النقل والرحلات'!B5:B304,">="&DATE(2026,1,1),'🚚 النقل والرحلات'!B5:B304,"<"&DATE(2026,1+1,1))),0) | H35: =IFERROR(COUNTIFS('🚚 النقل والرحلات'!B5:B304,">="&DATE(2026,2,1),'🚚 النقل والرحلات'!B5:B304,"<"&DATE(2026,2+1,1),'🚚 النقل والرحلات'!G5:G304,"مملوك درب")/MAX(1,COUNTIFS('🚚 النقل والرحلات'!B5:B304,">="&DATE(2026,2,1),'🚚 النقل والرحلات'!B5:B304,"<"&DATE(2026,2+1,1))),0) | I35: =IFERROR(COUNTIFS('🚚 النقل والرحلات'!B5:B304,">="&DATE(2026,3,1),'🚚 النقل والرحلات'!B5:B304,"<"&DATE(2026,3+1,1),'🚚 النقل والرحلات'!G5:G304,"مملوك درب")/MAX(1,COUNTIFS('🚚 النقل والرحلات'!B5:B304,">="&DATE(2026,3,1),'🚚 النقل والرحلات'!B5:B304,"<"&DATE(2026,3+1,1))),0) | J35: =IFERROR(COUNTIFS('🚚 النقل والرحلات'!B5:B304,">="&DATE(2026,4,1),'🚚 النقل والرحلات'!B5:B304,"<"&DATE(2026,4+1,1),'🚚 النقل والرحلات'!G5:G304,"مملوك درب")/MAX(1,COUNTIFS('🚚 النقل والرحلات'!B5:B304,">="&DATE(2026,4,1),'🚚 النقل والرحلات'!B5:B304,"<"&DATE(2026,4+1,1))),0) | K35: =IFERROR(COUNTIFS('🚚 النقل والرحلات'!B5:B304,">="&DATE(2026,5,1),'🚚 النقل والرحلات'!B5:B304,"<"&DATE(2026,5+1,1),'🚚 النقل والرحلات'!G5:G304,"مملوك درب")/MAX(1,COUNTIFS('🚚 النقل والرحلات'!B5:B304,">="&DATE(2026,5,1),'🚚 النقل والرحلات'!B5:B304,"<"&DATE(2026,5+1,1))),0) | L35: =IFERROR(COUNTIFS('🚚 النقل والرحلات'!B5:B304,">="&DATE(2026,6,1),'🚚 النقل والرحلات'!B5:B304,"<"&DATE(2026,6+1,1),'🚚 النقل والرحلات'!G5:G304,"مملوك درب")/MAX(1,COUNTIFS('🚚 النقل والرحلات'!B5:B304,">="&DATE(2026,6,1),'🚚 النقل والرحلات'!B5:B304,"<"&DATE(2026,6+1,1))),0) | M35: =IFERROR(COUNTIFS('🚚 النقل والرحلات'!B5:B304,">="&DATE(2026,7,1),'🚚 النقل والرحلات'!B5:B304,"<"&DATE(2026,7+1,1),'🚚 النقل والرحلات'!G5:G304,"مملوك درب")/MAX(1,COUNTIFS('🚚 النقل والرحلات'!B5:B304,">="&DATE(2026,7,1),'🚚 النقل والرحلات'!B5:B304,"<"&DATE(2026,7+1,1))),0) | N35: =IFERROR(COUNTIFS('🚚 النقل والرحلات'!B5:B304,">="&DATE(2026,8,1),'🚚 النقل والرحلات'!B5:B304,"<"&DATE(2026,8+1,1),'🚚 النقل والرحلات'!G5:G304,"مملوك درب")/MAX(1,COUNTIFS('🚚 النقل والرحلات'!B5:B304,">="&DATE(2026,8,1),'🚚 النقل والرحلات'!B5:B304,"<"&DATE(2026,8+1,1))),0) | O35: =IFERROR(COUNTIFS('🚚 النقل والرحلات'!B5:B304,">="&DATE(2026,9,1),'🚚 النقل والرحلات'!B5:B304,"<"&DATE(2026,9+1,1),'🚚 النقل والرحلات'!G5:G304,"مملوك درب")/MAX(1,COUNTIFS('🚚 النقل والرحلات'!B5:B304,">="&DATE(2026,9,1),'🚚 النقل والرحلات'!B5:B304,"<"&DATE(2026,9+1,1))),0) | P35: =IFERROR(COUNTIFS('🚚 النقل والرحلات'!B5:B304,">="&DATE(2026,10,1),'🚚 النقل والرحلات'!B5:B304,"<"&DATE(2026,10+1,1),'🚚 النقل والرحلات'!G5:G304,"مملوك درب")/MAX(1,COUNTIFS('🚚 النقل والرحلات'!B5:B304,">="&DATE(2026,10,1),'🚚 النقل والرحلات'!B5:B304,"<"&DATE(2026,10+1,1))),0) | Q35: =IFERROR(COUNTIFS('🚚 النقل والرحلات'!B5:B304,">="&DATE(2026,11,1),'🚚 النقل والرحلات'!B5:B304,"<"&DATE(2026,11+1,1),'🚚 النقل والرحلات'!G5:G304,"مملوك درب")/MAX(1,COUNTIFS('🚚 النقل والرحلات'!B5:B304,">="&DATE(2026,11,1),'🚚 النقل والرحلات'!B5:B304,"<"&DATE(2026,11+1,1))),0) | R35: =IFERROR(COUNTIFS('🚚 النقل والرحلات'!B5:B304,">="&DATE(2026,12,1),'🚚 النقل والرحلات'!B5:B304,"<"&DATE(2026,12+1,1),'🚚 النقل والرحلات'!G5:G304,"مملوك درب")/MAX(1,COUNTIFS('🚚 النقل والرحلات'!B5:B304,">="&DATE(2026,12,1),'🚚 النقل والرحلات'!B5:B304,"<"&DATE(2026,12+1,1))),0)
A37: ⚙️ مُدخلات الحساب اليدوية (حسب طريقة قياس الإدارة)
A38: عدد نقاط المنتج (محطات × منتجات) — لحساب «توفر الوقود» | F38: 300
A39: ℹ️ الافتراضي 300 = 9000 ÷ 30 (مكافئ للثابت القديم في الأشهر ذات 30 يوماً). غيّره ليعكس عدد (المحطات × المنتجات) الفعلي.

Sheet 📊 لوحة مُكثّفة (٩ مؤشرات)
A1: 📊 لوحة المؤشرات المُكثّفة — بعد دمج المتكرر (٩ مؤشرات)
A2: دُمج المتكرر: عدد الانقطاعات←التوفر · الدوران←أيام المخزون · Fill Rate (حُذف) · حوادث النقل←الامتثال/السلامة
A3: 📌 المؤشر | G3: 📅 الأشهر — خطة (يدوي) vs فعلي (آلي)
A4: # | B4: المؤشر | C4: الوحدة | D4: الهدف | E4: النوع | F4: الانحراف | G4: يناير | H4: فبراير | I4: مارس | J4: أبريل | K4: مايو | L4: يونيو | M4: يوليو | N4: أغسطس | O4: سبتمبر | P4: أكتوبر | Q4: نوفمبر | R4: ديسمبر
A5: ◀ 👥 خدمة العميل
A6: 1 | B6: توفر الوقود (يطوي عدد الانقطاعات) | C6: % | D6: ≥ 99.5% | E6: خطة | G6: 0.995 | H6: 0.995 | I6: 0.995 | J6: 0.995 | K6: 0.995 | L6: 0.995 | M6: 0.995 | N6: 0.995 | O6: 0.995 | P6: 0.995 | Q6: 0.995 | R6: 0.995
E7: فعلي | F7: =IFERROR(IF(AVERAGE(G6:R6)=0,"",IF(IFERROR(AVERAGEIF(G7:R7,">0",G7:R7),0)>=AVERAGE(G6:R6),"✅ ",IF(IFERROR(AVERAGEIF(G7:R7,">0",G7:R7),0)>=AVERAGE(G6:R6)*0.85,"🟡 ","🔴 "))&TEXT((IFERROR(AVERAGEIF(G7:R7,">0",G7:R7),0)-AVERAGE(G6:R6))/AVERAGE(G6:R6),"+0.0%;-0.0%")),"") | G7: =IFERROR(1-(SUMIFS('🛢️ انقطاعات الوقود'!F5:F104,'🛢️ انقطاعات الوقود'!B5:B104,">="&DATE(2026,1,1),'🛢️ انقطاعات الوقود'!B5:B104,"<"&DATE(2026,1+1,1))/('📊 ملخص آلي + KPIs'!$F$38*DAY(DATE(2026,1+1,1)-1))),1) | H7: =IFERROR(1-(SUMIFS('🛢️ انقطاعات الوقود'!F5:F104,'🛢️ انقطاعات الوقود'!B5:B104,">="&DATE(2026,2,1),'🛢️ انقطاعات الوقود'!B5:B104,"<"&DATE(2026,2+1,1))/('📊 ملخص آلي + KPIs'!$F$38*DAY(DATE(2026,2+1,1)-1))),1) | I7: =IFERROR(1-(SUMIFS('🛢️ انقطاعات الوقود'!F5:F104,'🛢️ انقطاعات الوقود'!B5:B104,">="&DATE(2026,3,1),'🛢️ انقطاعات الوقود'!B5:B104,"<"&DATE(2026,3+1,1))/('📊 ملخص آلي + KPIs'!$F$38*DAY(DATE(2026,3+1,1)-1))),1) | J7: =IFERROR(1-(SUMIFS('🛢️ انقطاعات الوقود'!F5:F104,'🛢️ انقطاعات الوقود'!B5:B104,">="&DATE(2026,4,1),'🛢️ انقطاعات الوقود'!B5:B104,"<"&DATE(2026,4+1,1))/('📊 ملخص آلي + KPIs'!$F$38*DAY(DATE(2026,4+1,1)-1))),1) | K7: =IFERROR(1-(SUMIFS('🛢️ انقطاعات الوقود'!F5:F104,'🛢️ انقطاعات الوقود'!B5:B104,">="&DATE(2026,5,1),'🛢️ انقطاعات الوقود'!B5:B104,"<"&DATE(2026,5+1,1))/('📊 ملخص آلي + KPIs'!$F$38*DAY(DATE(2026,5+1,1)-1))),1) | L7: =IFERROR(1-(SUMIFS('🛢️ انقطاعات الوقود'!F5:F104,'🛢️ انقطاعات الوقود'!B5:B104,">="&DATE(2026,6,1),'🛢️ انقطاعات الوقود'!B5:B104,"<"&DATE(2026,6+1,1))/('📊 ملخص آلي + KPIs'!$F$38*DAY(DATE(2026,6+1,1)-1))),1) | M7: =IFERROR(1-(SUMIFS('🛢️ انقطاعات الوقود'!F5:F104,'🛢️ انقطاعات الوقود'!B5:B104,">="&DATE(2026,7,1),'🛢️ انقطاعات الوقود'!B5:B104,"<"&DATE(2026,7+1,1))/('📊 ملخص آلي + KPIs'!$F$38*DAY(DATE(2026,7+1,1)-1))),1) | N7: =IFERROR(1-(SUMIFS('🛢️ انقطاعات الوقود'!F5:F104,'🛢️ انقطاعات الوقود'!B5:B104,">="&DATE(2026,8,1),'🛢️ انقطاعات الوقود'!B5:B104,"<"&DATE(2026,8+1,1))/('📊 ملخص آلي + KPIs'!$F$38*DAY(DATE(2026,8+1,1)-1))),1) | O7: =IFERROR(1-(SUMIFS('🛢️ انقطاعات الوقود'!F5:F104,'🛢️ انقطاعات الوقود'!B5:B104,">="&DATE(2026,9,1),'🛢️ انقطاعات الوقود'!B5:B104,"<"&DATE(2026,9+1,1))/('📊 ملخص آلي + KPIs'!$F$38*DAY(DATE(2026,9+1,1)-1))),1) | P7: =IFERROR(1-(SUMIFS('🛢️ انقطاعات الوقود'!F5:F104,'🛢️ انقطاعات الوقود'!B5:B104,">="&DATE(2026,10,1),'🛢️ انقطاعات الوقود'!B5:B104,"<"&DATE(2026,10+1,1))/('📊 ملخص آلي + KPIs'!$F$38*DAY(DATE(2026,10+1,1)-1))),1) | Q7: =IFERROR(1-(SUMIFS('🛢️ انقطاعات الوقود'!F5:F104,'🛢️ انقطاعات الوقود'!B5:B104,">="&DATE(2026,11,1),'🛢️ انقطاعات الوقود'!B5:B104,"<"&DATE(2026,11+1,1))/('📊 ملخص آلي + KPIs'!$F$38*DAY(DATE(2026,11+1,1)-1))),1) | R7: =IFERROR(1-(SUMIFS('🛢️ انقطاعات الوقود'!F5:F104,'🛢️ انقطاعات الوقود'!B5:B104,">="&DATE(2026,12,1),'🛢️ انقطاعات الوقود'!B5:B104,"<"&DATE(2026,12+1,1))/('📊 ملخص آلي + KPIs'!$F$38*DAY(DATE(2026,12+1,1)-1))),1)
A8: 2 | B8: توفر المواد المخزنية (تسليم ≤ 3 أيام) | C8: % | D8: 100% | E8: خطة | G8: 1 | H8: 1 | I8: 1 | J8: 1 | K8: 1 | L8: 1 | M8: 1 | N8: 1 | O8: 1 | P8: 1 | Q8: 1 | R8: 1
E9: فعلي | F9: =IFERROR(IF(AVERAGE(G8:R8)=0,"",IF(IFERROR(AVERAGEIF(G9:R9,">0",G9:R9),0)>=AVERAGE(G8:R8),"✅ ",IF(IFERROR(AVERAGEIF(G9:R9,">0",G9:R9),0)>=AVERAGE(G8:R8)*0.85,"🟡 ","🔴 "))&TEXT((IFERROR(AVERAGEIF(G9:R9,">0",G9:R9),0)-AVERAGE(G8:R8))/AVERAGE(G8:R8),"+0.0%;-0.0%")),"") | G9: =IFERROR(COUNTIFS('🛒 الطلبات والمشتريات'!C5:C204,">="&DATE(2026,1,1),'🛒 الطلبات والمشتريات'!C5:C204,"<"&DATE(2026,1+1,1),'🛒 الطلبات والمشتريات'!D5:D204,"مواد مخزنية",'🛒 الطلبات والمشتريات'!I5:I204,"*ضمن*")/MAX(1,COUNTIFS('🛒 الطلبات والمشتريات'!C5:C204,">="&DATE(2026,1,1),'🛒 الطلبات والمشتريات'!C5:C204,"<"&DATE(2026,1+1,1),'🛒 الطلبات والمشتريات'!D5:D204,"مواد مخزنية")),0) | H9: =IFERROR(COUNTIFS('🛒 الطلبات والمشتريات'!C5:C204,">="&DATE(2026,2,1),'🛒 الطلبات والمشتريات'!C5:C204,"<"&DATE(2026,2+1,1),'🛒 الطلبات والمشتريات'!D5:D204,"مواد مخزنية",'🛒 الطلبات والمشتريات'!I5:I204,"*ضمن*")/MAX(1,COUNTIFS('🛒 الطلبات والمشتريات'!C5:C204,">="&DATE(2026,2,1),'🛒 الطلبات والمشتريات'!C5:C204,"<"&DATE(2026,2+1,1),'🛒 الطلبات والمشتريات'!D5:D204,"مواد مخزنية")),0) | I9: =IFERROR(COUNTIFS('🛒 الطلبات والمشتريات'!C5:C204,">="&DATE(2026,3,1),'🛒 الطلبات والمشتريات'!C5:C204,"<"&DATE(2026,3+1,1),'🛒 الطلبات والمشتريات'!D5:D204,"مواد مخزنية",'🛒 الطلبات والمشتريات'!I5:I204,"*ضمن*")/MAX(1,COUNTIFS('🛒 الطلبات والمشتريات'!C5:C204,">="&DATE(2026,3,1),'🛒 الطلبات والمشتريات'!C5:C204,"<"&DATE(2026,3+1,1),'🛒 الطلبات والمشتريات'!D5:D204,"مواد مخزنية")),0) | J9: =IFERROR(COUNTIFS('🛒 الطلبات والمشتريات'!C5:C204,">="&DATE(2026,4,1),'🛒 الطلبات والمشتريات'!C5:C204,"<"&DATE(2026,4+1,1),'🛒 الطلبات والمشتريات'!D5:D204,"مواد مخزنية",'🛒 الطلبات والمشتريات'!I5:I204,"*ضمن*")/MAX(1,COUNTIFS('🛒 الطلبات والمشتريات'!C5:C204,">="&DATE(2026,4,1),'🛒 الطلبات والمشتريات'!C5:C204,"<"&DATE(2026,4+1,1),'🛒 الطلبات والمشتريات'!D5:D204,"مواد مخزنية")),0) | K9: =IFERROR(COUNTIFS('🛒 الطلبات والمشتريات'!C5:C204,">="&DATE(2026,5,1),'🛒 الطلبات والمشتريات'!C5:C204,"<"&DATE(2026,5+1,1),'🛒 الطلبات والمشتريات'!D5:D204,"مواد مخزنية",'🛒 الطلبات والمشتريات'!I5:I204,"*ضمن*")/MAX(1,COUNTIFS('🛒 الطلبات والمشتريات'!C5:C204,">="&DATE(2026,5,1),'🛒 الطلبات والمشتريات'!C5:C204,"<"&DATE(2026,5+1,1),'🛒 الطلبات والمشتريات'!D5:D204,"مواد مخزنية")),0) | L9: =IFERROR(COUNTIFS('🛒 الطلبات والمشتريات'!C5:C204,">="&DATE(2026,6,1),'🛒 الطلبات والمشتريات'!C5:C204,"<"&DATE(2026,6+1,1),'🛒 الطلبات والمشتريات'!D5:D204,"مواد مخزنية",'🛒 الطلبات والمشتريات'!I5:I204,"*ضمن*")/MAX(1,COUNTIFS('🛒 الطلبات والمشتريات'!C5:C204,">="&DATE(2026,6,1),'🛒 الطلبات والمشتريات'!C5:C204,"<"&DATE(2026,6+1,1),'🛒 الطلبات والمشتريات'!D5:D204,"مواد مخزنية")),0) | M9: =IFERROR(COUNTIFS('🛒 الطلبات والمشتريات'!C5:C204,">="&DATE(2026,7,1),'🛒 الطلبات والمشتريات'!C5:C204,"<"&DATE(2026,7+1,1),'🛒 الطلبات والمشتريات'!D5:D204,"مواد مخزنية",'🛒 الطلبات والمشتريات'!I5:I204,"*ضمن*")/MAX(1,COUNTIFS('🛒 الطلبات والمشتريات'!C5:C204,">="&DATE(2026,7,1),'🛒 الطلبات والمشتريات'!C5:C204,"<"&DATE(2026,7+1,1),'🛒 الطلبات والمشتريات'!D5:D204,"مواد مخزنية")),0) | N9: =IFERROR(COUNTIFS('🛒 الطلبات والمشتريات'!C5:C204,">="&DATE(2026,8,1),'🛒 الطلبات والمشتريات'!C5:C204,"<"&DATE(2026,8+1,1),'🛒 الطلبات والمشتريات'!D5:D204,"مواد مخزنية",'🛒 الطلبات والمشتريات'!I5:I204,"*ضمن*")/MAX(1,COUNTIFS('🛒 الطلبات والمشتريات'!C5:C204,">="&DATE(2026,8,1),'🛒 الطلبات والمشتريات'!C5:C204,"<"&DATE(2026,8+1,1),'🛒 الطلبات والمشتريات'!D5:D204,"مواد مخزنية")),0) | O9: =IFERROR(COUNTIFS('🛒 الطلبات والمشتريات'!C5:C204,">="&DATE(2026,9,1),'🛒 الطلبات والمشتريات'!C5:C204,"<"&DATE(2026,9+1,1),'🛒 الطلبات والمشتريات'!D5:D204,"مواد مخزنية",'🛒 الطلبات والمشتريات'!I5:I204,"*ضمن*")/MAX(1,COUNTIFS('🛒 الطلبات والمشتريات'!C5:C204,">="&DATE(2026,9,1),'🛒 الطلبات والمشتريات'!C5:C204,"<"&DATE(2026,9+1,1),'🛒 الطلبات والمشتريات'!D5:D204,"مواد مخزنية")),0) | P9: =IFERROR(COUNTIFS('🛒 الطلبات والمشتريات'!C5:C204,">="&DATE(2026,10,1),'🛒 الطلبات والمشتريات'!C5:C204,"<"&DATE(2026,10+1,1),'🛒 الطلبات والمشتريات'!D5:D204,"مواد مخزنية",'🛒 الطلبات والمشتريات'!I5:I204,"*ضمن*")/MAX(1,COUNTIFS('🛒 الطلبات والمشتريات'!C5:C204,">="&DATE(2026,10,1),'🛒 الطلبات والمشتريات'!C5:C204,"<"&DATE(2026,10+1,1),'🛒 الطلبات والمشتريات'!D5:D204,"مواد مخزنية")),0) | Q9: =IFERROR(COUNTIFS('🛒 الطلبات والمشتريات'!C5:C204,">="&DATE(2026,11,1),'🛒 الطلبات والمشتريات'!C5:C204,"<"&DATE(2026,11+1,1),'🛒 الطلبات والمشتريات'!D5:D204,"مواد مخزنية",'🛒 الطلبات والمشتريات'!I5:I204,"*ضمن*")/MAX(1,COUNTIFS('🛒 الطلبات والمشتريات'!C5:C204,">="&DATE(2026,11,1),'🛒 الطلبات والمشتريات'!C5:C204,"<"&DATE(2026,11+1,1),'🛒 الطلبات والمشتريات'!D5:D204,"مواد مخزنية")),0) | R9: =IFERROR(COUNTIFS('🛒 الطلبات والمشتريات'!C5:C204,">="&DATE(2026,12,1),'🛒 الطلبات والمشتريات'!C5:C204,"<"&DATE(2026,12+1,1),'🛒 الطلبات والمشتريات'!D5:D204,"مواد مخزنية",'🛒 الطلبات والمشتريات'!I5:I204,"*ضمن*")/MAX(1,COUNTIFS('🛒 الطلبات والمشتريات'!C5:C204,">="&DATE(2026,12,1),'🛒 الطلبات والمشتريات'!C5:C204,"<"&DATE(2026,12+1,1),'🛒 الطلبات والمشتريات'!D5:D204,"مواد مخزنية")),0)
A10: 3 | B10: إصدار أوامر الشراء (≤ 5 أيام عمل) | C10: % | D10: ≥ 95% | E10: خطة | G10: 0.95 | H10: 0.95 | I10: 0.95 | J10: 0.95 | K10: 0.95 | L10: 0.95 | M10: 0.95 | N10: 0.95 | O10: 0.95 | P10: 0.95 | Q10: 0.95 | R10: 0.95
E11: فعلي | F11: =IFERROR(IF(AVERAGE(G10:R10)=0,"",IF(IFERROR(AVERAGEIF(G11:R11,">0",G11:R11),0)>=AVERAGE(G10:R10),"✅ ",IF(IFERROR(AVERAGEIF(G11:R11,">0",G11:R11),0)>=AVERAGE(G10:R10)*0.85,"🟡 ","🔴 "))&TEXT((IFERROR(AVERAGEIF(G11:R11,">0",G11:R11),0)-AVERAGE(G10:R10))/AVERAGE(G10:R10),"+0.0%;-0.0%")),"") | G11: =IFERROR(COUNTIFS('🛒 الطلبات والمشتريات'!C5:C204,">="&DATE(2026,1,1),'🛒 الطلبات والمشتريات'!C5:C204,"<"&DATE(2026,1+1,1),'🛒 الطلبات والمشتريات'!D5:D204,"أمر شراء",'🛒 الطلبات والمشتريات'!I5:I204,"*ضمن*")/MAX(1,COUNTIFS('🛒 الطلبات والمشتريات'!C5:C204,">="&DATE(2026,1,1),'🛒 الطلبات والمشتريات'!C5:C204,"<"&DATE(2026,1+1,1),'🛒 الطلبات والمشتريات'!D5:D204,"أمر شراء")),0) | H11: =IFERROR(COUNTIFS('🛒 الطلبات والمشتريات'!C5:C204,">="&DATE(2026,2,1),'🛒 الطلبات والمشتريات'!C5:C204,"<"&DATE(2026,2+1,1),'🛒 الطلبات والمشتريات'!D5:D204,"أمر شراء",'🛒 الطلبات والمشتريات'!I5:I204,"*ضمن*")/MAX(1,COUNTIFS('🛒 الطلبات والمشتريات'!C5:C204,">="&DATE(2026,2,1),'🛒 الطلبات والمشتريات'!C5:C204,"<"&DATE(2026,2+1,1),'🛒 الطلبات والمشتريات'!D5:D204,"أمر شراء")),0) | I11: =IFERROR(COUNTIFS('🛒 الطلبات والمشتريات'!C5:C204,">="&DATE(2026,3,1),'🛒 الطلبات والمشتريات'!C5:C204,"<"&DATE(2026,3+1,1),'🛒 الطلبات والمشتريات'!D5:D204,"أمر شراء",'🛒 الطلبات والمشتريات'!I5:I204,"*ضمن*")/MAX(1,COUNTIFS('🛒 الطلبات والمشتريات'!C5:C204,">="&DATE(2026,3,1),'🛒 الطلبات والمشتريات'!C5:C204,"<"&DATE(2026,3+1,1),'🛒 الطلبات والمشتريات'!D5:D204,"أمر شراء")),0) | J11: =IFERROR(COUNTIFS('🛒 الطلبات والمشتريات'!C5:C204,">="&DATE(2026,4,1),'🛒 الطلبات والمشتريات'!C5:C204,"<"&DATE(2026,4+1,1),'🛒 الطلبات والمشتريات'!D5:D204,"أمر شراء",'🛒 الطلبات والمشتريات'!I5:I204,"*ضمن*")/MAX(1,COUNTIFS('🛒 الطلبات والمشتريات'!C5:C204,">="&DATE(2026,4,1),'🛒 الطلبات والمشتريات'!C5:C204,"<"&DATE(2026,4+1,1),'🛒 الطلبات والمشتريات'!D5:D204,"أمر شراء")),0) | K11: =IFERROR(COUNTIFS('🛒 الطلبات والمشتريات'!C5:C204,">="&DATE(2026,5,1),'🛒 الطلبات والمشتريات'!C5:C204,"<"&DATE(2026,5+1,1),'🛒 الطلبات والمشتريات'!D5:D204,"أمر شراء",'🛒 الطلبات والمشتريات'!I5:I204,"*ضمن*")/MAX(1,COUNTIFS('🛒 الطلبات والمشتريات'!C5:C204,">="&DATE(2026,5,1),'🛒 الطلبات والمشتريات'!C5:C204,"<"&DATE(2026,5+1,1),'🛒 الطلبات والمشتريات'!D5:D204,"أمر شراء")),0) | L11: =IFERROR(COUNTIFS('🛒 الطلبات والمشتريات'!C5:C204,">="&DATE(2026,6,1),'🛒 الطلبات والمشتريات'!C5:C204,"<"&DATE(2026,6+1,1),'🛒 الطلبات والمشتريات'!D5:D204,"أمر شراء",'🛒 الطلبات والمشتريات'!I5:I204,"*ضمن*")/MAX(1,COUNTIFS('🛒 الطلبات والمشتريات'!C5:C204,">="&DATE(2026,6,1),'🛒 الطلبات والمشتريات'!C5:C204,"<"&DATE(2026,6+1,1),'🛒 الطلبات والمشتريات'!D5:D204,"أمر شراء")),0) | M11: =IFERROR(COUNTIFS('🛒 الطلبات والمشتريات'!C5:C204,">="&DATE(2026,7,1),'🛒 الطلبات والمشتريات'!C5:C204,"<"&DATE(2026,7+1,1),'🛒 الطلبات والمشتريات'!D5:D204,"أمر شراء",'🛒 الطلبات والمشتريات'!I5:I204,"*ضمن*")/MAX(1,COUNTIFS('🛒 الطلبات والمشتريات'!C5:C204,">="&DATE(2026,7,1),'🛒 الطلبات والمشتريات'!C5:C204,"<"&DATE(2026,7+1,1),'🛒 الطلبات والمشتريات'!D5:D204,"أمر شراء")),0) | N11: =IFERROR(COUNTIFS('🛒 الطلبات والمشتريات'!C5:C204,">="&DATE(2026,8,1),'🛒 الطلبات والمشتريات'!C5:C204,"<"&DATE(2026,8+1,1),'🛒 الطلبات والمشتريات'!D5:D204,"أمر شراء",'🛒 الطلبات والمشتريات'!I5:I204,"*ضمن*")/MAX(1,COUNTIFS('🛒 الطلبات والمشتريات'!C5:C204,">="&DATE(2026,8,1),'🛒 الطلبات والمشتريات'!C5:C204,"<"&DATE(2026,8+1,1),'🛒 الطلبات والمشتريات'!D5:D204,"أمر شراء")),0) | O11: =IFERROR(COUNTIFS('🛒 الطلبات والمشتريات'!C5:C204,">="&DATE(2026,9,1),'🛒 الطلبات والمشتريات'!C5:C204,"<"&DATE(2026,9+1,1),'🛒 الطلبات والمشتريات'!D5:D204,"أمر شراء",'🛒 الطلبات والمشتريات'!I5:I204,"*ضمن*")/MAX(1,COUNTIFS('🛒 الطلبات والمشتريات'!C5:C204,">="&DATE(2026,9,1),'🛒 الطلبات والمشتريات'!C5:C204,"<"&DATE(2026,9+1,1),'🛒 الطلبات والمشتريات'!D5:D204,"أمر شراء")),0) | P11: =IFERROR(COUNTIFS('🛒 الطلبات والمشتريات'!C5:C204,">="&DATE(2026,10,1),'🛒 الطلبات والمشتريات'!C5:C204,"<"&DATE(2026,10+1,1),'🛒 الطلبات والمشتريات'!D5:D204,"أمر شراء",'🛒 الطلبات والمشتريات'!I5:I204,"*ضمن*")/MAX(1,COUNTIFS('🛒 الطلبات والمشتريات'!C5:C204,">="&DATE(2026,10,1),'🛒 الطلبات والمشتريات'!C5:C204,"<"&DATE(2026,10+1,1),'🛒 الطلبات والمشتريات'!D5:D204,"أمر شراء")),0) | Q11: =IFERROR(COUNTIFS('🛒 الطلبات والمشتريات'!C5:C204,">="&DATE(2026,11,1),'🛒 الطلبات والمشتريات'!C5:C204,"<"&DATE(2026,11+1,1),'🛒 الطلبات والمشتريات'!D5:D204,"أمر شراء",'🛒 الطلبات والمشتريات'!I5:I204,"*ضمن*")/MAX(1,COUNTIFS('🛒 الطلبات والمشتريات'!C5:C204,">="&DATE(2026,11,1),'🛒 الطلبات والمشتريات'!C5:C204,"<"&DATE(2026,11+1,1),'🛒 الطلبات والمشتريات'!D5:D204,"أمر شراء")),0) | R11: =IFERROR(COUNTIFS('🛒 الطلبات والمشتريات'!C5:C204,">="&DATE(2026,12,1),'🛒 الطلبات والمشتريات'!C5:C204,"<"&DATE(2026,12+1,1),'🛒 الطلبات والمشتريات'!D5:D204,"أمر شراء",'🛒 الطلبات والمشتريات'!I5:I204,"*ضمن*")/MAX(1,COUNTIFS('🛒 الطلبات والمشتريات'!C5:C204,">="&DATE(2026,12,1),'🛒 الطلبات والمشتريات'!C5:C204,"<"&DATE(2026,12+1,1),'🛒 الطلبات والمشتريات'!D5:D204,"أمر شراء")),0)
A12: ◀ 💰 التكاليف
A13: 4 | B13: فواقد الوقود لكل 33K لتر | C13: لتر | D13: ≤ 100 | E13: خطة | G13: 100 | H13: 100 | I13: 100 | J13: 100 | K13: 100 | L13: 100 | M13: 100 | N13: 100 | O13: 100 | P13: 100 | Q13: 100 | R13: 100
E14: فعلي | F14: =IFERROR(IF(AVERAGE(G13:R13)=0,"",IF(IFERROR(AVERAGEIF(G14:R14,">0",G14:R14),0)<=AVERAGE(G13:R13),"✅ ",IF(IFERROR(AVERAGEIF(G14:R14,">0",G14:R14),0)<=AVERAGE(G13:R13)*1.3,"🟡 ","🔴 "))&TEXT((IFERROR(AVERAGEIF(G14:R14,">0",G14:R14),0)-AVERAGE(G13:R13))/AVERAGE(G13:R13),"+0.0%;-0.0%")),"") | G14: =IFERROR(SUMIFS('💧 الردود والفاقد'!G5:G304,'💧 الردود والفاقد'!B5:B304,">="&DATE(2026,1,1),'💧 الردود والفاقد'!B5:B304,"<"&DATE(2026,1+1,1))/COUNTIFS('💧 الردود والفاقد'!B5:B304,">="&DATE(2026,1,1),'💧 الردود والفاقد'!B5:B304,"<"&DATE(2026,1+1,1)),0) | H14: =IFERROR(SUMIFS('💧 الردود والفاقد'!G5:G304,'💧 الردود والفاقد'!B5:B304,">="&DATE(2026,2,1),'💧 الردود والفاقد'!B5:B304,"<"&DATE(2026,2+1,1))/COUNTIFS('💧 الردود والفاقد'!B5:B304,">="&DATE(2026,2,1),'💧 الردود والفاقد'!B5:B304,"<"&DATE(2026,2+1,1)),0) | I14: =IFERROR(SUMIFS('💧 الردود والفاقد'!G5:G304,'💧 الردود والفاقد'!B5:B304,">="&DATE(2026,3,1),'💧 الردود والفاقد'!B5:B304,"<"&DATE(2026,3+1,1))/COUNTIFS('💧 الردود والفاقد'!B5:B304,">="&DATE(2026,3,1),'💧 الردود والفاقد'!B5:B304,"<"&DATE(2026,3+1,1)),0) | J14: =IFERROR(SUMIFS('💧 الردود والفاقد'!G5:G304,'💧 الردود والفاقد'!B5:B304,">="&DATE(2026,4,1),'💧 الردود والفاقد'!B5:B304,"<"&DATE(2026,4+1,1))/COUNTIFS('💧 الردود والفاقد'!B5:B304,">="&DATE(2026,4,1),'💧 الردود والفاقد'!B5:B304,"<"&DATE(2026,4+1,1)),0) | K14: =IFERROR(SUMIFS('💧 الردود والفاقد'!G5:G304,'💧 الردود والفاقد'!B5:B304,">="&DATE(2026,5,1),'💧 الردود والفاقد'!B5:B304,"<"&DATE(2026,5+1,1))/COUNTIFS('💧 الردود والفاقد'!B5:B304,">="&DATE(2026,5,1),'💧 الردود والفاقد'!B5:B304,"<"&DATE(2026,5+1,1)),0) | L14: =IFERROR(SUMIFS('💧 الردود والفاقد'!G5:G304,'💧 الردود والفاقد'!B5:B304,">="&DATE(2026,6,1),'💧 الردود والفاقد'!B5:B304,"<"&DATE(2026,6+1,1))/COUNTIFS('💧 الردود والفاقد'!B5:B304,">="&DATE(2026,6,1),'💧 الردود والفاقد'!B5:B304,"<"&DATE(2026,6+1,1)),0) | M14: =IFERROR(SUMIFS('💧 الردود والفاقد'!G5:G304,'💧 الردود والفاقد'!B5:B304,">="&DATE(2026,7,1),'💧 الردود والفاقد'!B5:B304,"<"&DATE(2026,7+1,1))/COUNTIFS('💧 الردود والفاقد'!B5:B304,">="&DATE(2026,7,1),'💧 الردود والفاقد'!B5:B304,"<"&DATE(2026,7+1,1)),0) | N14: =IFERROR(SUMIFS('💧 الردود والفاقد'!G5:G304,'💧 الردود والفاقد'!B5:B304,">="&DATE(2026,8,1),'💧 الردود والفاقد'!B5:B304,"<"&DATE(2026,8+1,1))/COUNTIFS('💧 الردود والفاقد'!B5:B304,">="&DATE(2026,8,1),'💧 الردود والفاقد'!B5:B304,"<"&DATE(2026,8+1,1)),0) | O14: =IFERROR(SUMIFS('💧 الردود والفاقد'!G5:G304,'💧 الردود والفاقد'!B5:B304,">="&DATE(2026,9,1),'💧 الردود والفاقد'!B5:B304,"<"&DATE(2026,9+1,1))/COUNTIFS('💧 الردود والفاقد'!B5:B304,">="&DATE(2026,9,1),'💧 الردود والفاقد'!B5:B304,"<"&DATE(2026,9+1,1)),0) | P14: =IFERROR(SUMIFS('💧 الردود والفاقد'!G5:G304,'💧 الردود والفاقد'!B5:B304,">="&DATE(2026,10,1),'💧 الردود والفاقد'!B5:B304,"<"&DATE(2026,10+1,1))/COUNTIFS('💧 الردود والفاقد'!B5:B304,">="&DATE(2026,10,1),'💧 الردود والفاقد'!B5:B304,"<"&DATE(2026,10+1,1)),0) | Q14: =IFERROR(SUMIFS('💧 الردود والفاقد'!G5:G304,'💧 الردود والفاقد'!B5:B304,">="&DATE(2026,11,1),'💧 الردود والفاقد'!B5:B304,"<"&DATE(2026,11+1,1))/COUNTIFS('💧 الردود والفاقد'!B5:B304,">="&DATE(2026,11,1),'💧 الردود والفاقد'!B5:B304,"<"&DATE(2026,11+1,1)),0) | R14: =IFERROR(SUMIFS('💧 الردود والفاقد'!G5:G304,'💧 الردود والفاقد'!B5:B304,">="&DATE(2026,12,1),'💧 الردود والفاقد'!B5:B304,"<"&DATE(2026,12+1,1))/COUNTIFS('💧 الردود والفاقد'!B5:B304,">="&DATE(2026,12,1),'💧 الردود والفاقد'!B5:B304,"<"&DATE(2026,12+1,1)),0)
A15: 5 | B15: نسبة المواد التالفة (يدوي شهرياً) | C15: % | D15: ≤ 2% | E15: خطة | G15: 0.02 | H15: 0.02 | I15: 0.02 | J15: 0.02 | K15: 0.02 | L15: 0.02 | M15: 0.02 | N15: 0.02 | O15: 0.02 | P15: 0.02 | Q15: 0.02 | R15: 0.02
E16: فعلي | F16: =IFERROR(IF(AVERAGE(G15:R15)=0,"",IF(IFERROR(AVERAGEIF(G16:R16,">0",G16:R16),0)<=AVERAGE(G15:R15),"✅ ",IF(IFERROR(AVERAGEIF(G16:R16,">0",G16:R16),0)<=AVERAGE(G15:R15)*1.3,"🟡 ","🔴 "))&TEXT((IFERROR(AVERAGEIF(G16:R16,">0",G16:R16),0)-AVERAGE(G15:R15))/AVERAGE(G15:R15),"+0.0%;-0.0%")),"")
A17: ◀ 🏦 السيولة المالية
A18: 6 | B18: أيام مخزون الوقود (يطوي الدوران) | C18: يوم | D18: ≤ 3 | E18: خطة | G18: 3 | H18: 3 | I18: 3 | J18: 3 | K18: 3 | L18: 3 | M18: 3 | N18: 3 | O18: 3 | P18: 3 | Q18: 3 | R18: 3
