Workbook

Sheet دليل الملف
A1: القسم التجاري — درب · ملف البيانات والخطط
A2: كل الأرقام والخطط لكل منفذ. الخلايا الزرقاء = مُدخلات تُعدَّل · السوداء = معادلات محسوبة · الصفراء = تحتاج تعبئة.
A4: الورقة | B4: المحتوى | C4: المصدر
A5: بطاقات المنافذ | B5: بيانات كل محطة: الموقع، النوع، المساحة، التشغيل (مضخات/خزان/عمّال/خدمة ذاتية) | C5: سجل الأصول + خرائط جوجل
A6: شرائح العملاء | B6: لكل محطة: الشريحة، ملفها، ما تحتاجه، والعرض المقدّم لها | C6: تحليلات درب + دراسة الموقع
A7: المحيط التنافسي | B7: بطاقة السيناريو، المنافسون، الميزة، الفجوة، البراندات المقترحة | C7: خرائط جوجل — سحب فعلي
A8: وحدات التأجير | B8: كل وحدة: النوع، العدد، الخدمة، النوع الفرعي، الحالة، الإيجار، المساحة | C8: جرد المحطة
A9: مبيعات المستأجرين | B9: مبيعات كل مستأجر شهرياً + نسبة الإيجار ومبيعات/م² (معادلات) | C9: تقارير المستأجرين
A10: مبيعات الوقود | B10: مزيج المنتجات وحجم ولتر وربح كل منتج + الاتجاه الشهري | C10: لوحة تحليلات درب
A11: فرص B2B | B11: الجوار التجاري كأهداف بيع: القناة، القيمة، الحالة، الأولوية | C11: خرائط جوجل + المسح الميداني
A12: عقود الأساطيل | B12: فئات الأساطيل، آلية التعاقد، الجهات المستهدفة، الحجم والربح | C12: إدارة الشراكات
A13: المكس التسويقي | B13: ٧Ps لكل محطة + توزيع ميزانية الترويج + الحملات | C13: إدارة التسويق
A14: النموذج المالي | B14: الدخل والمصاريف لكل محطة → الصافي وتكلفة اللتر ونقطة التعادل (معادلات) | C14: المالية + التشغيل
A15: بطاقة الأداء المشتركة | B15: المؤشرات المشتركة لكل منفذ: الربح/الزيارة، حصة التطبيق، التغطية | C15: محسوبة من الأوراق أعلاه
A16: خطة التنفيذ | B16: الركائز، قواعد فضّ التعارض، والتسلسل التنفيذي ٣ مراحل | C16: استراتيجية التكامل
A18: ملاحظة | B18: الأرقام المالية (الهوامش والإيجارات والمصاريف) تقديرات نموذجية للاعتماد — تُستبدل بالأرقام المعتمدة من المالية.

Sheet بطاقات المنافذ
A1: بطاقات المنافذ
A3: الرمز | B3: اسم المحطة | C3: المدينة | D3: نمط الموقع | E3: الحجم | F3: المساحة | G3: خدمة ذاتية | H3: عدد المضخات | I3: سعة الخزان (لتر) | J3: عدد العمّال | K3: الزيارات/شهر | L3: الوصف
A4: MK007 | B4: درب — العمرة الجديدة | C4: مكة | D4: خط سفر (ممر معتمرين) | E4: كبيرة جداً | F4: 120,000 م² | G4: لا | H4: 20 | I4: 300000 | J4: 30 | K4: 127775 | L4: أكبر محطة وقود في مكة، على طريق المدينة المنورة (ممر المعتمرين) — وجهة متكاملة بأكثر من 32 علامة تجارية، الأعلى تقييماً في محيطها.
A5: MK003 | B5: درب — العوالي | C5: مكة | D5: خط سفر | E5: كبيرة | F5: 19,994 م² | G5: لا | H5: 12 | I5: 180000 | J5: 18 | K5: 106830 | L5: محطة كبيرة على خط سفر مميز في مكة (~20 ألف م²) — عملاء ركّاب أعلى إنفاقاً وحصة بنزين ٩٥ مرتفعة.
A6: MK008 | B6: درب — الحسينية | C6: مكة | D6: حي | E6: متوسطة | F6: 3,408 م² | G6: لا | H6: 6 | I6: 90000 | J6: 10 | K6: 49290 | L6: محطة حي داخل الحسينية تخدم السكان — عملاء متكرّرون، ذروة مسائية (21:00)، وغالبية بنزين ٩١.
A8: التشغيل (المضخات/الخزان/العمّال) تقديرات مبدئية — تُعتمد من سجل الأصول والموارد البشرية.

Sheet شرائح العملاء
A1: شرائح العملاء — مَن نبيع له في كل منفذ
A3: الرمز | B3: الشريحة | C3: الحصة/الوزن | D3: ملف الشريحة | E3: ما تحتاجه | F3: العرض المقدّم
A4: MK007 | B4: 🕋 معتمرون وعابرون | C4: الشريحة الأساسية | D4: قادمون على طريق المدينة (ممر المعتمرين) — فنادق وشركات معتمرين حول الموقع. | E4: تعبئة سريعة + وجبة + قهوة + مصلّى ودورات مياه. | F4: بنزين 95/91 · وجبات سريعة · خدمات معتمرين · قهوة عالمية (مقترحة).
A5: MK007 | B5: 🚌 الأساطيل | C5: ديزل 28٪ من الحجم | D5: حافلات نقل معتمرين + أساطيل توزيع (المراعي، i كومكس، ميداء). | E5: ديزل متوفر + خدمة شاحنات سريعة + عقود تزويد. | F5: عقود وقود أسطول B2B · ديزل · خدمة سريعة.
A6: MK007 | B6: 🏘️ سكان الحي | C6: تكرار يومي | D6: عائلات شابة — كثافة مدارس ورياض أطفال · 63٪ تحت الـ30. | E6: سعر تنافسي 91 + متجر + برنامج ولاء. | F6: بنزين 91 اقتصادي · تانكي · بنده.
A7: MK003 | B7: 🚗 عابرون وزوّار | C7: الشريحة الأساسية | D7: مسافرون على خط سفر مميز — إنفاق أعلى وتعبئة أكبر. | E7: تعبئة سريعة + استراحة + قهوة ووجبة. | F7: بنزين 95/91 · مطعم/كافيه عابرين · خدمة سيارات.
A8: MK003 | B8: ⭐ مفضّلو الممتاز 95 | C8: بنزين 95 = 49.8٪ | D8: عملاء سيارات أحدث / أعلى إنفاقاً. | E8: توفّر 95 دائماً + خدمة مميزة. | F8: عروض 95 · خدمة سريعة عند المضخة.
A9: MK003 | B9: 🏘️ سكان مجاورون | C9: استخدام متكرّر | D9: سكان الأحياء القريبة. | E9: سعر 91 تنافسي + سرعة + ولاء. | F9: بنزين 91 · تانكي · متجر.
A10: MK008 | B10: 🏘️ سكان الحي | C10: الشريحة الأساسية | D10: عائلات حي الحسينية — زيارات متكرّرة. | E10: سعر 91 تنافسي + احتياج يومي + سرعة. | F10: بنزين 91 · مخبز/بقالة/صيدلية · تانكي.
A11: MK008 | B11: 💰 حسّاسون للسعر | C11: بنزين 91 = 58.7٪ | D11: عملاء يوازنون السعر ويكرّرون الزيارة. | E11: أفضل سعر 91 + خدمة سريعة. | F11: تنافسية 91 · عروض تانكي.
A12: MK008 | B12: 🛒 احتياج يومي (مسائي) | C12: ذروة 21:00 | D12: متسوّقون بعد الدوام — أسر الحي. | E12: مخبز / بقالة / صيدلية / مغسلة قرب المنزل. | F12: وحدات خدمات يومية · نقاط توصيل.

Sheet المحيط التنافسي
A1: المحيط التنافسي وبطاقة السيناريو
A3: MK007 — درب — العمرة الجديدة
A4: الطريق | B4: طريق المدينة المنورة (ممر المعتمرين) — الشريان الرئيسي مكة ↔ المدينة
A5: المحطة السابقة | B5: محطة درب (فرع ثانٍ) — نفس الحي · 4.9★/755 (ننتبه للتغذية الذاتية بين الفرعين)
A6: المحطة التالية | B6: الدريس — النوارية · 3.9★/2106 (المنافس الأقوى حضوراً)
A7: كثافة المنافسة | B7: ~16 محطة في المحيط · الأبرز: الدريس (٣ فروع)، المملكة، بترومين، بروتايم، المجد
A8: الميزة التنافسية | B8: الأوسع براندات (32+ مقابل ١)، الأعلى تقييماً (4.8★)، ومسجد ومرافق كاملة على ممر المعتمرين.
A9: الفجوة | B9: غياب مرساة قهوة عالمية بحجم «تيم هورتنز» لدى المنافس.
A10: العلامات في المحطة | B10: 🍔 مطاعم: ماكدونالدز · بيتزا ريتا · صامولجي · قيس آيسكريم | ☕ مقاهي: المذاق المغربي · بوبا بيرلز · رو · جوينت | 🛒 ماركت: بنده
A11: المنافسون | B11: بترومين: تيم هورتنز (1114) | الدريس: كورس جرايند · ٣ فروع | المملكة: عصير صمدو | بروتايم: بروست الزعيم
A12: براندات مقترحة | B12: قهوة عالمية (عالية) | وجبات سريعة (عالية) | خدمات معتمرين (عالية) | مطعم عائلي (متوسطة)
A14: MK003 — درب — العوالي
A15: الطريق | B15: خط سفر مميز — مكة
A16: المحطة السابقة | B16: ⚠️ يُستكمل من الخرائط
A17: المحطة التالية | B17: ⚠️ يُستكمل من الخرائط
A18: كثافة المنافسة | B18: المحطات المجاورة تُستكمل من خرائط جوجل
A19: الميزة التنافسية | B19: موقع خط سفر مميز ومساحة كبيرة (~20 ألف م²) تتيح وحدات متعددة وخدمات عابرين.
A20: الفجوة | B20: بيانات المنافسين والوحدات الشاغرة تُستكمل بالمسح الميداني والخرائط.
A21: العلامات في المحطة | B21: ⛽ الوقود: بنزين 91 · 95 (لا ديزل تقريباً) | 🏪 الوحدات: ⚠️ جرد الوحدات والبراندات يُستكمل ميدانياً
A22: المنافسون | B22: المنافسون: ⚠️ يُستكمل من خرائط جوجل
A23: براندات مقترحة | B23: مطعم/كافيه عابرين (عالية) | خدمة سيارات (زيوت/كفرات) (عالية) | متجر سفر (متوسطة)
A25: MK008 — درب — الحسينية
A26: الطريق | B26: داخل حي الحسينية السكني
A27: المحطة السابقة | B27: ⚠️ يُستكمل من الخرائط
A28: المحطة التالية | B28: ⚠️ يُستكمل من الخرائط
A29: كثافة المنافسة | B29: محطات أحياء مجاورة — تُستكمل من خرائط جوجل
A30: الميزة التنافسية | B30: قرب من السكان وذروة مسائية (21:00) تناسب خدمات ما بعد الدوام والاحتياج اليومي.
A31: الفجوة | B31: لا حملات موثّقة بعد — فرصة عروض شراكة متجر وربطها بتانكي.
A32: العلامات في المحطة | B32: ⛽ الوقود: بنزين 91 (غالب) · 95 | 🏪 الوحدات: ⚠️ جرد الوحدات يُستكمل ميدانياً
A33: المنافسون | B33: المنافسون: ⚠️ محطات أحياء مجاورة — يُستكمل من الخرائط
A34: براندات مقترحة | B34: مخبز (عالية) | صيدلية (عالية) | بقالة/سوبرماركت (عالية) | مغسلة (متوسطة)

Sheet وحدات التأجير
A1: وحدات التأجير — مكوّنات المحطة
A3: الرمز | B3: اسم الوحدة/المستأجر | C3: نوع الوحدة | D3: العدد | E3: قسم الخدمة | F3: النوع الفرعي | G3: الحالة | H3: الإيجار/شهر | I3: المساحة م²
A4: MK007 | B4: ماكدونالدز | C4: دريف ثرو | D4: 1 | E4: مطاعم | F4: وجبات سريعة | G4: مؤجّرة | H4: 15000 | I4: 120
A5: MK007 | B5: بيتزا ريتا | C5: محل تجاري | D5: 1 | E5: مطاعم | F5: وجبات سريعة | G5: مؤجّرة | H5: 0 | I5: 0
A6: MK007 | B6: صامولجي | C6: كشك | D6: 1 | E6: مطاعم | F6: فطاير | G6: مؤجّرة | H6: 0 | I6: 0
A7: MK007 | B7: قيس آيسكريم | C7: كشك | D7: 1 | E7: آيس كريم | F7: آيسكريم | G7: مؤجّرة | H7: 0 | I7: 0
A8: MK007 | B8: المذاق المغربي | C8: محل تجاري | D8: 1 | E8: كافيهات | F8: تجاري | G8: مؤجّرة | H8: 10000 | I8: 80
A9: MK007 | B9: بوبا بيرلز | C9: كشك | D9: 1 | E9: كافيهات | F9: تجاري | G9: مؤجّرة | H9: 0 | I9: 0
A10: MK007 | B10: رو (Raw) | C10: محل تجاري | D10: 1 | E10: كافيهات | F10: قهوة مختصة | G10: مؤجّرة | H10: 9000 | I10: 60
A11: MK007 | B11: جوينت | C11: كشك | D11: 1 | E11: كافيهات | F11: قهوة مختصة | G11: مؤجّرة | H11: 0 | I11: 0
A12: MK007 | B12: بنده | C12: سوبر ماركت | D12: 1 | E12: سوبر ماركت | F12: ماركت صغير | G12: مؤجّرة | H12: 22000 | I12: 300
A13: MK007 | B13: مغسلة سيارات | C13: محل تجاري | D13: 1 | E13: مغاسل | F13: آلية | G13: مؤجّرة | H13: 0 | I13: 0
A14: MK007 | B14: تغيير زيت | C14: محل تجاري | D14: 1 | E14: زيوت | F14: خدمة شاملة | G14: مؤجّرة | H14: 0 | I14: 0
A15: MK007 | B15: صراف آلي | C15: كشك | D15: 1 | E15: صراف | F15: صراف آلي | G15: مؤجّرة | H15: 0 | I15: 0
... A23: MK008 | B23: بقالة | C23: محل تجاري | D23: 1 | E23: سوبر ماركت | F23: ماركت صغير | G23: شاغرة | H23: 0 | I23: 0
A24: الإجمالي | D24: =SUM(D4:D23) -> 21 | H24: =SUM(H4:H23) -> 56000 | I24: =SUM(I4:I23) -> 560

Sheet مبيعات المستأجرين
A1: مبيعات المستأجرين الشهرية
A2: نسبة الإيجار = الإيجار ÷ مبيعات آخر شهر (الصحّي ≤ ١٥٪) · مبيعات/م² = مبيعات آخر شهر ÷ المساحة
A4: الرمز | B4: المستأجر | C4: قسم الخدمة | D4: يناير 2026 | E4: فبراير 2026 | F4: مارس 2026 | G4: أبريل 2026 | H4: مايو 2026 | I4: يونيو 2026 | J4: الإيجار/شهر | K4: المساحة م² | L4: نسبة الإيجار | M4: مبيعات/م²
A5: MK007 | B5: ماكدونالدز | C5: مطاعم | D5: 82000 | E5: 88000 | F5: 90000 | G5: 79000 | H5: 85000 | I5: 92000 | J5: 15000 | K5: 120 | L5: =IFERROR(J5/I5,"") -> 0.16304348 | M5: =IFERROR(I5/K5,"") -> 766.66667
A6: MK007 | B6: بيتزا ريتا | C6: مطاعم | D6: 0 | E6: 0 | F6: 0 | G6: 0 | H6: 0 | I6: 0 | J6: 0 | K6: 0 | L6: =IFERROR(J6/I6,"") | M6: =IFERROR(I6/K6,"")
A7: MK007 | B7: صامولجي | C7: مطاعم | D7: 0 | E7: 0 | F7: 0 | G7: 0 | H7: 0 | I7: 0 | J7: 0 | K7: 0 | L7: =IFERROR(J7/I7,"") | M7: =IFERROR(I7/K7,"")
A8: MK007 | B8: قيس آيسكريم | C8: آيس كريم | D8: 0 | E8: 0 | F8: 0 | G8: 0 | H8: 0 | I8: 0 | J8: 0 | K8: 0 | L8: =IFERROR(J8/I8,"") | M8: =IFERROR(I8/K8,"")
A9: MK007 | B9: المذاق المغربي | C9: كافيهات | D9: 48000 | E9: 52000 | F9: 55000 | G9: 50000 | H9: 53000 | I9: 58000 | J9: 10000 | K9: 80 | L9: =IFERROR(J9/I9,"") -> 0.17241379 | M9: =IFERROR(I9/K9,"") -> 725
A10: MK007 | B10: بوبا بيرلز | C10: كافيهات | D10: 0 | E10: 0 | F10: 0 | G10: 0 | H10: 0 | I10: 0 | J10: 0 | K10: 0 | L10: =IFERROR(J10/I10,"") | M10: =IFERROR(I10/K10,"")
A11: MK007 | B11: رو (Raw) | C11: كافيهات | D11: 36000 | E11: 40000 | F11: 42000 | G11: 38000 | H11: 39000 | I11: 44000 | J11: 9000 | K11: 60 | L11: =IFERROR(J11/I11,"") -> 0.20454545 | M11: =IFERROR(I11/K11,"") -> 733.33333
A12: MK007 | B12: جوينت | C12: كافيهات | D12: 0 | E12: 0 | F12: 0 | G12: 0 | H12: 0 | I12: 0 | J12: 0 | K12: 0 | L12: =IFERROR(J12/I12,"") | M12: =IFERROR(I12/K12,"")
A13: MK007 | B13: بنده | C13: سوبر ماركت | D13: 165000 | E13: 172000 | F13: 180000 | G13: 168000 | H13: 175000 | I13: 185000 | J13: 22000 | K13: 300 | L13: =IFERROR(J13/I13,"") -> 0.11891892 | M13: =IFERROR(I13/K13,"") -> 616.66667
A14: MK007 | B14: مغسلة سيارات | C14: مغاسل | D14: 0 | E14: 0 | F14: 0 | G14: 0 | H14: 0 | I14: 0 | J14: 0 | K14: 0 | L14: =IFERROR(J14/I14,"") | M14: =IFERROR(I14/K14,"")
A15: MK007 | B15: تغيير زيت | C15: زيوت | D15: 0 | E15: 0 | F15: 0 | G15: 0 | H15: 0 | I15: 0 | J15: 0 | K15: 0 | L15: =IFERROR(J15/I15,"") | M15: =IFERROR(I15/K15,"")
A16: MK007 | B16: صراف آلي | C16: صراف | D16: 0 | E16: 0 | F16: 0 | G16: 0 | H16: 0 | I16: 0 | J16: 0 | K16: 0 | L16: =IFERROR(J16/I16,"") | M16: =IFERROR(I16/K16,"")
A17: MK007 | B17: مسجد / مصلّى | C17: أخرى | D17: 0 | E17: 0 | F17: 0 | G17: 0 | H17: 0 | I17: 0 | J17: 0 | K17: 0 | L17: =IFERROR(J17/I17,"") | M17: =IFERROR(I17/K17,"")
A18: الإجمالي | D18: =SUM(D5:D17) -> 331000 | E18: =SUM(E5:E17) -> 352000 | F18: =SUM(F5:F17) -> 367000 | G18: =SUM(G5:G17) -> 335000 | H18: =SUM(H5:H17) -> 352000 | I18: =SUM(I5:I17) -> 379000 | J18: =SUM(J5:J17) -> 56000 | K18: =SUM(K5:K17) -> 560 | L18: =IFERROR(J18/I18,"") -> 0.14775726

Sheet مبيعات الوقود
A1: مبيعات الوقود — مزيج المنتجات
A2: لتر المنتج = الحصة × إجمالي اللترات · ربح المنتج = لتر المنتج × هامش الوقود
A4: الرمز | B4: المنتج | C4: الحصة % | D4: إجمالي اللترات/شهر | E4: هامش ر.س/لتر | F4: لتر المنتج/شهر | G4: ربح المنتج/شهر
A5: MK007 | B5: بنزين 91 | C5: 0.357 | D5: 3915547 | E5: 0.15 | F5: =C5*D5 -> 1397850.3 | G5: =F5*E5 -> 209677.54
A6: MK007 | B6: بنزين 95 | C6: 0.362 | D6: 3915547 | E6: 0.15 | F6: =C6*D6 -> 1417428 | G6: =F6*E6 -> 212614.2
A7: MK007 | B7: ديزل | C7: 0.281 | D7: 3915547 | E7: 0.15 | F7: =C7*D7 -> 1100268.7 | G7: =F7*E7 -> 165040.31
A8: MK003 | B8: بنزين 91 | C8: 0.495 | D8: 2914000 | E8: 0.15 | F8: =C8*D8 -> 1442430 | G8: =F8*E8 -> 216364.5
A9: MK003 | B9: بنزين 95 | C9: 0.498 | D9: 2914000 | E9: 0.15 | F9: =C9*D9 -> 1451172 | G9: =F9*E9 -> 217675.8
A10: MK003 | B10: ديزل | C10: 0.007 | D10: 2914000 | E10: 0.15 | F10: =C10*D10 -> 20398 | G10: =F10*E10 -> 3059.7
A11: MK008 | B11: بنزين 91 | C11: 0.587 | D11: 955000 | E11: 0.15 | F11: =C11*D11 -> 560585 | G11: =F11*E11 -> 84087.75
A12: MK008 | B12: بنزين 95 | C12: 0.408 | D12: 955000 | E12: 0.15 | F12: =C12*D12 -> 389640 | G12: =F12*E12 -> 58446
A13: MK008 | B13: ديزل | C13: 0.005 | D13: 955000 | E13: 0.15 | F13: =C13*D13 -> 4775 | G13: =F13*E13 -> 716.25
A15: الاتجاه الشهري (مليون لتر)
A16: الرمز | B16: يناير 2026 | C16: فبراير 2026 | D16: مارس 2026 | E16: أبريل 2026 | F16: مايو 2026 | G16: يونيو 2026
A17: MK007 | B17: 4.25 | C17: 4.17 | D17: 4.91 | E17: 3.6 | F17: 3.13 | G17: 3.43
A18: MK003 | B18: 2.85 | C18: 2.92 | D18: 3.05 | E18: 2.88 | F18: 2.8 | G18: 2.95
A19: MK008 | B19: 0.98 | C19: 0.95 | D19: 1.02 | E19: 0.93 | F19: 0.9 | G19: 0.96

Sheet فرص B2B
A1: فرص المبيعات — الجوار التجاري (B2B)
A3: الرمز | B3: الجهة | C3: النشاط / الوصف | D3: قناة البيع | E3: القيمة ر.س/شهر | F3: الحالة | G3: الأولوية
A4: MK007 | B4: المراعي (Almarai) | C4: 🚚 أسطول توزيع — ديزل | D4: ⛽ وقود أسطول | E4: 60000 | F4: فرصة | G4: عالية
A5: MK007 | B5: ميداء لخدمات المعتمرين | C5: 🚌 أساطيل نقل معتمرين · 4.9★/109 | D5: ⛽ وقود أسطول | E5: 45000 | F5: تواصل | G5: عالية
A6: MK007 | B6: i كومكس | C6: 📦 أسطول شحن وتوصيل · 4.9★/875 | D6: ⛽ وقود أسطول | E6: 22000 | F6: فرصة | G6: متوسطة
A7: MK007 | B7: مرساة قهوة عالمية | C7: ☕ سدّ الفجوة مقابل تيم هورتنز | D7: 🏪 تأجير | E7: 28000 | F7: فرصة | G7: عالية
A8: MK007 | B8: حنيذ الغربي / مندي وبس | C8: 🍽️ مطعم شعبي · 4.4★/560 | D8: 🏪 تأجير | E8: 18000 | F8: فرصة | G8: عالية
A9: MK007 | B9: واحد تكا | C9: 🍔 وجبات سريعة · 4.9★/285 | D9: 🏪 تأجير | E9: 12000 | F9: فرصة | G9: متوسطة
A10: MK007 | B10: مجموعة ريتاج العربية | C10: 🍽️ مورد أطعمة/تموين للمستأجرين | D10: 🤝 شراكة | E10: 12000 | F10: فرصة | G10: متوسطة
A11: MK007 | B11: اجواد الكرم | C11: 🛒 سوبرماركت · 4.1★/465 | D11: 🔄 بيع متقاطع | E11: 6000 | F11: فرصة | G11: منخفضة
A12: MK007 | B12: سيارة اب (فليت مانجمنت B2B) | C12: 🚗 منصّة إدارة أساطيل — تضم مكاتب التأجير القريبة: ذيب · يلو · الغزال · حسين · المصباح (٦ مكاتب ضمن 2.3كم) | D12: ⛽ وقود أسطول | E12: 49000 | F12: فرصة | G12: عالية
A13: MK007 | B13: جوتكس للخدمات اللوجستية | C13: 🚚 لوجستيات وشحن · 4.1★/16 · 0.8كم | D13: ⛽ وقود أسطول | E13: 20000 | F13: فرصة | G13: عالية
A14: MK007 | B14: الحربي للنقل (حج وعمرة) | C14: 🚌 نقل حجاج ومعتمرين · 4.6★/42 · 3.3كم | D14: ⛽ وقود أسطول | E14: 25000 | F14: فرصة | G14: عالية
A15: MK003 | B15: مشغّل مطعم/كافيه | C15: 🍽️ عابرون وزوّار | D15: 🏪 تأجير | E15: 20000 | F15: فرصة | G15: عالية
... A22: MK008 | B22: مغسلة / نقطة توصيل | C22: 🧺 خدمة مسائية | D22: 🏪 تأجير | E22: 6000 | F22: فرصة | G22: متوسطة
A23: إجمالي خط الأنابيب | E23: =SUM(E4:E22) -> 385000
A25: المتعاقد | B25: =SUMIF(F4:F22,"متعاقد",E4:E22) -> 0
A26: فرص مفتوحة | B26: =E23-B25 -> 385000

Sheet عقود الأساطيل
A1: عقود وقود الأساطيل (B2B)
A3: الرمز | B3: فئة الأسطول | C3: المنتج | D3: آلية التعاقد | E3: الجهات المستهدفة | F3: الحجم لتر/شهر | G3: هامش ر.س/لتر | H3: ربح متوقّع/شهر | I3: الحالة
A4: MK007 | B4: 🚌 باصات الحجاج والمعتمرين | C4: ديزل | D4: عقد موسمي (حج/عمرة) + بطاقة وقود أسطول + خصم حجمي + مسار حافلات سريع + دفع آجل ٣٠ يوم | E4: ميداء للمعتمرين · شركات النقل الجماعي · مؤسسات الطوافة · نقل تضامني | F4: 90000 | G4: 0.15 | H4: =F4*G4 -> 13500 | I4: تواصل
A5: MK007 | B5: 🚚 شاحنات اللوجستيات | C5: ديزل | D5: بطاقة وقود أسطول + خصم حجمي متدرّج + عقد سنوي + دفع آجل + خدمة 24/7 ومسار شاحنات مخصّص | E5: المراعي · i كومكس · شركات الشحن والتوزيع العابرة | F5: 120000 | G5: 0.15 | H5: =F5*G5 -> 18000 | I5: فرصة
A6: MK007 | B6: 🚕 تكاسي المسافرين للمدينة | C6: بنزين 91/95 | D6: برنامج ولاء سائقين (تانكي) + بطاقة وقود للمكاتب + خصم جماعي + نقطة استراحة سائقين + ربط بالتطبيق | E6: الحربي للنقل (حج وعمرة، 3.3كم) · مكاتب الشبيكة/المعابدة · تطبيقات النقل | F6: 40000 | G6: 0.15 | H6: =F6*G6 -> 6000 | I6: فرصة
A7: MK007 | B7: 🚗 سيارة اب — فليت مانجمنت (B2B) | C7: بنزين 91/95 | D7: اتفاقية تزويد عبر منصّة إدارة الأساطيل: بطاقة وقود موحّدة لكل مركبة + فوترة مركزية شهرية + خصم حجمي على إجمالي أسطول المنصّة + تقارير استهلاك لكل مركبة + ربط رقمي (API/تطبيق) + تسعير تفضيلي مقابل توجيه التعبئة للمحطة | E7: محفظة عملاء المنصّة — شركات تأجير السيارات القريبة تدخل تحتها: ذيب · يلو · الغزال · حسين · المصباح (٦ مكاتب ضمن 2.3كم) + أساطيل الشركات | F7: 55000 | G7: 0.15 | H7: =F7*G7 -> 8250 | I7: فرصة
A8: MK003 | B8: 🚌 حافلات وعابرون | C8: ديزل | D8: بطاقة وقود + خصم حجمي + مسار سريع — يُستكمل | E8: شركات النقل العابرة على خط السفر | F8: 30000 | G8: 0.15 | H8: =F8*G8 -> 4500 | I8: فرصة
A9: MK003 | B9: 🚕 تكاسي ونقل | C9: بنزين 91/95 | D9: ولاء سائقين (تانكي) + اتفاق مع مكاتب النقل | E9: مكاتب النقل والأجرة المحلية | F9: 15000 | G9: 0.15 | H9: =F9*G9 -> 2250 | I9: فرصة
A10: MK008 | B10: 🛵 مندوبو التوصيل | C10: بنزين 91 | D10: برنامج ولاء سائقين (تانكي) + خصم جماعي + ربط بالتطبيق | E10: تطبيقات التوصيل المحلية · مطاعم الحي | F10: 8000 | G10: 0.15 | H10: =F10*G10 -> 1200 | I10: فرصة
A11: الإجمالي | F11: =SUM(F4:F10) -> 358000 | H11: =SUM(H4:H10) -> 53700

Sheet المكس التسويقي
A1: المكس التسويقي (٧Ps) — حسب نمط الموقع
A3: الرمز | B3: العنصر | C3: القرار الاستراتيجي
A4: MK007 | B4: 📦 المنتج | C4: الزيارة الكاملة: وقود (91/95/ديزل) + وجبات سريعة + قهوة عالمية (فجوة) + خدمات معتمرين + مسجد ومرافق.
A5: MK007 | B5: 🏷️ السعر | C5: الوقود مقنَّن ⇒ خصم حجمي للأساطيل · إيجار = ثابت + نسبة من مبيعات المستأجر · تانكي بدل الخصم السعري.
A6: MK007 | B6: 📍 المكان | C6: وجهة على ممر المعتمرين + مسار سريع للحافلات والشاحنات + التطبيق كمنفذ رقمي.
A7: MK007 | B7: 📣 الترويج | C7: تفعيل التطبيق عند المضخة · حملات موسمية (حج/عمرة) · حملات مشتركة مع المستأجرين (نموذج المذاق المغربي +9.5٪).
A8: MK007 | B8: 👥 الناس | C8: مندوب متكامل للأساطيل والجوار + موظف المحطة كنقطة تفعيل بحافز · خدمة متعددة اللغات (معتمرون).
A9: MK007 | B9: ⚙️ العمليات | C9: سرعة الخدمة عند ذروة 17:00 · تفعيل رقمي بخطوة واحدة · عقد أسطول (بطاقة + فوترة + تقارير).
A10: MK007 | B10: 🏛️ الدليل المادي | C10: المسجد والمرافق ودورات المياه — ميزة موثّقة في التقييمات (4.8★) · النظافة والتوجيه.
A11: MK003 | B11: 📦 المنتج | C11: استراحة عابرين: بنزين 95 (49.8٪ من المزيج) + قهوة ووجبة + خدمة سيارات (زيوت/كفرات).
A12: MK003 | B12: 🏷️ السعر | C12: الوقود مقنَّن ⇒ عروض قيمة على غير الوقود · إيجار ثابت + نسبة · تانكي للولاء.
A13: MK003 | B13: 📍 المكان | C13: خط سفر مميز ومساحة ~20 ألف م² تتيح وحدات متعددة — الوحدات الشاغرة أولوية.
A14: MK003 | B14: 📣 الترويج | C14: تفعيل التطبيق عند المضخة · عروض حول ذروة 17:00 والخميس · عروض متجر مشتركة.
... A24: MK008 | B24: 🏛️ الدليل المادي | C24: إضاءة ونظافة وأمان مسائي — عامل حاسم لعملاء الحي بعد الدوام.
A26: توزيع ميزانية الترويج
A27: الرمز | B27: البند | C27: الحصة %
A28: MK007 | B28: تفعيل التطبيق | C28: 0.5
A29: MK007 | B29: حملات مشتركة مع المستأجرين | C29: 0.2
A30: MK007 | B30: ترويج B2B مباشر | C30: 0.2
A31: MK007 | B31: الدليل المادي والهوية | C31: 0.1
B32: المجموع (يجب أن يساوي ١٠٠٪) | C32: =SUM(C28:C31) -> 1
A34: MK003 | B34: تفعيل التطبيق | C34: 0.5
A35: MK003 | B35: حملات مشتركة مع المستأجرين | C35: 0.2
A36: MK003 | B36: ترويج B2B مباشر | C36: 0.2
A37: MK003 | B37: الدليل المادي والهوية | C37: 0.1
B38: المجموع (يجب أن يساوي ١٠٠٪) | C38: =SUM(C34:C37) -> 1
A40: MK008 | B40: تفعيل التطبيق | C40: 0.5
A41: MK008 | B41: حملات مشتركة مع المستأجرين | C41: 0.2
A42: MK008 | B42: ترويج B2B مباشر | C42: 0.2
A43: MK008 | B43: الدليل المادي والهوية | C43: 0.1
B44: المجموع (يجب أن يساوي ١٠٠٪) | C44: =SUM(C40:C43) -> 1
A46: الحملات
A47: الرمز | B47: الحملة | C47: النوع | D47: المموّل | E47: التكلفة ر.س | F47: الأثر % | G47: الحالة
A48: MK007 | B48: اليوم العالمي للشاي × المذاق المغربي | C48: حملة مشتركة مع مستأجر | D48: الشريك | E48: 0 | F48: 0.095 | G48: منفّذة
A49: MK007 | B49: تفعيل التطبيق عند المضخة | C49: تحويل رقمي | D49: التسويق | E49: 40000 | F49: 0 | G49: مقترحة
A50: MK007 | B50: موسم العمرة — باقة تعبئة + وجبة | C50: باقة مجمّعة | D50: مشترك | E50: 25000 | F50: 0 | G50: مقترحة
A51: MK003 | B51: تفعيل التطبيق عند المضخة | C51: تحويل رقمي | D51: التسويق | E51: 25000 | F51: 0 | G51: مقترحة
A52: MK003 | B52: عروض ذروة 17:00 | C52: عرض توقيت | D52: مشترك | E52: 12000 | F52: 0 | G52: مقترحة
A53: MK008 | B53: تانكي — تكرار الزيارة | C53: ولاء | D53: التسويق | E53: 10000 | F53: 0 | G53: مقترحة
A54: MK008 | B54: عروض مسائية 21:00 | C54: عرض توقيت | D54: مشترك | E54: 8000 | F54: 0 | G54: مقترحة
...

Sheet النموذج المالي
A1: النموذج المالي لكل منفذ (شهرياً)
A2: المُدخلات بالأزرق · النتائج بالأسود (معادلات). عدّل أي مُدخل ليعاد الحساب.
A4: البند | B4: الوحدة | C4: MK007 درب — العمرة الجديدة | D4: MK003 درب — العوالي | E4: MK008 درب — الحسينية | F4: المحفظة
A5: ⛽ الوقود
A6: اللترات | B6: لتر/شهر | C6: 3915547 | D6: 2914000 | E6: 955000
A7: هامش الوقود | B7: ر.س/لتر | C7: 0.15 | D7: 0.15 | E7: 0.15
A8: دخل الوقود | B8: ر.س | C8: =C6*C7 -> 587332.05 | D8: =D6*D7 -> 437100 | E8: =E6*E7 -> 143250 | F8: =C8+D8+E8 -> 1167682.1
A9: 🏪 التأجير والخدمات
A10: عدد الوحدات | B10: وحدة | C10: 35 | D10: 20 | E10: 12
A11: نسبة الإشغال | B11: % | C11: 90 | D11: 70 | E11: 60
A12: متوسط الإيجار للوحدة | B12: ر.س | C12: 8000 | D12: 7000 | E12: 5000
A13: دخل المتجر/الخدمات | B13: ر.س | C13: 120000 | D13: 60000 | E13: 30000
A14: دخل التأجير | B14: ر.س | C14: =C10*C11/100*C12 -> 252000 | D14: =D10*D11/100*D12 -> 98000 | E14: =E10*E11/100*E12 -> 36000 | F14: =C14+D14+E14 -> 386000
A15: إجمالي غير الوقود | B15: ر.س | C15: =C14+C13 -> 372000 | D15: =D14+D13 -> 158000 | E15: =E14+E13 -> 66000 | F15: =C15+D15+E15 -> 596000
A16: 💸 المصاريف
A17: رواتب | B17: ر.س | C17: 120000 | D17: 90000 | E17: 60000
A18: إيجار/تشغيل | B18: ر.س | C18: 80000 | D18: 60000 | E18: 35000
A19: كهرباء وماء | B19: ر.س | C19: 40000 | D19: 30000 | E19: 20000
A20: صيانة وأخرى | B20: ر.س | C20: 40000 | D20: 25000 | E20: 15000
A21: إجمالي المصاريف | B21: ر.س | C21: =SUM(C17:C20) -> 280000 | D21: =SUM(D17:D20) -> 205000 | E21: =SUM(E17:E20) -> 130000 | F21: =C21+D21+E21 -> 615000
A22: 🏭 التشغيل
A23: عدد العمّال | B23: عامل | C23: 30 | D23: 18 | E23: 10
A24: سعة الخزان | B24: لتر | C24: 300000 | D24: 180000 | E24: 90000
A25: عدد المضخات | B25: مضخة | C25: 20 | D25: 12 | E25: 6
A26: الزيارات | B26: زيارة/شهر | C26: 127775 | D26: 106830 | E26: 49290
A27: 📊 النتائج
A28: إجمالي الدخل | B28: ر.س | C28: =C8+C15 -> 959332.05 | D28: =D8+D15 -> 595100 | E28: =E8+E15 -> 209250 | F28: =C28+D28+E28 -> 1763682.1
A29: صافي الربح/الخسارة | B29: ر.س | C29: =C28-C21 -> 679332.05 | D29: =D28-D21 -> 390100 | E29: =E28-E21 -> 79250 | F29: =C29+D29+E29 -> 1148682.1
A30: الربح لكل زيارة | B30: ر.س | C30: =IFERROR(C29/C26,"") -> 5.3166273 | D30: =IFERROR(D29/D26,"") -> 3.651596 | E30: =IFERROR(E29/E26,"") -> 1.6078312 | F30: =IFERROR(F29/(C26+D26+E26),"") -> 4.046151
A31: تكلفة التشغيل/لتر | B31: ر.س | C31: =IFERROR(C21/C6,"") -> 0.071509804 | D31: =IFERROR(D21/D6,"") -> 0.070350034 | E31: =IFERROR(E21/E6,"") -> 0.13612565
A32: تكلفة الرواتب/عامل | B32: ر.س | C32: =IFERROR(C17/C23,"") -> 4000 | D32: =IFERROR(D17/D23,"") -> 5000 | E32: =IFERROR(E17/E23,"") -> 6000
A33: تغطية غير الوقود للمصاريف | B33: % | C33: =IFERROR(C15/C21,"") -> 1.3285714 | D33: =IFERROR(D15/D21,"") -> 0.77073171 | E33: =IFERROR(E15/E21,"") -> 0.50769231
A34: أيام تغطية الخزان | B34: يوم | C34: =IFERROR(C24/(C6/30),"") -> 2.2985294 | D34: =IFERROR(D24/(D6/30),"") -> 1.8531229 | E34: =IFERROR(E24/(E6/30),"") -> 2.8272251
A35: لتر لكل مضخة | B35: لتر/شهر | C35: =IFERROR(C6/C25,"") -> 195777.35 | D35: =IFERROR(D6/D25,"") -> 242833.33 | E35: =IFERROR(E6/E25,"") -> 159166.67
A36: نقطة التعادل (لترات) | B36: لتر | C36: =IFERROR(MAX(0,C21-C15)/C7,"") -> 0 | D36: =IFERROR(MAX(0,D21-D15)/D7,"") -> 313333.33 | E36: =IFERROR(MAX(0,E21-E15)/E7,"") -> 426666.67

Sheet بطاقة الأداء المشتركة
A1: بطاقة الأداء المشتركة — المؤشرات التي تُقاس عليها الإدارات معاً
A2: القيم مرتبطة بورقة «النموذج المالي» — أي تعديل هناك ينعكس هنا تلقائياً.
A4: الرمز | B4: المنفذ | C4: الزيارات/شهر | D4: الربح/الزيارة | E4: حصة التطبيق | F4: مستهدف التطبيق | G4: تغطية غير الوقود | H4: ربح المنفذ
A5: MK007 | B5: درب — العمرة الجديدة | C5: ='النموذج المالي'!C26 -> 127775 | D5: ='النموذج المالي'!C30 -> 5.3166273 | E5: 0.006 | F5: 0.05 | G5: =IFERROR('النموذج المالي'!C15/'النموذج المالي'!C21,"") -> 1.3285714 | H5: ='النموذج المالي'!C29 -> 679332.05
A6: MK003 | B6: درب — العوالي | C6: ='النموذج المالي'!D26 -> 106830 | D6: ='النموذج المالي'!D30 -> 3.651596 | E6: 0.005 | F6: 0.05 | G6: =IFERROR('النموذج المالي'!D15/'النموذج المالي'!D21,"") -> 0.77073171 | H6: ='النموذج المالي'!D29 -> 390100
A7: MK008 | B7: درب — الحسينية | C7: ='النموذج المالي'!E26 -> 49290 | D7: ='النموذج المالي'!E30 -> 1.6078312 | E7: 0.003 | F7: 0.05 | G7: =IFERROR('النموذج المالي'!E15/'النموذج المالي'!E21,"") -> 0.50769231 | H7: ='النموذج المالي'!E29 -> 79250
B8: المحفظة | C8: =SUM(C5:C7) -> 283895 | D8: =IFERROR(H8/C8,"") -> 4.046151 | H8: =SUM(H5:H7) -> 1148682.1
A10: أثر رفع غير الوقود ١ ر.س لكل زيارة | C10: =C8 -> 283895 | D10: ر.س/شهر على مستوى المحفظة

Sheet خطة التنفيذ
A1: خطة التنفيذ — التكامل بين الإدارات
A3: الوقود يجلب الحركة · غير الوقود يصنع الربح · التطبيق يربطهما · المندوب ينفّذها
A4: وحدة القياس المشتركة: الربح لكل زيارة في كل منفذ — لأن هامش الوقود مُقنَّن ومساحة النمو في غير الوقود.
A6: الركائز الهيكلية
A7: الركيزة | B7: التفصيل
A8: مالك منفذ واحد (P&L) | B8: مسؤول عن ربح المحطة الكامل، والإدارات الأربع خدمات مشتركة تخدمه.
A9: بطاقة أداء موحّدة | B9: مؤشر الإدارة (مساءلة) + مؤشر مشترك (تكامل) على نفس البطاقة.
A10: حوافز مشتركة ٦٠/٤٠ | B10: ٦٠٪ على هدف الإدارة و٤٠٪ على ربح المنفذ المشترك.
A12: دورة النمو
A13: # | B13: المرحلة | C13: الأثر
A14: 1 | B14: 🤝 عقود الأساطيل | C14: حجم وقود مضمون + تدفّق متكرّر
A15: 2 | B15: 🏪 جاذبية الموقع | C15: إشغال وإيجار أعلى
A16: 3 | B16: ⛽ سبب زيارة إضافي | C16: وقود أكثر لكل زيارة
A17: 4 | B17: 📱 التطبيق يلتقط الهوية | C17: إعادة استهداف مُقاسة
A18: 5 | B18: 📣 تكرار الزيارة | C18: مبيعات مستأجر أعلى → إيجار أعلى
A20: قواعد فضّ التعارض
A21: التعارض | B21: القاعدة الحاكمة
A22: التسويق يريد خصماً · الوقود يحمي الهامش | B22: الخصم يُموَّل من هامش غير الوقود أو ميزانية الشريك — لا من هامش الوقود
A23: التأجير يريد أعلى إيجار · الوقود يريد جاذب حركة | B23: المستأجر يُقيَّم على (الإيجار + مساهمته في الحركة) — لا الإيجار وحده
A24: الشراكات تعد بأسعار · التشغيل يتحمّلها | B24: أي التزام سعري يمرّ باعتماد مالك المنفذ
A25: محطتان متجاورتان على نفس العميل | B25: تُدار المنطقة كمحفظة واحدة لتفادي التغذية الذاتية
A27: التسلسل التنفيذي
A28: المرحلة | B28: التركيز | C28: المبادرات | D28: المبرّر | E28: المسؤول | F28: الحالة
A29: ٠–٣ أشهر | B29: التأسيس | C29: مالك منفذ · بطاقة موحّدة · تفعيل التطبيق عند المضخة | D29: البنية التحتية للقياس
A30: ٣–٦ أشهر | B30: ملء الطاقة | C30: تغطية الوحدات الشاغرة + عقود الأساطيل | D30: أكبر مجمّعَي إيراد جاهزَين
A31: ٦–١٢ شهراً | B31: تسييل الدورة | C31: المستأجر يشتري وصولاً للتطبيق · عروض مجمّعة · تسعير بالشريحة | D31: تحويل التكامل إلى ربح
A33: الخلايا الصفراء (المسؤول/الحالة) تُعبَّأ عند الاعتماد.
