Workbook

Sheet الإطار
A1: الخطة التجارية — ثلاثة منافذ بيع
A2: الوقود (شركات · أفراد) · العقار والتأجير · الإكسسوارات
A4: # | B4: المنفذ | C4: القناة | D4: المسيطر على السوق | E4: موقعنا | F4: محور الخطة
A5: 1 | B5: الوقود | C5: أفراد | D5: كل مشغّلي المحطات — الدريس · ساسكو · أرامكو | E5: 126 محطة تحت الهوية | F5: سرعة الخدمة: تدريب العمالة · مستهدف لكل محطة · حافز لكل عامل · خفض المصاريف
A6: 2 | B6: الوقود | C6: شركات | D6: بترو آب · واعي · سيارة آب · Fleet Plus · كنترول | E6: حجم قائم بلا عقود | F6: مندوب أساطيل الحج والعمرة · خصم هللة لكل لتر · الاشتراك في كل منصة
A7: 3 | B7: العقار والتأجير | C7: وسطاء | D7: الوسطاء العقاريون — لا سلسلة مسيطرة | E7: 96 وحدة شاغرة · إشغال 25% | F7: شبكة وسطاء بعمولة · ومعيار افتتاح: مغسلة وسوبرماركت مع كل محطة
A8: 4 | B8: الإكسسوارات | C8: تجزئة | D8: أصحاب محلات التجزئة — سوق مجزّأ | E8: غير مُفعّل | F8: تأجير مساحة بيع ومساحة في التطبيق مقابل نسبة من المبيعات
B10: المبدأ
C11: • ثلاثة منافذ فقط — وكل ما عداها يخدمها أو يتبعها
C12: • الوقود قناتان مختلفتان تماماً في العميل وأداة البيع والمنافس
C13: • في العقار والإكسسوارات لا مسيطر — وهما أضعف منافذنا وأقلّها منافسة
B15: قاعدة القرار
C16: • الوحدة الشاغرة تُحسب تكلفة لا فرصة ضائعة — التمويل والإهلاك مدفوعان
C17: • فعمولة الوسيط أرخص من بقاء الوحدة شاغرة
C18: • وسعر الوقود مقنَّن — فالربح من الحجم والخدمة لا من السعر

Sheet الأداء المالي — يوليو ٢٠٢٦
A1: الأداء المالي — يناير إلى يوليو ٢٠٢٦
A2: من تقرير درب التجاري (النسخة المصححة) · ألف ريال سعودي
A4: ① قائمة الدخل التراكمية
A5: # | B5: البند | C5: الفعلي | D5: الموازنة | E5: الفرق | F5: العام الماضي | K5: ملاحظة
A6: 1 | B6: إيرادات الوقود | C6: 1173578 | D6: 1219570 | E6: -45992 | F6: 411451
A7: 2 | B7: تكلفة المبيعات | C7: -1133905 | D7: -1177404 | E7: 43499 | F7: -391474
A8: 3 | B8: هامش المساهمة — الوقود | C8: 39673 | D8: 42166 | E8: -2493 | F8: 19976
A9: 4 | B9: صافي الإيراد العقاري | C9: 31465 | D9: 33138 | E9: -1673 | F9: 24887
A10: 5 | B10: إهلاك أصول حق الاستخدام | C10: -15347 | D10: -15999 | E10: 652 | F10: -12391
A11: 6 | B11: تكلفة التمويل | C11: -15525 | D11: -14569 | E11: -956 | F11: -9828
A12: 7 | B12: هامش المساهمة — العقارات | C12: 593 | D12: 2570 | E12: -1977 | F12: 2669
A13: 8 | B13: مصاريف التشغيل | C13: -28704 | D13: -27760 | E13: -944 | F13: -13962
A14: 9 | B14: مجمل الربح | C14: 11563 | D14: 16976 | E14: -5413 | F14: 8683
A15: 10 | B15: عمومية وإدارية + بيع وتوزيع | C15: -13958 | D15: -10927 | E15: -3031 | F15: -12063
A16: 11 | B16: فوائد القروض | C16: -3043 | D16: -1653 | E16: -1390 | F16: -459
A17: 12 | B17: الزكاة | C17: -120 | D17: -110 | E17: -10 | F17: -101
A18: 13 | B18: صافي الدخل | C18: -5535 | D18: 4285 | E18: -9820 | F18: -3941
A20: ② أداء نماذج العمل — قبل التحميل المركزي وبعده
A21: # | B21: النموذج | C21: محطات | D21: لتر (مليون) | E21: الإيراد | F21: هامش الوقود | G21: هللة/لتر | H21: قبل التحميل | I21: التحميل | J21: صافي الربح | K21: القراءة
A22: 1 | B22: استثماري | C22: 6 | D22: 91.8 | E22: 174309 | F22: 10765 | G22: 11.72658 | H22: 9505 | I22: -4279 | J22: 2722 | K22: الوحيد الرابح — وأعلى هامش لكل لتر
A23: 2 | B23: إيجاري | C23: 17 | D23: 77.7 | E23: 146564 | F23: 8787 | G23: 11.30888 | H23: -1290 | I23: -4279 | J23: -7038 | K23: الخسارة من إهلاك حق الاستخدام والتمويل لا من التشغيل
A24: 3 | B24: تشغيلي | C24: 26 | D24: 141.2 | E24: 268915 | F24: 15984 | G24: 11.320113 | H24: 6864 | I24: -5135 | J24: -1869 | K24: يربح قبل التحميل ويخسر بعده
A25: 4 | B25: امتياز | C25: 92 | D25: 350.8 | E25: 583790 | F25: 4136 | G25: 1.1790194 | H25: 3296 | I25: -3424 | J25: 609 | K25: نصف اللترات وعُشر الهامش — ١٫١٨ هللة/لتر
B26: الإجمالي | C26: =SUM(C22:C25) | D26: =SUM(D22:D25) | E26: =SUM(E22:E25) | F26: =SUM(F22:F25) | G26: =IFERROR(F26*1000/(D26*1000000)*100,"") | H26: =SUM(H22:H25) | I26: =SUM(I22:I25) | J26: =SUM(J22:J25)
A28: ③ نقطة التعادل — أين تقف الشركة
B29: مجمل الربح | C29: =C14 | K29: من قائمة الدخل أعلاه
B30: التحميل المركزي | C30: =-I26 | K30: بيع وتوزيع + عمومية + فوائد محمّلة
B31: التحميل ÷ مجمل الربح | C31: =C30/C29 | K31: التحميل يتجاوز مجمل الربح — هنا أصل الخسارة
B32: المحطات النشطة | C32: 146 | K32: خطة يوليو ١٩٨ · هدف ديسمبر ٢٣٢
B33: مجمل الربح لكل محطة | C33: =C29/C32 | K33: ألف ريال / ٧ أشهر
B34: محطات التعادل المطلوبة | C34: =ROUND(C30/C33,0) | K34: عند مجمل الربح الحالي لكل محطة — الموازنة نفسها (١٩٨) كانت دون التعادل
B37: ما تقوله الأرقام
C38: • المحطات تربح +١٨٫٤ مليون قبل التحميل المركزي — والشركة تخسر (٥٫٥) بعده
C39: • الامتياز ٥٣٪ من اللترات و١٠٪ من الهامش: ١٫١٨ هللة/لتر مقابل ١١٫٣ لبقية النماذج
C40: • محطة استثمارية واحدة تعادل ٦٩ محطة امتياز في صافي الربح
C41: • الفوائد ٦٫٦ أضعاف العام الماضي وتجاوز الموازنة ٨٤٪ — أسرع بند نمواً
B43: ما يحتاج تحققاً قبل أي قرار
C44: • مفتاح توزيع العمومية غير مُفسَّر: ٦ محطات استثمارية تحمل ما تحمله ١٧ إيجارية
C45: • خسارة العقار قد تكون محاسبية لا نقدية — تمويل IFRS 16 مُقدَّم التحميل والعقود جديدة
C46: • رفع هامش الامتياز نقطة يعطي ٥٫٨ مليون، لكن هامش المُمتاز نفسه غير معروض
...

Sheet وقود · أفراد
A1: الوقود — قناة الأفراد
A2: المنافس: كل مشغّلي المحطات · السلاح: سرعة الخدمة · الأداة: مستهدف لكل محطة وحافز لكل عامل
A3: محاور الخطة الأربعة
A4: 1 | B4: تدريب العمالة | C4: الشكاوى | D4: 56% من الشكاوى عن العامل: بطء الخدمة وسلوك | E4: برنامج تدريب على زمن الخدمة والتعامل | K4: يُقاس بانخفاض الشكاوى وزمن التعبئة
A5: 2 | B5: فهم مشاكل العملاء | C5: الشكاوى + قوقل ماب | D5: 41 من 103 شكوى منشورة على قوقل ماب | E5: تصنيف أسبوعي للشكاوى وإغلاقها بإجراء لا بتنبيه | K5: من 58 شكوى: 31 انتهت بتنبيه وصفر إجراء
A6: 3 | B6: مستهدف وحافز | C6: الجدول أدناه | D6: مستهدف لكل محطة وحافز مرتبط به | E6: الحافز نسبة من هامش اللتر الإضافي | K6: يربط أجر العامل بنتيجة المحطة
A7: 4 | B7: خفض مصاريف المحطة | C7: قائمة الدخل | D7: المصاريف النقدية 0.94 هللة لكل لتر فقط | E7: المجال ضيق — الأولوية للحجم لا للخفض | K7: 88% من المصاريف إهلاك غير قابل للخفض
A9: مُدخلات النموذج
B10: سعر البيع المرجّح (ريال/لتر) | C10: 2.25
B11: هامش المساهمة لكل لتر (هللة)
B12: نسبة الحافز من الهامش الإضافي
B13: معدل النمو المستهدف للبنزين
A15: المستهدف والحافز لكل محطة
A16: # | B16: المحطة | C16: المنطقة | D16: بنزين سنوي | E16: زيارة/يوم | F16: عمال | G16: الشكاوى | H16: المستهدف | I16: الزيادة | J16: الحافز (ريال/سنة) | K16: لكل عامل شهرياً
A17: 1 | B17: العوالي | C17: مكة | D17: 35464924 | E17: 3561 | F17: 42 | H17: =IFERROR(D17*(1+$C$13),"") | I17: =IFERROR(H17-D17,"") | J17: =IFERROR(I17*$C$11/100*$C$12,"") | K17: =IFERROR(J17/F17/12,"")
A18: 2 | B18: العمرة الجديدة | C18: مكة | D18: 34063312 | E18: 4236 | F18: 32 | G18: 58 | H18: =IFERROR(D18*(1+$C$13),"") | I18: =IFERROR(H18-D18,"") | J18: =IFERROR(I18*$C$11/100*$C$12,"") | K18: =IFERROR(J18/F18/12,"")
A19: 3 | B19: عاصفة الصحراء | C19: الطائف | D19: 19648510 | E19: 2137 | F19: 19 | H19: =IFERROR(D19*(1+$C$13),"") | I19: =IFERROR(H19-D19,"") | J19: =IFERROR(I19*$C$11/100*$C$12,"") | K19: =IFERROR(J19/F19/12,"")
A20: 4 | B20: العزيزية | C20: مكة | D20: 16732843 | E20: 2359 | F20: 14 | G20: 28 | H20: =IFERROR(D20*(1+$C$13),"") | I20: =IFERROR(H20-D20,"") | J20: =IFERROR(I20*$C$11/100*$C$12,"") | K20: =IFERROR(J20/F20/12,"")
A21: 5 | B21: الشيباني | C21: الطائف | D21: 16309064 | E21: 1726 | F21: 18 | H21: =IFERROR(D21*(1+$C$13),"") | I21: =IFERROR(H21-D21,"") | J21: =IFERROR(I21*$C$11/100*$C$12,"") | K21: =IFERROR(J21/F21/12,"")
A22: 6 | B22: النسيم | C22: جدة | D22: 16280701 | E22: 2041 | F22: 20 | H22: =IFERROR(D22*(1+$C$13),"") | I22: =IFERROR(H22-D22,"") | J22: =IFERROR(I22*$C$11/100*$C$12,"") | K22: =IFERROR(J22/F22/12,"")
A23: 7 | B23: أحلى مساء | C23: الطائف | D23: 14309768 | E23: 1414 | F23: 13 | H23: =IFERROR(D23*(1+$C$13),"") | I23: =IFERROR(H23-D23,"") | J23: =IFERROR(I23*$C$11/100*$C$12,"") | K23: =IFERROR(J23/F23/12,"")
A24: 8 | B24: الحليس - طريق الجنوب | C24: الطائف | D24: 13354076 | E24: 1694 | F24: 12 | H24: =IFERROR(D24*(1+$C$13),"") | I24: =IFERROR(H24-D24,"") | J24: =IFERROR(I24*$C$11/100*$C$12,"") | K24: =IFERROR(J24/F24/12,"")
A25: 9 | B25: جنوب الطائف | C25: الطائف | D25: 13311973 | E25: 1483 | F25: 13 | H25: =IFERROR(D25*(1+$C$13),"") | I25: =IFERROR(H25-D25,"") | J25: =IFERROR(I25*$C$11/100*$C$12,"") | K25: =IFERROR(J25/F25/12,"")
A26: 10 | B26: جبل النور | C26: مكة | D26: 13248903 | E26: 1872 | F26: 10 | H26: =IFERROR(D26*(1+$C$13),"") | I26: =IFERROR(H26-D26,"") | J26: =IFERROR(I26*$C$11/100*$C$12,"") | K26: =IFERROR(J26/F26/12,"")
A27: 11 | B27: الدائري الشمالي | C27: الرياض | D27: 13247588 | E27: 1169 | F27: 10 | H27: =IFERROR(D27*(1+$C$13),"") | I27: =IFERROR(H27-D27,"") | J27: =IFERROR(I27*$C$11/100*$C$12,"") | K27: =IFERROR(J27/F27/12,"")
A28: 12 | B28: القادسية | C28: مكة | D28: 12654914 | E28: 1702 | F28: 10 | H28: =IFERROR(D28*(1+$C$13),"") | I28: =IFERROR(H28-D28,"") | J28: =IFERROR(I28*$C$11/100*$C$12,"") | K28: =IFERROR(J28/F28/12,"")
A29: 13 | B29: الدائري الثالث - الذكرى | C29: مكة | D29: 11988986 | E29: 1566 | F29: 12 | H29: =IFERROR(D29*(1+$C$13),"") | I29: =IFERROR(H29-D29,"") | J29: =IFERROR(I29*$C$11/100*$C$12,"") | K29: =IFERROR(J29/F29/12,"")
A30: 14 | B30: الصفا - أحد المسارحة | C30: جازان | D30: 11882308 | E30: 1807 | H30: =IFERROR(D30*(1+$C$13),"") | I30: =IFERROR(H30-D30,"") | J30: =IFERROR(I30*$C$11/100*$C$12,"") | K30: =IFERROR(J30/F30/12,"")
A31: 15 | B31: الحسينية | C31: مكة | D31: 11625662 | E31: 1643 | F31: 9 | H31: =IFERROR(D31*(1+$C$13),"") | I31: =IFERROR(H31-D31,"") | J31: =IFERROR(I31*$C$11/100*$C$12,"") | K31: =IFERROR(J31/F31/12,"")
A32: 16 | B32: الرصيفة | C32: مكة | D32: 11101203 | E32: 1573 | F32: 11 | H32: =IFERROR(D32*(1+$C$13),"") | I32: =IFERROR(H32-D32,"") | J32: =IFERROR(I32*$C$11/100*$C$12,"") | K32: =IFERROR(J32/F32/12,"")
A33: 17 | B33: طريق الليث - الفضيلة | C33: جدة | D33: 10864480 | E33: 1892 | H33: =IFERROR(D33*(1+$C$13),"") | I33: =IFERROR(H33-D33,"") | J33: =IFERROR(I33*$C$11/100*$C$12,"") | K33: =IFERROR(J33/F33/12,"")
A34: 18 | B34: عرفات الشوقية | C34: مكة | D34: 9931491 | E34: 1290 | F34: 9 | G34: 8 | H34: =IFERROR(D34*(1+$C$13),"") | I34: =IFERROR(H34-D34,"") | J34: =IFERROR(I34*$C$11/100*$C$12,"") | K34: =IFERROR(J34/F34/12,"")
A35: 19 | B35: ممشى الشوقية | C35: مكة | D35: 9558604 | E35: 1363 | F35: 9 | H35: =IFERROR(D35*(1+$C$13),"") | I35: =IFERROR(H35-D35,"") | J35: =IFERROR(I35*$C$11/100*$C$12,"") | K35: =IFERROR(J35/F35/12,"")
A36: 20 | B36: السواط - شهار | C36: الطائف | D36: 9064151 | E36: 1144 | F36: 9 | H36: =IFERROR(D36*(1+$C$13),"") | I36: =IFERROR(H36-D36,"") | J36: =IFERROR(I36*$C$11/100*$C$12,"") | K36: =IFERROR(J36/F36/12,"")
A37: 21 | B37: أبو وافي العمرة | C37: مكة | D37: 8548346 | E37: 1380 | F37: 13 | H37: =IFERROR(D37*(1+$C$13),"") | I37: =IFERROR(H37-D37,"") | J37: =IFERROR(I37*$C$11/100*$C$12,"") | K37: =IFERROR(J37/F37/12,"")
A38: 22 | B38: الفلاح - فلسطين | C38: جدة | D38: 7867941 | E38: 1328 | H38: =IFERROR(D38*(1+$C$13),"") | I38: =IFERROR(H38-D38,"") | J38: =IFERROR(I38*$C$11/100*$C$12,"") | K38: =IFERROR(J38/F38/12,"")
A39: 23 | B39: كورنيش جيزان | C39: جازان | D39: 7444371 | E39: 922 | F39: 8 | H39: =IFERROR(D39*(1+$C$13),"") | I39: =IFERROR(H39-D39,"") | J39: =IFERROR(I39*$C$11/100*$C$12,"") | K39: =IFERROR(J39/F39/12,"")
A40: 24 | B40: الجعرانة | C40: مكة | D40: 7193020 | E40: 1112 | F40: 9 | H40: =IFERROR(D40*(1+$C$13),"") | I40: =IFERROR(H40-D40,"") | J40: =IFERROR(I40*$C$11/100*$C$12,"") | K40: =IFERROR(J40/F40/12,"")
A41: 25 | B41: الحمرا - طريق الملك عبدالله | C41: الخرج | D41: 7191456 | E41: 864 | F41: 7 | H41: =IFERROR(D41*(1+$C$13),"") | I41: =IFERROR(H41-D41,"") | J41: =IFERROR(I41*$C$11/100*$C$12,"") | K41: =IFERROR(J41/F41/12,"")
A42: 26 | B42: المعيصم | C42: مكة | D42: 6999984 | E42: 913 | F42: 7 | G42: 3 | H42: =IFERROR(D42*(1+$C$13),"") | I42: =IFERROR(H42-D42,"") | J42: =IFERROR(I42*$C$11/100*$C$12,"") | K42: =IFERROR(J42/F42/12,"")
...

Sheet المنافسون
A1: المنافسون حسب المنفذ
A2: من يسيطر · وبماذا · وردّنا — مع الشاهد الميداني
A3: # | B3: المنافس | C3: المنفذ والقناة | D3: الحجم | E3: مصدر السيطرة | F3: الردّ | G3: شاهد ميداني — خمس محطات مكة
A4: 1 | B4: الدريس | C4: وقود · أفراد | D4: ١٬٣٨٣ محطة · ١٨٫٩٥٪ | E4: الانتشار وسرعة ضمّ المستقلين | F4: المنافسة على الخدمة والربح لكل زيارة لا على السعر | G4: ٤٠٪ من أقرب المنافسين حول محطاتنا — وأقرب منافس في الفردوس (٤١١ م) والشرايع (٤٨٨ م)
A5: 2 | B5: ساسكو | C5: وقود · أفراد | D5: ~٦٨٣ محطة · تشمل نفط | E5: النمو بالاستحواذ · وتطبيق أفراد ناضج | F5: تحسين تجربة المحطة وربط التطبيق بالمستأجرين | G5: ساسكو ونفط مجتمعتين ١٢٪ فقط حول محطاتنا — الضغط أخف مما توحي الحصة الوطنية
A6: 3 | B6: بترو آب | C6: وقود · شركات | D6: ٥٠٠ ألف مركبة · ١٠ آلاف منشأة | E6: ملكية العلاقة مع المنشأة بلا أصول | F6: الاشتراك كنقطة قبول + التعاقد المباشر مع أساطيل الحج والعمرة
A7: 4 | B7: واعي (الدريس) | C7: وقود · شركات | D7: شبكة الدريس ١٬٣٨٣ محطة | E7: شريحة في فوهة المضخة تثبّت الأسطول | F7: خصم هللة لكل لتر يفوق ميزة الأداة التقنية
A8: 5 | B8: سيارة آب | C8: وقود · شركات | D8: ٢٬٥٠٠+ محطة قبول | E8: منصة وشبكة معاً بعد استحواذ ٢٠٢٦ | F8: شراكة قائمة — رفع أساطيلنا عليها
A9: 6 | B9: درب باي | C9: وقود · شركات | D9: مرخّصة من ساما — ١١ نوفمبر ٢٠٢٥ | E9: لا تبني شبكة قبول — تركب على شبكة Visa فتُقبل في كل محطة | F9: لا سبيل للاشتراك معها — الردّ بالتعاقد المباشر مع الأسطول قبل أن تصله | G9: تشابه اسم مع علامتنا في القناة نفسها — والقضية منظورة
A10: 7 | B10: Fleet Plus (كفرات بلس) | C10: إكسسوارات وخدمات · شركات | D10: ٥٬٠٠٠+ مزوّد خدمة | E10: أصلها خدمات سيارات ثم أضافت الوقود — تنافس على الوحدة المؤجّرة قبل اللتر | F10: شراكة لا مواجهة — عرض مغاسلنا ومراكز خدمتنا كنقاط تنفيذ ضمن شبكتها
A11: 8 | B11: الوسطاء العقاريون | C11: عقار | D11: مجزّأ — لا سلسلة مسيطرة | E11: ملكية قائمة المستأجرين الباحثين | F11: التحالف لا المنافسة — عمولة مقابل إشغال
A12: 9 | B12: محلات التجزئة | C12: إكسسوارات | D12: مجزّأ — متاجر ومعارض | E12: المخزون والخبرة وعلاقة المورّد | F12: التعاقد لا المنافسة — مساحة مقابل نسبة
B14: القراءة
C15: • في قناة الأفراد المنافس مشغّل محطات — والسلاح تجربة الخدمة
C16: • في قناة الشركات المنافس منصة أو أداة — والسلاح السعر والعقد
C17: • في العقار والإكسسوارات لا مسيطر — والسلاح الشراكة لا المواجهة
B19: منافسان يحتاجان تصنيفاً مختلفاً
C20: • درب باي وحدها لا يمكن التفاوض معها — لا تحتاج شبكتنا لأنها تُقبل عبر Visa
C21: • Fleet Plus أصلها خدمات سيارات لا وقود — فالأولى شراكتها على الوحدات المؤجّرة

Sheet السيطرة الميدانية
A1: السيطرة الميدانية — من يسيطر فعلاً حول محطاتنا
A2: قياس القرب من خرائط جوجل (يوليو ٢٠٢٦) — خمس محطات مكة محل الدراسة
A3: ① العلامات المنافسة حول محطاتنا — من عيّنة أقرب المحطات
A4: # | B4: العلامة | C4: مرات | D4: الحصة | E4: أقرب مسافة | F4: متوسط المسافة | K4: الدلالة
A5: 1 | B5: الدريس | C5: 16 | D5: 0.4 | E5: 411 | F5: 1810 | K5: أقرب منافس في محطتين من خمس — الانتشار ليس دعوى سوقية بل واقع مقيس
A6: 2 | B6: مستقلة/أخرى | C6: 13 | D6: 0.325 | E6: 181 | F6: 2123 | K6: سوق مجزّأ حول محطاتنا — لا علامة واحدة تحتكر الجوار
A7: 3 | B7: بتروجين | C7: 3 | D7: 0.075 | E7: 923 | F7: 2259 | K7: حضور محدود لكنه بتقييم مرتفع — منافس على الخدمة لا على العدد
A8: 4 | B8: ساسكو | C8: 3 | D8: 0.075 | E8: 1701 | F8: 1789 | K8: حضور متفرّق وبعيد نسبياً — الضغط منها أقل مما توحي حصتها الوطنية
A9: 5 | B9: أومكو | C9: 3 | D9: 0.075 | E9: 1755 | F9: 2013 | K9: حضور هامشي بعيد
A10: 6 | B10: نفط | C10: 2 | D10: 0.05 | E10: 695 | F10: 1038 | K10: تابعة لساسكو — تُحسب ضمن ثقلها الفعلي
B11: ساسكو ونفط علامة واحدة بعد الاستحواذ: 5 مرة (12٪) — وتبقى دون نصف حضور الدريس
B12: العيّنة 40 محطة (أقرب ١٠ لكل محطة) من أصل 79 محطة مرصودة ضمن ٥ كم
A14: ② المنافسة حول كل محطة — القرب مقابل النمو
A15: # | B15: المحطة | C15: الكود | D15: منافسون ≤٥كم | E15: أقرب منافس | F15: مسافته | G15: تقييمنا | H15: متوسطهم | I15: الفارق | J15: النمو | K15: القراءة
A16: 1 | B16: عرفات الشوقية | C16: MK017 | D16: 6 | E16: محطة نوفل | F16: 2450 | G16: 4.9 | H16: 4.1 | I16: 0.8 | J16: 0.07 | K16: أبعد منافس وأقل كثافة — والوحيدة النامية
A17: 2 | B17: النورية | C17: MK007 | D17: 4 | E17: محطة المملكة | F17: 2194 | G17: 4.8 | H17: 4 | I17: 0.8 | J17: -0.22 | K17: جوار شبه خالٍ — تراجعها موسمي لا تنافسي، وقد تعافت
A18: 3 | B18: عرفات الشرائع | C18: MK019 | D18: 23 | E18: Aldrees | F18: 488 | G18: 4.9 | H18: 3.6 | I18: 1.3 | J18: -0.25 | K18: منافس على ٤٨٨ م يعترض العميل قبلنا — يطابق ما تأكد ميدانياً
A19: 4 | B19: الفردوس | C19: MK023 | D19: 28 | E19: Aldrees | F19: 411 | G19: 4.9 | H19: 3.6 | I19: 1.3 | J19: -0.12 | K19: أعلى كثافة في المجموعة (٢٨ محطة) ومنافس على ٤١١ م
A20: 5 | B20: المعيصم | C20: MK002 | D20: 18 | E20: محطة المعيصم | F20: 181 | G20: 4.8 | H20: 3.7 | I20: 1.1 | J20: -0.53 | K20: منافس على ١٨١ م — لكن السبب الأول تغيّر مسار الطريق لا المنافسة
A22: ③ أي علامة عند أي محطة
A23: # | B23: المحطة | C23: الدريس | D23: مستقلة/أخرى | E23: بتروجين | F23: ساسكو | G23: أومكو | H23: نفط
A24: 1 | B24: عرفات الشوقية | C24: 3 | D24: 2 | E24: 1 | F24: 0 | G24: 0 | H24: 0
A25: 2 | B25: النورية | C25: 2 | D25: 2 | E25: 0 | F25: 0 | G25: 0 | H25: 0
A26: 3 | B26: عرفات الشرائع | C26: 4 | D26: 2 | E26: 1 | F26: 1 | G26: 1 | H26: 1
A27: 4 | B27: الفردوس | C27: 4 | D27: 4 | E27: 0 | F27: 1 | G27: 1 | H27: 0
A28: 5 | B28: المعيصم | C28: 3 | D28: 3 | E28: 1 | F28: 1 | G28: 1 | H28: 1
B30: ما يغيّره القياس في دعوى السيطرة
C31: • الدريس ٤٠٪ من أقرب المنافسين حولنا — أي ضعف حصتها الوطنية (١٨.٩٥٪) تقريباً
C32: • وهي صاحبة أقرب منافس في الفردوس (٤١١ م) والشرايع (٤٨٨ م) — المحطتان الهابطتان
C33: • ساسكو حضورها حول محطاتنا أقل بكثير مما توحي حصتها الوطنية — الضغط منها أخف
C34: • ثلث الجوار مستقلات — فالسوق حولنا مجزّأ ولا تحتكره علامة واحدة
B36: ما لا يغيّره
C37: • درب أعلى تقييماً من كل منافسيها في المواقع الخمسة — الخسارة ليست في جودة الخدمة
C38: • المعيصم سببها الأول تغيّر مسار الطريق لا المنافسة — القرب عامل مساعد لا سبباً
C39: • النورية جوارها شبه خالٍ وتراجعها موسمي — لا يُقرأ ضمن ضغط المنافسة
B41: حدود هذا القياس
C42: • العيّنة أقرب ١٠ محطات لكل موقع — لا كل المرصود ضمن ٥ كم
C43: • خرائط جوجل لا ترصد كل المحطات ولا تُحدّث فوراً — الأرقام أرضية لا سقف
C44: • القرب لا يقيس الحجم — محطة قريبة صغيرة أخف أثراً من بعيدة كبيرة

Sheet وقود · شركات
A1: الوقود — قناة الشركات
A2: المنافس: بترو آب وواعي والمنصات · السلاح: مندوب أساطيل + خصم هللة + الاشتراك في كل منصة
A3: الخطة
A4: 1 | B4: تعيين مندوب أساطيل | C4: حج وعمرة أولاً | D4: حصر الشركات والمكاتب والمشغّلين | E4: قائمة أساطيل مستهدفة بأرقام مركبات | G4: الأساطيل موجودة في محطاتنا اليوم بلا عقد
A5: 2 | B5: خصم هللة لكل لتر | C5: أداة التعاقد | D5: سعر تفضيلي مقابل التزام حجم | E5: عقد سنوي بحد أدنى شهري | G5: الاقتصاديات في الجدول أدناه
A6: 3 | B6: الرفع على سيارة آب | C6: الشراكة القائمة | D6: إدراج أساطيلنا على المنصة | E6: استفادة من شبكتها 2,500 محطة | G6: شراكة قائمة — أسرع مسار
A7: 4 | B7: الاشتراك في كل منصة | C7: بترو آب · Fleet Plus | D7: نقطة قبول في شبكاتها | E7: حجم فوري مقابل عمولة | G7: 500 ألف مركبة و10 آلاف منشأة خارج شبكتنا
A9: اقتصاديات خصم الهللة
B10: هامش المساهمة قبل الخصم (هللة)
B11: الخصم الممنوح (هللة) | C11: 1
B12: اللترات المتعاقدة المستهدفة (سنوياً)
A13: # | B13: البند | C13: القيمة | G13: الدلالة
A14: 1 | B14: الهامش بعد الخصم (هللة) | C14: =C10-C11 | G14: ما يتبقى لنا لكل لتر
A15: 2 | B15: نسبة التنازل من الهامش | C15: =IFERROR(C11/C10,"") | G15: كلفة اكتساب العقد
A16: 3 | B16: هامش اللترات المتعاقدة (ريال/سنة) | C16: =C12*(C10-C11)/100 | G16: الربح من الحجم المتعاقد
A17: 4 | B17: قيمة الخصم الممنوح (ريال/سنة) | C17: =C12*C11/100 | G17: ما تنازلنا عنه
A18: 5 | B18: نقطة التعادل — لتر إضافي مطلوب | C18: =IFERROR(C12*C11/(C10-C11),"") | G18: الحجم الإضافي الذي يعوّض الخصم
A19: 6 | B19: نسبة النمو المطلوبة للتعادل | C19: =IFERROR(C11/(C10-C11),"") | G19: إن تحقق أقل منها فالخصم خاسر
A21: السوق المتاح — بصمة الأسطول في بياناتنا
A22: # | B22: المحطة | C22: حصة الديزل | D22: ديزل سنوي (لتر) | E22: لتر/زيارة | G22: القراءة
A23: 1 | B23: MK289 طريق الليث - الفضيلة | C23: 0.641 | D23: 19344811 | E23: 43.7 | G23: أرقام أسطول لا أفراد
A24: 2 | B24: MK014 خليص | C24: 0.559 | D24: 4805625 | E24: 55.7 | G24: أرقام أسطول لا أفراد
A25: 3 | B25: MK033 أبو وافي العمرة | C25: 0.458 | D25: 7210207 | E25: 31.3
A26: 4 | B26: QS055 الدائري الشرقي | C26: 0.392 | D26: 2324712 | E26: 36.9 | G26: أرقام أسطول لا أفراد
A27: 5 | B27: JA061 طريق صبيا | C27: 0.373 | D27: 2493275 | E27: 34
A28: 6 | B28: MK054 طريق السيل | C28: 0.349 | D28: 3252431 | E28: 37.5 | G28: أرقام أسطول لا أفراد
A29: 7 | B29: MK004 عاصفة الصحراء | C29: 0.344 | D29: 10303487 | E29: 38.4 | G29: أرقام أسطول لا أفراد
A30: 8 | B30: MK210 الفلاح - فلسطين | C30: 0.329 | D30: 3857753 | E30: 24.2
B32: حجم الفرصة
C33: • الديزل 109.4 مليون لتر سنوياً — وهو سوق الأساطيل المتاح داخل شبكتنا
C34: • MK289 ديزلها 64% و43.7 لتر لكل زيارة — أرقام أسطول لا أفراد
C35: • الحجم يمرّ عندنا اليوم بلا عقد — فالتعاقد تثبيت لا اكتساب
B37: لماذا المساران معاً
C38: • المندوب يصل إلى أساطيل الحج والعمرة مباشرة — عقد وبيانات وهامش كامل
C39: • والمنصات تلتقط ما لا يصله المندوب مقابل عمولة
C40: • المعيار: عمولة المنصة لكل لتر مقابل تكلفة المندوب لكل لتر — يُراجع كل ربع
B42: شرط التنفيذ
C43: • آلية ائتمان وفوترة قبل أول عقد — لا يمكن بيع الأسطول نقداً
C44: • تعريف الحد الأدنى للحجم الذي يستحق الخصم

Sheet العقار والتأجير
A1: العقار والتأجير
A2: المسيطر: الوسطاء · القاعدة: الوحدة الشاغرة تكلفة لا فرصة ضائعة
A3: الخطة
A4: 1 | B4: شبكة وسطاء وطنية | C4: الوسطاء يملكون قائمة المستأجرين | D4: عمولة مقابل إشغال | E4: التحالف لا المنافسة | G4: أرخص من بقاء الوحدة شاغرة
A5: 2 | B5: تسعير العمولة | C5: نسبة من الإيجار السنوي | D5: تُقارن بتكلفة الشغور الشهرية | E5: النموذج أدناه | G5: الحد الأعلى للعمولة = تكلفة الشغور
A6: 3 | B6: معيار افتتاح إلزامي | C6: مغسلة + سوبرماركت | D6: مع كل محطة جديدة | E6: يمنع تكرار الشغور | G6: 52 محطة تحت الإنشاء — النافذة مفتوحة الآن
A7: 4 | B7: حصر وتصنيف الشواغر | C7: 60 وحدة بلا نوع | D7: شرط لأي تسويق | E7: عمل ميداني 4–6 أسابيع | G7: ما لم يُحصر لا يُسوَّق
A9: الوحدة الشاغرة تكلفة — نموذج العمولة
B10: الإيجار السنوي المتوقع للوحدة
B11: تكلفة التمويل والإهلاك للوحدة سنوياً
B12: عمولة الوسيط (% من الإيجار السنوي)
B13: أشهر الشغور المتوقعة بلا وسيط
A14: # | B14: البند | C14: القيمة | G14: الدلالة
A15: 1 | B15: تكلفة الوحدة الشاغرة شهرياً | C15: =C11/12 | G15: تُدفع سواء أُجّرت أم لا
A16: 2 | B16: خسارة الشغور المتوقعة | C16: =C11/12*C13+C10/12*C13 | G16: التكلفة الثابتة + الإيجار الفائت
A17: 3 | B17: قيمة عمولة الوسيط | C17: =C10*C12 | G17: تُدفع مرة واحدة
A18: 4 | B18: صافي الفرق لصالح الوسيط | C18: =C16-C17 | G18: موجب يعني أن العمولة أرخص
A19: 5 | B19: الحد الأعلى المبرَّر للعمولة | C19: =IFERROR(C16/C10,"") | G19: النسبة التي تتساوى عندها العمولة مع خسارة الشغور
A21: معيار افتتاح المحطة الجديدة
A22: # | B22: النشاط | C22: الإلزام | D22: التوقيت | E22: المسؤول | G22: السبب
A23: 1 | B23: مغسلة | C23: إلزامي | D23: قبل الافتتاح | E23: التأجير | G23: تفتح نافذة مكوث 20 دقيقة وتغذّي القهوة والماركت
A24: 2 | B24: سوبرماركت | C24: إلزامي | D24: قبل الافتتاح | E24: التأجير | G24: أعلى اختراق مثبت — فريش واي في 17 محطة
A25: 3 | B25: قهوة | C25: مُوصى به | D25: قبل الافتتاح | E25: التأجير | G25: 49% اختراق حالي · يرفع سلة الزيارة
A26: 4 | B26: خدمات سيارات | C26: مُوصى به | D26: خلال سنة | E26: الشراكات | G26: أعلى سلة · 61 محطة بلا خدمة إطارات
A27: 5 | B27: صراف آلي | C27: مُوصى به | D27: خلال سنة | E27: الشراكات | G27: إيراد ثابت بلا تشغيل — البنك يركّب
A28: 6 | B28: مساحة إكسسوارات | C28: مُوصى به | D28: خلال سنة | E28: التأجير | G28: تُؤجَّر بنسبة لا بإيجار ثابت
B30: لماذا الوسطاء
C31: • الوسيط يملك قائمة المستأجرين الباحثين — ونحن لا نملكها
C32: • ووكيل الامتياز هو من يقرّر أين تفتح العلامة فرعها لا العلامة نفسها
C33: • العمولة تكلفة متغيرة تُدفع عند الإشغال فقط
B35: الحساب الحاسم
C36: • التمويل وإهلاك حق الاستخدام مدفوعان على الأرض كاملة
C37: • في العمرة يلتهمان 63% من دخل الإيجار وفي الشرايع 106%
C38: • فكل ريال إيجار إضافي يتدفّق إلى الربح شبه كاملاً
B40: النافذة
C41: • 52 محطة تحت الإنشاء — إدراج المغسلة والسوبرماركت في تصميمها الآن
C42: • التعاقد قبل الافتتاح أرخص وأسرع من ملء محطة عاملة

Sheet الإكسسوارات
A1: الإكسسوارات
A2: المسيطر: أصحاب محلات التجزئة · النموذج: مساحة بيع ومساحة في التطبيق مقابل نسبة
A3: الخطة
A4: 1 | B4: التعاقد مع محلات التجزئة | C4: لا تشغيل ذاتي | D4: المخزون والمرتجعات على الشريك | E4: التجزئة تملك الخبرة والمورّد | G4: سوق مجزّأ بلا سلسلة مسيطرة
A5: 2 | B5: تأجير مساحة البيع | C5: وحدة أو ركن | D5: داخل المحطة | E5: من الوحدات الشاغرة القائمة | G5: لا يحتاج استثماراً جديداً
A6: 3 | B6: تأجير مساحة في التطبيق | C6: واجهة بيع رقمية | D6: ظهور للمنتجات | E6: أصل رقمي نملكه | G6: يوسّع السوق خارج المحطة
A7: 4 | B7: نسبة من المبيعات | C7: بدل الإيجار الثابت | D7: أو حد أدنى مضمون + نسبة | E7: يربط عائدنا بأداء الشريك | G7: يخفض مخاطرة الشريك ويرفع سقف عائدنا
A9: نموذج التعاقد — يُعبّأ لكل شريك
A10: # | B10: الحقل | C10: القيمة | D10: الوحدة | E10: المصدر | G10: ملاحظة
A11: 1 | B11: اسم الشريك | D11: نص | E11: يدوي
A12: 2 | B12: الفئة | D12: نص | E12: يدوي
A13: 3 | B13: المحطات المشمولة | D13: عدد | E13: يدوي
A14: 4 | B14: مساحة البيع لكل محطة | D14: م² | E14: يدوي
A15: 5 | B15: مساحة التطبيق | D15: نعم / لا | E15: يدوي
A16: 6 | B16: الحد الأدنى المضمون شهرياً | D16: ريال | E16: يدوي
A17: 7 | B17: نسبة درب من المبيعات | D17: % | E17: يدوي
A18: 8 | B18: مبيعات الشريك المتوقعة شهرياً | D18: ريال | E18: يدوي
A19: 9 | B19: عائد النسبة شهرياً | C19: =IFERROR(C18*C17,"") | D19: ريال | E19: صيغة | G19: المبيعات × النسبة
A20: 10 | B20: العائد الفعلي (الأعلى بين الحد والنسبة) | C20: =IFERROR(MAX(C16,C19),"") | D20: ريال | E20: صيغة | G20: الأعلى بين الحد الأدنى وعائد النسبة
A21: 11 | B21: العائد السنوي لكل المحطات | C21: =IFERROR(C20*12*C13,"") | D21: ريال | E21: صيغة | G21: العائد الشهري × 12 × عدد المحطات
A22: 12 | B22: مدة العقد | D22: شهر | E22: يدوي
A23: 13 | B23: شرط مشاركة بيانات المبيعات | D23: نعم / لا | E23: يدوي | G23: شرط أساسي — بدونه لا يمكن التحقق من النسبة
B26: لماذا النسبة لا الإيجار الثابت
C27: • المخزون بطيء والمرتجعات عالية — والمخاطرة على الشريك
C28: • الحد الأدنى المضمون يحمي عائدنا والنسبة ترفع سقفه
C29: • شرط مشاركة بيانات المبيعات أساس العقد — بدونه لا يمكن التحقق
B31: مساحة التطبيق
C32: • أصل رقمي نملكه ولا نبيعه اليوم
C33: • تُسعَّر ضمن الحزمة مع مساحة البيع
C34: • توسّع سوق الشريك خارج المحطة وترفع قيمة التطبيق نفسه
B36: الشريحتان
C37: • سريع الدوران (زيوت · معطرات · شواحن): رفّ عند الكاشير — يبدأ فوراً
C38: • الزينة والتجهيز (تظليل · أفلام · إضاءة): وحدة مستقلة لمتخصص

Sheet تكلفة اللتر
A1: اقتصاديات اللتر
A2: أرقام محققة من قائمة الدخل — النصف الأول 2026 · الوحدة: هللة
A3: # | B3: البند | C3: MK007 العمرة | D3: MK019 الشرايع | E3: الفارق | F3: الدلالة
A4: 1 | B4: الإيراد لكل لتر | C4: 182.51 | D4: 196.77 | E4: =C4-D4 | F4: قسمة الإيراد على اللترات
A5: 2 | B5: تكلفة البضاعة | C5: -170 | D5: -180.67 | E5: =C5-D5 | F5: 93% من الإيراد — خارج سيطرتنا
A6: 3 | B6: النقل | C6: -1.89 | D6: -1.88 | E6: =C6-D6 | F6: أجرة الرحلة الفعلية 623 ريال
A7: 4 | B7: التبخّر | C7: -0.54 | D7: -0.84 | E7: =C7-D7 | F7: 0.32% من التكلفة
A8: 5 | B8: هامش مساهمة الوقود | C8: 10.07 | D8: 13.38 | E8: =C8-D8 | F8: الهدف 15 هللة
A9: 6 | B9: صافي التأجير | C9: 5.3 | D9: -2.25 | E9: =C9-D9 | F9: سالب في الشرايع
A10: 7 | B10: المصاريف التشغيلية | C10: -10.23 | D10: -7.21 | E10: =C10-D10 | F10: 88% منها إهلاك غير نقدي
A11: 8 | B11: صافي الربح | C11: 5.15 | D11: 3.87 | E11: =C11-D11 | F11: الفجوة عن الهدف 9.9 و11.1 هللة
B13: لماذا لا يمرّ الحل عبر التكلفة
C14: • المصاريف النقدية 0.94 هللة لكل لتر فقط
C15: • الإهلاك 88% من المصاريف — غير نقدي وغير قابل للخفض
C16: • فرفع الحجم 5% يعطي أضعاف ما يعطيه أي خفض ممكن
B18: الديزل يسحب الهامش
C19: • العمرة ديزلها 28% وهامشها 10.07 هللة
C20: • الشرايع بلا ديزل وهامشها 13.36 هللة
C21: • ورفع حصة البنزين رفع مباشر للهامش لا مجرد زيادة إيراد
B23: التأجير رافعة الربح
C24: • التمويل وإهلاك حق الاستخدام ثابتان ومدفوعان
C25: • يلتهمان 63% من دخل الإيجار في العمرة و106% في الشرايع
C26: • فكل إيجار إضافي ربح شبه صافٍ

Sheet تجريبي — ثلاث محطات
A1: النموذج التجريبي
A2: محطتان للوقود ومحطة للمستأجرين
A3: التصميم
A4: 1 | B4: عرفات الشوقية MK017 | C4: وقود | D4: نامية +6.9% | F4: المرجع — ماذا تفعل الناجحة
A5: 2 | B5: بن درويش MK023 | C5: وقود | D5: هابطة −12.1% | F5: الهدف — ما الذي يمكن تغييره
A6: 3 | B6: النورية MK007 | C6: مستأجرون | D6: أعلى حركة 4,236 زيارة/يوم | F6: حملات المستأجرين وقياس أثرها
A8: مقارنة محطتَي الوقود
A9: # | B9: المؤشر | C9: عرفات الشوقية | D9: بن درويش | E9: الفارق | F9: الدلالة
A10: 1 | B10: النمو | C10: +6.9% | D10: -12.1% | F10: المتغيّر المراد تفسيره
A11: 2 | B11: المنطقة والنمط | C11: مكة · حيوية | D11: مكة · حيوية | F11: متطابق
A12: 3 | B12: المزيج | C12: 51.7 / 48.3 | D12: 54.0 / 46.0 | F12: متطابق · بلا ديزل
A13: 4 | B13: طريقة الدفع | C13: نقد 100% | D13: نقد 100% | F13: صفر شبكة وصفر تطبيق
A14: 5 | B14: الزيارات يومياً | C14: 1290 | D14: 807 | E14: =C14-D14
A15: 6 | B15: اللترات يومياً | C15: 27210 | D15: 16162 | E15: =C15-D15
A16: 7 | B16: لتر لكل زيارة | C16: 21.1 | D16: 20.04 | E16: =C16-D16 | F16: سلة أكبر في عرفات
A17: 8 | B17: المضخات | C17: 9 | D17: 4 | E17: =C17-D17
A18: 9 | B18: زيارة لكل مضخة | C18: 143 | D18: 202 | E18: =C18-D18 | F18: بن درويش أزحم رغم أنها أصغر
A19: 10 | B19: العمال | C19: 9 | D19: 7 | E19: =C19-D19 | F19: مطابق للمتفق عليه
A20: 11 | B20: الشكاوى | C20: 8 | D20: 0 | E20: =C20-D20 | F20: بن درويش بلا شكاوى رغم تراجعها
B22: ما يعزله التصميم
C23: • نفس المنطقة والنمط والمزيج وطريقة الدفع
C24: • فالفارق لا يُفسَّر بالموقع ولا المنتج ولا نوع العميل
B26: ما يُقاس ميدانياً
C27: • زمن الخدمة لكل تعبئة في ساعة الذروة (21)
C28: • عدد المركبات التي تدخل ولا تعبّئ
C29: • المنافس الأقرب والمسافة إليه · وتغيّرات المسار
B31: فرصة فورية مشتركة
C32: • الدفع نقد 100% في المحطتين — تفعيل الشبكة والتطبيق يبني قاعدة تعريف من الصفر
C33: • بن درويش 4 مضخات لـ807 زيارة — أقل من نصف طاقة عرفات

Sheet تشخيص فقدان الحركة
A1: تشخيص فقدان الحركة — مكة
A2: بيانات يناير – 4 أغسطس 2026 · السبب مؤكَّد ميدانياً لكل حالة
A3: الاكتشاف: التراجع في عدد الزيارات لا في سلة العميل
A4: # | B4: المحطة | C4: زيارات يناير | D4: زيارات يونيو–يوليو | E4: التغيّر | F4: لتر/زيارة | G4: السبب المؤكَّد
A5: 1 | B5: MK002 المعيصم | C5: 2163 | D5: 601 | E5: =IFERROR(D5/C5-1,"") | F5: 20.51 ← 20.90 | G5: تغيّر مسار الطريق
A6: 2 | B6: MK019 الشرايع | C6: 830 | D6: 380 | E6: =IFERROR(D6/C6-1,"") | F6: 22.10 ← 23.15 | G6: منافس فتح قبلنا على المسار
A7: 3 | B7: MK072 العزيزية | C7: 2778 | D7: 2488 | E7: =IFERROR(D7/C7-1,"") | F7: — ← 20.29 | G7: تراجع موسمي · تعافت من يونيو
A8: 4 | B8: MK007 العمرة الجديدة | C8: 4322 | D8: 4266 | E8: =IFERROR(D8/C8-1,"") | F8: 31.72 ← 28.99 | G8: تراجع موسمي · عادت لمستوى يناير
A9: 5 | B9: MK017 عرفات الشوقية | C9: 1210 | D9: 1391 | E9: =IFERROR(D9/C9-1,"") | F9: 20.44 ← 20.84 | G9: نمو — المرجع
A11: أثر الحدثين
A12: # | B12: البند | C12: MK002 المعيصم | D12: MK019 الشرايع | E12: المجموع | G12: الدلالة
A13: 1 | B13: الزيارات المفقودة يومياً | C13: 1562 | D13: 451 | E13: =C13+D13 | F13: زيارة | G13: العميل لم يعد يمرّ
A14: 2 | B14: اللترات المفقودة سنوياً | C14: 11920000 | D14: 3810000 | E14: =C14+D14 | F14: لتر | G14: بسلة ثابتة لكل زيارة
A15: 3 | B15: الهامش المفقود سنوياً | C15: 1590000 | D15: 510000 | E15: =C15+D15 | F15: ريال | G15: بهامش 13.36 هللة لكل لتر
A17: الردّ — مختلف لكل حالة
A18: # | B18: الحالة | C18: طبيعة الفقد | D18: هل يُسترد؟ | E18: الردّ | G18: المؤشر
A19: 1 | B19: MK002 — تغيّر المسار | C19: دائم | D19: لا يُسترد بالسعر ولا بالخدمة | E19: تحويل المحطة من ممرّ إلى وجهة: مغسلة وسوبرماركت ومطعم · وإعادة تحجيم العمالة والمصاريف على الحركة الجديدة | G19: إيراد غير وقودي لكل زيارة
A20: 2 | B20: MK019 — منافس قبلنا | C20: قابل للاسترداد | D20: المنافس يعترض العميل قبل وصوله | E20: سبب للتجاوز: عرض سعري أو خدمة لا توجد عنده · ولافتات مبكرة قبل نقطة اعتراضه · وتعاقد مع الأساطيل المارّة | G20: الزيارات اليومية مقابل خط الأساس
A21: 3 | B21: عام — كل الشبكة | C21: مخاطرة قائمة | D21: اكتُشف بعد شهور من وقوعه | E21: إنذار مبكر: تنبيه آلي عند انخفاض الزيارات أسبوعياً بأكثر من 15% مقابل المتوسط · ومسح ربعي للمنافسين وأعمال الطرق | G21: زمن اكتشاف الحدث
B23: ما تثبته البيانات
C24: • سلة العميل ثابتة في كل المحطات — فالفقد في عدد العملاء لا في سلوكهم
C25: • المعيصم والشرايع سقطتا في فبراير بنسبة 60% و53% في شهر واحد
C26: • العمرة والعزيزية تراجعتا موسمياً في أبريل–مايو ثم تعافتا في يونيو–يوليو
B28: ما ينفيه
C29: • الخدمة ليست السبب — لو كانت لانخفضت السلة أو لتدرّج الأثر
C30: • المضخات ليست السبب — الطاقة لم تتغيّر والزيارات هي التي اختفت
C31: • التسعير ليس السبب — السعر مقنَّن وموحّد
B33: الدرس الأهم
C34: • حدثان خارجيان كلّفانا 2.1 مليون ريال هامش سنوياً
C35: • واكتُشفا بعد شهور — لا بنظام إنذار بل بتحليل لاحق
C36: • الأولوية: نظام تنبيه أسبوعي على مستوى المحطة قبل أي مبادرة أخرى

Sheet نموذج العامل
A1: نموذج مبيعات العامل — مستهدف وحافز
A2: خط الأساس يُشتق من حصة الوردية الفعلية من الزيارات ÷ عدد عمالها — لا يُقدَّر يدوياً
A3: ① مُدخلات المحطة — اختر المحطة والباقي يُعبَّأ من بيانات التشغيل
B4: المحطة | D4: =IFERROR("ذروة "&INDEX('بيانات الورديات'!$I$4:$I$8,MATCH($C$4,'بيانات الورديات'!$B$4:$B$8,0)),"") | E4: اختر من القائمة ▼
B5: الشهر | E5: مثال: أغسطس ٢٠٢٦
B6: لتر لكل زيارة | C6: =IFERROR(INDEX('بيانات الورديات'!$C$4:$C$8,MATCH($C$4,'بيانات الورديات'!$B$4:$B$8,0)),0) | E6: من بيانات المحطة
B7: زيارات المحطة (زيارة/يوم) | C7: =IFERROR(INDEX('بيانات الورديات'!$D$4:$D$8,MATCH($C$4,'بيانات الورديات'!$B$4:$B$8,0)),0) | E7: متوسط ٢١٢ يوماً
B8: عمال المضخات — صباحية | C8: =IFERROR(INDEX('بيانات الورديات'!$E$4:$E$8,MATCH($C$4,'بيانات الورديات'!$B$4:$B$8,0)),0) | E8: ٦ ص – ٦ م
B9: عمال المضخات — مسائية | C9: =IFERROR(INDEX('بيانات الورديات'!$F$4:$F$8,MATCH($C$4,'بيانات الورديات'!$B$4:$B$8,0)),0) | E9: ٦ م – ٦ ص
B10: حصة الصباح من الزيارات | C10: =IFERROR(INDEX('بيانات الورديات'!$G$4:$G$8,MATCH($C$4,'بيانات الورديات'!$B$4:$B$8,0)),0) | E10: من الحركة الفعلية
B11: حصة المساء من الزيارات | C11: =IFERROR(INDEX('بيانات الورديات'!$H$4:$H$8,MATCH($C$4,'بيانات الورديات'!$B$4:$B$8,0)),0) | E11: من الحركة الفعلية
B12: هامش المساهمة (هللة/لتر) | C12: =IFERROR(INDEX('بيانات الورديات'!$P$4:$P$8,MATCH($C$4,'بيانات الورديات'!$B$4:$B$8,0)),0) | E12: من تقرير يوليو ٢٠٢٦
B13: نسبة الحافز من الهامش | C13: 0.15 | E13: قرار الإدارة
B14: سقف الحافز الشهري للعامل | C14: 100 | E14: معتمد: ١٠٠ ريال
B15: أيام الشهر | C15: 30
B16: نسبة النمو المستهدف | C16: 0.05 | E16: حرّكها ← تتحرك كل المستهدفات
B17: يُشترط صافي محطة موجب | C17: نعم | E17: يحمي نسبة الـ١٥٪
A19: ② بطاقة العامل — اختر الوردية فيُشتق خط الأساس · عبّئ الفعلي وبوابة الجودة
A20: # | B20: اسم العامل | C20: الوردية | D20: خط الأساس المشتق | E20: تعديل معتمد | F20: المستهدف | G20: الفعلي | H20: الفارق | I20: نسبة الإنجاز | J20: بوابة الجودة | K20: الحافز (ريال) | L20: ملاحظة
A21: 1 | D21: =IF(OR($C21="",$C$7=0),"",ROUND(IF($C21="صباحية",$C$7*$C$10/MAX($C$8,1),$C$7*$C$11/MAX($C$9,1)),0)) | F21: =IF($D21="","",ROUND(IF($E21="",$D21,$E21)*(1+$C$16),0)) | H21: =IF(OR($G21="",$F21=""),"",$G21-$F21) | I21: =IFERROR(IF($F21="","",$G21/$F21),"") | K21: =IF(OR($H21="",$J21<>"مستوفاة"),0,IF(AND($C$17="نعم",$H$41<=0),0,MIN(MAX($H21,0)*$C$6*$C$12/100*$C$13*$C$15,$C$14)))
A22: 2 | D22: =IF(OR($C22="",$C$7=0),"",ROUND(IF($C22="صباحية",$C$7*$C$10/MAX($C$8,1),$C$7*$C$11/MAX($C$9,1)),0)) | F22: =IF($D22="","",ROUND(IF($E22="",$D22,$E22)*(1+$C$16),0)) | H22: =IF(OR($G22="",$F22=""),"",$G22-$F22) | I22: =IFERROR(IF($F22="","",$G22/$F22),"") | K22: =IF(OR($H22="",$J22<>"مستوفاة"),0,IF(AND($C$17="نعم",$H$41<=0),0,MIN(MAX($H22,0)*$C$6*$C$12/100*$C$13*$C$15,$C$14)))
A23: 3 | D23: =IF(OR($C23="",$C$7=0),"",ROUND(IF($C23="صباحية",$C$7*$C$10/MAX($C$8,1),$C$7*$C$11/MAX($C$9,1)),0)) | F23: =IF($D23="","",ROUND(IF($E23="",$D23,$E23)*(1+$C$16),0)) | H23: =IF(OR($G23="",$F23=""),"",$G23-$F23) | I23: =IFERROR(IF($F23="","",$G23/$F23),"") | K23: =IF(OR($H23="",$J23<>"مستوفاة"),0,IF(AND($C$17="نعم",$H$41<=0),0,MIN(MAX($H23,0)*$C$6*$C$12/100*$C$13*$C$15,$C$14)))
A24: 4 | D24: =IF(OR($C24="",$C$7=0),"",ROUND(IF($C24="صباحية",$C$7*$C$10/MAX($C$8,1),$C$7*$C$11/MAX($C$9,1)),0)) | F24: =IF($D24="","",ROUND(IF($E24="",$D24,$E24)*(1+$C$16),0)) | H24: =IF(OR($G24="",$F24=""),"",$G24-$F24) | I24: =IFERROR(IF($F24="","",$G24/$F24),"") | K24: =IF(OR($H24="",$J24<>"مستوفاة"),0,IF(AND($C$17="نعم",$H$41<=0),0,MIN(MAX($H24,0)*$C$6*$C$12/100*$C$13*$C$15,$C$14)))
A25: 5 | D25: =IF(OR($C25="",$C$7=0),"",ROUND(IF($C25="صباحية",$C$7*$C$10/MAX($C$8,1),$C$7*$C$11/MAX($C$9,1)),0)) | F25: =IF($D25="","",ROUND(IF($E25="",$D25,$E25)*(1+$C$16),0)) | H25: =IF(OR($G25="",$F25=""),"",$G25-$F25) | I25: =IFERROR(IF($F25="","",$G25/$F25),"") | K25: =IF(OR($H25="",$J25<>"مستوفاة"),0,IF(AND($C$17="نعم",$H$41<=0),0,MIN(MAX($H25,0)*$C$6*$C$12/100*$C$13*$C$15,$C$14)))
A26: 6 | D26: =IF(OR($C26="",$C$7=0),"",ROUND(IF($C26="صباحية",$C$7*$C$10/MAX($C$8,1),$C$7*$C$11/MAX($C$9,1)),0)) | F26: =IF($D26="","",ROUND(IF($E26="",$D26,$E26)*(1+$C$16),0)) | H26: =IF(OR($G26="",$F26=""),"",$G26-$F26) | I26: =IFERROR(IF($F26="","",$G26/$F26),"") | K26: =IF(OR($H26="",$J26<>"مستوفاة"),0,IF(AND($C$17="نعم",$H$41<=0),0,MIN(MAX($H26,0)*$C$6*$C$12/100*$C$13*$C$15,$C$14)))
A27: 7 | D27: =IF(OR($C27="",$C$7=0),"",ROUND(IF($C27="صباحية",$C$7*$C$10/MAX($C$8,1),$C$7*$C$11/MAX($C$9,1)),0)) | F27: =IF($D27="","",ROUND(IF($E27="",$D27,$E27)*(1+$C$16),0)) | H27: =IF(OR($G27="",$F27=""),"",$G27-$F27) | I27: =IFERROR(IF($F27="","",$G27/$F27),"") | K27: =IF(OR($H27="",$J27<>"مستوفاة"),0,IF(AND($C$17="نعم",$H$41<=0),0,MIN(MAX($H27,0)*$C$6*$C$12/100*$C$13*$C$15,$C$14)))
A28: 8 | D28: =IF(OR($C28="",$C$7=0),"",ROUND(IF($C28="صباحية",$C$7*$C$10/MAX($C$8,1),$C$7*$C$11/MAX($C$9,1)),0)) | F28: =IF($D28="","",ROUND(IF($E28="",$D28,$E28)*(1+$C$16),0)) | H28: =IF(OR($G28="",$F28=""),"",$G28-$F28) | I28: =IFERROR(IF($F28="","",$G28/$F28),"") | K28: =IF(OR($H28="",$J28<>"مستوفاة"),0,IF(AND($C$17="نعم",$H$41<=0),0,MIN(MAX($H28,0)*$C$6*$C$12/100*$C$13*$C$15,$C$14)))
A29: 9 | D29: =IF(OR($C29="",$C$7=0),"",ROUND(IF($C29="صباحية",$C$7*$C$10/MAX($C$8,1),$C$7*$C$11/MAX($C$9,1)),0)) | F29: =IF($D29="","",ROUND(IF($E29="",$D29,$E29)*(1+$C$16),0)) | H29: =IF(OR($G29="",$F29=""),"",$G29-$F29) | I29: =IFERROR(IF($F29="","",$G29/$F29),"") | K29: =IF(OR($H29="",$J29<>"مستوفاة"),0,IF(AND($C$17="نعم",$H$41<=0),0,MIN(MAX($H29,0)*$C$6*$C$12/100*$C$13*$C$15,$C$14)))
A30: 10 | D30: =IF(OR($C30="",$C$7=0),"",ROUND(IF($C30="صباحية",$C$7*$C$10/MAX($C$8,1),$C$7*$C$11/MAX($C$9,1)),0)) | F30: =IF($D30="","",ROUND(IF($E30="",$D30,$E30)*(1+$C$16),0)) | H30: =IF(OR($G30="",$F30=""),"",$G30-$F30) | I30: =IFERROR(IF($F30="","",$G30/$F30),"") | K30: =IF(OR($H30="",$J30<>"مستوفاة"),0,IF(AND($C$17="نعم",$H$41<=0),0,MIN(MAX($H30,0)*$C$6*$C$12/100*$C$13*$C$15,$C$14)))
A31: 11 | D31: =IF(OR($C31="",$C$7=0),"",ROUND(IF($C31="صباحية",$C$7*$C$10/MAX($C$8,1),$C$7*$C$11/MAX($C$9,1)),0)) | F31: =IF($D31="","",ROUND(IF($E31="",$D31,$E31)*(1+$C$16),0)) | H31: =IF(OR($G31="",$F31=""),"",$G31-$F31) | I31: =IFERROR(IF($F31="","",$G31/$F31),"") | K31: =IF(OR($H31="",$J31<>"مستوفاة"),0,IF(AND($C$17="نعم",$H$41<=0),0,MIN(MAX($H31,0)*$C$6*$C$12/100*$C$13*$C$15,$C$14)))
A32: 12 | D32: =IF(OR($C32="",$C$7=0),"",ROUND(IF($C32="صباحية",$C$7*$C$10/MAX($C$8,1),$C$7*$C$11/MAX($C$9,1)),0)) | F32: =IF($D32="","",ROUND(IF($E32="",$D32,$E32)*(1+$C$16),0)) | H32: =IF(OR($G32="",$F32=""),"",$G32-$F32) | I32: =IFERROR(IF($F32="","",$G32/$F32),"") | K32: =IF(OR($H32="",$J32<>"مستوفاة"),0,IF(AND($C$17="نعم",$H$41<=0),0,MIN(MAX($H32,0)*$C$6*$C$12/100*$C$13*$C$15,$C$14)))
... A40: 20 | D40: =IF(OR($C40="",$C$7=0),"",ROUND(IF($C40="صباحية",$C$7*$C$10/MAX($C$8,1),$C$7*$C$11/MAX($C$9,1)),0)) | F40: =IF($D40="","",ROUND(IF($E40="",$D40,$E40)*(1+$C$16),0)) | H40: =IF(OR($G40="",$F40=""),"",$G40-$F40) | I40: =IFERROR(IF($F40="","",$G40/$F40),"") | K40: =IF(OR($H40="",$J40<>"مستوفاة"),0,IF(AND($C$17="نعم",$H$41<=0),0,MIN(MAX($H40,0)*$C$6*$C$12/100*$C$13*$C$15,$C$14)))
B41: الإجمالي | C41: =COUNTA($B21:$B40)&" عامل" | D41: =SUM(D21:D40) | F41: =SUM(F21:F40) | G41: =SUM(G21:G40) | H41: =SUM(H21:H40) | I41: =IFERROR($G41/$F41,"") | K41: =SUM(K21:K40)
A43: ③ ملخص المحطة — يتحدّث مع كل رقم تُدخله
A44: # | B44: البند | C44: القيمة | L44: الدلالة
A45: 1 | B45: الزيادة الإجمالية (زيارة/يوم) | C45: =$H$41 | L45: مجموع فروق العمال
A46: 2 | B46: اللترات الإضافية شهرياً | C46: =$C$45*$C$6*$C$15 | L46: الزيادة × لتر/زيارة × الأيام
A47: 3 | B47: الهامش الإضافي شهرياً (ريال) | C47: =$C$46*$C$12/100 | L47: قبل خصم الحافز
A48: 4 | B48: إجمالي الحافز شهرياً (ريال) | C48: =$K$41 | L48: ما يُصرف للعمال
A49: 5 | B49: صافي المكسب للشركة (ريال) | C49: =$C$47-$C$48 | L49: الهامش ناقص الحافز
...

Sheet مطابقة الوردية مع الطلب
A1: مطابقة الوردية مع الطلب
A2: كل المحطات توزّع العمالة نصفين متساويين — بينما الطلب ليس نصفين
A3: # | B3: المحطة | C3: زيارات الصباح | D3: زيارات المساء | E3: عمال صباحاً | F3: عمال مساءً | G3: حصة العمالة مساءً | H3: الفجوة | I3: حِمل عامل الصباح | J3: حِمل عامل المساء | K3: الفارق | L3: القرار
A4: 1 | B4: النورية | C4: 2087 | D4: 2174 | E4: 11 | F4: 9 | G4: 0.45 | H4: 0.0601 | I4: 190 | J4: 242 | K4: 0.27261799 | L4: انقل 1 عامل من الصباح إلى المساء
A5: 2 | B5: عرفات الشوقية | C5: 567 | D5: 702 | E5: 3 | F5: 3 | G5: 0.5 | H5: 0.0529 | I5: 189 | J5: 234 | K5: 0.2366361 | L5: الفجوة أقل من عامل — عالجها بمواعيد الدخول لا بالعدد
A6: 3 | B6: المعيصم | C6: 429 | D6: 435 | E6: 2 | F6: 2 | G6: 0.5 | H6: 0.0036 | I6: 214 | J6: 218 | K6: 0.014504432 | L6: الفجوة أقل من عامل — عالجها بمواعيد الدخول لا بالعدد
A7: 4 | B7: الفردوس | C7: 356 | D7: 434 | E7: 2 | F7: 2 | G7: 0.5 | H7: 0.0489 | I7: 178 | J7: 217 | K7: 0.21680337 | L7: الفجوة أقل من عامل — عالجها بمواعيد الدخول لا بالعدد
A8: 5 | B8: عرفات الشرائع | C8: 194 | D8: 249 | E8: 2 | F8: 2 | G8: 0.5 | H8: 0.061 | I8: 97 | J8: 124 | K8: 0.27790433 | L8: الفجوة أقل من عامل — عالجها بمواعيد الدخول لا بالعدد
B10: ما تقوله الأرقام
C11: • عامل المساء يخدم ٢٢–٢٨٪ زيارات أكثر من عامل الصباح في أربع محطات من خمس
C12: • السبب أن العمالة موزّعة ٥٠/٥٠ بينما الطلب المسائي ٥٥–٥٦٪ من الزيارات
C13: • المعيصم وحدها متوازنة — لأن ذروتها ٥ إلى ٧ مساءً لا بعد التاسعة
B15: لماذا يهم هذا في نموذج الحافز
C16: • خط أساس موحّد لكل العمال يظلم عامل المساء ويكافئ عامل الصباح على أقل جهد
C17: • لذلك يُشتق خط الأساس من حصة الوردية الفعلية — لا من متوسط المحطة
C18: • الاشتقاق يجعل ٥٪ نمو تعني الجهد نفسه على الورديتين
B20: حدود ما يمكن تنفيذه
C21: • النورية وحدها فيها عمالة تكفي لنقل عامل كامل (٢٠ عاملاً على المضخات)
C22: • بقية المحطات فجوتها أقل من عامل — الحل تعديل مواعيد الدخول لا زيادة العدد
C23: • تكديس الورديات بين ٨ و١٠ مساءً يغطي الذروة دون تكلفة إضافية

Sheet تجربة الشرايع
A1: تجربة الشرايع MK019 — خدمة ممتازة وتوزيع مناديل
A2: المنافس يعترض العميل قبلنا · والعميل ما زال يمرّ — فالتجربة اختبار لسبب التجاوز
A3: خط الأساس
A4: # | B4: المؤشر | C4: القيمة | D4: الفترة | G4: ملاحظة
A5: 1 | B5: الزيارات يومياً | C5: 378 | D5: يونيو – 4 أغسطس | G5: يناير كان 830
A6: 2 | B6: لتر لكل زيارة | C6: 23.15 | D6: ثابت طوال الفترة | G6: السلة لم تتأثر — الفقد في العدد
A7: 3 | B7: هامش المساهمة لكل زيارة | C7: 3.09 | D7: ريال | G7: 23.15 لتر × 13.36 هللة
A8: 4 | B8: العمال | C8: 5 | D8: المتفق 6 | G8: نقص عامل واحد
A9: 5 | B9: المضخات | C9: 6 | G9: الطاقة غير مقيِّدة
A10: 6 | B10: ساعة الذروة | C10: 21 | G10: توقيت التوزيع الأمثل
A12: اقتصاديات التدخل
B13: تكلفة الوحدة الموزّعة (ريال)
B14: نسبة الزيارات التي تُوزَّع عليها
B15: تكلفة إضافية أخرى شهرياً (تدريب · مشرف)
B16: مدة التجربة (أسبوع) | C16: 8
A18: # | B18: البند | C18: القيمة | G18: الدلالة
A19: 1 | B19: تكلفة التوزيع يومياً | C19: =378*C14*C13 | G19: قبل أي نمو
A20: 2 | B20: الزيارات الإضافية للتعادل | C20: =IFERROR(C19/3.09,"") | G20: الهامش لكل زيارة 3.09 ريال
A21: 3 | B21: نسبة النمو المطلوبة للتعادل | C21: =IFERROR(C20/378,"") | G21: دون هذه النسبة التجربة خاسرة
A22: 4 | B22: سقف الاسترداد الممكن | C22: =830-378 | G22: العودة الكاملة لمستوى يناير
A23: 5 | B23: أقصى نمو ممكن | C23: =IFERROR(C22/378,"") | G23: الحد الأعلى لما يمكن استرداده
A25: المتابعة — ما يُسجَّل يومياً
A26: # | B26: المؤشر | C26: المصدر | D26: التكرار | E26: المسؤول | G26: لماذا هذا المؤشر
A27: 1 | B27: الزيارات اليومية | C27: نظام المحطة | D27: يومي | E27: مدير المحطة | G27: المؤشر الرئيسي — الفقد كان في العدد
A28: 2 | B28: اللترات اليومية | C28: نظام المحطة | D28: يومي | E28: مدير المحطة | G28: للتأكد أن السلة لم تنخفض
A29: 3 | B29: لتر لكل زيارة | C29: محسوب | D29: يومي | E29: — | G29: إن انخفض فالنمو من عملاء أصغر
A30: 4 | B30: الوحدات الموزّعة | C30: سجل يدوي | D30: يومي | E30: المشرف | G30: لربط التكلفة بالأثر
A31: 5 | B31: زمن التعبئة في الذروة | C31: قياس عيّنة | D31: أسبوعي | E31: المشرف | G31: الخدمة الممتازة يجب أن تُقاس
A32: 6 | B32: الشكاوى | C32: خدمة العملاء | D32: أسبوعي | E32: خدمة العملاء | G32: مؤشر عكسي للجودة
A33: 7 | B33: زيارات المحطة المرجع | C33: نظام المحطة | D33: أسبوعي | E33: التحليل | G33: لعزل أثر الموسم عن أثر التدخل
A35: سجل المتابعة الأسبوعي
A36: الأسبوع | B36: زيارة/يوم | C36: لتر/زيارة | D36: وحدات موزّعة | E36: التكلفة | F36: الفارق عن الأساس | G36: الحكم
A37: أسبوع 1 | F37: =IF(B37="","",B37-378) | G37: =IF(B37="","",IF(F37*3.09>E37/7,"مربح","دون التعادل"))
A38: أسبوع 2 | F38: =IF(B38="","",B38-378) | G38: =IF(B38="","",IF(F38*3.09>E38/7,"مربح","دون التعادل"))
A39: أسبوع 3 | F39: =IF(B39="","",B39-378) | G39: =IF(B39="","",IF(F39*3.09>E39/7,"مربح","دون التعادل"))
A40: أسبوع 4 | F40: =IF(B40="","",B40-378) | G40: =IF(B40="","",IF(F40*3.09>E40/7,"مربح","دون التعادل"))
A41: أسبوع 5 | F41: =IF(B41="","",B41-378) | G41: =IF(B41="","",IF(F41*3.09>E41/7,"مربح","دون التعادل"))
A42: أسبوع 6 | F42: =IF(B42="","",B42-378) | G42: =IF(B42="","",IF(F42*3.09>E42/7,"مربح","دون التعادل"))
A43: أسبوع 7 | F43: =IF(B43="","",B43-378) | G43: =IF(B43="","",IF(F43*3.09>E43/7,"مربح","دون التعادل"))
A44: أسبوع 8 | F44: =IF(B44="","",B44-378) | G44: =IF(B44="","",IF(F44*3.09>E44/7,"مربح","دون التعادل"))
...

Sheet البيانات
A1: بيانات المحطات
A2: 55 محطة · 1 يناير – 30 يونيو 2026 · 181 يوماً
A3: الرمز | B3: المحطة | C3: المنطقة | D3: نمط الموقع | E3: أيام البيانات | F3: بنزين سنوي | G3: ديزل سنوي | H3: زيارة/يوم | I3: النمو | J3: عمال | K3: مضخات | L3: شكاوى | M3: التطبيق
A4: MK007 | B4: العمرة الجديدة | C4: مكة | D4: حيوية | E4: 181 | F4: 34063312 | G4: 13312643 | H4: 4236 | I4: -0.223 | J4: 32 | K4: 18 | L4: 58 | M4: 0.006
A5: MK003 | B5: العوالي | C5: مكة | D5: خط سفر | E5: 91 | F5: 35464924 | G5: 0 | H5: 3561 | I5: 0 | J5: 42 | K5: 21 | M5: 0
A6: MK289 | B6: طريق الليث - الفضيلة | C6: جدة | D6: خط سفر | E6: 176 | F6: 10864480 | G6: 19344811 | H6: 1892 | I6: 0.273 | M6: 0
A7: MK004 | B7: عاصفة الصحراء | C7: الطائف | D7: حيوية | E7: 91 | F7: 19648510 | G7: 10303487 | H7: 2137 | I7: 0 | J7: 19 | K7: 12 | M7: 0
A8: MK046 | B8: الحليس - طريق الجنوب | C8: الطائف | D8: مختلط | E8: 55 | F8: 13354076 | G8: 5980304 | H8: 1694 | I8: 0 | J8: 12 | K8: 8 | M8: 0
A9: MK072 | B9: العزيزية | C9: مكة | D9: حيوية | E9: 180 | F9: 16732843 | G9: 2589147 | H9: 2359 | I9: -0.211 | J9: 14 | K9: 6 | L9: 28 | M9: 0
A10: MK047 | B10: القادسية | C10: مكة | D10: حيوية | E10: 181 | F10: 12654914 | G10: 4848425 | H10: 1702 | I10: -0.09 | J10: 10 | K10: 9 | M10: 0
A11: MK015 | B11: النسيم | C11: جدة | D11: حيوية | E11: 65 | F11: 16280701 | G11: 0 | H11: 2041 | I11: 0 | J11: 20 | K11: 12 | M11: 0
A12: MK005 | B12: الشيباني | C12: الطائف | D12: حيوية | E12: 63 | F12: 16309064 | G12: 98445 | H12: 1726 | I12: 0 | J12: 18 | K12: 9 | M12: 0
A13: MK033 | B13: أبو وافي العمرة | C13: مكة | D13: خط سفر | E13: 181 | F13: 8548346 | G13: 7210207 | H13: 1380 | I13: -0.217 | J13: 13 | K13: 10 | M13: 0
A14: MK028 | B14: أحلى مساء | C14: الطائف | D14: مختلط | E14: 181 | F14: 14309768 | G14: 1278215 | H14: 1414 | I14: -0.119 | J14: 13 | K14: 9 | M14: 0
A15: MK029 | B15: الدائري الثالث - الذكرى | C15: مكة | D15: حيوية | E15: 181 | F15: 11988986 | G15: 3596696 | H15: 1566 | I15: -0.034 | J15: 12 | K15: 8 | M15: 0.038
A16: RY075 | B16: الدائري الشمالي | C16: الرياض | D16: حيوية | E16: 181 | F16: 13247588 | G16: 1088450 | H16: 1169 | I16: 0.151 | J16: 10 | K16: 16 | M16: 0
A17: MK006 | B17: جنوب الطائف | C17: الطائف | D17: حيوية | E17: 57 | F17: 13311973 | G17: 0 | H17: 1483 | I17: 0 | J17: 13 | K17: 12 | M17: 0
A18: MK001 | B18: جبل النور | C18: مكة | D18: حيوية | E18: 181 | F18: 13248903 | G18: 0 | H18: 1872 | I18: -0.03 | J18: 10 | K18: 4 | M18: 0
A19: JA092 | B19: الصفا - أحد المسارحة | C19: جازان | D19: غير مصنفة | E19: 130 | F19: 11882308 | G19: 599108 | H19: 1807 | I19: 0.275 | M19: 0
A20: MK210 | B20: الفلاح - فلسطين | C20: جدة | D20: حيوية | E20: 147 | F20: 7867941 | G20: 3857753 | H20: 1328 | I20: 0.068 | M20: 0
A21: MK008 | B21: الحسينية | C21: مكة | D21: حي | E21: 70 | F21: 11625662 | G21: 0 | H21: 1643 | I21: 0 | J21: 9 | K21: 6 | M21: 0
A22: MK016 | B22: الرصيفة | C22: مكة | D22: حيوية | E22: 181 | F22: 11101203 | G22: 0 | H22: 1573 | I22: -0.112 | J22: 11 | K22: 9 | M22: 0
A23: MK064 | B23: الجعرانة | C23: مكة | D23: حي | E23: 181 | F23: 7193020 | G23: 2745883 | H23: 1112 | I23: -0.033 | J23: 9 | K23: 6 | M23: 0
A24: MK017 | B24: عرفات الشوقية | C24: مكة | D24: حيوية | E24: 181 | F24: 9931491 | G24: 0 | H24: 1290 | I24: 0.069 | J24: 9 | K24: 9 | L24: 8 | M24: 0
A25: MK063 | B25: السواط - شهار | C25: الطائف | D25: مختلط | E25: 181 | F25: 9064151 | G25: 558090 | H25: 1144 | I25: 0.177 | J25: 9 | K25: 9 | M25: 0
A26: MK020 | B26: ممشى الشوقية | C26: مكة | D26: حيوية | E26: 181 | F26: 9558604 | G26: 0 | H26: 1363 | I26: 0.042 | J26: 9 | K26: 4 | M26: 0
A27: MK035 | B27: الجمعية الوسام | C27: الطائف | D27: مختلط | E27: 181 | F27: 6835043 | G27: 2528030 | H27: 823 | I27: 0.083 | J27: 6 | K27: 4 | M27: 0
A28: MK054 | B28: طريق السيل | C28: مكة | D28: خط سفر | E28: 111 | F28: 6066855 | G28: 3252431 | H28: 680 | I28: -0.033 | J28: 11 | K28: 16 | M28: 0
A29: MK022 | B29: بطحاء قريش 1 | C29: مكة | D29: حي | E29: 181 | F29: 6241831 | G29: 2950851 | H29: 816 | I29: -0.045 | J29: 8 | K29: 6 | M29: 0
A30: MK014 | B30: خليص | C30: مكة | D30: خط سفر | E30: 181 | F30: 3791200 | G30: 4805625 | H30: 423 | I30: -0.084 | J30: 9 | K30: 6 | M30: 0.015
A31: MK018 | B31: الرصيفة المسار | C31: مكة | D31: حيوية | E31: 92 | F31: 6955614 | G31: 1485665 | H31: 1025 | I31: 0 | J31: 6 | K31: 8 | M31: 0
A32: RY025 | B32: الحمرا - طريق الملك عبدالله | C32: الخرج | D32: غير مصنفة | E32: 181 | F32: 7191456 | G32: 642374 | H32: 864 | I32: 0.186 | J32: 7 | K32: 15 | M32: 0
A33: AS153 | B33: مدخل محايل | C33: عسير | D33: غير مصنفة | E33: 69 | F33: 6980426 | G33: 801543 | H33: 952 | I33: 0 | J33: 7 | K33: 7 | M33: 0
A34: JA069 | B34: كورنيش جيزان | C34: جازان | D34: حيوية | E34: 181 | F34: 7444371 | G34: 175072 | H34: 922 | I34: 0.18 | J34: 8 | K34: 6 | M34: 0
A35: MK068 | B35: الجموم - الكنيدري | C35: مكة | D35: مختلط | E35: 181 | F35: 6267957 | G35: 814480 | H35: 931 | I35: -0.068 | J35: 7 | K35: 4 | M35: 0
A36: MK002 | B36: المعيصم | C36: مكة | D36: حيوية | E36: 181 | F36: 6999984 | G36: 0 | H36: 913 | I36: -0.533 | J36: 7 | K36: 10 | L36: 3 | M36: 0
A37: MK071 | B37: الأجاويد | C37: جدة | D37: حيوية | E37: 181 | F37: 5722940 | G37: 1147336 | H37: 938 | I37: 0.083 | J37: 7 | K37: 3 | M37: 0.015
A38: JA348 | B38: جنوب صبيا | C38: جازان | D38: غير مصنفة | E38: 26 | F38: 6046920 | G38: 778046 | H38: 1227 | I38: 0 | M38: 0
A39: JA061 | B39: طريق صبيا | C39: جازان | D39: حيوية | E39: 181 | F39: 4191108 | G39: 2493275 | H39: 538 | I39: -0.044 | J39: 6 | K39: 5 | M39: 0
A40: MK084 | B40: الكر النازل | C40: مكة | D40: خط سفر | E40: 181 | F40: 5545862 | G40: 657563 | H40: 537 | I40: -0.126 | J40: 8 | K40: 9 | M40: 0.002
...

Sheet بيانات الورديات
A1: بيانات المحطات المرجعية
A2: من تقرير المطابقة التشغيلية — يناير إلى يوليو ٢٠٢٦ (٢١٢ يوماً فعلياً)
A3: # | B3: المحطة | C3: لتر/زيارة | D3: زيارات/يوم | E3: عمال صباحية | F3: عمال مسائية | G3: حصة الصباح | H3: حصة المساء | I3: ساعات الذروة | J3: الطاقم المعياري | K3: الفعلي | L3: الكود | M3: اسم المقياس | N3: العقد | O3: المضخات | P3: هامش المساهمة (هللة/لتر) | Q3: نموذج العمل | T3: الورديات | U3: بوابة الجودة
A4: 1 | B4: النورية | C4: 30.56 | D4: 4261 | E4: 11 | F4: 9 | G4: 0.4899 | H4: 0.5101 | I4: 17:00 · 21:00 · 22:00 | J4: 32 | K4: 34 | L4: MK007 | M4: العمرة | N4: ايجار | O4: 18 | P4: 10.15 | Q4: استثماري | T4: صباحية | U4: مستوفاة
A5: 2 | B5: عرفات الشوقية | C5: 21.07 | D5: 1269 | E5: 3 | F5: 3 | G5: 0.4471 | H5: 0.5529 | I5: 17:00 · 21:00 · 22:00 | J5: 9 | K5: 9 | L5: MK017 | M5: عرفات الشوقية | N5: ايجار | O5: 9 | P5: 12.58 | Q5: إيجاري | T5: مسائية | U5: غير مستوفاة
A6: 3 | B6: المعيصم | C6: 20.99 | D6: 864 | E6: 2 | F6: 2 | G6: 0.4964 | H6: 0.5036 | I6: 17:00 · 18:00 · 19:00 | J6: 7 | K6: 8 | L6: MK002 | M6: المعيصم | N6: ايجار | O6: 10 | P6: 13.11 | Q6: إيجاري
A7: 4 | B7: الفردوس | C7: 20.01 | D7: 790 | E7: 2 | F7: 2 | G7: 0.4511 | H7: 0.5489 | I7: 17:00 · 21:00 · 22:00 | J7: 7 | K7: 7 | L7: MK023 | M7: بن درويش | N7: تشغيل | O7: 4 | P7: 11.29 | Q7: تشغيلي
A8: 5 | B8: عرفات الشرائع | C8: 23.16 | D8: 443 | E8: 2 | F8: 2 | G8: 0.439 | H8: 0.561 | I8: 17:00 · 21:00 · 22:00 | J8: 5 | K8: 6 | L8: MK019 | M8: عرفات الشرائع | N8: ايجار | O8: 6 | P8: 11.4 | Q8: إيجاري
B10: «حصة الصباح/المساء» من عدد الزيارات الفعلي — الوردية الصباحية ٦ ص إلى ٦ م والمسائية ٦ م إلى ٦ ص
B11: «اسم المقياس» هو الاسم المستخدم في ملف العمالة — يختلف عن اسم السجل في محطتين
