Workbook

Sheet الملخص
A1: القسم التجاري — الحاسبة والخطة في ملف واحد
A2: 55 محطة · 276.8 مليون لتر · 626.5 مليون ريال · 10.96 مليون زيارة · 10,959,777 صفّاً من كاش إن
A4: قاعدة هذا الملف: التشخيص قبل الوصفة. لا يدخل رقمٌ خانة «مبيعات» حتى يُستبعد قبله الوصولُ والبياناتُ والعقدُ والإمدادُ والرقابةُ والعمالة. ولذلك تجد في كل ورقة عموداً اسمه «البوابة» — محطةٌ عليها بوابة مفتوحة لا تدخل حملةً قبل إقفالها، لأن نتيجتها ستُنسب إلى الحملة وهي من البوابة.
B6: الفرصة المؤكَّدة | C6: منها بعدد التعبئات | D6: ومنها بحجم التعبئة | E6: فجوة العمولة | F6: محطات دون المتوقَّع | G6: وحدات تجارية شاغرة
B7: 3185078.5 | C7: 853324 | D7: 2331754.5 | E7: 1132872 | F7: 33 | G7: 1089
B8: ريال/سنة هامش مساهمة | C8: 767 معاملة/يوم في ساعات الذروة | D8: 58,839 لتر/يوم · تُفسَّر بالمزيج | E8: ريال/سنة — لا تحتاج حملةً بل تفاوضاً | F8: من 52 محطة مقيسة | G8: من 1733 — إشغال 37٪
A10: ① أين المال فعلاً — وهل يحتاج بيعاً أصلاً؟
B11: الفرصة | C11: القيمة ر/سنة | D11: الصنف | E11: من يملكها | I11: هل تحتاج حملةً؟
B12: فجوة العمولة في محطات التشغيل | C12: 1132872 | D12: عقد | E12: التجاري + المالية | I12: لا — تفاوض عقود. وهي أكبر رقم في الخطة كلها
B13: حجم التعبئة دون المتوقَّع | C13: 2331754.5 | D13: سلة | E13: التجاري | I13: جزئياً — وثلثا تباينها مزيج وقود لا سلوك، فتُفسَّر ولا تُطالَب
B14: فاقد ساعات الذروة | C14: 853324 | D14: معاملات | E14: التجاري + العمليات | I14: لا — تغطية طاقم وسرعة خدمة. وهذا وحده ما يُطالَب به
B15: الوحدات الشاغرة المقيسة حركتها | C15: غير مُسعَّرة | D15: تأجير | E15: التأجير | I15: لا — اكتتاب. 139 وحدة من 1089 حركتها مقيسة اليوم
B16: كلفة آلية الهدية لو عُمِّمت | C16: -400407.49 | D16: كلفة | E16: التجاري | I16: بالعكس — تُدفع على القائم والعائد من الإضافي · محطة العمرة وحدها
A17: أكبر رقمٍ في الجدول لا يحتاج لتراً إضافياً ولا حملة — يحتاج جلسة تفاوض. وأضخم الفرص كثيراً ما تكون خارج دائرة البيع، وعلامة الخبرة أن تقول «هذه ليست مشكلة مبيعات» حين تكون كذلك.
A19: ② البوابات — حالاتٌ تُغلق قبل أي إنفاق
B20: الحالة المرصودة | C20: الفعل | E20: كيف | H20: الصنف | I20: محطات عليها
B21: ⛔ فجوة مطابقة تتجاوز ٥٪ | C21: تحقيق ورقابة — لا حملة | E21: جرد خزانات · معايرة عدادات · مطابقة إشعارات | H21: رقابة | I21: 2
B22: ⛔ تغيير مسار أو مدخل | C22: هندسة وصول — لا حملة | E22: تصحيح المدخل على الخرائط · لافتة على المسار · إعادة تحجيم العمالة | H22: وصول | I22: 2
B23: ⛔ وسيلة الدفع غير مسجّلة | C23: تفعيل النظام قبل أي حملة | E23: ضبط نقاط البيع · تدريب الوردية · مؤشر في حافز العامل | H23: بيانات | I23: 18
B24: ⛔ تغطية خزان دون ٤ أيام | C24: تأمين الإمداد قبل رفع الطلب | E24: حد أدنى تعاقدي · ناقل بديل · دراسة خزان | H24: إمداد | I24: —
B25: ⛔ نقدي المحطة فوق ٧٠٪ · الوسيط ٤٠٪ | C25: فحص نقاط البيع أولاً | E25: اختبار قارئ البطاقة · مطابقة تسليم النقد · المحفظة تُطلق هنا | H25: رقابة | I25: —
B26: فاقد في ساعات الذروة | C26: تغطية لا حملة | E26: طاقم الذروة · فحص المضخات · تدرّج التسليم | H26: معاملات | I26: 11
B27: عبء المسائية يفوق الصباحية | C27: نقل طاقم لا توظيف | E27: إعادة جدولة المناوبات · مستهدف وردية لا محطة | H27: عمالة | I27: —
B28: تعبئة دون ما يفسّره مزيجها | C28: رفع السلة | E28: علبة المناديل عند العتبة · نص موحّد · لوحة عند المضخة | H28: سلة | I28: 33
B29: حصة الديزل ٣٠٪ فأكثر | C29: تعاقد أساطيل | E29: حصر ناقلي المنطقة · سعر متدرج · تسجيل في التطبيق | H29: أساطيل | I29: 16
B30: عشر وحدات شاغرة فأكثر | C30: باقة تأجير حسب الفئة | E30: التدريج لتحت التنفيذ · النسبة للمشغّلة · المسوّق للامتياز | H30: تأجير | I30: 3
A31: الأربع الأولى بوابات: تُغلق قبل أي حملة. والستّ الباقية أفعالٌ تجارية تبدأ بعدها. وعمود «محطات عليها» يقول كم محطةً ترفع كل علامة اليوم — والتفصيل في ورقة المحطات.
A33: ③ التصنيف — مصطلحات الشركة نفسها من ملف التحليلات
B34: التصنيف | C34: محطات | D34: لتر/يوم | E34: لتر/زيارة | F34: ديزل٪ | G34: R² | I34: المحرّك الأول والفعل
B35: حيوية | C35: 25 | D35: 780547.86 | E35: 24.500747 | F35: 0.18308469 | G35: 0.43294574 | I35: تغطية ساعات الذروة — طاقم الذروة · توفّر المضخات · سرعة الخدمة
B36: خط سفر | C36: 8 | D36: 318207.12 | E36: 34.583377 | F36: 0.38007422 | G36: 0.55423645 | I36: التعاقد وسلة التعبئة — عقود ديزل متدرجة · خدمات شاحنات · ممر سريع
B37: حي | C37: 8 | D37: 140722.34 | E37: 24.55017 | F37: 0.20000121 | G37: 0.5460303 | I37: التردد — ساعات العمل · مزيج المستأجرين · سرعة الذروة
B38: مختلط | C38: 8 | D38: 241126.4 | E38: 25.982599 | F38: 0.16772694 | G38: 0.3925932 | I38: فصل الطلبين — عرض للسكّان وآخر للعابرين · لا رسالة واحدة
B39: نائية | C39: 3 | D39: 28978 | E39: 23.247048 | F39: 0.18664371 | G39: 0.64674581 | I39: حماية الربحية — ضبط العمالة · تأجير الوحدات · لا إنفاق تسويقي
B40: الإجمالي | C40: =SUM(C35:C39) | D40: =SUM(D35:D39)
A41: R² هو مدى ما يفسّره التصنيف من تباين حجم التعبئة داخله. وتصنيف الشركة متماسكٌ سلوكياً لا اسماً: خط سفر ديزله ٤٨٪ وسلته ٣٦ لتراً، والحيوية ديزلها ١٨٪. ولذلك يُقارَن كلٌّ بشكله لا بمتوسط الشبكة.

Sheet حاسبة المبيعات
A1: حاسبة المبيعات — اختر المحطة وغيّر الأصفر وحده
A2: كل خلية بيضاء صيغةٌ حيّة · الذهبية مُدخَلات · وبيانات المحطة تُسحب تلقائياً من ورقة المحطات
A4: الحاسبة تجيب سؤالاً واحداً: كم يساوي أن نضيف معاملةً في اليوم في هذه المحطة — وكم يكلّف. فالمعاملة تُطلَب، وحجم التعبئة يُفسَّر بمزيج الوقود ولا يُطالَب به.
A6: ① المحطة — اخترها من القائمة وكل ما تحتها يتغيّر
B7: المحطة | C7: العمرة الجديدة | F7: ◀ اضغط الخلية ثم اختر من السهم | G7: من 52 محطة مقيسة
B8: من بيانات المحطة | C8: القيمة | F8: من بيانات المحطة | G8: القيمة
B9: الرمز | C9: =VLOOKUP($C$7,'المحطات'!$B$5:$R$56,2,FALSE) | F9: متوسط الفاتورة | G9: =VLOOKUP($C$7,'المحطات'!$B$5:$R$56,8,FALSE)
B10: المنطقة | C10: =VLOOKUP($C$7,'المحطات'!$B$5:$R$56,3,FALSE) | F10: حصة الديزل | G10: =VLOOKUP($C$7,'المحطات'!$B$5:$R$56,9,FALSE)
B11: التصنيف | C11: =VLOOKUP($C$7,'المحطات'!$B$5:$R$56,4,FALSE) | F11: حصة الليل | G11: =VLOOKUP($C$7,'المحطات'!$B$5:$R$56,10,FALSE)
B12: زيارة/يوم | C12: =VLOOKUP($C$7,'المحطات'!$B$5:$R$56,5,FALSE) | F12: فجوة الذروة معاملة/يوم | G12: =VLOOKUP($C$7,'المحطات'!$B$5:$R$56,12,FALSE)
B13: لتر/يوم | C13: =VLOOKUP($C$7,'المحطات'!$B$5:$R$56,6,FALSE) | F13: فجوة السلة لتر/زيارة | G13: =VLOOKUP($C$7,'المحطات'!$B$5:$R$56,13,FALSE)
B14: لتر لكل زيارة | C14: =VLOOKUP($C$7,'المحطات'!$B$5:$R$56,7,FALSE) | F14: البوابات والحالات | G14: =VLOOKUP($C$7,'المحطات'!$B$5:$R$56,17,FALSE)
A16: ② المُدخَلات — الذهبيّ وحده قابل للتغيير
B17: المُدخَل | C17: القيمة | D17: الوحدة | F17: المُدخَل | G17: القيمة | H17: الوحدة
B18: نسبة إغلاق الفجوة | C18: 0.4 | D18: ٪ خلال ستة أشهر | F18: أساس الكلفة | G18: تشغيل المحطة — محمَّل بالكامل | H18: اختر
B19: معاملات إضافية في اليوم | C19: =$G$12*$C$18 | D19: اكتب فوقها رقمك إن شئت | F19: هدية على كل فاتورة مؤهَّلة؟ | G19: لا | H19: نعم / لا
B20: هامش لتر البنزين | C20: 0.1266 | D20: ريال/لتر = ١٢٫٦٦ هللة | F20: كلفة العلبة | G20: 0.62 | H20: ريال
B21: هامش لتر الديزل | C21: 0.0447 | D21: ريال/لتر = ٤٫٤٧ هللة | F21: حصة الفواتير المؤهَّلة | G21: 0.38981717 | H21: ٪ — مقيسة في العمرة
B22: أيام التطبيق | C22: 365 | D22: يوم | F22: سعر البيع للتر | G22: 2.1090053 | H22: ريال/لتر
A23: أسُس الكلفة الثلاثة — ولكلٍّ قرارٌ يخصّه
B24: الأساس | C24: هللة/لتر | F24: يصلح لقرار
B25: حدّية — لتر إضافي على طاقم قائم | C25: 0 | F25: يصلح لقرار: هل نغلق الفجوة بالطاقم الحالي؟
B26: تشغيل المحطة — محمَّل بالكامل | C26: 9.15 | F26: يصلح لقرار: هل نفتح وردية أو نوظّف؟
B27: المحمَّل الكامل — مع مصاريف المركز | C27: 13.56 | F27: يصلح لقرار: هل تستحق المحطة رأس مال جديداً؟
A28: الأساس الحدّي صفرٌ لأن النقص في ساعات الذروة طاقةُ خدمةٍ لا طاقة ضخّ: المضخّات والمرافق والأجور مدفوعة أصلاً، فاللتر الإضافي على الطاقم القائم لا يضيف كلفةً مقيسة. ومن يقرّر فتح وردية أو توظيفاً يستعمل الأساس الثاني، ومن يقرّر رأس مال جديداً يستعمل الثالث.
A30: ③ النتيجة — محسوبة من المُدخَلات أعلاه
B31: السطر | C31: في اليوم | D31: في السنة | F31: السطر | G31: القيمة
B32: لترات إضافية | C32: =$C$19*$C$14 | D32: =C32*$C$22 | F32: الهامش المرجَّح للتر — ريالاً | G32: =$C$20*(1-$G$10)+$C$21*$G$10
B33: مبيعات إضافية | C33: =C32*$G$22 | D33: =C33*$C$22 | F33: قيمة معاملةٍ واحدة إضافية في اليوم | G33: =$C$14*$G$32*$C$22
B34: هامش مساهمة المستهدف | C34: =C32*$G$32 | D34: =C34*$C$22 | F34: الزيادة على حركة المحطة | G34: =$C$19/$C$12
B35: كلفة لترات المستهدف | C35: =-C32*VLOOKUP($G$18,$B$25:$C$27,2,FALSE)/100 | D35: =C35*$C$22 | F35: قيمة إغلاق الفجوة كاملةً | G35: =$G$12*$C$14*$G$32*$C$22
B36: صافي المستهدف | C36: =C34+C35 | D36: =C36*$C$22 | F36: الفواتير المؤهَّلة للهدية اليوم | G36: =($C$12+$C$19)*$G$21
B37: كلفة الهدية — على المحطة كلها | C37: =-IF($G$19="نعم",($C$12+$C$19)*$G$21*$G$20,0) | D37: =C37*$C$22 | F37: لترات/يوم تدفع كلفة الهدية | G37: =-C37/$G$32
B38: الصافي بعد الهدية | C38: =C36+C37 | D38: =C38*$C$22 | F38: وهي من حجم المحطة | G38: =-C37/$G$32/($C$12*$C$14)
A39: السطران الأخيران يخلطان أساسين عمداً ليُرى الخلط: الهدية تُدفع على كل فاتورةٍ مؤهَّلة — القائمة والإضافية معاً — بينما العائد يأتي من الإضافية وحدها. فلذلك تُقارَن كلفتها بحجم المحطة لا بحجم الزيادة، والسطر «وهي من حجم المحطة» يقول النسبة مباشرة.
A41: ④ حجم التعبئة — يُعرض ولا يُطالَب به
B42: السطر | C42: القيمة | D42: في السنة | F42: لماذا لا يُطالَب به
B43: فجوة السلة لكل زيارة | C43: =$G$13 | D43: — | F43: الفرق بين لتر زيارتنا وما يفسّره مزيج تصنيفنا
B44: لترات/يوم لو أُغلقت كاملةً | C44: =C43*$C$12 | D44: =C44*$C$22 | F44: ثلثا تباين حجم التعبئة مزيج وقود لا سلوك — R²=٠٫٦٦
B45: قيمتها هامشَ مساهمة | C45: =C44*$G$32 | D45: =C45*$C$22 | F45: فتُفسَّر بالمزيج وتُتابَع، ولا تُحمَّل على وردية
...

Sheet المحطات
A1: المحطات — جدول واحد تقرأ منه الحاسبة وكل الأوراق
A2: 52 محطة مقيسة من كاش إن · 9,058 يوم-محطة · مرتَّبة بقيمة الفرصة · والبوابة في آخر عمود
B4: المحطة | C4: الرمز | D4: المنطقة | E4: التصنيف | F4: زيارة/يوم | G4: لتر/يوم | H4: لتر/زيارة | I4: الفاتورة | J4: ديزل٪ | K4: ليلي٪ | L4: ذروة | M4: فجوة الذروة | N4: فجوة السلة | O4: قيمة المعاملات | P4: قيمة السلة | Q4: الإجمالي ر/سنة | R4: البوابات والحالات
B5: جنوب صبيا | C5: JA348 | D5: جازان | E5: مختلط | F5: 1435.8421 | G5: 22127.571 | H5: 15.410867 | I5: 33.82 | J5: 0.12697075 | K5: 0.56816099 | L5: 21 | M5: 12.7745 | N5: 9.6696525 | O5: 8349.7611 | P5: 235548.65 | Q5: =O5+P5 | R5: سلة دون المتوقَّع
B6: أبو وافي العمرة | C6: MK033 | D6: مكة | E6: خط سفر | F6: 1411.1085 | G6: 43568.316 | H6: 30.875242 | I6: 62.44 | J6: 0.50792373 | K6: 0.50477512 | L6: 19 | M6: 13.271917 | N6: 12.613827 | O6: 12713.384 | P6: 220894.25 | Q6: =O6+P6 | R6: سلة دون المتوقَّع · ديزل مرتفع
B7: الصفا - أحد المسارحة | C7: JA092 | D7: جازان | E7: حيوية | F7: 1856.5776 | G7: 35294.708 | H7: 19.010629 | I7: 42.31 | J7: 0.06239457 | K7: 0.5412383 | L7: 21 | M7: 6.5229517 | N7: 5.4777198 | O7: 5498.8722 | P7: 180387.28 | Q7: =O7+P7 | R7: سلة دون المتوقَّع
B8: الحسينية | C8: MK008 | D8: مكة | E8: حي | F8: 1697.7228 | G8: 32430.704 | H8: 19.102473 | I8: 42.95 | J8: 0 | K8: 0.53679361 | L8: 20 | M8: 37.024554 | N8: 4.3350058 | O8: 32681.803 | P8: 136032.6 | Q8: =O8+P8 | R8: ⛔ فجوة مطابقة · فاقد ذروة · سلة دون المتوقَّع
B9: الفلاح - فلسطين | C9: MK210 | D9: جدة | E9: حيوية | F9: 1340.9494 | G9: 32438.989 | H9: 24.191061 | I9: 49.83 | J9: 0.38342677 | K9: 0.51852829 | L9: 21 | M9: 13.851714 | N9: 7.1336947 | O9: 11643.301 | P9: 132954.99 | Q9: =O9+P9 | R9: سلة دون المتوقَّع · ديزل مرتفع
B10: جبل النور | C10: MK001 | D10: مكة | E10: حيوية | F10: 1853.4087 | G10: 35781.711 | H10: 19.305894 | I10: 43.52 | J10: 0 | K10: 0.52901489 | L10: 17 | M10: 5.6639567 | N10: 3.853757 | O10: 5052.8501 | P10: 132020.71 | Q10: =O10+P10 | R10: ⛔ بيانات دفع مفقودة · سلة دون المتوقَّع
B11: الأجاويد | C11: MK071 | D11: جدة | E11: حيوية | F11: 946.74057 | G11: 18946.88 | H11: 20.012748 | I11: 42.95 | J11: 0.19696465 | K11: 0.51008674 | L11: 17 | M11: 17.046337 | N11: 7.3412819 | O11: 13755.282 | P11: 112097.15 | Q11: =O11+P11 | R11: سلة دون المتوقَّع
B12: الرصيفة | C12: MK016 | D12: مكة | E12: حيوية | F12: 1565.8718 | G12: 30241.955 | H12: 19.313174 | I12: 43.48 | J12: 0 | K12: 0.53877417 | L12: 21 | M12: 6.2631001 | N12: 3.846477 | O12: 5589.4565 | P12: 111328.38 | Q12: =O12+P12 | R12: ⛔ بيانات دفع مفقودة · سلة دون المتوقَّع
B13: العوالي | C13: MK003 | D13: مكة | E13: خط سفر | F13: 3491.5094 | G13: 94813.459 | H13: 27.155436 | I13: 61.41 | J13: 0 | K13: 0.49138746 | L13: 17 | M13: 91.427843 | N13: 0 | O13: 114725.99 | P13: 0 | Q13: =O13+P13 | R13: فاقد ذروة
B14: ممشى الشوقية | C14: MK020 | D14: مكة | E14: حيوية | F14: 1361.7547 | G14: 26167.552 | H14: 19.216054 | I14: 43.41 | J14: 0 | K14: 0.55345489 | L14: 21 | M14: 12.125832 | N14: 3.9435974 | O14: 10767.188 | P14: 99260.857 | Q14: =O14+P14 | R14: ⛔ بيانات دفع مفقودة · سلة دون المتوقَّع
B15: عاصفة الصحراء | C15: MK004 | D15: الطائف | E15: حيوية | F15: 2209.9508 | G15: 85791.346 | H15: 38.820478 | I15: 81.07 | J15: 0.39763938 | K15: 0.49781169 | L15: 17 | M15: 80.544537 | N15: 0 | O15: 107317.78 | P15: 0 | Q15: =O15+P15 | R15: فاقد ذروة · ديزل مرتفع
B16: الرصيفة المسار | C16: MK018 | D16: مكة | E16: حيوية | F16: 1062.9756 | G16: 23542.562 | H16: 22.147791 | I16: 47.63 | J16: 0.20946467 | K16: 0.50442843 | L16: 22 | M16: 13.77089 | N16: 5.4724272 | O16: 12183.74 | P16: 92950.441 | Q16: =O16+P16 | R16: سلة دون المتوقَّع
... B48: المركب | C48: NJ219 | D48: نجران | E48: نائية | F48: 274.51351 | G48: 6166.0716 | H48: 22.461815 | I48: 48.47 | J48: 0.17941512 | K48: 0.48587181 | L48: 16 | M48: 4.0788307 | N48: 0.96078983 | O48: 3742.1947 | P48: 4309.2131 | Q48: =O48+P48 | R48: سلة دون المتوقَّع · وحدات شاغرة
B49: الناصفة | C49: RY042 | D49: الخرج | E49: حي | F49: 412.43396 | G49: 12106.137 | H49: 29.352911 | I49: 62.81 | J49: 0.24569633 | K49: 0.45416076 | L49: 16 | M49: 4.1267636 | N49: 0 | O49: 4707.728 | P49: 0 | Q49: =O49+P49
B50: خبت نخلان | C50: JA053 | D50: جازان | E50: نائية | F50: 652.93868 | G50: 14945.315 | H50: 22.889309 | I50: 49.22 | J50: 0.23265245 | K50: 0.51111448 | L50: 21 | M50: 4.4570087 | N50: 0 | O50: 4004.6294 | P50: 0 | Q50: =O50+P50
B51: غرناطة - طريق الملك عبدالله | C51: RY024 | D51: الخرج | E51: حي | F51: 463.74227 | G51: 11784.084 | H51: 25.410848 | I51: 57.2 | J51: 0 | K51: 0.53555788 | L51: 21 | M51: 2.1106877 | N51: 0 | O51: 2478.3904 | P51: 0 | Q51: =O51+P51 | R51: ⛔ فجوة مطابقة · بيانات دفع مفقودة
B52: العريفي | C52: HA043 | D52: حائل | E52: نائية | F52: 325.83756 | G52: 7866.6138 | H52: 24.142747 | I52: 53.65 | J52: 0.093643063 | K52: 0.57476242 | L52: 21 | M52: 1.3465101 | N52: 0.13906414 | O52: 1411.1815 | P52: 786.79734 | Q52: =O52+P52 | R52: ⛔ بيانات دفع مفقودة
B53: كورنيش الخبر | C53: EP051 | D53: الشرقية | E53: حيوية | F53: 604.7217 | G53: 15616.837 | H53: 25.824833 | I53: 56.84 | J53: 0.089673021 | K53: 0.50089313 | L53: 17 | M53: 1.1393139 | N53: 0 | O53: 1280.7172 | P53: 0 | Q53: =O53+P53
B54: الكر النازل | C54: MK084 | D54: مكة | E54: خط سفر | F54: 573.14151 | G54: 18101.529 | H54: 31.583001 | I54: 69.52 | J54: 0.12800634 | K54: 0.60136125 | L54: 19 | M54: 0.86767189 | N54: 0 | O54: 1161.435 | P54: 0 | Q54: =O54+P54
B55: الشرايع | C55: MK019 | D55: مكة | E55: حيوية | F55: 442.81517 | G55: 10255.445 | H55: 23.159651 | I55: 52.43 | J55: 0 | K55: 0.56102704 | L55: 21 | M55: 0.13254212 | N55: 0 | O55: 141.8445 | P55: 0 | Q55: =O55+P55 | R55: ⛔ تغيير مسار · بيانات دفع مفقودة
B56: بطحاء قريش 1 | C56: MK022 | D56: مكة | E56: حي | F56: 811.29245 | G56: 24771.502 | H56: 30.533381 | I56: 63.82 | J56: 0.36474162 | K56: 0.52826261 | L56: 17 | M56: 0 | N56: 0 | O56: 0 | P56: 0 | Q56: =O56+P56 | R56: ⛔ بيانات دفع مفقودة · ديزل مرتفع
B57: الإجمالي | F57: =SUM(F5:F56) | G57: =SUM(G5:G56) | M57: =SUM(M5:M56) | N57: =SUM(N5:N56) | O57: =SUM(O5:O56) | P57: =SUM(P5:P56) | Q57: =SUM(Q5:Q56)
A58: ⛔ الصفّ الذهبي = بوابة مفتوحة (فجوة مطابقة · تغيير مسار · بيانات دفع مفقودة). «فجوة الذروة» معاملة/يوم مقارنةً بشكل ساعات تصنيف المحطة، و«فجوة السلة» لتراً لكل زيارة دون ما يفسّره مزيجها. والقيمة تُحتسب بهامش مرجَّح بمزيج كل محطة لا بمتوسط الشبكة.

Sheet ر١ و ر٢ للمحطات
A1: مبيعات الربع الأول والثاني — المحطات المشغّلة
A2: 26 محطة من تقرير ربحية الربع الثاني · المبيعات والحجم والصافي والأجور · وحصّتنا مقارنةً بالعمولة المعيارية (٣ هللات بنزين · ١٫٥ ديزل)
B4: المحطة | C4: الرمز | D4: مبيعات ر١ | E4: مبيعات ر٢ | F4: التغيّر | G4: حجم ر١ لتر | H4: حجم ر٢ لتر | I4: التغيّر | J4: صافي ر١ | K4: صافي ر٢ | L4: هامش ر٢ | M4: أجور ر٢ | N4: مرافق ر٢ | O4: حصّتنا ر٢ | P4: المعياري ر٢ | Q4: الفجوة ر٢ | R4: شروط العقد ونوعها
B5: أبو وافي | C5: MK033 | D5: 7649675 | E5: 5978632 | F5: =IF(D5=0,"—",E5/D5-1) | G5: 4362356 | H5: 3410759 | I5: =IF(G5=0,"—",H5/G5-1) | J5: 193001 | K5: 143676 | L5: 0.024 | M5: 115500 | N5: 22408 | O5: 18678 | P5: 76336.688 | Q5: =O5-P5 | R5: نسبة ثابتة من الصافي — نسبة ١٥٪ في ر١ ثم ١٣٪ في ر٢
B6: الذكرى الخالدة | C6: MK029 | D6: 7413928 | E6: 7243350 | F6: =IF(D6=0,"—",E6/D6-1) | G6: 4041498 | H6: 3860413 | I6: =IF(G6=0,"—",H6/G6-1) | J6: 256990 | K6: 268282 | L6: 0.037 | M6: 108500 | N6: — | O6: 49360 | P6: 104231.15 | Q6: =O6-P6 | R6: عمولة دون المعياري — عمولة ٠٫٠١٥ بنزين · ٠٫٠٠٥ ديزل — الأدنى في الشبكة
B7: الدائري الشمالي | C7: RY075 | D7: 6315203 | E7: 7351302 | F7: =IF(D7=0,"—",E7/D7-1) | G7: 3290913 | H7: 3827940 | I7: =IF(G7=0,"—",H7/G7-1) | J7: 238105 | K7: 287219 | L7: 0.039 | M7: 105000 | N7: 25490 | O7: 57444 | P7: 103354.38 | Q7: =O7-P7 | R7: نسبة ثابتة من الصافي — نسبة ٢٠٪ ثابتة
B8: صبيا خبت نخلان | C8: JA053 | D8: 2482548 | E8: 2486549 | F8: =IF(D8=0,"—",E8/D8-1) | G8: 1325213 | H8: 1325693 | I8: =IF(G8=0,"—",H8/G8-1) | J8: 49026 | K8: 46503 | L8: 0.019 | M8: 73500 | N8: — | O8: 6975 | P8: 35144.404 | Q8: =O8-P8 | R8: نسبة ثابتة من الصافي — نسبة ١٥٪ ثابتة
B9: بريدة القصيم | C9: QS055 | D9: 2510791 | E9: 2554762 | F9: =IF(D9=0,"—",E9/D9-1) | G9: 1400083 | H9: 1447839 | I9: =IF(G9=0,"—",H9/G9-1) | J9: 60508 | K9: 27133 | L9: 0.011 | M9: 63000 | N9: 23468 | O9: 5427 | P9: 33519.73 | Q9: =O9-P9 | R9: نسبة ثابتة من الصافي — نسبة ٢٠٪ ثابتة
B10: القسوم | C10: JA041 | D10: 0 | E10: 2150813 | F10: =IF(D10=0,"—",E10/D10-1) | G10: 0 | H10: 1111929 | I10: =IF(G10=0,"—",H10/G10-1) | J10: 0 | K10: 30748 | L10: 0.014 | M10: — | N10: — | O10: 4612 | P10: 32121.547 | Q10: =O10-P10 | R10: نسبة ثابتة من الصافي — نسبة ١٥٪ — محطة جديدة في ر٢
B11: الجمعية | C11: MK035 | D11: 3932845 | E11: 4579569 | F11: =IF(D11=0,"—",E11/D11-1) | G11: 2102148 | H11: 2468597 | I11: =IF(G11=0,"—",H11/G11-1) | J11: 136774 | K11: 177835 | L11: 0.039 | M11: 63000 | N11: 4902 | O11: 35567 | P11: 62126.657 | Q11: =O11-P11 | R11: نسبة ثابتة من الصافي — نسبة ٢٠٪ ثابتة
B12: الرصيفة | C12: MK016 | D12: 5684187 | E12: 5115259 | F12: =IF(D12=0,"—",E12/D12-1) | G12: 2904948 | H12: 2611625 | I12: =IF(G12=0,"—",H12/G12-1) | J12: 247404 | K12: 214310 | L12: 0.042 | M12: 101500 | N12: 9912 | O12: 53577 | P12: 78348.75 | Q12: =O12-P12 | R12: نسبة ثابتة من الصافي — نسبة ٢٥٪ ثابتة
B13: الأجاويد | C13: MK071 | D13: 3033342 | E13: 3320850 | F13: =IF(D13=0,"—",E13/D13-1) | G13: 1623305 | H13: 1783599 | I13: =IF(G13=0,"—",H13/G13-1) | J13: 95402 | K13: 119629 | L13: 0.036 | M13: 63000 | N13: — | O13: 23926 | P13: 48238.381 | Q13: =O13-P13 | R13: نسبة ثابتة من الصافي — نسبة ٢٠٪ ثابتة
B14: كورنيش جيزان | C14: JA069 | D14: 3363012 | E14: 4013901 | F14: =IF(D14=0,"—",E14/D14-1) | G14: 1721282 | H14: 2053365 | I14: =IF(G14=0,"—",H14/G14-1) | J14: 102022 | K14: 147356 | L14: 0.037 | M14: 84000 | N14: 15537 | O14: 36839 | P14: 60710.74 | Q14: =O14-P14 | R14: نسبة ثابتة من الصافي — نسبة ٢٥٪ ثابتة
B15: بن درويش | C15: MK023 | D15: 3038405 | E15: 2700766 | F15: =IF(D15=0,"—",E15/D15-1) | G15: 1548580 | H15: 1376226 | I15: =IF(G15=0,"—",H15/G15-1) | J15: 105623 | K15: 115715 | L15: 0.043 | M15: 49000 | N15: 3058 | O15: 23143 | P15: 41286.78 | Q15: =O15-P15 | R15: نسبة ثابتة من الصافي — نسبة ٢٠٪ ثابتة
B16: الكوثر | C16: MK100 | D16: 1410031 | E16: 1489789 | F16: =IF(D16=0,"—",E16/D16-1) | G16: 779165 | H16: 822350 | I16: =IF(G16=0,"—",H16/G16-1) | J16: 30204 | K16: 30859 | L16: 0.021 | M16: 42000 | N16: 4675 | O16: 6172 | P16: 20487.425 | Q16: =O16-P16 | R16: نسبة ثابتة من الصافي — نسبة ٢٠٪ ثابتة
B17: المودة الروابي | C17: JA056 | D17: 1070511 | E17: 1288142 | F17: =IF(D17=0,"—",E17/D17-1) | G17: 573437 | H17: 688372 | I17: =IF(G17=0,"—",H17/G17-1) | J17: 6204 | K17: 20580 | L17: 0.016 | M17: 42000 | N17: 11280 | O17: 4116 | P17: 18394.645 | Q17: =O17-P17 | R17: نسبة ثابتة من الصافي — نسبة ٢٠٪ ثابتة
B18: ممشى الشوقية | C18: MK020 | D18: 4536406 | E18: 4777169 | F18: =IF(D18=0,"—",E18/D18-1) | G18: 2309336 | H18: 2431417 | I18: =IF(G18=0,"—",H18/G18-1) | J18: 161698 | K18: 184802 | L18: 0.039 | M18: 80500 | N18: 30337 | O18: 60785 | P18: 72942.51 | Q18: =O18-P18 | R18: عمولة دون المعياري — عمولة ٠٫٠٢٥ بنزين · ٠٫٠١٥ ديزل — دون المعياري
B19: محطة طريق السيل | C19: MK054 | D19: 946016 | E19: 4149274 | F19: =IF(D19=0,"—",E19/D19-1) | G19: 512886 | H19: 2311916 | I19: =IF(G19=0,"—",H19/G19-1) | J19: 9059 | K19: 77515 | L19: 0.019 | M19: 94500 | N19: 6583 | O19: 49793 | P19: 53929.934 | Q19: =O19-P19 | R19: عمولة دون المعياري — عمولة ٠٫٠٣ بنزين · ٠٫٠١ ديزل — دون المعياري · ر١ جزئي ٢٠ يوماً
B20: الحليس | C20: MK046 | D20: 8130579 | E20: 8694181 | F20: =IF(D20=0,"—",E20/D20-1) | G20: 4437805 | H20: 4764070 | I20: =IF(G20=0,"—",H20/G20-1) | J20: 304825 | K20: 313375 | L20: 0.036 | M20: 126000 | N20: 13100 | O20: 116558 | P20: 119257.87 | Q20: =O20-P20 | R20: عمولة معيارية — عمولة ٠٫٠٣ بنزين · ٠٫٠١٥ ديزل
B21: الملك خالد | C21: MK093 | D21: 2616390 | E21: 2863669 | F21: =IF(D21=0,"—",E21/D21-1) | G21: 1355996 | H21: 1483276 | I21: =IF(G21=0,"—",H21/G21-1) | J21: 94729 | K21: 101451 | L21: 0.035 | M21: 52500 | N21: — | O21: 41708 | P21: 42386.947 | Q21: =O21-P21 | R21: عمولة دون المعياري — عمولة ٠٫٠٣ بنزين · ٠٫٠١ ديزل — دون المعياري
B22: أحلى مسا | C22: MK028 | D22: 7957528 | E22: 7010487 | F22: =IF(D22=0,"—",E22/D22-1) | G22: 4104111 | H22: 3624705 | I22: =IF(G22=0,"—",H22/G22-1) | J22: 362198 | K22: 267281 | L22: 0.038 | M22: 126000 | N22: 12809 | O22: 102784 | P22: 103220.42 | Q22: =O22-P22 | R22: عمولة معيارية — عمولة ٠٫٠٣ بنزين · ٠٫٠١٥ ديزل
B23: حائل العريفي | C23: HA043 | D23: 1406710 | E23: 1382515 | F23: =IF(D23=0,"—",E23/D23-1) | G23: 726195 | H23: 716645 | I23: =IF(G23=0,"—",H23/G23-1) | J23: 6648 | K23: 6521 | L23: 0.005 | M23: 63000 | N23: 12256 | O23: 20411 | P23: 20492.718 | Q23: =O23-P23 | R23: عمولة معيارية — عمولة ٠٫٠٣ · ٠٫٠١٥ — العمولة تتجاوز الربح فيخسر المالك
B24: الكر النازل | C24: MK084 | D24: 3125576 | E24: 2760743 | F24: =IF(D24=0,"—",E24/D24-1) | G24: 1634115 | H24: 1441961 | I24: =IF(G24=0,"—",H24/G24-1) | J24: 99193 | K24: 81831 | L24: 0.03 | M24: 73500 | N24: 11406 | O24: 40435 | P24: 40490.128 | Q24: =O24-P24 | R24: عمولة معيارية — عمولة ٠٫٠٣ بنزين · ٠٫٠١٥ ديزل
B25: مدخل محايل | C25: AS153 | D25: 0 | E25: 2835373 | F25: =IF(D25=0,"—",E25/D25-1) | G25: 0 | H25: 1470777 | I25: =IF(G25=0,"—",H25/G25-1) | J25: 0 | K25: 87704 | L25: 0.031 | M25: 51100 | N25: 4814 | O25: 41374 | P25: 41186.94 | Q25: =O25-P25 | R25: عمولة معيارية — عمولة ٠٫٠٣ · ٠٫٠١٥ — محطة جديدة في ر٢
B26: القادسية | C26: MK047 | D26: 8197921 | E26: 7796113 | F26: =IF(D26=0,"—",E26/D26-1) | G26: 4472655 | H26: 4234727 | I26: =IF(G26=0,"—",H26/G26-1) | J26: 314127 | K26: 305040 | L26: 0.039 | M26: 108500 | N26: 11847 | O26: 106868 | P26: 106333.6 | Q26: =O26-P26 | R26: عمولة معيارية — عمولة ٠٫٠٣ بنزين · ٠٫٠١٥ ديزل
B27: الجعرانة | C27: MK064 | D27: 4544806 | E27: 4422661 | F27: =IF(D27=0,"—",E27/D27-1) | G27: 2482613 | H27: 2394191 | I27: =IF(G27=0,"—",H27/G27-1) | J27: 129578 | K27: 119319 | L27: 0.027 | M27: 87500 | N27: 10335 | O27: 61224 | P27: 59997.256 | Q27: =O27-P27 | R27: عمولة معيارية — عمولة ٠٫٠٣ بنزين · ٠٫٠١٥ ديزل
B28: خليص | C28: MK014 | D28: 0 | E28: 0 | F28: =IF(D28=0,"—",E28/D28-1) | G28: 2173835 | H28: 2089097 | I28: =IF(G28=0,"—",H28/G28-1) | J28: 84146 | K28: 66940 | L28: — | M28: — | N28: — | O28: 66940 | P28: 42951.659 | Q28: =O28-P28 | R28: عمولة أعلى من المعياري — عمولة لتر فقط ٠٫٠٦ بنزين · ٠٫٠٢ ديزل — تحت مسمى نسبة المالك
B29: البيعة | C29: MK099 | D29: 0 | E29: 0 | F29: =IF(D29=0,"—",E29/D29-1) | G29: 778238 | H29: 894334 | I29: =IF(G29=0,"—",H29/G29-1) | J29: 45968 | K29: 52787 | L29: — | M29: — | N29: — | O29: 52787 | P29: 26530.414 | Q29: =O29-P29 | R29: عمولة أعلى من المعياري — عمولة لتر فقط ٠٫٠٦ بنزين · ٠٫٠١٥ ديزل — تحت مسمى نسبة المالك
B30: الجموم | C30: MK068 | D30: 0 | E30: 0 | F30: =IF(D30=0,"—",E30/D30-1) | G30: 1803115 | H30: 1708786 | I30: =IF(G30=0,"—",H30/G30-1) | J30: 130387 | K30: 120967 | L30: — | M30: — | N30: — | O30: 120967 | P30: 47666.324 | Q30: =O30-P30 | R30: عمولة أعلى من المعياري — عمولة لتر فقط ٠٫٠٨ بنزين · ٠٫٠٢ ديزل — تحت مسمى نسبة المالك
B31: الإجمالي | D31: =SUM(D5:D30) | E31: =SUM(E5:E30) | F31: =E31/D31-1 | G31: =SUM(G5:G30) | H31: =SUM(H5:H30) | I31: =H31/G31-1 | J31: =SUM(J5:J30) | K31: =SUM(K5:K30) | L31: =K31/E31 | M31: =SUM(M5:M30) | N31: =SUM(N5:N30) | O31: =SUM(O5:O30) | P31: =SUM(P5:P30) | Q31: =SUM(Q5:Q30)
A32: «المعياري» هو ما كانت حصّتنا ستكونه بعمولة درب المعيارية على حجم الربع الثاني، و«الفجوة» الفرقُ — كلاهما للربع لا للسنة. ومجموع الفجوة -283,218 للربع، أي -1,132,872 ريال في السنة — أكبر رقمٍ في الخطة كلها، ولا يحتاج لتراً إضافياً ولا حملة: يحتاج جلسة تفاوض على العقود. والصفوف الحمراء هي التي تتجاوز فجوتها ٥٠ ألف ريال في الربع.
A34: الخلاصة — الربع الثاني مقابل الأول على مستوى هذه المحطات
B35: المقياس | C35: الربع الأول | D35: الربع الثاني | E35: التغيّر | R35: القراءة
B36: المبيعات ريال | C36: 89366410 | D36: 96965869 | E36: =D36/C36-1 | R36: وهي مبيعات المحطات المشغّلة وحدها لا الشبكة
B37: الحجم لتر | C37: 52463828 | D37: 56354609 | E37: =D37/C37-1 | R37: الحجم يهبط أكثر من المبيعات — أي أن السعر المتوسط ارتفع بالمزيج
B38: صافي المحطات ريال | C38: 3263819 | D38: 3415378 | E38: =D38/C38-1
B39: عدد العمّال | C39: 513 | D39: 508 | E39: =D39/C39-1 | R39: قلّ مع الحجم — فالعمالة تُضبط فعلاً
B40: فجوة العمولة عن المعياري | C40: 1208470 | D40: 1491688 | E40: =C40-D40 | R40: حصّتنا الفعلية مقابل المعياري — والعمودان هنا ليسا ر١ و ر٢ بل الفعلي والمعياري للربع الثاني
A41: وفجوة الربع -283,218 ريالاً × أربعة أرباع = -1,132,872 ريال في السنة — وهو الرقم المعروض في الملخص.
A42: والقراءة الواحدة من الجدولين: الربع الثاني أضعف حجماً في أغلب المحطات، لكن الفارق الأكبر في صافينا ليس الحجم — هو بنود العقد. فمن يعالج هذا الربع بحملةٍ يعالج العَرَض.

Sheet العمرة — بيان يومي
A1: MK007 · العمرة الجديدة — البيان اليومي الوحيد لدينا
A2: كاش إن — تقرير محطة العمرة اليومي · 263 يوماً كاملاً (2026-01-01 → 2026-09-20) · 1,140,208 عملية · يوم 2026-09-21 ناقص فاستُبعد · وهي المحطة الوحيدة التي نملك لها بياناً بالساعة
A4: الحكم أولاً: هذه المحطة ليست في انحدار. مقابل يناير هي +9.2٪ معاملةً و+0.1٪ لتراً، ووسيط نظائرها في مكة +1.1٪. أمّا الـ−٢٢٪ المتداولة فهي قياسٌ على ذروة مارس، وذروة مارس موسم لا خطَّ أساس. وما بقي بعد الفرز فجوةٌ واحدة: ساعات الذروة المسائية.
A6: ① أي خط أساس تقيس عليه — هو ما يقرّر أترى أزمةً أم استواءً
B7: خط الأساس | C7: لتر/يوم | D7: معاملة/يوم | G7: الفرق لتراً | H7: الفرق معاملةً | K7: القراءة
B8: يناير — قبل الموسم | C8: 137112.16 | D8: 4321.9032 | G8: =C10/C8-1 | H8: =D10/D8-1 | K8: لا أزمة — الحال اليوم كحال يناير
B9: ذروة مارس ٣–١٦ | C9: 160932.04 | D9: 4735.7857 | G9: =C10/C9-1 | H9: =D10/D9-1 | K9: موسم لا خطَّ أساس — القياس عليه يصنع أزمةً ورقية
B10: آخر أربعة عشر يوماً | C10: 137223.89 | D10: 4719.4286 | G10: — | H10: — | K10: الحال اليوم
A11: والانحدار نفسه ليس شكل منافسة: من القمة 2026-03-09 إلى القاع 2026-05-04 انزلاقٌ في 56 يوماً لا هبوطٌ في ليلة. ورافقه هبوط حصة الديزل من 39٪ إلى 25٪ — وحجم التعبئة يُفسَّر بالمزيج لا يُطالَب به.
A13: ① ب · رقمان مختلفان عمداً — ولا تناقض بينهما
B14: الرقم | C14: في ورقة المحطات والحاسبة | D14: في هذه الورقة | K14: لماذا يختلفان
B15: النافذة المقيسة | C15: ٢١٢ يوماً · يناير–يوليو | D15: 82 يوماً · الربع الثالث | K15: ورقة المحطات تستعمل نافذة الشبكة كلها ليكون القياس واحداً عبر ٥٢ محطة
B16: زيارة/يوم | C16: 4260.64 | D16: 4538.9634 | K16: المحطة تعافت، فالنافذة الأحدث أعلى حركةً
B17: لتر لكل زيارة | C17: 30.562 | D17: 30.095004 | K17: وأقلّ سلّةً — لأن حصة الديزل لم تعُد إلى مستوى الربع الأول
B18: فجوة ساعات الذروة | C18: 90.9 | D18: 64.671467 | K18: والفجوة الأحدث أصغر لأن التعافي أغلق جزءاً منها فعلاً
A19: فمن يخطّط للشبكة يستعمل ورقة المحطات — نافذتها واحدة لكل محطة. ومن يخطّط لهذه المحطة وحدها يستعمل هذه الورقة — نافذتها أحدث. والرقم الأصغر هنا ليس تحفّظاً: هو ما بقي من الفجوة بعد التعافي.
A21: ② الأرباع — معدّلات يومية، فالأرباع غير متساوية الطول
B22: المقياس | C22: الربع الأول | D22: الربع الثاني | E22: الربع الثالث | G22: ر١←ر٢ | H22: ر٢←ر٣ | I22: ر١←ر٣ | K22: القراءة
B23: أيام مقيسة | C23: 90 | D23: 91 | E23: 82 | G23: — | H23: — | I23: — | K23: —
B24: معاملات/يوم | C24: 4560.3667 | D24: 3914.4396 | E24: 4538.9634 | G24: =D24/C24-1 | H24: =E24/D24-1 | I24: =E24/C24-1 | K24: عادت فوق مستوى الربع الأول
B25: لترات/يوم | C25: 148118.02 | D25: 111676.99 | E25: 136600.12 | G25: =D25/C25-1 | H25: =E25/D25-1 | I25: =E25/C25-1 | K25: دونه قليلاً — والفارق مزيج لا حركة
B26: مبيعات/يوم | C26: 308601.08 | D26: 239741.46 | E26: 288090.38 | G26: =D26/C26-1 | H26: =E26/D26-1 | I26: =E26/C26-1
B27: لتر لكل معاملة | C27: 32.47941 | D27: 28.529497 | E27: 30.095004 | G27: =D27/C27-1 | H27: =E27/D27-1 | I27: =E27/C27-1 | K27: يتحرّك مع حصة الديزل لا مع سلوك العميل
B28: متوسط الفاتورة | C28: 67.670234 | D28: 61.245412 | E28: 63.470523 | G28: =D28/C28-1 | H28: =E28/D28-1 | I28: =E28/C28-1
B29: حصة الديزل من اللترات | C29: 0.38644075 | D29: 0.25382853 | E29: 0.33255858 | G29: =D29-C29 | H29: =E29-D29 | I29: =E29-C29 | K29: المتغيّر الأكبر — وسلّة الديزل ضعف البنزين
B30: فواتير ٦٠ ريالاً فأكثر | C30: 0.41111217 | D30: 0.37621767 | E30: 0.38981717 | G30: =D30-C30 | H30: =E30-D30 | I30: =E30-C30
B31: حصة النقدي من المبيعات | C31: 0.58147608 | D31: 0.40624223 | E31: 0.45319285 | G31: =D31-C31 | H31: =E31-D31 | I31: =E31-C31 | K31: هبطت ١٣ نقطة في أبريل ولم تعُد — تغيّر قنوات لا تغيّر عميل
B32: حصة الوردية المسائية | C32: 0.59077852 | D32: 0.60886714 | E32: 0.60502693 | G32: =D32-C32 | H32: =E32-D32 | I32: =E32-C32 | K32: ثابتة نحو ٦٠٪ في الأرباع الثلاثة
B33: زمن الخدمة | C33: 101.14781 | D33: 97.815178 | E33: 106.20121 | G33: =D33/C33-1 | H33: =E33/D33-1 | I33: =E33/C33-1 | K33: ارتفع في الربع الثالث مع ارتفاع الحركة
A34: وأعمدة الفرق تُقرأ بحسب سطرها: صفوف الأعداد (معاملات · لترات · مبيعات · لتر لكل معاملة) فرقُها نسبةٌ مئوية، وصفوف النسب (ديزل · نقدي · مسائية · ٦٠ فأكثر) فرقُها نقاطٌ مئوية.
A35: اقرأ السطرين معاً: المعاملات ر١←ر٣ موجبة واللترات سالبة. أي أن عدد العملاء لم ينقص — نقصت لترات الفاتورة، ونقصت لأن الديزل نقص. ومن يبني حملةً على «تراجع المبيعات» هنا يبيع لعميلٍ لم يذهب أصلاً.
A37: ③ المنتجات — أين تحرّك المزيج بالضبط
B38: المنتج | C38: ر١ لتر/يوم | D38: ر٢ لتر/يوم | E38: ر٣ لتر/يوم | G38: حصة ر١ | H38: حصة ر٣ | I38: الفرق | K38: لتر/معاملة ر٣
B39: بنزين ٩١ | C39: 47431.277 | D39: 42009.227 | E39: 47018.937 | G39: 0.32022624 | H39: 0.3442086 | I39: =H39-G39 | K39: 22.149439
B40: بنزين ٩٥ | C40: 43447.918 | D40: 41320.962 | E40: 44153.644 | G40: 0.2933331 | H40: 0.32323283 | I40: =H40-G40 | K40: 26.815476
B41: ديزل | C41: 57238.839 | D41: 28346.807 | E41: 45427.543 | G41: 0.38644075 | H41: 0.33255858 | I41: =H41-G41 | K41: 59.028595
B42: الإجمالي | C42: =SUM(C39:C41) | D42: =SUM(D39:D41) | E42: =SUM(E39:E41) | G42: =SUM(G39:G41) | H42: =SUM(H39:H41) | K42: 30.095004
A43: سلّة الديزل 59.0 لتراً مقابل 22.1 للبنزين ٩١ — فنقطةٌ واحدة من حصة الديزل تُحرّك لتر الفاتورة أكثر مما يُحرّكه أي عرضٍ تسويقي.
A45: ④ قنوات الدفع — ما تغيّر في أبريل ليس عميلاً بل نظاماً
B46: القناة | C46: أول ظهور | D46: آخر ظهور | E46: أيام | G46: حصة ر١ | H46: حصة ر٢ | I46: حصة ر٣ | K46: القراءة
...

Sheet الساعة والوردية
A1: الساعة والوردية — أين الفجوة بالضبط، وفي أي وردية
A2: العمرة بالساعة (المحطة الوحيدة) ثم 40 محطة بالوردية · المقارنة بشكل تصنيف «حيوية» — وسيط 25 محطة
A4: ① العمرة — الفجوة لكل ساعة
B5: الساعة | C5: فعلي/يوم | D5: حصتنا | E5: شكل التصنيف | F5: المتوقَّع/يوم | H5: الفجوة | I5: ذروة؟ | J5: الوردية | K5: ملاحظة
B6: 00:٠٠ | C6: 226.08537 | D6: 0.049809911 | E6: 0.049378873 | F6: =E6*4538.9634 | H6: =MAX(0,F6-C6) | I6: ★ | J6: صباحية
B7: 01:٠٠ | C7: 166.87805 | D7: 0.036765674 | E7: 0.037044531 | F7: =E7*4538.9634 | H7: =MAX(0,F7-C7) | J7: صباحية
B8: 02:٠٠ | C8: 130.23171 | D8: 0.028691949 | E8: 0.030223245 | F8: =E8*4538.9634 | H8: =MAX(0,F8-C8) | J8: صباحية
B9: 03:٠٠ | C9: 105.12195 | D9: 0.023159903 | E9: 0.022824313 | F9: =E9*4538.9634 | H9: =MAX(0,F9-C9) | J9: صباحية
B10: 04:٠٠ | C10: 90.402439 | D10: 0.019916979 | E10: 0.018420833 | F10: =E10*4538.9634 | H10: =MAX(0,F10-C10) | J10: صباحية
B11: 05:٠٠ | C11: 123.79268 | D11: 0.027273338 | E11: 0.023482439 | F11: =E11*4538.9634 | H11: =MAX(0,F11-C11) | J11: صباحية
B12: 06:٠٠ | C12: 162.52439 | D12: 0.035806499 | E12: 0.034333024 | F12: =E12*4538.9634 | H12: =MAX(0,F12-C12) | J12: صباحية
B13: 07:٠٠ | C13: 173.73171 | D13: 0.038275635 | E13: 0.040036313 | F13: =E13*4538.9634 | H13: =MAX(0,F13-C13) | J13: صباحية
B14: 08:٠٠ | C14: 162.79268 | D14: 0.035865608 | E14: 0.034517165 | F14: =E14*4538.9634 | H14: =MAX(0,F14-C14) | J14: صباحية
B15: 09:٠٠ | C15: 149.70732 | D15: 0.032982711 | E15: 0.032267179 | F15: =E15*4538.9634 | H15: =MAX(0,F15-C15) | J15: صباحية
B16: 10:٠٠ | C16: 155.28049 | D16: 0.034210562 | E16: 0.032097599 | F16: =E16*4538.9634 | H16: =MAX(0,F16-C16) | J16: صباحية
B17: 11:٠٠ | C17: 146.21951 | D17: 0.032214296 | E17: 0.03033723 | F17: =E17*4538.9634 | H17: =MAX(0,F17-C17) | J17: صباحية
B18: 12:٠٠ | C18: 157.09756 | D18: 0.034610889 | E18: 0.032258593 | F18: =E18*4538.9634 | H18: =MAX(0,F18-C18) | J18: مسائية
... B21: 15:٠٠ | C21: 210.34146 | D21: 0.0463413 | E21: 0.04090588 | F21: =E21*4538.9634 | H21: =MAX(0,F21-C21) | J21: مسائية
B22: 16:٠٠ | C22: 231.91463 | D22: 0.051094185 | E22: 0.052718114 | F22: =E22*4538.9634 | H22: =MAX(0,F22-C22) | I22: ★ | J22: مسائية
B23: 17:٠٠ | C23: 278.18293 | D23: 0.061287766 | E23: 0.063531117 | F23: =E23*4538.9634 | H23: =MAX(0,F23-C23) | I23: ★ | J23: مسائية
B24: 18:٠٠ | C24: 266.5 | D24: 0.058713846 | E24: 0.055930719 | F24: =E24*4538.9634 | H24: =MAX(0,F24-C24) | I24: ★ | J24: مسائية
B25: 19:٠٠ | C25: 257.52439 | D25: 0.056736388 | E25: 0.05749562 | F25: =E25*4538.9634 | H25: =MAX(0,F25-C25) | I25: ★ | J25: مسائية
B26: 20:٠٠ | C26: 257.13415 | D26: 0.056650412 | E26: 0.059743013 | F26: =E26*4538.9634 | H26: =MAX(0,F26-C26) | I26: ★ | J26: مسائية
B27: 21:٠٠ | C27: 264.04878 | D27: 0.058173807 | E27: 0.06160965 | F27: =E27*4538.9634 | H27: =MAX(0,F27-C27) | I27: ★ | J27: مسائية
B28: 22:٠٠ | C28: 251.30488 | D28: 0.055366139 | E28: 0.058459252 | F28: =E28*4538.9634 | H28: =MAX(0,F28-C28) | I28: ★ | J28: مسائية
B29: 23:٠٠ | C29: 190.20732 | D29: 0.041905453 | E29: 0.050639231 | F29: =E29*4538.9634 | H29: =MAX(0,F29-C29) | J29: مسائية | K29: ساعة تسليم الورديات
B30: المجموع | C30: =SUM(C6:C29) | D30: =SUM(D6:D29) | E30: =SUM(E6:E29) | F30: =SUM(F6:F29) | H30: =SUM(H6:H29)
A49: الساعة 23:٠٠ فيها 40 معاملة/يوم فاقداً — أكبر من أي ساعة ذروة. وتسقط من الرقم المحافظ (65 معاملة/يوم) لأنها ليست ضمن ساعاتنا الثماني الأعلى، وليست كذلك لأننا ننخفض فيها. وشكاوى المحطة تذكر تسليم الورديات صراحةً سبباً للتأخير عند منتصف الليل. فإغلاقها يُختبر أولاً بتغيير موعد التسليم — لا بحملة.
A51: ② العمرة — الوردية: الفجوة كلّها في جهةٍ واحدة
B52: المقياس | C52: الصباحية ٠٠–١١ | D52: المسائية ١٢–٢٣ | E52: الإجمالي | K52: القراءة
B53: معاملات/يوم | C53: 1792.7683 | D53: 2746.1951 | E53: =C53+D53 | K53: المسائية ٦٠٪ من الطلب
B54: عدد العمّال | C54: 11 | D54: 9 | E54: =C54+D54 | K54: وهي ٤٥٪ من العمالة — الطلب في جهةٍ والطاقم في أخرى
B55: معاملات لكل عامل | C55: =C53/C54 | D55: =D53/D54 | E55: =E53/E54 | K55: العامل المسائي يخدم 1.87× ما يخدمه الصباحي
B56: الفجوة في ساعات الذروة | C56: 0 | D56: 64.671467 | E56: =C56+D56 | K56: الرقم المؤكَّد — وكلّه في المسائية
B57: الفجوة في كل الساعات | C57: 16.207871 | D57: 104.31376 | E57: =C57+D57 | K57: يشمل ساعة تسليم الورديات وساعات الهدوء — لا يُطالَب به
B58: العدد المتوازن للعمّال | C58: 7.8994613 | D58: 12.100539 | E58: =C58+D58 | K58: أي نقل 3 عمّال من الصباحية إلى المسائية — بلا توظيف
A59: وسعة الخدمة تؤكّد القراءة: زمن الخدمة المقيس 106 ثانية، فالعامل الواحد يخدم 34 معاملة في الساعة نظرياً، و9 عمّال يخدمون 305. وساعة الذروة (17:٠٠) فيها 278 معاملة — أي 91٪ من السعة. والمحطة عند هذا الحدّ لا تُزاد مبيعاتها بعرضٍ بل بيدٍ إضافية أو بخدمةٍ أسرع.
A61: ③ الشبكة — 40 محطة عليها بيان وردية · اختلال الحِمل وقابلية النقل
B62: المحطة | C62: التصنيف | D62: عمّال | E62: حصة الطلب المسائية | F62: حصة العمالة المسائية | H62: الاختلال | I62: حِمل صباحي | J62: حِمل مسائي | K62: عمّال قابلون للنقل
B63: كورنيش الخبر | C63: حيوية | D63: 5 | E63: 0.67946178 | F63: 0.50457195 | H63: =E63-F63 | I63: 78.249467 | J63: 162.86362 | K63: 0.87444916
...

Sheet كلفة اللتر والمستهدف
A1: كلفة اللتر — لا قيمته
A2: القيمة تُقاس بالهامش، والتكلفة بما نُخرجه من جيبنا لنبيع لتراً: شراؤه ثم تشغيل المحطة التي باعته ثم ما يُحمَّل عليه من المركز · المصدر: قائمة الدخل · 141 محطة · 662 مليون لتر
A4: ① الطبقات الأربع — هللة لكل لتر، وبتفصيل نموذج العمل
B5: الطبقة | C5: الشبكة | D5: استثماري | E5: إيجاري | F5: تشغيلي | G5: امتياز | I5: ألف ريال | J5: ما تعنيه
B6: شراء الوقود | C6: 171.41436 | D6: 178.15251 | E6: 177.31918 | F6: 179.1296 | G6: 165.23774 | I6: 1133906 | J6: ما ندفعه لأرامكو — لا نملك فيه قراراً
B7: تشغيل المحطة | C7: 4.3212396 | D7: 11.075163 | E7: 5.6344916 | F7: 9.8413598 | G7: 0.041049031 | I7: 28585 | J7: أجور ومرافق وصيانة — هنا وحدها تُضبط التكلفة
B8: بيع وتسويق | C8: 0.3611489 | D8: 0.6503268 | E8: 0.76833977 | F8: 0.50779037 | G8: 0.13625998 | I8: 2389 | J8: محمّل من المركز
B9: عمومية وإدارية | C9: 1.7662887 | D9: 3.1819172 | E9: 3.7593308 | F9: 2.4822946 | G9: 0.66619156 | I9: 11684 | J9: محمّل من المركز
B10: فوائد القروض | C10: 0.46016629 | D10: 0.82897603 | E10: 0.97940798 | F10: 0.64660057 | G10: 0.17360319 | I10: 3044 | J10: محمّل من المركز
B11: مجموع الكلفة | C11: =SUM(C6:C10) | D11: =SUM(D6:D10) | E11: =SUM(E6:E10) | F11: =SUM(F6:F10) | G11: =SUM(G6:G10) | I11: =SUM(I6:I10)
A12: ٩٧٪ من كلفة اللتر شراؤه من أرامكو — ولا قرار لنا فيه. والقرار كلّه في الطبقة الثانية: تشغيل المحطة. ولذلك لا يُقاس أداء التجاري على الطبقة الأولى ولا يُلام عليها. ⚠ ولا يُطرح هذا الجدول من جدول ② أدناه: هامش المساهمة هناك محسوبٌ بعد الطبقة الأولى أصلاً، فطرحُها ثانيةً يحتسبها مرتين.
A14: ② قيمة اللتر بالمنتج — الهامش ليس واحداً
B15: المنتج | C15: سعر المضخة | D15: قبل الضريبة | E15: هامش اللتر | F15: خصم التشغيل | G15: الصافي | I15: الوزن في المزيج | J15: الملاحظة
B16: بنزين ٩١ | C16: 2.191 | D16: 1.9052174 | E16: 12.66 | F16: -9.15 | G16: =E16+F16 | I16: 0.555 | J16: من انحدار ١٩ محطة — لا من جدول معتمد
B17: بنزين ٩٥ | C17: 2.34 | D17: 2.0347826 | E17: 12.66 | F17: -9.15 | G17: =E17+F17 | I17: 0.36 | J17: من انحدار ١٩ محطة — لا من جدول معتمد
B18: ديزل | C18: 1.796 | D18: 1.5617391 | E18: 4.47 | F18: -9.15 | G18: =E18+F18 | I18: 0.085 | J18: من انحدار ١٩ محطة — لا من جدول معتمد
B19: المرجَّح بالمزيج | E19: =SUMPRODUCT(E16:E18,$I$16:$I$18) | F19: -9.15 | G19: =E19+F19 | I19: =SUM(I16:I18)
A20: ⛔ تحفُّظ صريح: هامشا البنزين (12.66 هللة) والديزل (4.47) مستنتجان بانحدار هامش ١٩ محطة على حصة ديزلها، وأقصى حصة ديزل مرصودة ٤٣٪ — فرقم الديزل استقراءٌ خارج المدى لا قياس. ويسنده هيكل عمولتنا (٣ هللات بنزين · ١٫٥ ديزل) ولا يغني عن جدول هامش معتمد من المالية.
A22: ③ داخل «تشغيل المحطة» — أجورٌ ومرافق، لأعلى وأدنى المحطات
B23: المحطة | C23: الرمز | D23: لتر الربع | E23: عمّال | F23: أجر/لتر | G23: مرافق/لتر | I23: لتر لكل عامل | J23: القراءة
B24: حائل العريفي | C24: HA043 | D24: 716645 | E24: 18 | F24: 8.7909634 | G24: 1.7101912 | I24: 39813.611 | J24: أعلى خمس كلفةَ عمالة
B25: المودة الروابي | C25: JA056 | D25: 688372 | E25: 12 | F25: 6.1013522 | G25: 1.6386489 | I25: 57364.333 | J25: أعلى خمس كلفةَ عمالة
B26: صبيا خبت نخلان | C26: JA053 | D26: 1325693 | E26: 21 | F26: 5.5442701 | G26: 0 | I26: 63128.238 | J26: أعلى خمس كلفةَ عمالة
B27: الكوثر | C27: MK100 | D27: 822350 | E27: 12 | F27: 5.1073144 | G27: 0.56849273 | I27: 68529.167 | J27: أعلى خمس كلفةَ عمالة
B28: الكر النازل | C28: MK084 | D28: 1441961 | E28: 21 | F28: 5.0972252 | G28: 0.79100614 | I28: 68664.81 | J28: أعلى خمس كلفةَ عمالة
B29: الحليس | C29: MK046 | D29: 4764070 | E29: 36 | F29: 2.6447974 | G29: 0.27497497 | I29: 132335.28 | J29: أدناها
B30: القادسية | C30: MK047 | D30: 4234727 | E30: 31 | F30: 2.5621486 | G30: 0.27975829 | I30: 136604.1 | J30: أدناها
B31: الجمعية | C31: MK035 | D31: 2468597 | E31: 18 | F31: 2.5520569 | G31: 0.19857433 | I31: 137144.28 | J31: أدناها
A32: ⛔ ومعدّل الأجر في هذا التقرير ليس مقيساً: الأجور ÷ عدد العمّال = ٣٬٥٠٠ ريالاً بالضبط في ٢١ محطة بلا استثناء واحد — أي أنه سعرٌ ثابت يُضرب في العدد، وهو أجرٌ شهري طُبِّق مرة بدل ثلاث. ولذلك مصاريف التقرير ٤٫٨٦ هللة بينما قائمة الدخل تقول ٩٫١٥ للمحطات نفسها — ٢٫٠٢×. فالقائمة هي المرجع، والتقرير للمقارنة النسبية بين المحطات لا لمستوى الكلفة المطلق.
A34: ④ ما لم يدخل الحساب لأنه غير مقيس — ولا يُملأ بتقدير
B35: البند | C35: الحالة | G35: لماذا يهمّ | J35: المالك
B36: رسوم البطاقات | C36: غير مقيسة | G36: 55٪ من المبيعات بطاقةٌ اليوم بعد أن كانت 42٪ — والرسم غير معروف لنا | J36: المالية — جدول رسوم مدى/فيزا
B37: الفروقات والفاقد | C37: غير مقيسة | G37: لا جرد خزانات في بياناتنا — والفرق يظهر هامشاً لا كلفة | J37: العمليات — جرد شهري
B38: النقل والتوريد | C38: غير مقيسة | G38: من يتحمّل أجرة الناقلة غير محسوم في أي ملف لدينا | J38: سلسلة الإمداد
A39: وهذه البنود تُقتطع من هامش كل لتر إضافي، فكلّما بقيت غير مقيسة بقي الصافي أعلى مما هو. والفرق بينها وبين التقدير أنها مكتوبة هنا باسمها وباسم من يملك سدّها.

Sheet خطة المستهدف
A1: خطة المستهدف — بالمعاملات لا باللترات
A2: المطلوب من الوردية عددُ عملاء تخدمهم لا لترات يضخّونها: اللترات تتبع المزيج ولا يملكها العامل
A4: ⛔ قبل أي مستهدف: البوابات تُقفل أولاً. والمستهدف أدناه صالحٌ للحساب والعرض، ولا يُحمَّل على وردية قبل إقرار جدول الورديات من العمليات.
A6: ① الشبكة — المستهدف بالتصنيف
B7: التصنيف | C7: محطات | D7: دون المتوقَّع | E7: فجوة الذروة | F7: فاقد السلة لتر/يوم | H7: قيمة المعاملات | I7: قيمة السلة | K7: المحرّك الأول والفعل
B8: حيوية | C8: 25 | D8: 18 | E8: 400.8012 | F8: 30707.648 | H8: 438083.09 | I8: 1294937.6 | K8: تغطية ساعات الذروة — طاقم الذروة · توفّر المضخات · سرعة الخدمة
B9: خط سفر | C9: 8 | D9: 5 | E9: 153.50912 | F9: 12336.258 | H9: 190711.45 | I9: 372255.76 | K9: التعاقد وسلة التعبئة — عقود ديزل متدرجة · خدمات شاحنات · ممر سريع
B10: حي | C10: 8 | D10: 5 | E10: 62.22889 | F10: 6941.3434 | H10: 57641.781 | I10: 292583.03 | K10: التردد — ساعات العمل · مزيج المستأجرين · سرعة الذروة
B11: مختلط | C11: 8 | D11: 4 | E11: 140.81259 | F11: 8729.8908 | H11: 157729.68 | I11: 366882.12 | K11: فصل الطلبين — عرض للسكّان وآخر للعابرين · لا رسالة واحدة
B12: نائية | C12: 3 | D12: 1 | E12: 9.8823495 | F12: 123.62484 | H12: 9158.0056 | I12: 5096.0104 | K12: حماية الربحية — ضبط العمالة · تأجير الوحدات · لا إنفاق تسويقي
B13: الإجمالي | C13: =SUM(C8:C12) | D13: =SUM(D8:D12) | E13: =SUM(E8:E12) | F13: =SUM(F8:F12) | H13: =SUM(H8:H12) | I13: =SUM(I8:I12)
A14: وفاقد ساعات الهدوء 1,880 معاملة/يوم غير مُدرَج عمداً: النقص في ساعات الهدوء اختلاف طلبٍ لا فاقد، ولا يُطالَب به من لا يملكه.
A16: ② أعلى خمس عشرة محطة قيمةً — ومن يملك كلاً منها
B17: المحطة | C17: التصنيف | D17: فجوة الذروة | E17: فجوة السلة | F17: الإجمالي ر/سنة | H17: المطلوب/يوم | I17: قيمة الإغلاق | K17: الفعل والبوابة
B18: جنوب صبيا | C18: مختلط | D18: 12.7745 | E18: 9.6696525 | F18: 243898.42 | H18: =D18*0.4 | I18: =F18*0.4 | K18: عرض للسكّان وآخر للعابرين · لا رسالة واحدة
B19: أبو وافي العمرة | C19: خط سفر | D19: 13.271917 | E19: 12.613827 | F19: 233607.63 | H19: =D19*0.4 | I19: =F19*0.4 | K19: عقود ديزل متدرجة · خدمات شاحنات · ممر سريع
B20: الصفا - أحد المسارحة | C20: حيوية | D20: 6.5229517 | E20: 5.4777198 | F20: 185886.15 | H20: =D20*0.4 | I20: =F20*0.4 | K20: طاقم الذروة · توفّر المضخات · سرعة الخدمة
B21: الحسينية | C21: حي | D21: 37.024554 | E21: 4.3350058 | F21: 168714.41 | H21: =D21*0.4 | I21: =F21*0.4 | K21: ⛔ فجوة مطابقة · فاقد ذروة · سلة دون المتوقَّع
B22: الفلاح - فلسطين | C22: حيوية | D22: 13.851714 | E22: 7.1336947 | F22: 144598.29 | H22: =D22*0.4 | I22: =F22*0.4 | K22: طاقم الذروة · توفّر المضخات · سرعة الخدمة
B23: جبل النور | C23: حيوية | D23: 5.6639567 | E23: 3.853757 | F23: 137073.56 | H23: =D23*0.4 | I23: =F23*0.4 | K23: ⛔ بيانات دفع مفقودة · سلة دون المتوقَّع
B24: الأجاويد | C24: حيوية | D24: 17.046337 | E24: 7.3412819 | F24: 125852.43 | H24: =D24*0.4 | I24: =F24*0.4 | K24: طاقم الذروة · توفّر المضخات · سرعة الخدمة
B25: الرصيفة | C25: حيوية | D25: 6.2631001 | E25: 3.846477 | F25: 116917.84 | H25: =D25*0.4 | I25: =F25*0.4 | K25: ⛔ بيانات دفع مفقودة · سلة دون المتوقَّع
B26: العوالي | C26: خط سفر | D26: 91.427843 | E26: 0 | F26: 114725.99 | H26: =D26*0.4 | I26: =F26*0.4 | K26: عقود ديزل متدرجة · خدمات شاحنات · ممر سريع
B27: ممشى الشوقية | C27: حيوية | D27: 12.125832 | E27: 3.9435974 | F27: 110028.05 | H27: =D27*0.4 | I27: =F27*0.4 | K27: ⛔ بيانات دفع مفقودة · سلة دون المتوقَّع
B28: عاصفة الصحراء | C28: حيوية | D28: 80.544537 | E28: 0 | F28: 107317.78 | H28: =D28*0.4 | I28: =F28*0.4 | K28: طاقم الذروة · توفّر المضخات · سرعة الخدمة
B29: الرصيفة المسار | C29: حيوية | D29: 13.77089 | E29: 5.4724272 | F29: 105134.18 | H29: =D29*0.4 | I29: =F29*0.4 | K29: طاقم الذروة · توفّر المضخات · سرعة الخدمة
... B32: الجعرانة | C32: حي | D32: 8.4650876 | E32: 5.3797824 | F32: 95404.013 | H32: =D32*0.4 | I32: =F32*0.4 | K32: ساعات العمل · مزيج المستأجرين · سرعة الذروة
B33: مجموع الخمس عشرة | D33: =SUM(D18:D32) | E33: =SUM(E18:E32) | F33: =SUM(F18:F32) | H33: =SUM(H18:H32) | I33: =SUM(I18:I32)
A35: ③ القياس قبل التنفيذ — بأي رقم نحكم ومتى
B36: السؤال | C36: الجواب | K36: لماذا
B37: ما الرقم الذي نحكم به؟ | C37: معاملات ساعات ذروة المحطة وحدها — لا مبيعاتها كلها | K37: مبيعات المحطة تتحرّك بالمزيج والموسم، وهما خارج يد الوردية
B38: مقابل أي خط أساس؟ | C38: الأسابيع الأربعة السابقة للتنفيذ في المحطة نفسها | K38: المقارنة بالعام الماضي تخلط الموسم بالأثر
B39: متى نحكم؟ | C39: بعد ستة أسابيع — ثم كل شهر | K39: أقصر من ذلك يقرأ التشتّت أثراً
B40: ما حدّ الأثر المقبول؟ | C40: أكثر من 8.8٪ — وهو تشتّت خط الأساس المقيس | K40: ما دونه لا يُحسب أثراً مهما بدا موجباً
B41: من يملك الرقم؟ | C41: مدير المحطة للتنفيذ · التجاري للقياس · العمليات للطاقم | K41: الهدف بلا مالكٍ واحد لا يُقاس ولا يُحاسَب عليه
B42: ما الذي لا نطالب به؟ | C42: لترات الفاتورة الواحدة | K42: ثلثا تباينها مزيج وقود لا سلوك — تُفسَّر ولا تُطلَب
A43: ما لا يُصمَّم قياسه قبلاً تُنسب نتيجته بعداً إلى أي سبب. والسؤال الكاشف لأي خطة: ما آخر هدفٍ بيعيّ رفضتَه، ولماذا؟

Sheet المنافسون بالمنتج
A1: لكل منتج منافسٌ مختلف ومقياسٌ مختلف ومصدرُ بيانات مختلف
A2: ولا يُجمعون في جدول واحد — فمن يقارن وقود الأفراد بالعقار يقارن سوقين لا منافسين
A4: ① وقود الأفراد — المسح الميداني حول محطاتنا
B5: العلامة | C5: مواقع | D5: الحصة | E5: أقرب مسافة م | F5: وسيط المسافة م | H5: التقييم | J5: الملاحظة
B6: الدريس | C6: 16 | D6: 0.4 | E6: 411 | F6: 1517 | H6: 3.76875 | J6: 42 مراجعة — وسيط
B7: مستقلة/أخرى | C7: 13 | D7: 0.325 | E7: 181 | F7: 1967 | H7: 3.8769231 | J7: 268 مراجعة — وسيط
B8: بتروجين | C8: 3 | D8: 0.075 | E8: 923 | F8: 1165 | H8: 3.4 | J8: 18 مراجعة — وسيط
B9: ساسكو | C9: 3 | D9: 0.075 | E9: 1701 | F9: 1806 | H9: 4 | J9: 21 مراجعة — وسيط
B10: أومكو | C10: 3 | D10: 0.075 | E10: 1755 | F10: 2116 | H10: 3.2 | J10: 108 مراجعة — وسيط
B11: نفط | C11: 2 | D11: 0.05 | E11: 695 | F11: 1038 | H11: 3 | J11: 6 مراجعة — وسيط
B12: درب | C12: 79 | H12: 4.86 | J12: فارقنا +1.15 نجمة
A13: ⛔ وهنا الفحص الثاني: تقييمنا 4.86★ مقابل 3.71 للمنافسين، وهو ثابتٌ على المواقع كلها. والنمو فيها يمتدّ من +7٪ إلى -53٪. وما يستقرّ لا يفسّر ما يتباين — فأياً كان محرّك النتيجة فليس هو التفوّق الخدمي. وارتباط فجوة التقييم بالنمو -0.32 على 40 موقعاً، وارتباط عدد المنافسين بالنمو -0.27: لا شيء في كليهما.
A15: ② وقود الشركات — والتصنيف بحجم السلة لا بالاسم
B16: القناة | C16: الإيراد ريال | D16: الزيارات | E16: متوسط الفاتورة | F16: الحصة | H16: التصنيف | J16: الدليل
B17: غير مسجَّلة | C17: 2.2631218e+08 | D17: 4072181 | E17: =C17/D17 | F17: 0.36124537 | H17: غير مسجَّلة | J17: وسيلة الدفع غير مسجَّلة — بوابة بيانات
B18: نقدي | C18: 1.8455862e+08 | D18: 3554445 | E18: =C18/D18 | F18: 0.29459725 | H18: نقاط بيع | J18: سلّتها بحجم النقدي — جهاز نقاط بيع لا أسطول
B19: شبكة (مدى) | C19: 1.792363e+08 | D19: 2805314 | E19: =C19/D19 | F19: 0.28610163 | H19: نقاط بيع | J19: سلّتها بحجم النقدي — جهاز نقاط بيع لا أسطول
B20: جهاز خارجي | C20: 24405655 | D20: 447764 | E20: =C20/D20 | F20: 0.038956939 | H20: نقاط بيع | J20: سلّتها بحجم النقدي — جهاز نقاط بيع لا أسطول
B21: تطبيق سيارة | C21: 7751172.9 | D21: 51926 | E21: =C21/D21 | F21: 0.012372623 | H21: أسطول | J21: سلّتها ثلاثة أضعاف النقدي — قناة أسطول
B22: تطبيق بترو | C22: 4205482.7 | D22: 24473 | E22: =C22/D22 | F22: 0.0067129004 | H22: أسطول | J22: سلّتها ثلاثة أضعاف النقدي — قناة أسطول
B23: بطاقة ذكية | C23: 8008.66 | D23: 166 | E23: =C23/D23 | F23: 1.2783631e-05 | H23: نقاط بيع | J23: سلّتها بحجم النقدي — جهاز نقاط بيع لا أسطول
B24: محفظة كاش إن | C24: 318 | D24: 8 | E24: =C24/D24 | F24: 5.0759984e-07 | H24: نقاط بيع | J24: سلّتها بحجم النقدي — جهاز نقاط بيع لا أسطول
A25: «الجهاز الخارجي» اسمٌ يوحي بقناة أسطول، وفاتورته 54.50 ريالاً — بحجم النقدي 51.92. فهو جهاز نقاط بيع. وحين حُسب أسطولاً انتفخت حصة الأسطول في كورنيش الخبر من ٠٫٩٪ الحقيقية إلى ٥١٫٣٪، فانتفخت معها شريحةٌ كاملة.
A27: ③ العقار والتأجير — بديل المستأجر لا متر المربّع
B28: الصيغة | C28: الوحدات | D28: المؤجَّرة | E28: الشاغرة | F28: الإشغال | J28: بديل المستأجر
B29: أسواق | C29: 110 | D29: 56 | E29: 54 | F29: =D29/C29 | J29: بقالة الحي
B30: أكشاك | C30: 415 | D30: 201 | E30: 214 | F30: =D30/C30 | J30: عربة أو كشك في ساحة تجارية
B31: سيّاقة | C31: 155 | D31: 69 | E31: 86 | F31: =D31/C31 | J31: لا بديل: نافذة السيّاقة تحتاج مسار سيارات
B32: مغاسل | C32: 266 | D32: 117 | E32: 149 | F32: =D32/C32 | J32: مغسلة حي مستقلة — لكن بلا حركة مرور مضمونة
B33: أخرى | C33: 23 | D33: 6 | E33: 14 | F33: =D33/C33 | J33: —
B34: محلات | C34: 764 | D34: 192 | E34: 572 | F34: =D34/C34 | J34: محل على شارع الحي — أوفر إيجاراً وأقرب للسكن
B35: الإجمالي | C35: =SUM(C29:C34) | D35: =SUM(D29:D34) | E35: =SUM(E29:E34) | F35: =D35/C35
A36: المحل هو الصيغة الوحيدة التي يملك مستأجرها مقارنةً يخسرها موقعُنا — 764 محلاً بإشغال 25.1٪، بينما الصيغ التي لا بديل لها بحركة مضمونة (أسواق · أكشاك · سيّاقة · مغاسل) بين ٤٤٪ و٥١٪. والإشغال العام 37٪. وهذه أفضل قراءة تحتملها البيانات، ويُثبتها نهائياً جدولُ إيجارات ومبيعاتُ مستأجرين لا نملكهما بعد.

Sheet الوحدات والاكتتاب
A1: سعِّر من دفتر المستأجر لا من متر المربّع
A2: الوحدة ليست مساحة — هي وصولٌ إلى تيّار حركة، وقيمتها ما يستطيع المستأجر تحويله منه · المدى 43× بين أعلى وأدنى
A4: ① المُدخَل الأول — حركةٌ لكل وحدة شاغرة
B5: المحطة | C5: الفئة | D5: وحدات | E5: شاغرة | F5: زيارة/يوم | G5: زيارة لكل وحدة شاغرة | I5: الحكم | J5: الفعل
B6: الحليس(طريق الجنوب) | C6: مشغّلة | D6: 16 | E6: 2 | F6: 1835.6395 | G6: =F6/E6 | I6: فوق الوسيط | J6: الحركة موجودة — سعِّر منها
B7: المعيصم | C7: مشغّلة | D7: 18 | E7: 1 | F7: 864.54717 | G7: =F7/E7 | I7: فوق الوسيط | J7: الحركة موجودة — سعِّر منها
B8: النورية العمرة الجديدة | C8: مشغّلة | D8: 62 | E8: 9 | F8: 4260.6368 | G8: =F8/E8 | I8: فوق الوسيط | J8: الحركة موجودة — سعِّر منها
B9: جعرانة | C9: مشغّلة | D9: 11 | E9: 3 | F9: 1122.9764 | G9: =F9/E9 | I9: فوق الوسيط | J9: الحركة موجودة — سعِّر منها
B10: العمرة الجديد (النورية حي الفتح) | C10: مشغّلة | D10: 15 | E10: 4 | F10: 1411.1085 | G10: =F10/E10 | I10: فوق الوسيط | J10: الحركة موجودة — سعِّر منها
B11: الكوثر | C11: مشغّلة | D11: 10 | E11: 1 | F11: 333.88679 | G11: =F11/E11 | I11: فوق الوسيط | J11: الحركة موجودة — سعِّر منها
B12: كورنيش الخبر | C12: مشغّلة | D12: 5 | E12: 2 | F12: 604.7217 | G12: =F12/E12 | I12: فوق الوسيط | J12: الحركة موجودة — سعِّر منها
B13: البيعه | C13: مشغّلة | D13: 10 | E13: 2 | F13: 455.95755 | G13: =F13/E13 | I13: فوق الوسيط | J13: الحركة موجودة — سعِّر منها
B14: كورنيش جيزان | C14: مشغّلة | D14: 17 | E14: 4 | F14: 909.72642 | G14: =F14/E14 | I14: فوق الوسيط | J14: الحركة موجودة — سعِّر منها
B15: احد المسارحة -الصفا محمد بن ناصر | C15: امتياز | D15: 15 | E15: 9 | F15: 1856.5776 | G15: =F15/E15 | I15: فوق الوسيط | J15: الحركة موجودة — سعِّر منها
B16: طريق صبيا | C16: مشغّلة | D16: 7 | E16: 3 | F16: 538.32995 | G16: =F16/E16 | I16: فوق الوسيط | J16: الحركة موجودة — سعِّر منها
B17: محطة مدخا محايل | C17: مشغّلة | D17: 25 | E17: 9 | F17: 998 | G17: =F17/E17 | I17: فوق الوسيط | J17: الحركة موجودة — سعِّر منها
... B28: طريق السلام | C28: امتياز | D28: 11 | E28: 11 | F28: 232.84286 | G28: =F28/E28 | I28: دون الوسيط | J28: لا يُصلحها خفض إيجار — مشكلة تحجيم أو ملكية مهمّة
B29: الوسيط | G29: =MEDIAN(G6:G28)
A30: المدى 43 ضعفاً — من 918 زيارة/يوم لكل وحدة شاغرة في الحليس(طريق ال إلى 21 في طريق السلام. فوق الوسيط: الحركة موجودة فسعِّر منها. دونه: لا يُصلحها خفض إيجار.
A32: ② التغطية — كم وحدةً نملك مُدخَلها الأول أصلاً؟
B33: الفئة | C33: شاغرة | D33: مقيسة | E33: التغطية | J33: لماذا وما الفعل
B34: مشغّلة | C34: 131 | D34: 119 | E34: =D34/C34 | J34: الحركة مقيسة — تُكتتب اليوم
B35: تحت التنفيذ | C35: 689 | D35: 0 | E35: =D35/C35 | J35: المحطة لم تُفتح — تُكتتب بمحطة نظيرة
B36: امتياز | C36: 269 | D36: 20 | E36: =D36/C36 | J36: المحطة تعمل ولا تصلنا معاملاتها — طلب بيانات
B37: الإجمالي | C37: =SUM(C34:C36) | D37: =SUM(D34:D36) | E37: =D37/C37
A38: التغطية 13٪ فقط: 139 من 1089 وحدة شاغرة نملك مُدخَلها الأول. وحين تجهل قيمة الحركة لا تراهن عليها — شارِك فيها: نموذج «نسبة من المبيعات» يُسعّر الموقع من دفتر المستأجر تلقائياً وينقل خطر التقدير الخاطئ عنّا.
A40: ③ ورقة الاكتتاب — أربعة مُدخَلات قبل النطق برقم
B41: المُدخَل | C41: عندنا؟ | J41: المصدر أو المالك
B42: الحركة المارّة بالوحدة | C42: ✓ عندنا — زيارة/يوم لكل محطة | J42: كاش إن
B43: ساعات الذروة | C43: ✓ عندنا — منحنى ٢٤ ساعة لكل محطة | J43: كاش إن
B44: تحويل الشكل من التيّار | C44: ✕ ليس عندنا — لكل صيغة — مطعم · مقهى · مغسلة | J44: التأجير — مسح تحويل لكل صيغة
B45: سلة المستأجر وهامشه | C45: ✕ ليس عندنا — مبيعات المستأجرين شهرياً | J45: التأجير — إقرار مبيعات المستأجرين شهرياً
A46: المُدخَلان الأولان عندنا، والأخيران لا. ولا يُملأ الفراغ بتقدير يبدو كقياس — بل يُكتب ما ينقص ومن يملك سدّه.

Sheet المنهجية والثغرات
A1: من أين جاء كل رقم — وما الذي لا نعرفه
A2: ولا يُدَّعى مسحٌ لم يُجرَ: حيث تنقص المعرفة يُكتب ما ينقص بالضبط ومن يملك سدّه
A4: ① المصادر
B5: المصدر | C5: النطاق | D5: ما يعطيه | F5: التحفّظ
B6: كاش إن — الشبكة | C6: 55 محطة · 9,058 يوم-محطة | D6: زيارات ولترات ومزيج وقود وقنوات دفع وشكل ساعات | F6: 10,959,777 صفّاً · محطات فُتحت أو أُغلقت داخل المدى فلا تُقارَن مجاميعها
B7: كاش إن — العمرة اليومي | C7: 263 يوماً كاملاً | D7: الساعة وشريحة الفاتورة وزمن الخدمة — المحطة الوحيدة | F7: يوم 2026-09-21 ناقص فاستُبعد · 7,217 مكرَّراً و70 صفّاً متجاوَزاً من 1,140,208
B8: ملف ساعات الشبكة | C8: 25 محطة حيوية | D8: شكل الساعات المرجعي الذي تُقاس عليه الفجوة | F8: وسيطٌ لا مستهدف — ونصف المحطات فوقه بالتعريف
B9: قائمة الدخل يناير–يوليو ٢٠٢٦ | C9: 141 محطة · 662 مليون لتر | D9: كلفة اللتر بأربع طبقات وبتفصيل نموذج العمل | F9: شبكيّة لا محطّية — ولا نملك تفصيل كل محطة
B10: تقرير ربحية الربع الثاني | C10: 22 محطة مشغّلة | D10: وحده يفصّل داخل «مصاريف التشغيل»: أجور · مرافق | F10: ⛔ الأجر فيه ٣٬٥٠٠ ريالاً ثابتة لكل عامل — سعرٌ لا قياس
B11: انحدار هامش ١٩ محطة | C11: من تقرير المالية | D11: هامش البنزين ١٢٫٦٦ هللة والديزل ٤٫٤٧ | F11: ⛔ استقراء: أقصى حصة ديزل مرصودة ٤٣٪ — وليسا جدولاً معتمداً
B12: ملفات الطاقم والعمليات | C12: 372 عاملاً · 40 محطة | D12: توزيع العمّال على الورديتين وحِمل كلٍّ منهما | F12: ⛔ 15 محطة بلا بيان عامل · والعمرة ٢٠ و٢٦ و٣٢ في ثلاثة ملفات
B13: مسح المنافسين الميداني | C13: 40 موقعاً حول محطاتنا | D13: العلامة والمسافة والتقييم — لوقود الأفراد وحده | F13: لا يوجد مسح مقابل للعقار ولا للإعلان ولا للإكسسوارات
B14: سجلّ الوحدات التجارية | C14: 186 محطة · 1733 وحدة | D14: الفئة والمؤجَّر والشاغر | F14: لا جدول إيجارات ولا مبيعات مستأجرين
B15: سجلّ الشكاوى | C15: 103 شكوى | D15: 58 منها للعمرة (56٪) | F15: الشكاوى ترتفع بالحجم — والحصة هنا تفوق حصة الحجم
A17: ② التعاريف — حتى لا يُقاس رقمان بتعريفين
B18: المصطلح | C18: التعريف | F18: لماذا هكذا
B19: الفجوة | C19: ما نحن دونه من شكل تصنيفنا في ساعات ذروتنا الثماني وحدها | F19: النقص في ساعات الهدوء اختلاف طلبٍ لا فاقد — فلا يُطالَب به
B20: الوردية | C20: صباحية ٠٠:٠٠–١١:٥٩ · مسائية ١٢:٠٠–٢٣:٥٩ | F20: حدود التقرير نفسه — لا حدودٌ من عندنا
B21: هامش المساهمة | C21: الإيراد ناقص شراء الوقود — قبل أي مصروف تشغيل | F21: هو وحده ما يتحرّك باللتر الإضافي
B22: خط الأساس | C22: الأسابيع الأربعة السابقة في المحطة نفسها | F22: القياس على ذروةٍ موسمية أو على عامٍ مضى يخلط الموسم بالأثر
B23: البوابة | C23: حالةٌ تُبطل نسبة أي نتيجة إلى حملة | F23: محطةٌ عليها بوابة لا تدخل حملة قبل إقفالها
B24: الربع الثالث للعمرة | C24: ١ يوليو – ٢٠ سبتمبر · ٨٢ يوماً | F24: ناقصٌ فتُقارَن المعدّلات اليومية لا المجاميع
A26: ③ الثغرات — ما ينقص بالضبط ومن يملك سدّه
B27: الناقص | C27: المالك | D27: الحال اليوم | F27: أثره على الرقم
B28: جدول ورديات معتمد | C28: العمليات | D28: ثلاثة ملفات تعطي أعداداً مختلفة للمحطة الواحدة | F28: ملزم قبل أي مستهدف وردية — والمستهدف يُحمَّل على وردية
B29: جدول هامش المنتجات | C29: المالية | D29: ١٢٫٦٦ و٤٫٤٧ هللة استُنتجا بانحدار لا بجدول | F29: يغيّر قيمة كل فجوة في الملف — والديزل ٣٣٪ في محطاتٍ كبرى
B30: رسوم البطاقات | C30: المالية | D30: لا نعرف الرسم ولا من يتحمّله | F30: يُقتطع من هامش كل لتر إضافي ولا يظهر في أي حساب هنا
B31: جرد الخزانات | C31: العمليات | D31: لا مطابقة بين المُورَّد والمُباع | F31: يفصل فجوة المطابقة عن فجوة البيع
B32: نموذج عمل كل محطة | C32: المالية + العمليات | D32: العمرة استثمارية وإيجارية وتشغيلية في ثلاثة ملفات | F32: يغيّر أساس الكلفة كلّه
B33: جدول إيجارات ومبيعات المستأجرين | C33: التأجير | D33: لا نملك دفتر المستأجر الذي نُسعّر منه | F33: المُدخَلان الثالث والرابع في ورقة الاكتتاب
B34: مسح منافسين للعقار والإعلان | C34: التجاري | D34: المسح الميداني لوقود الأفراد وحده | F34: لا حصص سوق لهذين المنتجين — ولا تُدَّعى
B35: أجرة النقل والتوريد | C35: سلسلة الإمداد | D35: غير محسوم من يتحمّلها | F35: بندٌ كامل خارج كلفة اللتر عندنا
A36: وأهمّها الأول: جدول ورديات معتمد. فالمستهدف يُحمَّل على وردية، ولا يُحمَّل على وردية عدد عمّالها ثلاثة أرقام في ثلاثة ملفات.
