Workbook

Sheet الوصف الوظيفي
A1: الوصف الوظيفي — أخصائي مبيعات الوقود
A2: قالب عام قابل للتكييف على أي منطقة أو قناة — الخانات الملوّنة تُعبَّأ
A4: ① بيانات الوظيفة
B5: المسمى الوظيفي | C5: أخصائي مبيعات وقود
B6: الإدارة | C6: الإدارة التجارية
B7: القسم | C7: مبيعات الوقود — قناة الشركات
B8: يرفع إلى | C8: مدير مبيعات الوقود
B9: الموقع / النطاق
B10: الدرجة الوظيفية
B11: عدد المرؤوسين | C11: لا يوجد
B12: تاريخ الاعتماد
A14: ② الغرض من الوظيفة
B15: تنمية حجم مبيعات الوقود للعملاء من المنشآت وأصحاب الأساطيل داخل النطاق المحدد،
B16: عبر التعاقد المباشر وتثبيت الحجم القائم بشرط نمو موثّق فوق خط الأساس،
B17: بما يحقق نمواً صافياً في الهامش لا مجرد تحويل حجم قائم إلى عقود مخفَّضة.
A20: ③ المسؤوليات الرئيسية
A21: # | B21: المسؤولية | C21: الوصف | D21: المخرج المتوقع | J21: الدورية
A22: 1 | B22: حصر السوق | C22: بناء قاعدة الأساطيل والمنشآت داخل النطاق وتصنيفها بالحجم والقطاع | D22: قاعدة عملاء محدَّثة بالحجم التقديري لكل أسطول | J22: شهرية
A23: 2 | B23: الاستهداف | C23: ترتيب العملاء بالأولوية: من لا يشتري منّا أولاً ثم من يشتري بلا عقد | D23: قائمة أولويات ربعية معتمدة من المدير | J23: ربعية
A24: 3 | B24: الزيارات الميدانية | C24: زيارة مقرات الأساطيل ومقابلة متخذ القرار لا موظف التشغيل | D24: تقرير زيارة لكل عميل يتضمن الحجم والمورّد الحالي | J24: أسبوعية
A25: 4 | B25: بناء العرض | C25: إعداد عرض سعري يوازن بين الخصم الممنوح والتزام الحجم | D25: عرض موقّع يتضمن حجماً ملتزماً وخط أساس مرجعي | J25: لكل فرصة
A26: 5 | B26: التعاقد | C26: إتمام العقد بالتنسيق مع الشؤون القانونية والائتمان | D26: عقد نافذ بحدود ائتمان ومدة وآلية فوترة | J26: لكل فرصة
A27: 6 | B27: التفعيل | C27: تسليم العميل لفريق التشغيل وضمان أول تعبئة خلال مدة محددة | D27: أول معاملة مسجّلة على العقد | J27: لكل عقد
A28: 7 | B28: المتابعة والتنمية | C28: مراقبة حجم كل عقد مقابل التزامه ومعالجة الانحراف | D28: تقرير انحراف شهري لكل عقد وخطة معالجة | J28: شهرية
A29: 8 | B29: التحصيل | C29: متابعة الفوترة والتحصيل ضمن المدة الائتمانية المعتمدة | D29: عمر ديون ضمن الحد المعتمد | J29: شهرية
A30: 9 | B30: رصد المنافسة | C30: توثيق عروض المنافسين وأسعارهم وشروطهم داخل النطاق | D30: تقرير منافسة ربعي | J30: ربعية
A32: ④ حدود الصلاحية
A33: # | B33: البند | C33: الحد | D33: من يعتمد ما يتجاوزه
A34: 1 | B34: الخصم الممنوح | C34: حتى الحد المعتمد لكل لتر | D34: مدير مبيعات الوقود
A35: 2 | B35: مدة الائتمان | C35: حتى المدة المعتمدة | D35: الإدارة المالية
A36: 3 | B36: سقف الائتمان لكل عميل | C36: حسب تصنيف العميل الائتماني | D36: لجنة الائتمان
A37: 4 | B37: مدة العقد | C37: سنة قابلة للتجديد | D37: مدير مبيعات الوقود
A38: 5 | B38: التسعير دون التكلفة | C38: غير مصرّح به إطلاقاً | D38: لا يُعتمد
A40: ⑤ المؤهلات والجدارات
A41: # | B41: البند | C41: الحد الأدنى | D41: المفضَّل
A42: 1 | B42: المؤهل العلمي | C42: بكالوريوس إدارة أعمال أو تسويق أو ما يعادله | D42: دبلوم مبيعات أو تمويل
A43: 2 | B43: سنوات الخبرة | C43: ٣ سنوات في مبيعات الشركات | D43: خبرة في الوقود أو النقل أو اللوجستيات
A44: 3 | B44: المعرفة الفنية | C44: احتساب الهامش لكل لتر وقراءة قائمة أسعار | D44: الإلمام بمنصات إدارة الأساطيل
A45: 4 | B45: الأدوات | C45: إكسل ونظام إدارة علاقات العملاء | D45: تحليل بيانات المبيعات
A46: 5 | B46: اللغة | C46: العربية بطلاقة | D46: الإنجليزية للتعامل مع الأساطيل الأجنبية
...

Sheet مؤشرات الأداء
A1: مؤشرات الأداء — أخصائي مبيعات الوقود
A2: ثلاث فئات: نتيجة · حركة · حماية — والأوزان تُعدَّل حسب مرحلة السوق
A4: # | B4: المؤشر | C4: التعريف | D4: طريقة الحساب | E4: المصدر | F4: الاتجاه | G4: الوزن | H4: المستهدف | I4: الحد الأدنى | J4: الدورية | K4: لماذا هذا المؤشر
A5: 1 | B5: الحجم المتعاقَد | C5: إجمالي اللترات المغطاة بعقود نافذة | D5: مجموع لترات العقود النشطة خلال الفترة | E5: نظام المبيعات | F5: أعلى أفضل | G5: 0.15 | J5: ربعية | K5: الحجم القائم يُقاس ولا يُكافأ وحده
A6: 2 | B6: الحجم الصافي المضاف | C6: اللترات فوق خط أساس العميل قبل التعاقد | D6: حجم الفترة ناقص خط الأساس المرجعي | E6: نظام المبيعات | F6: أعلى أفضل | G6: 0.25 | J6: ربعية | K6: هذا وحده ما يخلق قيمة — الباقي إعادة تسمية
A7: 3 | B7: هامش المساهمة المتحقق | C7: الهامش بعد الخصم الممنوح | D7: الحجم × (هامش اللتر ناقص الخصم) | E7: قائمة الدخل | F7: أعلى أفضل | G7: 0.15 | J7: ربعية | K7: الحجم بلا هامش قد يكون خسارة
A8: 4 | B8: عملاء جدد لم يشتروا منّا | C8: عقود مع أساطيل لم تكن تعبّئ لدينا | D8: عدد العقود التي خط أساسها صفر | E8: نظام المبيعات | F8: أعلى أفضل | G8: 0.1 | J8: ربعية | K8: كل لتر منها ربح صافٍ بلا خصم على حجم قائم
A9: 5 | B9: زيارات ميدانية مؤهَّلة | C9: زيارة لمتخذ قرار موثّقة بتقرير | D9: عدد الزيارات المسجّلة | E9: تقارير الزيارات | F9: أعلى أفضل | G9: 0.05 | J9: ربعية | K9: المؤشر المبكر الوحيد الذي يسبق النتيجة بأشهر
A10: 6 | B10: عروض مقدَّمة | C10: عرض سعري رسمي مسلَّم للعميل | D10: عدد العروض الصادرة | E10: نظام المبيعات | F10: أعلى أفضل | G10: 0.05 | J10: ربعية | K10: يكشف اختناق القمع: زيارات بلا عروض تعني ضعف تأهيل
A11: 7 | B11: معدل التحويل | C11: نسبة العروض التي تحولت إلى عقود | D11: عقود موقّعة ÷ عروض مقدَّمة | E11: نظام المبيعات | F11: أعلى أفضل | G11: 0.08 | J11: ربعية | K11: يفصل جودة الاستهداف عن كثرة النشاط
A12: 8 | B12: متوسط الخصم الممنوح | C12: الخصم الفعلي لكل لتر متعاقَد | D12: مجموع الخصم ÷ الحجم المتعاقَد | E12: نظام المبيعات | F12: أقل أفضل | G12: 0.07 | J12: ربعية | K12: يمنع شراء الحجم بالسعر
A13: 9 | B13: أيام التحصيل | C13: متوسط عمر الذمم المدينة | D13: الذمم × أيام الفترة ÷ المبيعات الآجلة | E13: الإدارة المالية | F13: أقل أفضل | G13: 0.05 | J13: ربعية | K13: البيع لا يكتمل إلا بالتحصيل
A14: 10 | B14: ديون متأخرة فوق ٩٠ يوماً | C14: نسبة الذمم المتجاوزة للمدة | D14: ذمم +٩٠ يوم ÷ إجمالي الذمم | E14: الإدارة المالية | F14: أقل أفضل | G14: 0.03 | J14: ربعية | K14: مؤشر مبكر على تساهل في الائتمان
A15: 11 | B15: معدل تجديد العقود | C15: نسبة العقود المجدَّدة عند انتهائها | D15: عقود مجدَّدة ÷ عقود مستحقة التجديد | E15: نظام المبيعات | F15: أعلى أفضل | G15: 0.02 | J15: ربعية | K15: يكشف إن كان البيع لمرة واحدة أم علاقة
B16: مجموع الأوزان | G16: =SUM(G5:G15) | H16: يجب أن يساوي ١٠٠٪ — يتلوّن بالأحمر إن اختلّ
B18: قواعد ضبط المؤشرات
C19: • «الحجم الصافي المضاف» أعلى وزن — لأنه وحده يفرّق بين النمو وإعادة التسمية
C20: • مؤشرات الحماية لا تُكافأ عند تحققها بل تُخصم عند اختلالها
C21: • كل مستهدف يُشتق من خط أساس موثّق — لا من تقدير
C22: • لا يُعتمد المؤشر ما لم يكن مصدره نظاماً لا تقريراً يدوياً
B24: الفخ الأساسي في مبيعات الوقود للشركات
C25: • منح خصم على أسطول يشتري منّا أصلاً يعني خسارة على كل لتر كان يشتريه
C26: • لذلك يشترط العقد نمواً فوق خط الأساس يغطي الخصم على الحجم القائم
C27: • احسب نقطة التعادل: نسبة النمو المطلوبة = الخصم ÷ (هامش اللتر ناقص الخصم)

Sheet نموذج التقييم
A1: نموذج التقييم الربعي
A2: عبّئ الفعلي فقط — النسبة والنقاط تُحتسب
A4: ① بيانات التقييم
B5: اسم الموظف | D5: الفترة | F5: المقيِّم
A7: ② الاحتساب
A8: # | B8: المؤشر | C8: الاتجاه | D8: الوزن | E8: المستهدف | F8: الفعلي | G8: نسبة الإنجاز | H8: النقاط | I8: ملاحظة
A9: 1 | B9: ='مؤشرات الأداء'!B5 | C9: ='مؤشرات الأداء'!F5 | D9: ='مؤشرات الأداء'!G5 | E9: ='مؤشرات الأداء'!H5 | G9: =IFERROR(IF(OR($F9="",$E9=""),"",IF($C9="أقل أفضل",$E9/$F9,$F9/$E9)),"") | H9: =IF($G9="","",MIN($G9,1.2)*$D9)
A10: 2 | B10: ='مؤشرات الأداء'!B6 | C10: ='مؤشرات الأداء'!F6 | D10: ='مؤشرات الأداء'!G6 | E10: ='مؤشرات الأداء'!H6 | G10: =IFERROR(IF(OR($F10="",$E10=""),"",IF($C10="أقل أفضل",$E10/$F10,$F10/$E10)),"") | H10: =IF($G10="","",MIN($G10,1.2)*$D10)
A11: 3 | B11: ='مؤشرات الأداء'!B7 | C11: ='مؤشرات الأداء'!F7 | D11: ='مؤشرات الأداء'!G7 | E11: ='مؤشرات الأداء'!H7 | G11: =IFERROR(IF(OR($F11="",$E11=""),"",IF($C11="أقل أفضل",$E11/$F11,$F11/$E11)),"") | H11: =IF($G11="","",MIN($G11,1.2)*$D11)
A12: 4 | B12: ='مؤشرات الأداء'!B8 | C12: ='مؤشرات الأداء'!F8 | D12: ='مؤشرات الأداء'!G8 | E12: ='مؤشرات الأداء'!H8 | G12: =IFERROR(IF(OR($F12="",$E12=""),"",IF($C12="أقل أفضل",$E12/$F12,$F12/$E12)),"") | H12: =IF($G12="","",MIN($G12,1.2)*$D12)
A13: 5 | B13: ='مؤشرات الأداء'!B9 | C13: ='مؤشرات الأداء'!F9 | D13: ='مؤشرات الأداء'!G9 | E13: ='مؤشرات الأداء'!H9 | G13: =IFERROR(IF(OR($F13="",$E13=""),"",IF($C13="أقل أفضل",$E13/$F13,$F13/$E13)),"") | H13: =IF($G13="","",MIN($G13,1.2)*$D13)
A14: 6 | B14: ='مؤشرات الأداء'!B10 | C14: ='مؤشرات الأداء'!F10 | D14: ='مؤشرات الأداء'!G10 | E14: ='مؤشرات الأداء'!H10 | G14: =IFERROR(IF(OR($F14="",$E14=""),"",IF($C14="أقل أفضل",$E14/$F14,$F14/$E14)),"") | H14: =IF($G14="","",MIN($G14,1.2)*$D14)
A15: 7 | B15: ='مؤشرات الأداء'!B11 | C15: ='مؤشرات الأداء'!F11 | D15: ='مؤشرات الأداء'!G11 | E15: ='مؤشرات الأداء'!H11 | G15: =IFERROR(IF(OR($F15="",$E15=""),"",IF($C15="أقل أفضل",$E15/$F15,$F15/$E15)),"") | H15: =IF($G15="","",MIN($G15,1.2)*$D15)
A16: 8 | B16: ='مؤشرات الأداء'!B12 | C16: ='مؤشرات الأداء'!F12 | D16: ='مؤشرات الأداء'!G12 | E16: ='مؤشرات الأداء'!H12 | G16: =IFERROR(IF(OR($F16="",$E16=""),"",IF($C16="أقل أفضل",$E16/$F16,$F16/$E16)),"") | H16: =IF($G16="","",MIN($G16,1.2)*$D16)
A17: 9 | B17: ='مؤشرات الأداء'!B13 | C17: ='مؤشرات الأداء'!F13 | D17: ='مؤشرات الأداء'!G13 | E17: ='مؤشرات الأداء'!H13 | G17: =IFERROR(IF(OR($F17="",$E17=""),"",IF($C17="أقل أفضل",$E17/$F17,$F17/$E17)),"") | H17: =IF($G17="","",MIN($G17,1.2)*$D17)
A18: 10 | B18: ='مؤشرات الأداء'!B14 | C18: ='مؤشرات الأداء'!F14 | D18: ='مؤشرات الأداء'!G14 | E18: ='مؤشرات الأداء'!H14 | G18: =IFERROR(IF(OR($F18="",$E18=""),"",IF($C18="أقل أفضل",$E18/$F18,$F18/$E18)),"") | H18: =IF($G18="","",MIN($G18,1.2)*$D18)
A19: 11 | B19: ='مؤشرات الأداء'!B15 | C19: ='مؤشرات الأداء'!F15 | D19: ='مؤشرات الأداء'!G15 | E19: ='مؤشرات الأداء'!H15 | G19: =IFERROR(IF(OR($F19="",$E19=""),"",IF($C19="أقل أفضل",$E19/$F19,$F19/$E19)),"") | H19: =IF($G19="","",MIN($G19,1.2)*$D19)
B20: النتيجة النهائية | D20: =SUM(D9:D19) | H20: =SUM(H9:H19)
A22: ③ سُلّم التقدير
A23: # | B23: النتيجة | C23: التقدير | D23: الأثر
A24: 1 | B24: ١٠٠٪ فأعلى | C24: متجاوز | D24: يستحق الحافز الكامل ويُرشَّح للتطوير
A25: 2 | B25: ٨٥٪ – ٩٩٪ | C25: مستوفٍ | D25: يستحق الحافز وفق النسبة المحققة
A26: 3 | B26: ٧٠٪ – ٨٤٪ | C26: دون المستهدف | D26: خطة تحسين مكتوبة لربع واحد
A27: 4 | B27: أقل من ٧٠٪ | C27: غير مستوفٍ | D27: مراجعة الاستمرار في الدور
B29: ملاحظات على الاحتساب
C30: • سقف الإنجاز ١٢٠٪ لكل مؤشر — يمنع أن يغطي مؤشر واحد استثنائي فشل البقية
C31: • مؤشرات «أقل أفضل» تُحتسب بالمقلوب: المستهدف ÷ الفعلي
C32: • لا تُصرف حوافز على نتيجة دون ٨٥٪ مهما بلغ مؤشر منفرد
