Workbook

Sheet نموذج العامل
A1: نموذج مبيعات العامل — مستهدف وحافز
A2: خط الأساس يُشتق من حصة الوردية الفعلية من الزيارات ÷ عدد عمالها — لا يُقدَّر يدوياً
A3: ① مُدخلات المحطة — اختر المحطة والباقي يُعبَّأ من بيانات التشغيل
B4: المحطة | D4: =IFERROR("ذروة "&INDEX('بيانات الورديات'!$I$4:$I$8,MATCH($C$4,'بيانات الورديات'!$B$4:$B$8,0)),"") | E4: اختر من القائمة ▼
B5: الشهر | E5: مثال: أغسطس ٢٠٢٦
B6: لتر لكل زيارة | C6: =IFERROR(INDEX('بيانات الورديات'!$C$4:$C$8,MATCH($C$4,'بيانات الورديات'!$B$4:$B$8,0)),0) -> 0 | E6: من بيانات المحطة
B7: زيارات المحطة (زيارة/يوم) | C7: =IFERROR(INDEX('بيانات الورديات'!$D$4:$D$8,MATCH($C$4,'بيانات الورديات'!$B$4:$B$8,0)),0) -> 0 | E7: متوسط ٢١٢ يوماً
B8: عمال المضخات — صباحية | C8: =IFERROR(INDEX('بيانات الورديات'!$E$4:$E$8,MATCH($C$4,'بيانات الورديات'!$B$4:$B$8,0)),0) -> 0 | E8: ٦ ص – ٦ م
B9: عمال المضخات — مسائية | C9: =IFERROR(INDEX('بيانات الورديات'!$F$4:$F$8,MATCH($C$4,'بيانات الورديات'!$B$4:$B$8,0)),0) -> 0 | E9: ٦ م – ٦ ص
B10: حصة الصباح من الزيارات | C10: =IFERROR(INDEX('بيانات الورديات'!$G$4:$G$8,MATCH($C$4,'بيانات الورديات'!$B$4:$B$8,0)),0) -> 0 | E10: من الحركة الفعلية
B11: حصة المساء من الزيارات | C11: =IFERROR(INDEX('بيانات الورديات'!$H$4:$H$8,MATCH($C$4,'بيانات الورديات'!$B$4:$B$8,0)),0) -> 0 | E11: من الحركة الفعلية
B12: هامش المساهمة (هللة/لتر) | C12: 13.36 | E12: من قائمة الدخل
B13: نسبة الحافز من الهامش | C13: 0.15 | E13: قرار الإدارة
B14: سقف الحافز الشهري للعامل | C14: 100 | E14: معتمد: ١٠٠ ريال
B15: أيام الشهر | C15: 30
B16: نسبة النمو المستهدف | C16: 0.05 | E16: حرّكها ← تتحرك كل المستهدفات
B17: يُشترط صافي محطة موجب | C17: نعم | E17: يحمي نسبة الـ١٥٪
A19: ② بطاقة العامل — اختر الوردية فيُشتق خط الأساس · عبّئ الفعلي وبوابة الجودة
A20: # | B20: اسم العامل | C20: الوردية | D20: خط الأساس المشتق | E20: تعديل معتمد | F20: المستهدف | G20: الفعلي | H20: الفارق | I20: نسبة الإنجاز | J20: بوابة الجودة | K20: الحافز (ريال) | L20: ملاحظة
A21: 1 | D21: =IF(OR($C21="",$C$7=0),"",ROUND(IF($C21="صباحية",$C$7*$C$10/MAX($C$8,1),$C$7*$C$11/MAX($C$9,1)),0)) | F21: =IF($D21="","",ROUND(IF($E21="",$D21,$E21)*(1+$C$16),0)) | H21: =IF(OR($G21="",$F21=""),"",$G21-$F21) | I21: =IFERROR(IF($F21="","",$G21/$F21),"") | K21: =IF(OR($H21="",$J21<>"مستوفاة"),0,IF(AND($C$17="نعم",$H$41<=0),0,MIN(MAX($H21,0)*$C$6*$C$12/100*$C$13*$C$15,$C$14))) -> 0
A22: 2 | D22: =IF(OR($C22="",$C$7=0),"",ROUND(IF($C22="صباحية",$C$7*$C$10/MAX($C$8,1),$C$7*$C$11/MAX($C$9,1)),0)) | F22: =IF($D22="","",ROUND(IF($E22="",$D22,$E22)*(1+$C$16),0)) | H22: =IF(OR($G22="",$F22=""),"",$G22-$F22) | I22: =IFERROR(IF($F22="","",$G22/$F22),"") | K22: =IF(OR($H22="",$J22<>"مستوفاة"),0,IF(AND($C$17="نعم",$H$41<=0),0,MIN(MAX($H22,0)*$C$6*$C$12/100*$C$13*$C$15,$C$14))) -> 0
A23: 3 | D23: =IF(OR($C23="",$C$7=0),"",ROUND(IF($C23="صباحية",$C$7*$C$10/MAX($C$8,1),$C$7*$C$11/MAX($C$9,1)),0)) | F23: =IF($D23="","",ROUND(IF($E23="",$D23,$E23)*(1+$C$16),0)) | H23: =IF(OR($G23="",$F23=""),"",$G23-$F23) | I23: =IFERROR(IF($F23="","",$G23/$F23),"") | K23: =IF(OR($H23="",$J23<>"مستوفاة"),0,IF(AND($C$17="نعم",$H$41<=0),0,MIN(MAX($H23,0)*$C$6*$C$12/100*$C$13*$C$15,$C$14))) -> 0
A24: 4 | D24: =IF(OR($C24="",$C$7=0),"",ROUND(IF($C24="صباحية",$C$7*$C$10/MAX($C$8,1),$C$7*$C$11/MAX($C$9,1)),0)) | F24: =IF($D24="","",ROUND(IF($E24="",$D24,$E24)*(1+$C$16),0)) | H24: =IF(OR($G24="",$F24=""),"",$G24-$F24) | I24: =IFERROR(IF($F24="","",$G24/$F24),"") | K24: =IF(OR($H24="",$J24<>"مستوفاة"),0,IF(AND($C$17="نعم",$H$41<=0),0,MIN(MAX($H24,0)*$C$6*$C$12/100*$C$13*$C$15,$C$14))) -> 0
A25: 5 | D25: =IF(OR($C25="",$C$7=0),"",ROUND(IF($C25="صباحية",$C$7*$C$10/MAX($C$8,1),$C$7*$C$11/MAX($C$9,1)),0)) | F25: =IF($D25="","",ROUND(IF($E25="",$D25,$E25)*(1+$C$16),0)) | H25: =IF(OR($G25="",$F25=""),"",$G25-$F25) | I25: =IFERROR(IF($F25="","",$G25/$F25),"") | K25: =IF(OR($H25="",$J25<>"مستوفاة"),0,IF(AND($C$17="نعم",$H$41<=0),0,MIN(MAX($H25,0)*$C$6*$C$12/100*$C$13*$C$15,$C$14))) -> 0
A26: 6 | D26: =IF(OR($C26="",$C$7=0),"",ROUND(IF($C26="صباحية",$C$7*$C$10/MAX($C$8,1),$C$7*$C$11/MAX($C$9,1)),0)) | F26: =IF($D26="","",ROUND(IF($E26="",$D26,$E26)*(1+$C$16),0)) | H26: =IF(OR($G26="",$F26=""),"",$G26-$F26) | I26: =IFERROR(IF($F26="","",$G26/$F26),"") | K26: =IF(OR($H26="",$J26<>"مستوفاة"),0,IF(AND($C$17="نعم",$H$41<=0),0,MIN(MAX($H26,0)*$C$6*$C$12/100*$C$13*$C$15,$C$14))) -> 0
A27: 7 | D27: =IF(OR($C27="",$C$7=0),"",ROUND(IF($C27="صباحية",$C$7*$C$10/MAX($C$8,1),$C$7*$C$11/MAX($C$9,1)),0)) | F27: =IF($D27="","",ROUND(IF($E27="",$D27,$E27)*(1+$C$16),0)) | H27: =IF(OR($G27="",$F27=""),"",$G27-$F27) | I27: =IFERROR(IF($F27="","",$G27/$F27),"") | K27: =IF(OR($H27="",$J27<>"مستوفاة"),0,IF(AND($C$17="نعم",$H$41<=0),0,MIN(MAX($H27,0)*$C$6*$C$12/100*$C$13*$C$15,$C$14))) -> 0
A28: 8 | D28: =IF(OR($C28="",$C$7=0),"",ROUND(IF($C28="صباحية",$C$7*$C$10/MAX($C$8,1),$C$7*$C$11/MAX($C$9,1)),0)) | F28: =IF($D28="","",ROUND(IF($E28="",$D28,$E28)*(1+$C$16),0)) | H28: =IF(OR($G28="",$F28=""),"",$G28-$F28) | I28: =IFERROR(IF($F28="","",$G28/$F28),"") | K28: =IF(OR($H28="",$J28<>"مستوفاة"),0,IF(AND($C$17="نعم",$H$41<=0),0,MIN(MAX($H28,0)*$C$6*$C$12/100*$C$13*$C$15,$C$14))) -> 0
A29: 9 | D29: =IF(OR($C29="",$C$7=0),"",ROUND(IF($C29="صباحية",$C$7*$C$10/MAX($C$8,1),$C$7*$C$11/MAX($C$9,1)),0)) | F29: =IF($D29="","",ROUND(IF($E29="",$D29,$E29)*(1+$C$16),0)) | H29: =IF(OR($G29="",$F29=""),"",$G29-$F29) | I29: =IFERROR(IF($F29="","",$G29/$F29),"") | K29: =IF(OR($H29="",$J29<>"مستوفاة"),0,IF(AND($C$17="نعم",$H$41<=0),0,MIN(MAX($H29,0)*$C$6*$C$12/100*$C$13*$C$15,$C$14))) -> 0
A30: 10 | D30: =IF(OR($C30="",$C$7=0),"",ROUND(IF($C30="صباحية",$C$7*$C$10/MAX($C$8,1),$C$7*$C$11/MAX($C$9,1)),0)) | F30: =IF($D30="","",ROUND(IF($E30="",$D30,$E30)*(1+$C$16),0)) | H30: =IF(OR($G30="",$F30=""),"",$G30-$F30) | I30: =IFERROR(IF($F30="","",$G30/$F30),"") | K30: =IF(OR($H30="",$J30<>"مستوفاة"),0,IF(AND($C$17="نعم",$H$41<=0),0,MIN(MAX($H30,0)*$C$6*$C$12/100*$C$13*$C$15,$C$14))) -> 0
A31: 11 | D31: =IF(OR($C31="",$C$7=0),"",ROUND(IF($C31="صباحية",$C$7*$C$10/MAX($C$8,1),$C$7*$C$11/MAX($C$9,1)),0)) | F31: =IF($D31="","",ROUND(IF($E31="",$D31,$E31)*(1+$C$16),0)) | H31: =IF(OR($G31="",$F31=""),"",$G31-$F31) | I31: =IFERROR(IF($F31="","",$G31/$F31),"") | K31: =IF(OR($H31="",$J31<>"مستوفاة"),0,IF(AND($C$17="نعم",$H$41<=0),0,MIN(MAX($H31,0)*$C$6*$C$12/100*$C$13*$C$15,$C$14))) -> 0
A32: 12 | D32: =IF(OR($C32="",$C$7=0),"",ROUND(IF($C32="صباحية",$C$7*$C$10/MAX($C$8,1),$C$7*$C$11/MAX($C$9,1)),0)) | F32: =IF($D32="","",ROUND(IF($E32="",$D32,$E32)*(1+$C$16),0)) | H32: =IF(OR($G32="",$F32=""),"",$G32-$F32) | I32: =IFERROR(IF($F32="","",$G32/$F32),"") | K32: =IF(OR($H32="",$J32<>"مستوفاة"),0,IF(AND($C$17="نعم",$H$41<=0),0,MIN(MAX($H32,0)*$C$6*$C$12/100*$C$13*$C$15,$C$14))) -> 0
... A40: 20 | D40: =IF(OR($C40="",$C$7=0),"",ROUND(IF($C40="صباحية",$C$7*$C$10/MAX($C$8,1),$C$7*$C$11/MAX($C$9,1)),0)) | F40: =IF($D40="","",ROUND(IF($E40="",$D40,$E40)*(1+$C$16),0)) | H40: =IF(OR($G40="",$F40=""),"",$G40-$F40) | I40: =IFERROR(IF($F40="","",$G40/$F40),"") | K40: =IF(OR($H40="",$J40<>"مستوفاة"),0,IF(AND($C$17="نعم",$H$41<=0),0,MIN(MAX($H40,0)*$C$6*$C$12/100*$C$13*$C$15,$C$14))) -> 0
B41: الإجمالي | C41: =COUNTA($B21:$B40)&" عامل" -> 0 عامل | D41: =SUM(D21:D40) -> 0 | F41: =SUM(F21:F40) -> 0 | G41: =SUM(G21:G40) -> 0 | H41: =SUM(H21:H40) -> 0 | I41: =IFERROR($G41/$F41,"") | K41: =SUM(K21:K40) -> 0
A43: ③ ملخص المحطة — يتحدّث مع كل رقم تُدخله
A44: # | B44: البند | C44: القيمة | L44: الدلالة
A45: 1 | B45: الزيادة الإجمالية (زيارة/يوم) | C45: =$H$41 -> 0 | L45: مجموع فروق العمال
A46: 2 | B46: اللترات الإضافية شهرياً | C46: =$C$45*$C$6*$C$15 -> 0 | L46: الزيادة × لتر/زيارة × الأيام
A47: 3 | B47: الهامش الإضافي شهرياً (ريال) | C47: =$C$46*$C$12/100 -> 0 | L47: قبل خصم الحافز
A48: 4 | B48: إجمالي الحافز شهرياً (ريال) | C48: =$K$41 -> 0 | L48: ما يُصرف للعمال
A49: 5 | B49: صافي المكسب للشركة (ريال) | C49: =$C$47-$C$48 -> 0 | L49: الهامش ناقص الحافز
...

Sheet مطابقة الوردية مع الطلب
A1: مطابقة الوردية مع الطلب
A2: كل المحطات توزّع العمالة نصفين متساويين — بينما الطلب ليس نصفين
A3: # | B3: المحطة | C3: زيارات الصباح | D3: زيارات المساء | E3: عمال صباحاً | F3: عمال مساءً | G3: حصة العمالة مساءً | H3: الفجوة | I3: حِمل عامل الصباح | J3: حِمل عامل المساء | K3: الفارق | L3: القرار
A4: 1 | B4: النورية | C4: 2087 | D4: 2174 | E4: 11 | F4: 9 | G4: 0.45 | H4: 0.0601 | I4: 190 | J4: 242 | K4: 0.27261799 | L4: انقل 1 عامل من الصباح إلى المساء
A5: 2 | B5: عرفات الشوقية | C5: 567 | D5: 702 | E5: 3 | F5: 3 | G5: 0.5 | H5: 0.0529 | I5: 189 | J5: 234 | K5: 0.2366361 | L5: الفجوة أقل من عامل — عالجها بمواعيد الدخول لا بالعدد
A6: 3 | B6: المعيصم | C6: 429 | D6: 435 | E6: 2 | F6: 2 | G6: 0.5 | H6: 0.0036 | I6: 214 | J6: 218 | K6: 0.014504432 | L6: الفجوة أقل من عامل — عالجها بمواعيد الدخول لا بالعدد
A7: 4 | B7: الفردوس | C7: 356 | D7: 434 | E7: 2 | F7: 2 | G7: 0.5 | H7: 0.0489 | I7: 178 | J7: 217 | K7: 0.21680337 | L7: الفجوة أقل من عامل — عالجها بمواعيد الدخول لا بالعدد
A8: 5 | B8: عرفات الشرائع | C8: 194 | D8: 249 | E8: 2 | F8: 2 | G8: 0.5 | H8: 0.061 | I8: 97 | J8: 124 | K8: 0.27790433 | L8: الفجوة أقل من عامل — عالجها بمواعيد الدخول لا بالعدد
B10: ما تقوله الأرقام
C11: • عامل المساء يخدم ٢٢–٢٨٪ زيارات أكثر من عامل الصباح في أربع محطات من خمس
C12: • السبب أن العمالة موزّعة ٥٠/٥٠ بينما الطلب المسائي ٥٥–٥٦٪ من الزيارات
C13: • المعيصم وحدها متوازنة — لأن ذروتها ٥ إلى ٧ مساءً لا بعد التاسعة
B15: لماذا يهم هذا في نموذج الحافز
C16: • خط أساس موحّد لكل العمال يظلم عامل المساء ويكافئ عامل الصباح على أقل جهد
C17: • لذلك يُشتق خط الأساس من حصة الوردية الفعلية — لا من متوسط المحطة
C18: • الاشتقاق يجعل ٥٪ نمو تعني الجهد نفسه على الورديتين
B20: حدود ما يمكن تنفيذه
C21: • النورية وحدها فيها عمالة تكفي لنقل عامل كامل (٢٠ عاملاً على المضخات)
C22: • بقية المحطات فجوتها أقل من عامل — الحل تعديل مواعيد الدخول لا زيادة العدد
C23: • تكديس الورديات بين ٨ و١٠ مساءً يغطي الذروة دون تكلفة إضافية

Sheet بيانات الورديات
A1: بيانات المحطات المرجعية
A2: من تقرير المطابقة التشغيلية — يناير إلى يوليو ٢٠٢٦ (٢١٢ يوماً فعلياً)
A3: # | B3: المحطة | C3: لتر/زيارة | D3: زيارات/يوم | E3: عمال صباحية | F3: عمال مسائية | G3: حصة الصباح | H3: حصة المساء | I3: ساعات الذروة | J3: الطاقم المعياري | K3: الفعلي | L3: الكود | M3: اسم المقياس | N3: العقد | O3: المضخات | Q3: الورديات | R3: بوابة الجودة
A4: 1 | B4: النورية | C4: 30.56 | D4: 4261 | E4: 11 | F4: 9 | G4: 0.4899 | H4: 0.5101 | I4: 17:00 · 21:00 · 22:00 | J4: 32 | K4: 34 | L4: MK007 | M4: العمرة | N4: ايجار | O4: 18 | Q4: صباحية | R4: مستوفاة
A5: 2 | B5: عرفات الشوقية | C5: 21.07 | D5: 1269 | E5: 3 | F5: 3 | G5: 0.4471 | H5: 0.5529 | I5: 17:00 · 21:00 · 22:00 | J5: 9 | K5: 9 | L5: MK017 | M5: عرفات الشوقية | N5: ايجار | O5: 9 | Q5: مسائية | R5: غير مستوفاة
A6: 3 | B6: المعيصم | C6: 20.99 | D6: 864 | E6: 2 | F6: 2 | G6: 0.4964 | H6: 0.5036 | I6: 17:00 · 18:00 · 19:00 | J6: 7 | K6: 8 | L6: MK002 | M6: المعيصم | N6: ايجار | O6: 10
A7: 4 | B7: الفردوس | C7: 20.01 | D7: 790 | E7: 2 | F7: 2 | G7: 0.4511 | H7: 0.5489 | I7: 17:00 · 21:00 · 22:00 | J7: 7 | K7: 7 | L7: MK023 | M7: بن درويش | N7: تشغيل | O7: 4
A8: 5 | B8: عرفات الشرائع | C8: 23.16 | D8: 443 | E8: 2 | F8: 2 | G8: 0.439 | H8: 0.561 | I8: 17:00 · 21:00 · 22:00 | J8: 5 | K8: 6 | L8: MK019 | M8: عرفات الشرائع | N8: ايجار | O8: 6
B10: «حصة الصباح/المساء» من عدد الزيارات الفعلي — الوردية الصباحية ٦ ص إلى ٦ م والمسائية ٦ م إلى ٦ ص
B11: «اسم المقياس» هو الاسم المستخدم في ملف العمالة — يختلف عن اسم السجل في محطتين
